Workbook
Name ANT: ' Vendedores P2P'!#REF!
Name SegmentaciónDeDatos_Año: #REF!
Name SegmentaciónDeDatos_Mes1: #REF!
Name ANTP: ' Vendedores P2P'!$V$2:$AC$41
Name SegmentaciónDeDatos_MES: #REF!
Name SegmentaciónDeDatos_Año1: #REF!
Name antR: 'Vendedores Reno'!$V$2:$AE$39
Name SlicerCache_Table_1_Col_1: #N/A
Name SlicerCache_Table_1_Col_2: #N/A
Name SlicerCache_Table_2_Col_1: #N/A
Name SlicerCache_Table_2_Col_2: #N/A

Sheet Hoja9

Sheet Vendedores Reno
B1: JUNIO | L1: MAYO | V1: 1 | W1: 2 | X1: 3 | Y1: 4 | Z1: 5 | AA1: 6 | AB1: 7 | AC1: 8 | AD1: 9 | AE1: 11
A2: Supervisor | B2: Asesores | C2: Contacto Real | D2: X diario Contacto Real | E2: Ventas Moviles Ingresadas | F2: Total Renov. Fact | G2: Total FACT Movil | H2: Fijo Instalado | I2: RGU Inst | J2: Tasa de cierre Movl | K2: QRT x Ventas Fact | L2: Contacto Real | M2: Ventas Moviles Ingresadas | N2: Total Renov. Fact | O2: Total FACT Movil | P2: Fijo Instalado | Q2: RGU Inst | R2: Tasa de cierre Movl | S2: QRT x Ventas Fact | V2: Asesores | W2: Contacto Real | X2: Ventas Moviles Ingresadas | Y2: Total Renov. Fact | Z2: Fijo Instalado | AA2: RGU Inst | AB2: FACT Movil | AC2: Tasa de Cierre Movil | AD2: MCR | AE2: QRT x Ventas Fact
A3: Jonathan Ortega | B3: Roderick Tack | C3: 838 | D3: =C3/25 -> 33.52 | E3: 70 | F3: 50 | G3: 56 | H3: 2 | I3: 4 | J3: 0.08353222 | K3: 1 | L3: =VLOOKUP($B3,antR,2,1) -> 557 | M3: =VLOOKUP($B3,antR,3,1) -> 50 | N3: =VLOOKUP($B3,antR,4,1) -> 39 | O3: =VLOOKUP($B3,antR,7,1) -> 0 | P3: =VLOOKUP($B3,antR,5,1) -> 41 | Q3: =VLOOKUP($B3,antR,6,1) -> 0 | R3: =VLOOKUP($B3,antR,8,1) -> 0.070017953 | S3: =VLOOKUP($B3,antR,10,1) -> 2 | V3: Alma Rosa Delago Garcia | W3: 873 | X3: 71 | Y3: 53 | Z3: 55 | AA3: 1 | AB3: 3 | AC3: =Y3/W3 -> 0.060710195 | AD3: 22.944444 | AE3: 1
A4: Manuel Garcia | B4: Alma Rosa Delago Garcia | C4: 780 | D4: =C4/25 -> 31.2 | E4: 63 | F4: 55 | G4: 59 | H4: 1 | I4: 3 | J4: 0.080769231 | K4: 3 | L4: =VLOOKUP($B4,antR,2,1) -> 873 | M4: =VLOOKUP($B4,antR,3,1) -> 71 | N4: =VLOOKUP($B4,antR,4,1) -> 53 | O4: =VLOOKUP($B4,antR,7,1) -> 3 | P4: =VLOOKUP($B4,antR,5,1) -> 55 | Q4: =VLOOKUP($B4,antR,6,1) -> 1 | R4: =VLOOKUP($B4,antR,8,1) -> 0.060710195 | S4: =VLOOKUP($B4,antR,10,1) -> 1 | V4: Yosuany Muñoz | W4: 606 | X4: 59 | Y4: 60 | Z4: 60 | AA4: 1 | AB4: 3 | AC4: =Y4/W4 -> 0.099009901 | AD4: 23.153846 | AE4: 1
A5: Manuel Garcia | B5: Ronaldo Rivera | C5: 556 | D5: =C5/25 -> 22.24 | E5: 57 | F5: 45 | G5: 47 | H5: 1 | I5: 3 | J5: 0.10251799 | K5: 4 | L5: =VLOOKUP($B5,antR,2,1) -> 1570 | M5: =VLOOKUP($B5,antR,3,1) -> 42 | N5: =VLOOKUP($B5,antR,4,1) -> 47 | O5: =VLOOKUP($B5,antR,7,1) -> 0 | P5: =VLOOKUP($B5,antR,5,1) -> 48 | Q5: =VLOOKUP($B5,antR,6,1) -> 0 | R5: =VLOOKUP($B5,antR,8,1) -> 0.029936306 | S5: =VLOOKUP($B5,antR,10,1) -> 2 | V5: Cristian Vega | W5: 326 | X5: 58 | Y5: 46 | Z5: 50 | AA5: 2 | AB5: 5 | AC5: =Y5/W5 -> 0.14110429 | AD5: 25.14 | AE5: 1
A6: Jonathan Ortega | B6: Ariadna Vasquez | C6: 1454 | D6: =C6/25 -> 58.16 | E6: 50 | F6: 44 | G6: 44 | H6: 1 | I6: 3 | J6: 0.034387895 | K6: 1 | L6: =VLOOKUP($B6,antR,2,1) -> 873 | M6: =VLOOKUP($B6,antR,3,1) -> 71 | N6: =VLOOKUP($B6,antR,4,1) -> 53 | O6: =VLOOKUP($B6,antR,7,1) -> 3 | P6: =VLOOKUP($B6,antR,5,1) -> 55 | Q6: =VLOOKUP($B6,antR,6,1) -> 1 | R6: =VLOOKUP($B6,antR,8,1) -> 0.060710195 | S6: =VLOOKUP($B6,antR,10,1) -> 1 | V6: Roderick Tack | W6: 0 | X6: 57 | Y6: 45 | Z6: 46 | AA6: 0 | AB6: 0 | AC6: =Y6/W6 -> #DIV/0! | AD6: 23.058824 | AE6: 1
A7: Manuel Garcia | B7: Emanuel Velez | C7: 379 | D7: =C7/25 -> 15.16 | E7: 50 | F7: 42 | G7: 43 | H7: 2 | I7: 6 | J7: 0.13192612 | K7: 4 | L7: =VLOOKUP($B7,antR,2,1) -> 873 | M7: =VLOOKUP($B7,antR,3,1) -> 71 | N7: =VLOOKUP($B7,antR,4,1) -> 53 | O7: =VLOOKUP($B7,antR,7,1) -> 3 | P7: =VLOOKUP($B7,antR,5,1) -> 55 | Q7: =VLOOKUP($B7,antR,6,1) -> 1 | R7: =VLOOKUP($B7,antR,8,1) -> 0.060710195 | S7: =VLOOKUP($B7,antR,10,1) -> 1 | V7: Valentina Ochoa | W7: 568 | X7: 51 | Y7: 40 | Z7: 42 | AA7: 1 | AB7: 3 | AC7: =Y7/W7 -> 0.070422535 | AD7: 22.595745 | AE7: 1
A8: Manuel Garcia | B8: Yosuany Muñoz | C8: 706 | D8: =C8/25 -> 28.24 | E8: 50 | F8: 42 | G8: 42 | H8: 0 | I8: 0 | J8: 0.07082153 | K8: 3 | L8: =VLOOKUP($B8,antR,2,1) -> 1182 | M8: =VLOOKUP($B8,antR,3,1) -> 22 | N8: =VLOOKUP($B8,antR,4,1) -> 23 | O8: =VLOOKUP($B8,antR,7,1) -> 2 | P8: =VLOOKUP($B8,antR,5,1) -> 23 | Q8: =VLOOKUP($B8,antR,6,1) -> 1 | R8: =VLOOKUP($B8,antR,8,1) -> 0.019458545 | S8: =VLOOKUP($B8,antR,10,1) -> 4 | V8: Josue Vasquez | W8: 557 | X8: 50 | Y8: 39 | Z8: 41 | AA8: 0 | AB8: 0 | AC8: =Y8/W8 -> 0.070017953 | AD8: 22.690476 | AE8: 2
A9: Manuel Garcia | B9: Yadira Isabel Fajardo Gil | C9: 700 | D9: =C9/25 -> 28 | E9: 50 | F9: 41 | G9: 42 | H9: 0 | I9: 0 | J9: 0.071428571 | K9: 4 | L9: =VLOOKUP($B9,antR,2,1) -> 1182 | M9: =VLOOKUP($B9,antR,3,1) -> 22 | N9: =VLOOKUP($B9,antR,4,1) -> 23 | O9: =VLOOKUP($B9,antR,7,1) -> 2 | P9: =VLOOKUP($B9,antR,5,1) -> 23 | Q9: =VLOOKUP($B9,antR,6,1) -> 1 | R9: =VLOOKUP($B9,antR,8,1) -> 0.019458545 | S9: =VLOOKUP($B9,antR,10,1) -> 4 | V9: Yadira Isabel Fajardo Gil | W9: 658 | X9: 49 | Y9: 58 | Z9: 60 | AA9: 1 | AB9: 3 | AC9: =Y9/W9 -> 0.088145897 | AD9: 24.266667 | AE9: 1
A10: Jonathan Ortega | B10: Gladis Peralta | C10: 1185 | D10: =C10/25 -> 47.4 | E10: 49 | F10: 38 | G10: 42 | H10: 2 | I10: 4 | J10: 0.041350211 | K10: 1 | L10: =VLOOKUP($B10,antR,2,1) -> 873 | M10: =VLOOKUP($B10,antR,3,1) -> 71 | N10: =VLOOKUP($B10,antR,4,1) -> 53 | O10: =VLOOKUP($B10,antR,7,1) -> 3 | P10: =VLOOKUP($B10,antR,5,1) -> 55 | Q10: =VLOOKUP($B10,antR,6,1) -> 1 | R10: =VLOOKUP($B10,antR,8,1) -> 0.060710195 | S10: =VLOOKUP($B10,antR,10,1) -> 1 | V10: Ariadna Vasquez | W10: 1315 | X10: 46 | Y10: 44 | Z10: 45 | AA10: 1 | AB10: 3 | AC10: =Y10/W10 -> 0.033460076 | AD10: 25.25 | AE10: 1
A11: Jonathan Ortega | B11: Yeimy Caicedo | C11: 777 | D11: =C11/25 -> 31.08 | E11: 49 | F11: 30 | G11: 30 | H11: 0 | I11: 0 | J11: 0.063063063 | K11: 2 | L11: =VLOOKUP($B11,antR,2,1) -> 1182 | M11: =VLOOKUP($B11,antR,3,1) -> 22 | N11: =VLOOKUP($B11,antR,4,1) -> 23 | O11: =VLOOKUP($B11,antR,7,1) -> 2 | P11: =VLOOKUP($B11,antR,5,1) -> 23 | Q11: =VLOOKUP($B11,antR,6,1) -> 1 | R11: =VLOOKUP($B11,antR,8,1) -> 0.019458545 | S11: =VLOOKUP($B11,antR,10,1) -> 4 | V11: Ronaldo Rivera | W11: 407 | X11: 46 | Y11: 45 | Z11: 45 | AA11: 1 | AB11: 3 | AC11: =Y11/W11 -> 0.11056511 | AD11: 23.512195 | AE11: 2
A12: Manuel Garcia | B12: Abdiel Alberto Vanega Simpson | C12: 1224 | D12: =C12/25 -> 48.96 | E12: 49 | F12: 40 | G12: 42 | H12: 1 | I12: 3 | J12: 0.04003268 | K12: 4 | L12: =VLOOKUP($B12,antR,2,1) -> #N/A | M12: =VLOOKUP($B12,antR,3,1) -> #N/A | N12: =VLOOKUP($B12,antR,4,1) -> #N/A | O12: =VLOOKUP($B12,antR,7,1) -> #N/A | P12: =VLOOKUP($B12,antR,5,1) -> #N/A | Q12: =VLOOKUP($B12,antR,6,1) -> #N/A | R12: =VLOOKUP($B12,antR,8,1) -> #N/A | S12: =VLOOKUP($B12,antR,10,1) -> #N/A | V12: Roberto Palacios | W12: 0 | X12: 44 | Y12: 35 | Z12: 35 | AA12: 0 | AB12: 0 | AC12: =Y12/W12 -> #DIV/0! | AD12: 23.897436 | AE12: 2
A13: Manuel Garcia | B13: Sanneth Soberon | C13: 1231 | D13: =C13/25 -> 49.24 | E13: 47 | F13: 39 | G13: 40 | H13: 1 | I13: 3 | J13: 0.038180341 | K13: 4 | L13: =VLOOKUP($B13,antR,2,1) -> 1570 | M13: =VLOOKUP($B13,antR,3,1) -> 42 | N13: =VLOOKUP($B13,antR,4,1) -> 47 | O13: =VLOOKUP($B13,antR,7,1) -> 0 | P13: =VLOOKUP($B13,antR,5,1) -> 48 | Q13: =VLOOKUP($B13,antR,6,1) -> 0 | R13: =VLOOKUP($B13,antR,8,1) -> 0.029936306 | S13: =VLOOKUP($B13,antR,10,1) -> 2 | V13: Amarilis Ramos | W13: 1261 | X13: 43 | Y13: 41 | Z13: 41 | AA13: 2 | AB13: 5 | AC13: =Y13/W13 -> 0.032513878 | AD13: 24.769231 | AE13: 2
A14: Jonathan Ortega | B14: Lerys Ariana Barrios Chacon | C14: 555 | D14: =C14/25 -> 22.2 | E14: 43 | F14: 34 | G14: 39 | H14: 0 | I14: 0 | J14: 0.077477477 | K14: 2 | L14: =VLOOKUP($B14,antR,2,1) -> 873 | M14: =VLOOKUP($B14,antR,3,1) -> 71 | N14: =VLOOKUP($B14,antR,4,1) -> 53 | O14: =VLOOKUP($B14,antR,7,1) -> 3 | P14: =VLOOKUP($B14,antR,5,1) -> 55 | Q14: =VLOOKUP($B14,antR,6,1) -> 1 | R14: =VLOOKUP($B14,antR,8,1) -> 0.060710195 | S14: =VLOOKUP($B14,antR,10,1) -> 1 | V14: Ashley Sanchez | W14: 1570 | X14: 42 | Y14: 47 | Z14: 48 | AA14: 0 | AB14: 0 | AC14: =Y14/W14 -> 0.029936306 | AD14: 24.025 | AE14: 2
... A39: Jonathan Ortega | B39: Alexander Jonathan Coley Ortega | C39: 154 | D39: =C39/25 -> 6.16 | E39: 14 | F39: 15 | G39: 15 | H39: 0 | I39: 0 | J39: 0.090909091 | K39: 4 | L39: =VLOOKUP($B39,antR,2,1) -> #N/A | M39: =VLOOKUP($B39,antR,3,1) -> #N/A | N39: =VLOOKUP($B39,antR,4,1) -> #N/A | O39: =VLOOKUP($B39,antR,7,1) -> #N/A | P39: =VLOOKUP($B39,antR,5,1) -> #N/A | Q39: =VLOOKUP($B39,antR,6,1) -> #N/A | R39: =VLOOKUP($B39,antR,8,1) -> #N/A | S39: =VLOOKUP($B39,antR,10,1) -> #N/A | V39: Yuleymi Pulgarin | W39: 369 | X39: 16 | Y39: 19 | Z39: 20 | AA39: 0 | AB39: 0 | AC39: =Y39/W39 -> 0.051490515 | AD39: 26 | AE39: 4
A40: Manuel Garcia | B40: Miguel Ángel Flores | C40: 458 | D40: =C40/25 -> 18.32 | E40: 12 | F40: 11 | G40: 11 | H40: 0 | I40: 0 | J40: 0.026200873 | K40: 4 | L40: =VLOOKUP($B40,antR,2,1) -> 873 | M40: =VLOOKUP($B40,antR,3,1) -> 71 | N40: =VLOOKUP($B40,antR,4,1) -> 53 | O40: =VLOOKUP($B40,antR,7,1) -> 3 | P40: =VLOOKUP($B40,antR,5,1) -> 55 | Q40: =VLOOKUP($B40,antR,6,1) -> 1 | R40: =VLOOKUP($B40,antR,8,1) -> 0.060710195 | S40: =VLOOKUP($B40,antR,10,1) -> 1
A41: Manuel Garcia | B41: Kamaris Rogers | C41: 0 | D41: =C41/25 -> 0 | E41: 3 | F41: 1 | G41: 1 | H41: 0 | I41: 0 | J41: 0 | K41: 4 | L41: =VLOOKUP($B41,antR,2,1) -> 873 | M41: =VLOOKUP($B41,antR,3,1) -> 71 | N41: =VLOOKUP($B41,antR,4,1) -> 53 | O41: =VLOOKUP($B41,antR,7,1) -> 3 | P41: =VLOOKUP($B41,antR,5,1) -> 55 | Q41: =VLOOKUP($B41,antR,6,1) -> 1 | R41: =VLOOKUP($B41,antR,8,1) -> 0.060710195 | S41: =VLOOKUP($B41,antR,10,1) -> 1

Sheet  Vendedores P2P
V1: 1 | W1: 2 | X1: 3 | Y1: 4 | Z1: 5 | AA1: 6 | AB1: 7 | AC1: 8
A2: Supervisor | B2: Vendedor | C2: Contacto Real | D2: X Contacto Real diario | E2: Ventas Moviles Ingresadas | F2: FACT Movil | G2: Fijo Instalado | H2: RGU Inst | I2: Tasa de cierre | J2: QRT x Ventas Fact | K2: Contacto Real | L2: Ventas Moviles Ingresadas | M2: Total FACT Movil | N2: Fijo Instalado | O2: RGU Inst | P2: Tasa de cierre Movl | Q2: QRT x Ventas Fact | V2: Asesores | W2: Contacto Real | X2: Ventas Moviles Ingresadas | Y2: FACT Movil | Z2: Fijo Instalado | AA2: RGU Inst | AB2: Tasa de cierre | AC2: QRT x Ventas Fact
A3: Lizeth Gonzalez | B3: Rose Cedeño | C3: 1503 | D3: =C3/25 -> 60.12 | E3: 63 | F3: 61 | G3: 2 | H3: 3 | I3: 0.041916168 | J3: 1 | K3: =VLOOKUP($B3,ANTP,2,0) -> 1652 | L3: =VLOOKUP($B3,ANTP,3,0) -> 53 | M3: =VLOOKUP($B3,ANTP,4,0) -> 52 | N3: =VLOOKUP($B3,ANTP,5,0) -> 3 | O3: =VLOOKUP($B3,ANTP,6,0) -> 5 | P3: =VLOOKUP($B3,ANTP,7,0) -> 0.032082324 | Q3: =VLOOKUP($B3,ANTP,8,0) -> 1 | V3: Rose Cedeño | W3: 1652 | X3: 53 | Y3: 52 | Z3: 3 | AA3: 5 | AB3: =X3/W3 -> 0.032082324 | AC3: 1
A4: Lizeth Gonzalez | B4: Rafael Alejandro Jordan Garrido | C4: 1299 | D4: =C4/25 -> 51.96 | E4: 52 | F4: 51 | G4: 1 | H4: 3 | I4: 0.040030793 | J4: 1 | K4: =VLOOKUP($B4,ANTP,2,0) -> 1115 | L4: =VLOOKUP($B4,ANTP,3,0) -> 22 | M4: =VLOOKUP($B4,ANTP,4,0) -> 21 | N4: =VLOOKUP($B4,ANTP,5,0) -> 1 | O4: =VLOOKUP($B4,ANTP,6,0) -> 3 | P4: =VLOOKUP($B4,ANTP,7,0) -> 0.019730942 | Q4: =VLOOKUP($B4,ANTP,8,0) -> 3 | V4: Jesus Grant | W4: 192 | X4: 51 | Y4: 47 | Z4: 2 | AA4: 6 | AB4: =X4/W4 -> 0.265625 | AC4: 1
A5: Lizeth Gonzalez | B5: Gustavo Carrión | C5: 227 | D5: =C5/25 -> 9.08 | E5: 51 | F5: 51 | G5: 7 | H5: 14 | I5: 0.2246696 | J5: 1 | K5: =VLOOKUP($B5,ANTP,2,0) -> 446 | L5: =VLOOKUP($B5,ANTP,3,0) -> 27 | M5: =VLOOKUP($B5,ANTP,4,0) -> 24 | N5: =VLOOKUP($B5,ANTP,5,0) -> 4 | O5: =VLOOKUP($B5,ANTP,6,0) -> 11 | P5: =VLOOKUP($B5,ANTP,7,0) -> 0.060538117 | Q5: =VLOOKUP($B5,ANTP,8,0) -> 2 | V5: Jose Luis Reyes | W5: 1454 | X5: 48 | Y5: 40 | Z5: 1 | AA5: 3 | AB5: =X5/W5 -> 0.03301238 | AC5: 1
A6: Lizeth Gonzalez | B6: Viviana Sarria | C6: 487 | D6: =C6/25 -> 19.48 | E6: 49 | F6: 46 | G6: 5 | H6: 13 | I6: 0.10061602 | J6: 1 | K6: =VLOOKUP($B6,ANTP,2,0) -> 255 | L6: =VLOOKUP($B6,ANTP,3,0) -> 8 | M6: =VLOOKUP($B6,ANTP,4,0) -> 7 | N6: =VLOOKUP($B6,ANTP,5,0) -> 1 | O6: =VLOOKUP($B6,ANTP,6,0) -> 3 | P6: =VLOOKUP($B6,ANTP,7,0) -> 0.031372549 | Q6: =VLOOKUP($B6,ANTP,8,0) -> 4 | V6: Erika White | W6: 807 | X6: 41 | Y6: 40 | Z6: 2 | AA6: 3 | AB6: =X6/W6 -> 0.050805452 | AC6: 1
A7: Lizeth Gonzalez | B7: Roberto Valdiviezo | C7: 1195 | D7: =C7/25 -> 47.8 | E7: 46 | F7: 44 | G7: 2 | H7: 5 | I7: 0.038493724 | J7: 1 | K7: =VLOOKUP($B7,ANTP,2,0) -> 1189 | L7: =VLOOKUP($B7,ANTP,3,0) -> 33 | M7: =VLOOKUP($B7,ANTP,4,0) -> 32 | N7: =VLOOKUP($B7,ANTP,5,0) -> 3 | O7: =VLOOKUP($B7,ANTP,6,0) -> 7 | P7: =VLOOKUP($B7,ANTP,7,0) -> 0.027754415 | Q7: =VLOOKUP($B7,ANTP,8,0) -> 1 | V7: Roberto Valdiviezo | W7: 1189 | X7: 33 | Y7: 32 | Z7: 3 | AA7: 7 | AB7: =X7/W7 -> 0.027754415 | AC7: 1
A8: Lizeth Gonzalez | B8: Abdiel Espinosa | C8: 1059 | D8: =C8/25 -> 42.36 | E8: 42 | F8: 41 | G8: 2 | H8: 3 | I8: 0.039660057 | J8: 1 | K8: =VLOOKUP($B8,ANTP,2,0) -> 1224 | L8: =VLOOKUP($B8,ANTP,3,0) -> 16 | M8: =VLOOKUP($B8,ANTP,4,0) -> 15 | N8: =VLOOKUP($B8,ANTP,5,0) -> 1 | O8: =VLOOKUP($B8,ANTP,6,0) -> 3 | P8: =VLOOKUP($B8,ANTP,7,0) -> 0.013071895 | Q8: =VLOOKUP($B8,ANTP,8,0) -> 3 | V8: Eloisa Ojo | W8: 726 | X8: 30 | Y8: 29 | Z8: 0 | AA8: 0 | AB8: =X8/W8 -> 0.041322314 | AC8: 1
A9: Lizeth Gonzalez | B9: Erika White | C9: 432 | D9: =C9/25 -> 17.28 | E9: 33 | F9: 30 | G9: 6 | H9: 13 | I9: 0.076388889 | J9: 2 | K9: =VLOOKUP($B9,ANTP,2,0) -> 807 | L9: =VLOOKUP($B9,ANTP,3,0) -> 41 | M9: =VLOOKUP($B9,ANTP,4,0) -> 40 | N9: =VLOOKUP($B9,ANTP,5,0) -> 2 | O9: =VLOOKUP($B9,ANTP,6,0) -> 3 | P9: =VLOOKUP($B9,ANTP,7,0) -> 0.050805452 | Q9: =VLOOKUP($B9,ANTP,8,0) -> 1 | V9: Madelay Castillo | W9: 542 | X9: 29 | Y9: 27 | Z9: 3 | AA9: 8 | AB9: =X9/W9 -> 0.053505535 | AC9: 2
A10: Lizeth Gonzalez | B10: Luis Abdiel Aguilar Pinillo | C10: 529 | D10: =C10/25 -> 21.16 | E10: 25 | F10: 25 | G10: 0 | H10: 0 | I10: 0.047258979 | J10: 3 | K10: =VLOOKUP($B10,ANTP,2,0) -> 956 | L10: =VLOOKUP($B10,ANTP,3,0) -> 9 | M10: =VLOOKUP($B10,ANTP,4,0) -> 9 | N10: =VLOOKUP($B10,ANTP,5,0) -> 0 | O10: =VLOOKUP($B10,ANTP,6,0) -> 0 | P10: =VLOOKUP($B10,ANTP,7,0) -> 0.0094142259 | Q10: =VLOOKUP($B10,ANTP,8,0) -> 4 | V10: Eleuterio Guevara | W10: 1107 | X10: 27 | Y10: 26 | Z10: 2 | AA10: 4 | AB10: =X10/W10 -> 0.024390244 | AC10: 2
A11: Lizeth Gonzalez | B11: Joswer Acosta | C11: 638 | D11: =C11/25 -> 25.52 | E11: 26 | F11: 23 | G11: 2 | H11: 6 | I11: 0.040752351 | J11: 3 | K11: =VLOOKUP($B11,ANTP,2,0) -> 689 | L11: =VLOOKUP($B11,ANTP,3,0) -> 23 | M11: =VLOOKUP($B11,ANTP,4,0) -> 23 | N11: =VLOOKUP($B11,ANTP,5,0) -> 1 | O11: =VLOOKUP($B11,ANTP,6,0) -> 3 | P11: =VLOOKUP($B11,ANTP,7,0) -> 0.033381713 | Q11: =VLOOKUP($B11,ANTP,8,0) -> 3 | V11: Gustavo Carrión | W11: 446 | X11: 27 | Y11: 24 | Z11: 4 | AA11: 11 | AB11: =X11/W11 -> 0.060538117 | AC11: 2
A12: Lizeth Gonzalez | B12: Eleuterio Guevara | C12: 1065 | D12: =C12/25 -> 42.6 | E12: 20 | F12: 18 | G12: 2 | H12: 4 | I12: 0.018779343 | J12: 4 | K12: =VLOOKUP($B12,ANTP,2,0) -> 1107 | L12: =VLOOKUP($B12,ANTP,3,0) -> 27 | M12: =VLOOKUP($B12,ANTP,4,0) -> 26 | N12: =VLOOKUP($B12,ANTP,5,0) -> 2 | O12: =VLOOKUP($B12,ANTP,6,0) -> 4 | P12: =VLOOKUP($B12,ANTP,7,0) -> 0.024390244 | Q12: =VLOOKUP($B12,ANTP,8,0) -> 2 | V12: Alejandra Nuñez | W12: 483 | X12: 27 | Y12: 26 | Z12: 0 | AA12: 0 | AB12: =X12/W12 -> 0.055900621 | AC12: 2
A13: Lizeth Gonzalez | B13: Anays Ellis | C13: 73 | D13: =C13/25 -> 2.92 | E13: 16 | F13: 16 | G13: 6 | H13: 15 | I13: 0.21917808 | J13: 4 | K13: =VLOOKUP($B13,ANTP,2,0) -> 148 | L13: =VLOOKUP($B13,ANTP,3,0) -> 13 | M13: =VLOOKUP($B13,ANTP,4,0) -> 11 | N13: =VLOOKUP($B13,ANTP,5,0) -> 12 | O13: =VLOOKUP($B13,ANTP,6,0) -> 25 | P13: =VLOOKUP($B13,ANTP,7,0) -> 0.087837838 | Q13: =VLOOKUP($B13,ANTP,8,0) -> 3 | V13: Liseth Rangel | W13: 180 | X13: 27 | Y13: 23 | Z13: 0 | AA13: 0 | AB13: =X13/W13 -> 0.15 | AC13: 2
A14: Lizeth Gonzalez | B14: David Gonzalez | C14: 0 | D14: =C14/25 -> 0 | E14: 15 | F14: 13 | G14: 0 | H14: 0 | I14: 0 | J14: 4 | K14: =VLOOKUP($B14,ANTP,2,0) -> #N/A | L14: =VLOOKUP($B14,ANTP,3,0) -> #N/A | M14: =VLOOKUP($B14,ANTP,4,0) -> #N/A | N14: =VLOOKUP($B14,ANTP,5,0) -> #N/A | O14: =VLOOKUP($B14,ANTP,6,0) -> #N/A | P14: =VLOOKUP($B14,ANTP,7,0) -> #N/A | Q14: =VLOOKUP($B14,ANTP,8,0) -> #N/A | V14: Taisha Catillo | W14: 1200 | X14: 26 | Y14: 25 | Z14: 0 | AA14: 0 | AB14: =X14/W14 -> 0.021666667 | AC14: 2
... A36: Maycol Lima | B36: Gina Batista | C36: 513 | D36: =C36/25 -> 20.52 | E36: 5 | F36: 4 | G36: 0 | H36: 0 | I36: 0.0097465887 | J36: 4 | K36: =VLOOKUP($B36,ANTP,2,0) -> #N/A | L36: =VLOOKUP($B36,ANTP,3,0) -> #N/A | M36: =VLOOKUP($B36,ANTP,4,0) -> #N/A | N36: =VLOOKUP($B36,ANTP,5,0) -> #N/A | O36: =VLOOKUP($B36,ANTP,6,0) -> #N/A | P36: =VLOOKUP($B36,ANTP,7,0) -> #N/A | Q36: =VLOOKUP($B36,ANTP,8,0) -> #N/A | V36: Jairo Espino Garcia | W36: 105 | X36: 5 | Y36: 5 | Z36: 0 | AA36: 0 | AB36: =X36/W36 -> 0.047619048 | AC36: 4
B37: Evelyn Torres | C37: 561 | D37: =C37/25 -> 22.44 | E37: 5 | F37: 3 | G37: 0 | H37: 0 | I37: 0.008912656 | J37: 4 | K37: =VLOOKUP($B37,ANTP,2,0) -> #N/A | L37: =VLOOKUP($B37,ANTP,3,0) -> #N/A | M37: =VLOOKUP($B37,ANTP,4,0) -> #N/A | N37: =VLOOKUP($B37,ANTP,5,0) -> #N/A | O37: =VLOOKUP($B37,ANTP,6,0) -> #N/A | P37: =VLOOKUP($B37,ANTP,7,0) -> #N/A | Q37: =VLOOKUP($B37,ANTP,8,0) -> #N/A | V37: Pauleth Pamela Rivera Gale | W37: 0 | X37: 2 | Y37: 2 | Z37: 0 | AA37: 0 | AB37: =X37/W37 -> #DIV/0! | AC37: 4
V38: Bolivar De Gracia | W38: 0 | X38: 0 | Y38: 0 | Z38: 0 | AA38: 0 | AB38: =X38/W38 -> #DIV/0! | AC38: 4
V39: Felix Barrios | W39: 66 | X39: 0 | Y39: 0 | Z39: 0 | AA39: 0 | AB39: =X39/W39 -> 0 | AC39: 4
V40: Jose Javier Velasquez | W40: 44 | X40: 0 | Y40: 0 | Z40: 0 | AA40: 0 | AB40: =X40/W40 -> 0 | AC40: 4
W41: =SUM(W3:W40) -> 24008 | X41: =SUM(X3:X40) -> 754 | Y41: =SUM(Y3:Y40) -> 699 | Z41: =SUM(Z3:Z40) -> 60 | AA41: =SUM(AA3:AA40) -> 152 | AB41: =SUM(AB3:AB40) -> #DIV/0! | AC41: 4

Sheet Renovaciones
F2: Reporte de Seguimiento
B3: 10 | C3: =TODAY() -> 46218
F4: Mes | G4: JULIO | H4: Facturadas a la fecha | I4: 532 | K4: Proyección de Cierre | L4: 1056 | N4: Frunos | Q4: Porcentaje de Cumplimiento | R4: =I4/U4 -> 0.30574713 | T4: Meta | U4: 1740
K5: Variaciòn | L5: =(I4/L4)-1 -> -0.49621212
F6: Comparativo Historicos
F7: Año | G7: MES | H7: Base | I7: Recorrido | J7: %Recorrido | K7: Intentos Totales | L7: Ratio llamadas | M7: Contactado | N7: %Contactado | O7: RPC | P7: %RPC | Q7: Renovación | R7: % Conv Reno | S7: Creadas CLientes Totales Fijo | T7: % Conv Creadas Totales Fijo | U7: Creadas RGU Fijo | V7: % Conv Creadas Fijo | W7: Rgu Fijo Fact | X7: %Conv Fijo | Y7: Rgu Movil Fact | Z7: % Conv Movil | AA7: Total FACT | AB7: % Conversion
F8: 2025 | G8: 46047 | H8: 28260 | I8: 28260 | J8: 100% | K8: 91677 | L8: 3.24 | M8: 26439 | N8: 94% | O8: 26187 | P8: 99% | Q8: 843 | R8: 3.2% | T8: 0.0% | U8: 57 | V8: 0.2% | W8: 51 | X8: 0.2% | Y8: 35 | Z8: 0.1% | AA8: 86 | AB8: 0.3%
F9: 2025 | G9: 45689 | H9: 40200 | I9: 40200 | J9: 100% | K9: 120669 | L9: 3 | M9: 20966 | N9: 52% | O9: 17952 | P9: 86% | Q9: 971 | R9: 4.6% | T9: 0.0% | U9: 90 | V9: 0.4% | W9: 72 | X9: 0.3% | Y9: 37 | Z9: 0.2% | AA9: 109 | AB9: 0.5%
F10: 2025 | G10: 45717 | H10: 34452 | I10: 34452 | J10: 100% | K10: 130356 | L10: 3.78 | M10: 18182 | N10: 53% | O10: 8505 | P10: 47% | Q10: 927 | R10: 5.1% | T10: 0.0% | U10: 60 | V10: 0.3% | W10: 30 | X10: 0.2% | Y10: 34 | Z10: 0.2% | AA10: 64 | AB10: 0.4%
F11: 2025 | G11: 45748 | H11: 44817 | I11: 35738 | J11: 80% | K11: 87097 | L11: 1.94 | M11: 16786 | N11: 47% | O11: 7172 | P11: 43% | Q11: 944 | R11: 5.6% | T11: 0.0% | U11: 156 | V11: 0.9% | W11: 93 | X11: 0.6% | Y11: 92 | Z11: 0.5% | AA11: 185 | AB11: 1.1%
F12: 2025 | G12: 45778 | H12: 46975 | I12: 35421 | J12: 75% | K12: 116270 | L12: 2.48 | M12: 20483 | N12: 58% | O12: 9300 | P12: 45% | Q12: 1561 | R12: 7.6% | T12: 0.0% | U12: 197 | V12: 1.0% | W12: 141 | X12: 0.7% | Y12: 96 | Z12: 0.5% | AA12: 237 | AB12: 1.2%
F13: 2025 | G13: 45809 | H13: 47904 | I13: 47904 | J13: 100% | K13: 101607 | L13: 2.12 | M13: 18279 | N13: 38% | O13: 8094 | P13: 44% | Q13: 1511 | R13: 8.3% | T13: 0.0% | U13: 141 | V13: 0.8% | W13: 129 | X13: 0.7% | Y13: 129 | Z13: 0.7% | AA13: 258 | AB13: 1.4%
F14: 2025 | G14: 45839 | H14: 48708 | I14: 48706 | J14: 100% | K14: 106478 | L14: 2.19 | M14: 22704 | N14: 47% | O14: 10402 | P14: 46% | Q14: 1777 | R14: 7.8% | T14: 0.0% | U14: 138 | V14: 0.6% | W14: 132 | X14: 0.6% | Y14: 118 | Z14: 0.5% | AA14: 250 | AB14: 1.1%
F15: 2025 | G15: 45870 | H15: 54965 | I15: 54922 | J15: 100% | K15: 101233 | L15: 1.84 | M15: 23770 | N15: 43% | O15: 11079 | P15: 47% | Q15: 1401 | R15: 5.9% | S15: 116 | T15: 0.5% | U15: 110 | V15: 0.5% | W15: 95 | X15: 0.4% | Y15: 121 | Z15: 0.5% | AA15: 216 | AB15: 0.9%
F16: 2025 | G16: 45901 | H16: 46516 | I16: 45493 | J16: 98% | K16: 147247 | L16: 3.17 | M16: 20873 | N16: 46% | O16: 11044 | P16: 53% | Q16: 1265 | R16: 6.1% | S16: 124 | T16: 0.6% | U16: 96 | V16: 0.5% | W16: 94 | X16: 0.5% | Y16: 126 | Z16: 0.6% | AA16: 220 | AB16: 1.1%
F17: 2025 | G17: 45931 | H17: 46615 | I17: 46596 | J17: 100% | K17: 100405 | L17: 2.15 | M17: 22625 | N17: 49% | O17: 12046 | P17: 53% | Q17: 1591 | R17: 7.0% | S17: 86 | T17: 0.4% | U17: 79 | V17: 0.3% | W17: 54 | X17: 0.2% | Y17: 69 | Z17: 0.3% | AA17: 123 | AB17: 0.5%
F18: 2025 | G18: 45962 | H18: 41479 | I18: 41469 | J18: 100% | K18: 92966 | L18: 2.24 | M18: 17440 | N18: 42% | O18: 9530 | P18: 55% | Q18: 834 | R18: 4.8% | S18: 25 | T18: 0.1% | U18: 22 | V18: 0.1% | W18: 29 | X18: 0.2% | Y18: 51 | Z18: 0.3% | AA18: 80 | AB18: 0.5%
F19: 2025 | G19: 45992 | H19: 52333 | I19: 52270 | J19: 100% | K19: 140358 | L19: 2.68 | M19: 25083 | N19: 48% | O19: 14644 | P19: 58% | Q19: 1404 | R19: 5.6% | S19: 34 | T19: 0.1% | U19: 21 | V19: 0.1% | W19: 21 | X19: 0.1% | Y19: 87 | Z19: 0.3% | AA19: 108 | AB19: 0.4%
F20: 2026 | G20: 46023 | H20: 42592 | I20: 41439 | J20: 97% | K20: 125289 | L20: 97 | M20: 21315 | N20: 51% | O20: 12337 | P20: 58% | Q20: 1355 | R20: 6.4% | S20: 60 | T20: 0.3% | U20: 42 | V20: 0.2% | W20: 33 | X20: 0.2% | Y20: 27 | Z20: 0.1% | AA20: 60 | AB20: 0.3%
F21: 2026 | G21: 46054 | H21: 40300 | I21: 37206 | J21: 92% | K21: 153667 | L21: 3.81 | M21: 19826 | N21: 53% | O21: 11990 | P21: 60% | Q21: 1072 | R21: 5.4% | S21: 74 | T21: 0.4% | U21: 71 | V21: 0.4% | W21: 71 | X21: 0.4% | Y21: 75 | Z21: 0.4% | AA21: 146 | AB21: 0.7%
F22: 2026 | G22: 46082 | H22: 49533 | I22: 49516 | J22: =Renovaciones!$I22/Renovaciones!$H22 -> 0.99965679 | K22: 205028 | L22: =Renovaciones!$K22/Renovaciones!$H22 -> 4.1392203 | M22: 22163 | N22: =Renovaciones!$M22/Renovaciones!$I22 -> 0.4475927 | O22: 12194 | P22: =Renovaciones!$O22/Renovaciones!$M22 -> 0.55019627 | Q22: 1210 | R22: =Renovaciones!$Q22/Renovaciones!$M22 -> 0.054595497 | S22: 30 | T22: =Renovaciones!$S22/Renovaciones!$M22 -> 0.0013536074 | U22: 26 | V22: =Renovaciones!$S22/Renovaciones!$M22 -> 0.0013536074 | W22: 62 | X22: =Renovaciones!$S22/Renovaciones!$M22 -> 0.0013536074 | Y22: 58 | Z22: =Renovaciones!$Y22/Renovaciones!$M22 -> 0.0026169742 | AA22: =Renovaciones!$Y22+Renovaciones!$W22 -> 120 | AB22: =Renovaciones!$AA22/Renovaciones!$M22 -> 0.0054144295
F23: 2026 | G23: 46113 | H23: 48829 | I23: 47984 | J23: =Renovaciones!$I23/Renovaciones!$H23 -> 0.98269471 | K23: 154619 | L23: =Renovaciones!$K23/Renovaciones!$I23 -> 3.2223033 | M23: 22837 | N23: =Renovaciones!$M23/Renovaciones!$I23 -> 0.47592948 | O23: 11345 | P23: =Renovaciones!$O23/Renovaciones!$M23 -> 0.49678154 | Q23: 1162 | R23: =Renovaciones!$Q23/Renovaciones!$M23 -> 0.05088234 | S23: 38 | T23: =Renovaciones!$S23/Renovaciones!$M23 -> 0.0016639664 | U23: 36 | V23: =Renovaciones!$U23/Renovaciones!$M23 -> 0.0015763892 | W23: 86 | X23: =Renovaciones!$W23/Renovaciones!$M23 -> 0.0037658186 | Y23: 53 | Z23: =Renovaciones!$Y23/Renovaciones!$M23 -> 0.0023207952 | AA23: =Renovaciones!$Y23+Renovaciones!$W23 -> 139 | AB23: =Renovaciones!$AA23/Renovaciones!$M23 -> 0.0060866138
F24: 2026 | G24: 46144 | H24: 54537 | I24: 54518 | J24: =Renovaciones!$I24/Renovaciones!$H24 -> 0.99965161 | K24: 171149 | L24: =Renovaciones!$K24/Renovaciones!$I24 -> 3.1393118 | M24: 27581 | N24: =Renovaciones!$M24/Renovaciones!$I24 -> 0.50590631 | O24: 16804 | P24: =Renovaciones!$O24/Renovaciones!$M24 -> 0.60926 | Q24: =J40+G40 -> 532 | R24: =Renovaciones!$Q24/Renovaciones!$M24 -> 0.019288641 | S24: 43 | T24: =Renovaciones!$S24/Renovaciones!$M24 -> 0.0015590443 | U24: 40 | V24: =Renovaciones!$U24/Renovaciones!$M24 -> 0.0014502737 | W24: 104 | X24: =Renovaciones!$W24/Renovaciones!$M24 -> 0.0037707117 | Y24: 27 | Z24: =Renovaciones!$Y24/Renovaciones!$M24 -> 0.00097893477 | AA24: =Renovaciones!$Y24+Renovaciones!$W24 -> 131 | AB24: =Renovaciones!$AA24/Renovaciones!$M24 -> 0.0047496465
F25: 2026 | G25: 46176 | H25: 55530 | I25: 55530 | J25: =Renovaciones!$I25/Renovaciones!$H25 -> 1 | K25: 213950 | L25: =Renovaciones!$K25/Renovaciones!$H25 -> 3.8528723 | M25: 28778 | N25: =Renovaciones!$M25/Renovaciones!$I25 -> 0.51824239 | O25: 18778 | P25: =Renovaciones!$O25/Renovaciones!$M25 -> 0.65251234 | Q25: 1164 | R25: =Renovaciones!$Q25/Renovaciones!$M25 -> 0.040447564 | S25: 47 | U25: 125 | V25: =Renovaciones!$U25/Renovaciones!$M25 -> 0.0043435958 | W25: 98 | X25: =Renovaciones!$S25/Renovaciones!$M25 -> 0.001633192 | Y25: 48 | Z25: =Renovaciones!$Y25/Renovaciones!$M25 -> 0.0016679408 | AA25: =Renovaciones!$Y25+Renovaciones!$W25+Renovaciones!$Q25 -> 1310 | AB25: =Renovaciones!$AA25/Renovaciones!$M25 -> 0.045520884
F26: 2026 | G26: 46229 | H26: 51956 | I26: 51956 | J26: =I26/H26 -> 1 | K26: 95819 | L26: =K26/I26 -> 1.8442336 | M26: 14386 | N26: =M26/I26 -> 0.27688814 | O26: 8705 | P26: =O26/M26 -> 0.60510218 | Q26: 532 | R26: =Q26/I26 -> 0.010239433 | S26: 20 | T26: =S26/I26 -> 0.0003849411 | U26: 48 | V26: =U26/I26 -> 0.00092385865 | W26: 42 | X26: =W26/I26 -> 0.00080837632 | Y26: 20 | Z26: =Y26/I26 -> 0.0003849411 | AA26: =Y26+W26 -> 62 | AB26: =W26/I26 -> 0.00080837632
F28: Comportamiento Base Actual
F30: Renovaciones
F31: Base de datos | G31: 51956 | I31: Base de datos
F32: BD Recorrida | G32: 51956 | I32: BD Recorrida
F33: % de Recorrido | G33: =G32/G31 -> 1 | I33: % de Recorrido
F34: Marcaciones | G34: 95819 | I34: Marcaciones
F35: Ratio de Llamadas | G35: =G34/G31 -> 1.8442336 | I35: Ratio de Llamadas
F36: Contactos | G36: 14386 | I36: Contactos
F37: % Contacto | G37: =G36/G32 -> 0.27688814 | I37: % Contacto
F38: RPC | G38: 8705 | I38: RPC
F39: % RPC | G39: =G38/G36 -> 0.60510218 | I39: % RPC
F40: Total de Ventas Fact | G40: 532 | I40: Total de Ventas
F41: Tasa de Cierre | G41: =G40/G32 -> 0.010239433 | I41: Tasa de Cierre
F43: Arrastre | G43: =I4-G40 -> 0 | I43: Arrastre | J43: =Q25-G40-J40 -> 632
E46: JUNIO | P46: MES ANTERIOR
...

Sheet Hoja2

Sheet P2P
B2: Act | C2: =TODAY() -> 46218 | F2: Reporte de Seguimiento
J4: MOVIL TOTAL
F5: Mes | G5: JUNIO | I5: Movil Facturadas a la fecha | J5: 1012 | M5: Proyección de Cierre | N5: 1060 | P5: Porcentaje de cumplimiento | Q5: =J5/T5 -> 0.8877193 | S5: Meta | T5: 1140
I6: Incluye Venta cruzada de renov | M6: Variaciòn | N6: =J5/N5-1 -> -0.045283019
F7: Comparativo Historicos
F8: Año | G8: Mes | H8: Base | I8: Recorrido | J8: %Recorrido | K8: Intentos Totales | L8: Ratio llamadas | M8: Contactado | N8: %Contactado | O8: RPC | P8: %RPC | Q8: Renovación | R8: % Conv Reno | S8: Creadas Clientes Totales Fijo | T8: % Conv Creadas Totales Fijo | U8: FACTURADAS Fijo | V8: % Conv FACT Fijo | W8: Rgu Fijo Fact | X8: %Conv Fijo RGU | Y8: Rgu Movil Fact | Z8: % Conv Movil | AA8: Total FACT | AB8: % Conv Total
F9: 2025 | G9: 45778 | H9: 8000 | I9: 8000 | J9: 100% | K9: 23971 | L9: 3 | M9: 2934 | N9: 0.37 | O9: 804 | P9: 27% | Q9: 0 | R9: 0.0% | T9: 0.0% | U9: 113 | V9: 3.9% | W9: 76 | X9: 2.6% | Y9: 127 | Z9: 4.3% | AA9: 203 | AB9: =P2P!$AA9/P2P!$M9 -> 0.069188821
F10: 2025 | G10: 45809 | H10: 15000 | I10: 15000 | J10: 100% | K10: 30472 | L10: 2.03 | M10: 6534 | N10: 44% | O10: 2164 | P10: 33% | Q10: 0 | R10: 0.0% | T10: 0.0% | U10: 212 | V10: 3.2% | W10: 179 | X10: 2.7% | Y10: 329 | Z10: 5.0% | AA10: 508 | AB10: =P2P!$AA10/P2P!$M10 -> 0.077747169
F11: 2025 | G11: 45839 | H11: 15000 | I11: 15000 | J11: 100% | K11: 46285 | L11: 3.09 | M11: 8808 | N11: 59% | O11: 2832 | P11: 32% | Q11: 0 | R11: 0.0% | T11: 0.0% | U11: 126 | V11: 1.4% | W11: 135 | X11: 1.5% | Y11: 500 | Z11: 5.7% | AA11: 635 | AB11: =P2P!$AA11/P2P!$M11 -> 0.072093551
F12: 2025 | G12: 45870 | H12: 21000 | I12: 21000 | J12: 100% | K12: 55958 | L12: 2.66 | M12: 11871 | N12: 57% | O12: 4149 | P12: 35% | Q12: 0 | R12: 0.0% | S12: 106 | T12: 0.9% | U12: 95 | V12: 0.8% | W12: 66 | X12: 0.6% | Y12: 454 | Z12: 3.8% | AA12: 520 | AB12: =P2P!$AA12/P2P!$M12 -> 0.043804229
F13: 2025 | G13: 45901 | H13: 18000 | I13: 18000 | J13: 100% | K13: 57490 | L13: 3.19 | M13: 9906 | N13: 55% | O13: 4671 | P13: 47% | Q13: 0 | R13: 0.0% | S13: 57 | T13: 0.6% | U13: 57 | V13: 0.6% | W13: 57 | X13: 0.6% | Y13: 470 | Z13: 4.7% | AA13: 527 | AB13: =P2P!$AA13/P2P!$M13 -> 0.053200081
F14: 2025 | G14: 45931 | H14: 19700 | I14: 19700 | J14: 100% | K14: 64183 | L14: 3.26 | M14: 11027 | N14: 56% | O14: 5200 | P14: 47% | Q14: 0 | R14: 0.0% | S14: 80 | T14: 0.7% | U14: 68 | V14: 0.6% | W14: 68 | X14: 0.6% | Y14: 527 | Z14: 4.8% | AA14: 595 | AB14: =P2P!$AA14/P2P!$M14 -> 0.053958466
F15: 2025 | G15: 45962 | H15: 18000 | I15: 18000 | J15: 100% | K15: 50931 | L15: 2.83 | M15: 9528 | N15: 53% | O15: 4061 | P15: 43% | Q15: 0 | R15: 0.0% | S15: 57 | T15: 0.6% | U15: 53 | V15: 0.6% | W15: 46 | X15: 0.5% | Y15: 346 | Z15: 3.6% | AA15: 392 | AB15: =P2P!$AA15/P2P!$M15 -> 0.041141898
F16: 2025 | G16: 45992 | H16: 21400 | I16: 21400 | J16: 100% | K16: 58960 | L16: 2.76 | M16: 11317 | N16: 53% | O16: 4663 | P16: 41% | Q16: 0 | R16: 0.0% | S16: 71 | T16: 0.6% | U16: 48 | V16: 0.4% | W16: 46 | X16: 0.4% | Y16: 370 | Z16: 3.3% | AA16: 416 | AB16: =P2P!$AA16/P2P!$M16 -> 0.036758858
F17: 2026 | G17: 46023 | H17: 22000 | I17: 19997 | J17: 91% | K17: 55718 | L17: 2.53 | M17: 10206 | N17: 51% | O17: 4474 | P17: 44% | Q17: 0 | R17: 0.0% | S17: 73 | T17: 0.7% | U17: 47 | V17: 0.5% | W17: 45 | X17: 0.4% | Y17: 262 | Z17: 2.6% | AA17: 307 | AB17: =P2P!$AA17/P2P!$M17 -> 0.030080345
F18: 2026 | G18: 46054 | H18: 29370 | I18: 29358 | J18: 100% | K18: 77963 | L18: 2.65 | M18: 14573 | N18: 50% | O18: 6569 | P18: 45% | Q18: 0 | R18: 0.0% | S18: 63 | T18: 0.4% | U18: 45 | V18: 0.3% | W18: 45 | X18: 0.3% | Y18: 477 | Z18: 3.3% | AA18: 522 | AB18: =P2P!$AA18/P2P!$M18 -> 0.035819667
F19: 2026 | G19: 46082 | H19: 28964 | I19: 28964 | J19: =P2P!$I19/P2P!$H19 -> 1 | K19: 180657 | L19: =P2P!$K19/P2P!$H19 -> 6.2372946 | M19: 17942 | N19: =P2P!$M19/P2P!$I19 -> 0.61945864 | O19: 8755 | P19: =P2P!$O19/P2P!$M19 -> 0.48796121 | Q19: 0 | R19: 0.0% | S19: 68 | T19: =P2P!$S19/P2P!$M19 -> 0.00378999 | U19: 53 | V19: =P2P!$U19/P2P!$M19 -> 0.0029539628 | W19: 126 | X19: =P2P!$W19/P2P!$M19 -> 0.0070226285 | Y19: 957 | Z19: =P2P!$Y19/P2P!$M19 -> 0.053338535 | AA19: =P2P!$Y19+P2P!$W19 -> 1083 | AB19: =P2P!$AA19/P2P!$M19 -> 0.060361164
F20: 2026 | G20: 46113 | H20: 30982 | I20: 30982 | J20: =P2P!$I20/P2P!$H20 -> 1 | K20: 172883 | L20: =P2P!$K20/P2P!$I20 -> 5.580111 | M20: 17229 | N20: =P2P!$M20/P2P!$I20 -> 0.55609709 | O20: 7719 | P20: =P2P!$O20/P2P!$M20 -> 0.44802368 | Q20: 0 | R20: 0 | S20: 46 | T20: =P2P!$S20/P2P!$M20 -> 0.002669917 | U20: 38 | V20: =P2P!$U20/P2P!$M20 -> 0.0022055836 | W20: 94 | X20: =P2P!$W20/P2P!$M20 -> 0.0054559173 | Y20: 828 | Z20: =P2P!$Y20/P2P!$M20 -> 0.048058506 | AA20: =P2P!$Y20+P2P!$W20 -> 922 | AB20: =P2P!$AA20/P2P!$M20 -> 0.053514423
F21: 2026 | G21: 46143 | H21: 31000 | I21: 30617 | J21: =P2P!$I21/P2P!$H21 -> 0.98764516 | K21: 114346 | L21: =P2P!$K21/P2P!$I21 -> 3.7347225 | M21: 18035 | N21: =P2P!$M21/P2P!$I21 -> 0.58905183 | O21: 7988 | P21: =P2P!$O21/P2P!$M21 -> 0.44291655 | Q21: 0 | R21: 0 | S21: 58 | T21: =P2P!$S21/P2P!$M21 -> 0.0032159689 | U21: 55 | V21: =P2P!$U21/P2P!$M21 -> 0.0030496257 | W21: 138 | X21: =P2P!$W21/P2P!$I21 -> 0.0045072999 | Y21: 413 | Z21: =P2P!$Y21/P2P!$M21 -> 0.022899917 | AA21: =P2P!$Y21+P2P!$W21 -> 551 | AB21: =P2P!$AA21/P2P!$M21 -> 0.030551705
F22: 2026 | G22: 46174 | H22: 25149 | I22: 25149 | J22: =P2P!$I22/P2P!$H22 -> 1 | K22: 88783 | L22: =P2P!$K22/P2P!$H22 -> 3.5302795 | M22: 13869 | N22: =P2P!$M22/P2P!$I22 -> 0.55147322 | O22: 6797 | P22: =P2P!$O22/P2P!$M22 -> 0.4900858 | Q22: 0 | R22: 0 | S22: 74 | T22: =P2P!$S22/P2P!$M22 -> 0.0053356406 | U22: 61 | V22: =P2P!$U22/P2P!$M22 -> 0.0043982984 | W22: 145 | X22: =P2P!$W22/P2P!$M22 -> 0.010454972 | Y22: 964 | Z22: =P2P!$Y22/P2P!$M22 -> 0.069507535 | AB22: =P2P!$AA22/P2P!$M22 -> 0
F23: 2026 | G23: 46204
F24: Comportamiento Base Actual
F26: P2P 1 JULIO | I26: P2P AB | N26: P2P AB Testing
F27: Base de datos | G27: 13126 | I27: Base de datos | J27: 12023 | O27: 5230
F28: BD Recorrida | G28: 13126 | I28: BD Recorrida | J28: 12023 | N28: BD Recorrida | O28: 4847
F29: % de Recorrido | G29: =G28/G27 -> 1 | I29: % de Recorrido | J29: =J28/J27 -> 1 | N29: % de Recorrido | O29: =O28/O27 -> 0.92676864
F30: Marcaciones | G30: 47118 | I30: Marcaciones | J30: 41665 | N30: Marcaciones | O30: 6483
F31: Ratio de Llamadas | G31: =G30/G27 -> 3.5896694 | I31: Ratio de Llamadas | J31: =J30/J27 -> 3.4654412 | N31: Ratio de Llamadas | O31: =O30/O27 -> 1.2395794
F32: Contactos | G32: 7629 | I32: Contactos | J32: 6263 | N32: Contactos | O32: 1575
F33: % Contacto | G33: =G32/G28 -> 0.58121286 | I33: % Contacto | J33: =J32/J28 -> 0.52091824 | N33: % Contacto | O33: =O32/O28 -> 0.32494326
F34: RPC | G34: 3887 | I34: RPC | J34: 2910 | N34: RPC | O34: 620
F35: % RPC | G35: =G34/G32 -> 0.50950321 | I35: % RPC | J35: =J34/J32 -> 0.46463356 | N35: % RPC | O35: =O34/O32 -> 0.39365079
F36: Total de ventas | G36: 367 | I36: Total de ventas | J36: 310 | N36: Total de ventas | O36: 17
F37: Tasa de Cierre | G37: =G36/G32 -> 0.048105912 | I37: Tasa de Cierre | J37: =J36/J32 -> 0.049497046 | N37: Tasa de Cierre | O37: =O36/O32 -> 0.010793651 | S37: abirl
F39: Resultado por Vendedor | H39: Total de base | I39: =G36+J36 -> 677
H40: Referidos | I40: =Y22-I39 -> 287
E42: JUNIO | O42: Mes Anterior
E43: Supervisor | F43: Vendedor | G43: Contacto Real | H43: X Contacto Real diario | I43: Ventas Moviles Ingresadas | J43: FACT Movil | K43: Fijo Instalado | L43: RGU Inst | M43: Tasa de cierre | N43: QRT x Ventas Fact | O43: Contacto Real | P43: Ventas Moviles Ingresadas | Q43: Total FACT Movil | R43: Fijo Instalado | S43: RGU Inst | T43: Tasa de cierre Movl | U43: QRT x Ventas Fact
E44: Lizeth Gonzalez | F44: Rose Cedeño | G44: 1503 | H44: 60.12 | I44: 63 | J44: 61 | K44: 2 | L44: 3 | M44: 0.041916168 | N44: 1 | O44: 1652 | P44: 53 | Q44: 52 | R44: 3 | S44: 5 | T44: 0.032082324 | U44: 1
E45: Lizeth Gonzalez | F45: Rafael Alejandro Jordan Garrido | G45: 1299 | H45: 51.96 | I45: 52 | J45: 51 | K45: 1 | L45: 3 | M45: 0.040030793 | N45: 1 | O45: 1115 | P45: 22 | Q45: 21 | R45: 1 | S45: 3 | T45: 0.019730942 | U45: 3
...

Sheet Análisis x Recargador
P27: Base al 7 de abril

Sheet Meta diaria
A2: Indicador | B2: Total requerido | C2: Recorrido Diario | D2: Por vendedor/día
A3: Contactos esperados | B3: 17.455 | C3: 793 | D3: 24
A4: RPC efectivos | B4: 9.077 | C4: 413 | D4: 13
A5: Renovaciones pendientes | B5: 1.513 | C5: 69 | D5: 2.08

Sheet Hoja1
A1: modelo matematico
B2: Recorrido
B3: marcaciones
B4: ventas

Sheet evidencia
A77: P2P
A78: Detalle | B78: may-25 | C78: jun-25 | D78: jul-25 | E78: ago-25 | F78: sep-25 | G78: oct-25 | H78: nov-25 | I78: dic-25 | J78: ene-26 | K78: feb-26 | L78: mar-26 | M78: Total general
A79: Base | B79: 8000 | C79: 15000 | D79: 15000 | E79: 21000 | F79: 18000 | G79: 19700 | H79: 18000 | I79: 21400 | J79: 22000 | K79: 29370 | M79: 187470
A80: Recorrido | B80: 8000 | C80: 15000 | D80: 15000 | E80: 21000 | F80: 18000 | G80: 19700 | H80: 18000 | I80: 21400 | J80: 19997 | K80: 29358 | M80: 185455
A81: %Recorrido | B81: 100% | C81: 100% | D81: 100% | E81: 100% | F81: 100% | G81: 100% | H81: 100% | I81: 100% | J81: 91% | K81: 100% | M81: 99%
A82: Intentos Totales | B82: 23971 | C82: 30472 | D82: 46285 | E82: 55958 | F82: 57490 | G82: 64183 | H82: 50931 | I82: 58960 | J82: 55718 | K82: 77963 | M82: 521931
A83: Ratio llamadas | B83: 3 | C83: 2.03 | D83: 3.09 | E83: 2.66 | F83: 3.19 | G83: 3.26 | H83: 2.83 | I83: 2.76 | J83: 2.53 | K83: 2.65 | M83: 2.78
A84: Contactado | B84: 2934 | C84: 6534 | D84: 8808 | E84: 11871 | F84: 9906 | G84: 11027 | H84: 9528 | I84: 11317 | J84: 10206 | K84: 14573 | M84: 96704
A85: %Contactado | B85: 37% | C85: 44% | D85: 59% | E85: 57% | F85: 55% | G85: 56% | H85: 53% | I85: 53% | J85: 51% | K85: 50% | M85: 52%
A86: RPC | B86: 804 | C86: 2164 | D86: 2832 | E86: 4149 | F86: 4671 | G86: 5200 | H86: 4061 | I86: 4663 | J86: 4474 | K86: 6569 | M86: 39587
A87: %RPC | B87: 27% | C87: 33% | D87: 32% | E87: 35% | F87: 47% | G87: 47% | H87: 43% | I87: 41% | J87: 44% | K87: 45% | M87: 41%
A88: Renovación | B88: 0 | C88: 0 | D88: 0 | E88: 0 | F88: 0 | G88: 0 | H88: 0 | I88: 0 | J88: 0 | K88: 0 | M88: 0
A89: % Conv Reno | B89: 0.0% | C89: 0.0% | D89: 0.0% | E89: 0.0% | F89: 0.0% | G89: 0.0% | H89: 0.0% | I89: 0.0% | J89: 0.0% | K89: 0.0% | M89: 0.0%
A90: Creadas Totales Fijo | E90: 106 | F90: 57 | G90: 80 | H90: 57 | I90: 71 | J90: 73 | K90: 63 | M90: 507
A91: % Conv Creadas Totales Fijo | B91: 0.0% | C91: 0.0% | D91: 0.0% | E91: 0.9% | F91: 0.6% | G91: 0.7% | H91: 0.6% | I91: 0.6% | J91: 0.7% | K91: 0.4% | M91: 0.5%
A92: Creadas Fijo | B92: 113 | C92: 212 | D92: 126 | E92: 95 | F92: 57 | G92: 68 | H92: 53 | I92: 48 | J92: 47 | K92: 45 | M92: 864
A93: % Conv Creadas Fijo | B93: 3.9% | C93: 3.2% | D93: 1.4% | E93: 0.8% | F93: 0.6% | G93: 0.6% | H93: 0.6% | I93: 0.4% | J93: 0.5% | K93: 0.3% | M93: 0.9%
A94: Rgu Fijo Fact | B94: 76 | C94: 179 | D94: 135 | E94: 66 | F94: 57 | G94: 68 | H94: 46 | I94: 46 | J94: 45 | K94: 45 | M94: 763
A95: SPH Fijo | B95: 0.09 | C95: 0.07 | D95: 0.05 | E95: 0.03 | F95: 0.02 | G95: 0.03 | H95: 0.02 | I95: 0.03 | J95: 0.03 | K95: 0.02 | M95: 0.04
A96: %Conv Fijo | B96: 2.6% | C96: 2.7% | D96: 1.5% | E96: 0.6% | F96: 0.6% | G96: 0.6% | H96: 0.5% | I96: 0.4% | J96: 0.4% | K96: 0.3% | M96: 0.8%
A97: Rgu Movil Fact | B97: 127 | C97: 329 | D97: 500 | E97: 454 | F97: 470 | G97: 527 | H97: 346 | I97: 370 | J97: 262 | K97: 477 | M97: 3862
A98: SPH Movil | B98: 0.15 | C98: 0.13 | D98: 0.19 | E98: 0.18 | F98: 0.18 | G98: 0.2 | H98: 0.15 | I98: 0.23 | J98: 0.16 | K98: 0.22 | M98: 0.18
A99: % Conv Movil | B99: 4.3% | C99: 5.0% | D99: 5.7% | E99: 3.8% | F99: 4.7% | G99: 4.8% | H99: 3.6% | I99: 3.3% | J99: 2.6% | K99: 3.3% | M99: 4.0%
A100: Total FACT | B100: 203 | C100: 508 | D100: 635 | E100: 520 | F100: 527 | G100: 595 | H100: 392 | I100: 416 | J100: 307 | K100: 522 | M100: 4625
A101: % Conversion | B101: 6.9% | C101: 7.8% | D101: 7.2% | E101: 4.4% | F101: 5.3% | G101: 5.4% | H101: 4.1% | I101: 3.7% | J101: 3.0% | K101: 3.6% | M101: 4.8%
A104: renovaciones
A105: Detalle | B105: Columna1 | C105: Columna2 | D105: Columna3 | E105: Columna4 | F105: Columna5 | G105: Columna6 | H105: Columna7 | I105: Columna8 | J105: Columna9 | K105: Columna10 | L105: Columna11 | M105: dic-25 | N105: ene-26 | O105: feb-26 | P105: mar-26 | Q105: abr-26 | R105: Total general
A106: Base | B106: 28260 | C106: 40200 | D106: 34452 | E106: 44817 | F106: 46975 | G106: 47904 | H106: 48708 | I106: 54965 | J106: 46516 | K106: 46615 | L106: 41479 | M106: 52333 | N106: 42592 | O106: 40300 | R106: 616116
A107: Recorrido | B107: 28260 | C107: 40200 | D107: 34452 | E107: 35738 | F107: 35421 | G107: 47904 | H107: 48706 | I107: 54922 | J107: 45493 | K107: 46596 | L107: 41469 | M107: 52270 | N107: 41439 | O107: 37206 | R107: 590076
A108: %Recorrido | B108: 100% | C108: 100% | D108: 100% | E108: 80% | F108: 75% | G108: 100% | H108: 100% | I108: 100% | J108: 98% | K108: 100% | L108: 100% | M108: 100% | N108: 97% | O108: 92% | R108: 96%
A109: Intentos Totales | B109: 91677 | C109: 120669 | D109: 130356 | E109: 87097 | F109: 116270 | G109: 101607 | H109: 106478 | I109: 101233 | J109: 147247 | K109: 100405 | L109: 92966 | M109: 140358 | N109: 125289 | O109: 153667 | R109: 1615319
A110: Ratio llamadas | B110: 3.24 | C110: 3 | D110: 3.78 | E110: 1.94 | F110: 2.48 | G110: 2.12 | H110: 2.19 | I110: 1.84 | J110: 3.17 | K110: 2.15 | L110: 2.24 | M110: 2.68 | N110: 2.94 | O110: 3.81 | R110: 2.62
A111: Contactado | B111: 26439 | C111: 20966 | D111: 18182 | E111: 16786 | F111: 20483 | G111: 18279 | H111: 22704 | I111: 23770 | J111: 20873 | K111: 22625 | L111: 17440 | M111: 25083 | N111: 21315 | O111: 19826 | R111: 294771
A112: %Contactado | B112: 94% | C112: 52% | D112: 53% | E112: 47% | F112: 58% | G112: 38% | H112: 47% | I112: 43% | J112: 46% | K112: 49% | L112: 42% | M112: 48% | N112: 51% | O112: 53% | R112: 50%
A113: RPC | B113: 26187 | C113: 17952 | D113: 8505 | E113: 7172 | F113: 9300 | G113: 8094 | H113: 10402 | I113: 11079 | J113: 11044 | K113: 12046 | L113: 9530 | M113: 14644 | N113: 12337 | O113: 11990 | R113: 170282
A114: %RPC | B114: 99% | C114: 86% | D114: 47% | E114: 43% | F114: 45% | G114: 44% | H114: 46% | I114: 47% | J114: 53% | K114: 53% | L114: 55% | M114: 58% | N114: 58% | O114: 60% | R114: 58%
A115: Renovación | B115: 843 | C115: 971 | D115: 927 | E115: 944 | F115: 1561 | G115: 1511 | H115: 1777 | I115: 1401 | J115: 1265 | K115: 1591 | L115: 834 | M115: 1404 | N115: 1355 | O115: 1072 | R115: 17456
A116: % Conv Reno | B116: 3.2% | C116: 4.6% | D116: 5.1% | E116: 5.6% | F116: 7.6% | G116: 8.3% | H116: 7.8% | I116: 5.9% | J116: 6.1% | K116: 7.0% | L116: 4.8% | M116: 5.6% | N116: 6.4% | O116: 5.4% | R116: 5.9%
A117: Creadas Totales Fijo | I117: 116 | J117: 124 | K117: 86 | L117: 25 | M117: 34 | N117: 60 | O117: 74 | R117: 519
A118: % Conv Creadas Totales Fijo | B118: 0.0% | C118: 0.0% | D118: 0.0% | E118: 0.0% | F118: 0.0% | G118: 0.0% | H118: 0.0% | I118: 0.5% | J118: 0.6% | K118: 0.4% | L118: 0.1% | M118: 0.1% | N118: 0.3% | O118: 0.4% | R118: 0.2%
...
