Workbook

Sheet DASHBOARD2
A2: DATAPHONE | COBROS | H2: FUNNEL DE COBROS
H3: Status | I3: Cant
H4: Asignadas | I4: =datos!B33 -> 1073
H5: Gestionadas | I5: =datos!B34 -> 989
H6: Contactadas | I6: =datos!B35 -> 630
H7: Promesas | I7: =datos!B36 -> 85
H8: Pagos | I8: =datos!B37 -> 46
A12: RESUMEN | MES EN TRANSITO (MAYO) | C12: Resultados Financieros | F12: % PROMESA
A13: HC | B13: 1 | C13: Segmento | D13: Promesa de Pago | E13: Monto Recuperado | F13: =B20/B14 -> 0.079217148
A14: Cuentas asignadas | B14: =datos!B4 -> 1073 | C14: Call Center Outbound | D14: =+IFERROR(_xlfn.XLOOKUP(C14,datos!A16:A23,datos!B16:B23,,0),0) -> 234.44 | E14: =+IFERROR(_xlfn.XLOOKUP(C14,datos!A16:A23,datos!C16:C23,,0),0) -> 0
A15: Cartera ($) | B15: =datos!B5 -> 3570.68 | C15: Digital | D15: =+IFERROR(_xlfn.XLOOKUP(C15,datos!A17:A24,datos!B17:B24,,0),0) -> 160.35 | E15: =+IFERROR(_xlfn.XLOOKUP(C15,datos!A17:A24,datos!C17:C24,,0),0) -> 0
A16: Recuperación ($) | B16: =datos!B6 -> 1145.24 | C16: La doña | D16: =+IFERROR(_xlfn.XLOOKUP(C16,datos!A18:A25,datos!B18:B25,,0),0) -> 0 | E16: =+IFERROR(_xlfn.XLOOKUP(C16,datos!A18:A25,datos!C18:C25,,0),0) -> 0
A17: % Recuperación | B17: =datos!B7 -> 0.32073443 | C17: Masivo (D2D) | D17: =+IFERROR(_xlfn.XLOOKUP(C17,datos!A19:A26,datos!B19:B26,,0),0) -> 2542.91 | E17: =+IFERROR(_xlfn.XLOOKUP(C17,datos!A19:A26,datos!C19:C26,,0),0) -> 882.48
A18: Contactabilidad | B18: =datos!B8 -> 0.12745296 | C18: Movil | D18: =+IFERROR(_xlfn.XLOOKUP(C18,datos!A20:A27,datos!B20:B27,,0),0) -> 0 | E18: =+IFERROR(_xlfn.XLOOKUP(C18,datos!A20:A27,datos!C20:C27,,0),0) -> 0
A19: RPC | B19: =datos!B9 -> 0.79206349 | C19: Oeste | D19: =+IFERROR(_xlfn.XLOOKUP(C19,datos!A21:A28,datos!B21:B28,,0),0) -> 0 | E19: =+IFERROR(_xlfn.XLOOKUP(C19,datos!A21:A28,datos!C21:C28,,0),0) -> 0 | F19: % RECUPERACION
A20: Promesas | B20: =datos!B10 -> 85 | C20: Punto de ventas | D20: =+IFERROR(_xlfn.XLOOKUP(C20,datos!A22:A29,datos!B22:B29,,0),0) -> 0 | E20: =+IFERROR(_xlfn.XLOOKUP(C20,datos!A22:A29,datos!C22:C29,,0),0) -> 0 | F20: =B21/B14 -> 0.042870457
A21: Promesas cumplidas | B21: =datos!B11 -> 46 | C21: Soho | D21: =GETPIVOTDATA(" Promesa de Pago",datos!$A$16,"Canal","Soho") -> 600.74 | E21: =GETPIVOTDATA(" Monto Recuperado",datos!$A$16,"Canal","Soho") -> 262.76
A22: % Cumplimiento | B22: =datos!B12 -> 0.54117647 | C22: Soho -Callcenter | D22: =GETPIVOTDATA(" Promesa de Pago",datos!$A$16,"Canal","Soho -Callcenter") -> 32.24 | E22: =+IFERROR(_xlfn.XLOOKUP(C22,datos!A24:A31,datos!C24:C31,,0),0) -> 0
C23: Total general | D23: =SUM(D14:D22) -> 3570.68 | E23: =SUM(E14:E22) -> 1145.24
A25: PERFORMANCE POR AGENTE
A26: AGENTE | B26: Cartera | C26: Recuperado | D26: % Recuperación | E26: Promesas | F26: Cumplidas | G26: % Efectividad
A27: Lili Velez | B27: =datos!B27 -> 1073 | C27: =datos!C27 -> 46 | D27: =datos!D27 -> 0.042870457 | E27: =datos!E27 -> 3570.68 | F27: =datos!F27 -> 1145.24 | G27: =datos!G27 -> 0.32073443
A28: Total | B28: =+SUM(B27:B27) -> 1073 | C28: =+SUM(C27:C27) -> 46 | D28: =+SUM(D27:D27) -> 0.042870457 | E28: =+SUM(E27:E27) -> 3570.68 | F28: =+SUM(F27:F27) -> 1145.24 | G28: =AVERAGE(G27:G27) -> 0.32073443
A29: PRODUCTIVIDAD OPERATIVA | H29: PROMESA VS PAGOS
A30: AGENTE | B30: Llamadas | C30: Contactos | D30: RPC | E30: Cant Promesas de pago | F30: % RPC | G30: % Contactos
A31: Lili Velez | B31: =GETPIVOTDATA("Intentos",analisis!$A$11,"full_name","Lili Velez") -> 1157 | C31: =GETPIVOTDATA(" Connect",analisis!$A$21,"full_name","Lili Velez") -> 630 | D31: =GETPIVOTDATA(" RPC",analisis!$A$21,"full_name","Lili Velez") -> 499 | E31: =GETPIVOTDATA("Suma de Intentos de Promesas",analisis!$G$34,"Agente ","Lili Velez") -> 85 | F31: =D31/C31 -> 0.79206349 | G31: =C31/B31 -> 0.54451167
A32: Total | B32: =+SUM(B31:B31) -> 1157 | C32: =+SUM(C31:C31) -> 630 | D32: =+SUM(D31:D31) -> 499 | E32: =+SUM(E31:E31) -> 85 | F32: =D32/C32 -> 0.79206349 | G32: =C32/B32 -> 0.54451167
A33: DIVISION POR MES PENDIENTE | E33: Cuentas Cesadas / Al Dia
A34: PENDIENTES POR MES | B34: REGISTROS CARGADOS | C34: RECUPERADO | E34: Cliente al dia | F34: Cuenta cesada
A35: 1 MES PENDIENTE | B35: =datos!B57 -> 43 | C35: =datos!C57 -> 3 | E35: =GETPIVOTDATA("Contacto1",analisis!$Z$21,"_Producto_Linea","Cliente al dia") -> 8 | F35: =GETPIVOTDATA("Contacto1",analisis!$Z$21,"_Producto_Linea","Cuenta cesada") -> 82
A36: 2 MESES PENDIENTES | B36: =datos!B58 -> 159 | C36: =datos!C58 -> 10
A37: 3 MESES PENDIENTES | B37: =datos!B59 -> 178 | C37: =datos!C59 -> 3
A38: 4 MESES PENDIENTES | B38: =datos!B60 -> 25 | C38: =datos!C60 -> 0
A39: NPN | B39: =datos!B61 -> 359 | C39: =datos!C61 -> 30
A41: LLAMADAS DIARIAS

Sheet dashboard

Sheet analisis
B1: =GETPIVOTDATA("Intentos",$A$2) -> 4943 | S1: =GETPIVOTDATA("Intentos",$A$2,"full_name","Lili Velez") -> 1157 | AH1: Fecha | AI1: (Todas)
A2: Llamadas diarias | B2: Dia | AH2: Escenario | AI2: (Todas)
A3: Agentes | B3: 02/may | C3: 04/may | D3: 05/may | E3: 06/may | F3: 07/may | G3: 08/may | H3: 09/may | I3: 11/may | J3: 12/may | K3: 13/may | L3: 14/may | M3: 15/may | N3: 16/may | O3: 18/may | P3: 19/may | Q3: 20/may | R3: 21/may | S3: 22/may | T3: Total general | AI3: =GETPIVOTDATA(" Monto de Promesa de Pago",$G$34) -> 3570.68 | AJ3: =GETPIVOTDATA("Suma de Monto pagado",$G$34) -> 1145.24 | AK3: =GETPIVOTDATA("Suma de Intentos de Promesas",$G$34,"Agente ","Lili Velez") -> 85 | AL3: =GETPIVOTDATA("Suma de Intentos de pago",$G$34,"Agente ","Lili Velez") -> 46
A4: Lili Velez | B4: 17 | C4: 42 | D4: 27 | E4: 55 | F4: 38 | G4: 60 | H4: 48 | I4: 102 | J4: 110 | K4: 101 | L4: 99 | M4: 35 | N4: 21 | O4: 91 | P4: 83 | Q4: 95 | R4: 102 | S4: 31 | T4: 1157 | AH4: Agentes | AI4: Promesa de Pago | AJ4: Cant Promesa
A5: Outbound Auto Dial | B5: 51 | C5: 108 | D5: 44 | E5: 119 | F5: 75 | G5: 122 | H5: 150 | I5: 350 | J5: 354 | K5: 363 | L5: 355 | M5: 147 | N5: 70 | O5: 311 | P5: 298 | Q5: 309 | R5: 412 | S5: 148 | T5: 3786 | AH5: Lili Velez | AI5: 3570.68 | AJ5: 85
A6: Total general | B6: 68 | C6: 150 | D6: 71 | E6: 174 | F6: 113 | G6: 182 | H6: 198 | I6: 452 | J6: 464 | K6: 464 | L6: 454 | M6: 182 | N6: 91 | O6: 402 | P6: 381 | Q6: 404 | R6: 514 | S6: 179 | T6: 4943 | AH6: may | AI6: 3545 | AJ6: 84
Y8: PENDIENTES POR MES | Z8: REGISTROS CARGADOS | AA8: RECUPERADO | AH8: jun | AI8: 25.68 | AJ8: 1
A9: Contar | B9: (Todas) | Y9: 1 MES PENDIENTE | AH9: Total general | AI9: 3570.68 | AJ9: 85
D10: Contar | E10: 1 | H10: _Producto_Linea | I10: (Varios elementos) | K10: _Producto_Linea | L10: (Todas) | T10: Fecha | U10: (Todas) | Y10: 2 MESES PENDIENTES
A11: Agentes | B11: Llamadas | D11: unicos | H11: utiliuzada | K11: Base | T11: Escenario | U11: (Varios elementos) | Y11: 3 MESES PENDIENTES
A12: Lili Velez | B12: 1157 | D12: Agentes | E12: Llamadas | H12: Etiquetas de fila | I12: Cuenta de Contacto1 | K12: Etiquetas de fila | L12: Cuenta de Contacto1 | Y12: 4 MESES PENDIENTES
A13: Outbound Auto Dial | B13: 3786 | D13: Lili Velez | E13: 942 | H13: Cobros Mayo | I13: 989 | K13: Cobros Mayo | L13: 1073 | T13: Etiquetas de fila | U13: Cuenta de Tiempo de mora (días) | Y13: NPN
A14: Total general | B14: 4943 | D14: Outbound Auto Dial | E14: 322 | H14: Total general | I14: 989 | K14: Total general | L14: 1073 | T14: 1 MES PENDIENTE | U14: 43
D15: Total general | E15: 1264 | T15: 2 MESES PENDIENTES | U15: 159
T16: 3 MESES PENDIENTES | U16: 178
I17: =GETPIVOTDATA("Contacto1",$H$12,"Source.Name","Cobros Mayo") -> 989 | L17: =GETPIVOTDATA("Contacto1",$K$12) -> 1073 | T17: 4 MESES PENDIENTES | U17: 25
T18: NPN | U18: 359 | AH18: Fecha | AI18: (Todas)
A19: Contar | B19: 1 | T19: Total general | U19: 764 | Z19: Source.Name | AA19: Cobros Mayo | AH19: Escenario | AI19: (Todas)
H20: _Producto_Linea | I20: (Todas) | Z20: utiliuzada | AI20: =GETPIVOTDATA(" Monto de Promesa de Pago",$G$34) -> 3570.68 | AJ20: =GETPIVOTDATA("Suma de Monto pagado",$G$34) -> 1145.24
A21: Agentes | B21: Connect | C21: RPC | H21: Base | T21: Fecha | U21: (Todas) | Z21: Etiquetas de fila | AA21: Cuenta de Contacto1 | AH21: Meses | AI21: Monto pagado | AJ21: Intentos de pago
A22: Lili Velez | B22: 630 | C22: 499 | H22: Etiquetas de fila | I22: Cuenta de Contacto1 | T22: Mes Pago | U22: (Varios elementos) | Z22: Cliente al dia | AA22: 8 | AH22: abr | AI22: 197.5 | AJ22: 5
A23: Outbound Auto Dial | B23: 0 | C23: 0 | H23: Cobros Mayo | I23: 1073 | T23: Escenario | U23: (Todas) | Z23: Cuenta cesada | AA23: 82 | AH23: may | AI23: 947.74 | AJ23: 41
A24: Total general | B24: 630 | C24: 499 | H24: Total general | I24: 1073 | Z24: #N/D | AA24: 2 | AH24: Total general | AI24: 1145.24 | AJ24: 46
T25: Etiquetas de fila | U25: Cuenta de Mes Pago | Z25: Total general | AA25: 92
T26: 1 MES PENDIENTE | U26: 3
T27: 2 MESES PENDIENTES | U27: 10
T28: 3 MESES PENDIENTES | U28: 3
T29: NPN | U29: 30 | AA29: 1347
B30: =GETPIVOTDATA("Monto de Promesa de Pago",$A$34) -> 3570.68 | C30: =GETPIVOTDATA(" Monto Recuperado",$A$34) -> 1145.24 | T30: Total general | U30: 46 | AA30: -361
A31: Mes Pago | B31: (Todas) | G31: Fecha | H31: (Todas)
A32: Mes Promesa | B32: (Todas) | G32: Escenario | H32: (Todas) | Q32: Agentes | R32: Suma de Monto pagado
A33: Resultados Financieros | H33: =GETPIVOTDATA(" Monto de Promesa de Pago",$G$34) -> 3570.68 | I33: =GETPIVOTDATA("Suma de Monto pagado",$G$34) -> 1145.24 | J33: =GETPIVOTDATA("Suma de Intentos de Promesas",$G$34) -> 85 | K33: =GETPIVOTDATA("Cuenta de Intentos de pago",$G$45,"Agente ","Lili Velez") -> 46 | Q33: Lili Velez | R33: 1145.24
A34: Canal | B34: Promesa de Pago | C34: Monto Recuperado | G34: Canal | H34: Monto de Promesa de Pago | I34: Suma de Monto pagado | J34: Suma de Intentos de Promesas | K34: Suma de Intentos de pago | L34: Cartera | Q34: Total general | R34: 1145.24
A35: Call Center Outbound | B35: 234.44 | C35: 0 | G35: Lili Velez | H35: 3570.68 | I35: 1145.24 | J35: 85 | K35: 46 | L35: =C54/C55 -> 1073
A36: Digital | B36: 160.35 | C36: 0 | G36: Total general | H36: 3570.68 | I36: 1145.24 | J36: 85 | K36: 46 | L36: =C54/C55 -> 1073
A37: Masivo (D2D) | B37: 2542.91 | C37: 882.48
A38: Punto de ventas | B38: 0 | C38: 0
A39: Soho | B39: 600.74 | C39: 262.76
A40: Soho -Callcenter | B40: 32.24 | C40: 0
A41: Total general | B41: 3570.68 | C41: 1145.24 | G41: Fecha | H41: (Todas)
...

Sheet datos
A2: Resumen Ejecutivo | E2: Productividad Operativa
A3: HC | B3: 1 | E3: Indicador | F3: Valor
A4: Cuentas asignadas | B4: =analisis!L17 -> 1073 | E4: Llamadas | F4: Contactos | G4: RPC | H4: Cant Promesas de pago | I4: % RPC
A5: Cartera ($) | B5: =GETPIVOTDATA(" Monto de Promesa de Pago",analisis!$G$34) -> 3570.68 | E5: =GETPIVOTDATA("Intentos",analisis!$A$11) -> 4943 | F5: =GETPIVOTDATA(" Connect",analisis!$A$21) -> 630 | G5: =GETPIVOTDATA(" RPC",analisis!$A$21) -> 499 | H5: =analisis!J33 -> 85 | I5: =G5/F5 -> 0.79206349
A6: Recuperación ($) | B6: =GETPIVOTDATA("Suma de Monto pagado",analisis!$G$34) -> 1145.24
A7: % Recuperación | B7: =B6/B5 -> 0.32073443
A8: Contactabilidad | B8: =F5/E5 -> 0.12745296
A9: RPC | B9: =G5/F5 -> 0.79206349
A10: Promesas | B10: =H5 -> 85
A11: Promesas cumplidas | B11: =B37 -> 46
A12: % Cumplimiento | B12: =B11/B10 -> 0.54117647
A15: Resultados Financieros
A16: Canal | B16: Promesa de Pago | C16: Monto Recuperado
A17: Call Center Outbound | B17: 234.44 | C17: 0
A18: Digital | B18: 160.35 | C18: 0
A19: Masivo (D2D) | B19: 2542.91 | C19: 882.48
A20: Punto de ventas | B20: 0 | C20: 0
A21: Soho | B21: 600.74 | C21: 262.76
A22: Soho -Callcenter | B22: 32.24 | C22: 0
A23: Total general | B23: 3570.68 | C23: 1145.24
A25: Performance por Agente
A26: Agente | B26: Cartera | C26: Recuperado | D26: % Recuperación | E26: Promesas | F26: Cumplidas | G26: % Efectividad
A27: Lili Velez | B27: =analisis!C57 -> 1073 | C27: =GETPIVOTDATA("Suma de Intentos de pago",analisis!$G$34,"Agente ","Lili Velez") -> 46 | D27: =C27/B27 -> 0.042870457 | E27: =GETPIVOTDATA(" Monto de Promesa de Pago",analisis!$G$34,"Agente ","Lili Velez") -> 3570.68 | F27: =GETPIVOTDATA("Suma de Monto pagado",analisis!$G$34,"Agente ","Lili Velez") -> 1145.24 | G27: =F27/E27 -> 0.32073443
A31: Funnel de Cobranza
A32: Etapa | B32: Cantidad
A33: Asignadas | B33: =B4 -> 1073
A34: Gestionadas | B34: =analisis!I17 -> 989
A35: Contactadas | B35: =F5 -> 630
A36: Promesas | B36: =analisis!J33 -> 85
A37: Pagos | B37: =analisis!K33 -> 46
A40: Promesas vs Pagos
A41: Indicador | B41: Valor | C41: Porcentaje
A42: Promesas | B42: =H5 -> 85 | C42: =B42/$B$4 -> 0.079217148
A43: Pagos | B43: =B11 -> 46 | C43: =B43/$B$4 -> 0.042870457
A44: % Cumplimiento | B44: =(B43/B42) -> 0.54117647
A47: Efectividad de Cobranza
A48: Indicador | B48: Valor
A49: Gestiones Totales | B49: =analisis!L17 -> 1073
A50: Gestiones Productivas | B50: =analisis!I17 -> 989
A51: % Efectividad | B51: =B50/B49 -> 0.92171482
...

Sheet Resumen Ejecutivo
A2: Resumen Ejecutivo
A3: HC | B3: 2
A4: Cuentas asignadas | B4: 1000
A5: Cartera ($) | B5: 150000
A6: Recuperación ($) | B6: 45000
A7: % Recuperación | B7: =B6/B5 -> 0.3
A8: RPC | B8: 300
A9: Contactabilidad | B9: 0.65
A10: Promesas | B10: 120
A11: Promesas cumplidas | B11: 90
A12: % Cumplimiento | B12: =B11/B10 -> 0.75

Sheet Productividad
A1: Indicador | B1: Valor
A2: Llamadas | B2: Contactos | C2: RPC | D2: Cant Promesas de pago
A3: 2500 | B3: 1600 | C3: 300 | D3: 120

Sheet Financieros
A1: Segmento | B1: Recuperación ($)
A2: Call Center | B2: 30000
A3: Digital | B3: 15000

Sheet Agentes
A1: Agente | B1: Cartera | C1: Recuperado | D1: % Recuperación | E1: Promesas | F1: Cumplidas | G1: % Efectividad
A2: Agente 1 | B2: 75000 | C2: 25000 | D2: =C2/B2 -> 0.33333333 | E2: 70 | F2: 50 | G2: =F2/E2 -> 0.71428571
A3: Agente 2 | B3: 75000 | C3: 20000 | D3: =C3/B3 -> 0.26666667 | E3: 50 | F3: 40 | G3: =F3/E3 -> 0.8

Sheet Funnel
A1: Etapa | B1: Cantidad
A2: Asignadas | B2: 1000
A3: Gestionadas | B3: 800
A4: Contactadas | B4: 650
A5: Promesas | B5: 120
A6: Pagos | B6: 90

Sheet Promesas vs Pagos
A1: Indicador | B1: Valor
A2: Promesas | B2: 120
A3: Pagos | B3: 90
A4: % Cumplimiento | B4: =B3/B2 -> 0.75

Sheet Efectividad
A1: Indicador | B1: Valor
A2: Gestiones Totales | B2: 2500
A3: Gestiones Productivas | B3: 300
A4: % Efectividad | B4: =B3/B2 -> 0.12

Sheet bases UTILIZADAS
A1: Source.Name | B1: Nombre_Cliente | C1: Numero_Cuenta | D1: Nombre de Lista | E1: Provincia | F1: Dias_morosidad | G1: Fecha_Ult_Pago | H1: Contacto1 | I1: Contacto2 | J1: Contacto3 | K1: email | L1: Monto_Vencido | M1: Monto_Total | N1: Ciclo | O1: Fecha_Promesa_Pago | P1: Numero_de_orden | Q1: Segmentacion_de_cliente | R1: Direccion | S1: Cedula_del_cliente | T1: Canal | U1: Tiempo de mora | V1: _Producto_Linea | W1: _Renta_BB | X1: _Renta_Linea | Y1: _Renta_TV | Z1: Pago_de_entrada
A2: Cobros Abril Canal Fijo | B2: Delfina gonzalez Martinez | C2: 359331050000 | D2: Cobros Abril Canal Fijo 2 meses a NPN | E2: =+_xlfn.XLOOKUP(UTILIZADAS[[#This Row],[Numero_Cuenta]],'[1]cobros_marzo (fijo)'!$B:$B,'[1]cobros_marzo (fijo)'!$D:$D,,0) -> Provincia | G2: 46026 | H2: 67523877 | I2: 67523877 | K2: preciadoiranelda@gmail.com | O2: 46026 | S2: 10-8-653 | T2: MASIVO | U2: NPN | V2: =_xlfn.XLOOKUP(UTILIZADAS[[#This Row],[Contacto1]],Tabla2[phone_number_dialed],Tabla2[status_name],,0) -> #N/A
A3: Cobros Abril Canal Fijo | B3: Juliana concepción | C3: 356789000000 | D3: Cobros Abril Canal Fijo 2 meses a NPN | E3: =+_xlfn.XLOOKUP(UTILIZADAS[[#This Row],[Numero_Cuenta]],'[1]cobros_marzo (fijo)'!$B:$B,'[1]cobros_marzo (fijo)'!$D:$D,,0) -> PANAMA | G3: 46026 | H3: 68905432 | I3: 68905432 | K3: juancarlos@gmail.com | O3: 46026 | S3: 9-748-246 | T3: MASIVO | U3: NPN | V3: =_xlfn.XLOOKUP(UTILIZADAS[[#This Row],[Contacto1]],Tabla2[phone_number_dialed],Tabla2[status_name],,0) -> Agent Not Available
A4: Cobros Abril Canal Fijo | B4: Angeles barahona | C4: 355339190000 | D4: Cobros Abril Canal Fijo 2 meses a NPN | E4: =+_xlfn.XLOOKUP(UTILIZADAS[[#This Row],[Numero_Cuenta]],'[1]cobros_marzo (fijo)'!$B:$B,'[1]cobros_marzo (fijo)'!$D:$D,,0) -> PANAMA | G4: 46026 | H4: 68905432 | I4: 68905432 | K4: danirudas42@gmail.com | O4: 46026 | S4: 7-712-2265 | T4: MASIVO | U4: NPN | V4: =_xlfn.XLOOKUP(UTILIZADAS[[#This Row],[Contacto1]],Tabla2[phone_number_dialed],Tabla2[status_name],,0) -> Agent Not Available
A5: Cobros Abril Canal Fijo | B5: Stacy suseth Murillo de Leon | C5: 357337110000 | D5: Cobros Abril Canal Fijo 2 meses a NPN | E5: =+_xlfn.XLOOKUP(UTILIZADAS[[#This Row],[Numero_Cuenta]],'[1]cobros_marzo (fijo)'!$B:$B,'[1]cobros_marzo (fijo)'!$D:$D,,0) -> PANAMA | G5: 46026 | H5: 63277219 | I5: 63277219 | K5: stacymrillo28@icloud.com | O5: 46026 | S5: 8-994-968 | T5: MASIVO | U5: NPN | V5: =_xlfn.XLOOKUP(UTILIZADAS[[#This Row],[Contacto1]],Tabla2[phone_number_dialed],Tabla2[status_name],,0) -> #N/A
A6: Cobros Abril Canal Fijo | B6: Roberto Linton | C6: 359338710000 | D6: Cobros Abril Canal Fijo 2 meses a NPN | E6: =+_xlfn.XLOOKUP(UTILIZADAS[[#This Row],[Numero_Cuenta]],'[1]cobros_marzo (fijo)'!$B:$B,'[1]cobros_marzo (fijo)'!$D:$D,,0) -> 0 | G6: 46026 | H6: 64628032 | I6: 64628032 | K6: Fabian022431@gmail.com | O6: 46026 | S6: 8-257-865 | T6: MASIVO | U6: NPN | V6: =_xlfn.XLOOKUP(UTILIZADAS[[#This Row],[Contacto1]],Tabla2[phone_number_dialed],Tabla2[status_name],,0) -> #N/A
A7: Cobros Abril Canal Fijo | B7: MARIO AUGUSTO ARJONA ARJONA | C7: 352335700000 | D7: Cobros Abril Canal Fijo 2 meses a NPN | E7: =+_xlfn.XLOOKUP(UTILIZADAS[[#This Row],[Numero_Cuenta]],'[1]cobros_marzo (fijo)'!$B:$B,'[1]cobros_marzo (fijo)'!$D:$D,,0) -> PANAMA | G7: 46026 | H7: 65117775 | I7: 65117775 | K7: marioarjona1956@gmail.com | O7: 46026 | S7: 6-41-2503 | T7: MASIVO | U7: NPN | V7: =_xlfn.XLOOKUP(UTILIZADAS[[#This Row],[Contacto1]],Tabla2[phone_number_dialed],Tabla2[status_name],,0) -> #N/A
A8: Cobros Abril Canal Fijo | B8: Edith Montes | C8: 357338020000 | D8: Cobros Abril Canal Fijo 2 meses a NPN | E8: =+_xlfn.XLOOKUP(UTILIZADAS[[#This Row],[Numero_Cuenta]],'[1]cobros_marzo (fijo)'!$B:$B,'[1]cobros_marzo (fijo)'!$D:$D,,0) -> HERRERA | G8: 46026 | H8: 63822556 | I8: 63822556 | K8: Edithmontes300@gmail.com | O8: 46026 | S8: 9-742-14 | T8: MASIVO | U8: NPN | V8: =_xlfn.XLOOKUP(UTILIZADAS[[#This Row],[Contacto1]],Tabla2[phone_number_dialed],Tabla2[status_name],,0) -> #N/A
A9: Cobros Abril Canal Fijo | B9: CARLOSENRIQUE DOMINGUEZVERGARA | C9: 359339470000 | D9: Cobros Abril Canal Fijo 2 meses a NPN | E9: =+_xlfn.XLOOKUP(UTILIZADAS[[#This Row],[Numero_Cuenta]],'[1]cobros_marzo (fijo)'!$B:$B,'[1]cobros_marzo (fijo)'!$D:$D,,0) -> VERAGUAS | G9: 46026 | H9: 63701410 | I9: 63701410 | K9: Cdominguezvergara939@gmail.com | O9: 46026 | S9: 8-796-2451 | T9: MASIVO | U9: NPN | V9: =_xlfn.XLOOKUP(UTILIZADAS[[#This Row],[Contacto1]],Tabla2[phone_number_dialed],Tabla2[status_name],,0) -> #N/A
A10: Cobros Abril Canal Fijo | B10: Nelis Pérez Jiménez | C10: 356338650000 | D10: Cobros Abril Canal Fijo 2 meses a NPN | E10: =+_xlfn.XLOOKUP(UTILIZADAS[[#This Row],[Numero_Cuenta]],'[1]cobros_marzo (fijo)'!$B:$B,'[1]cobros_marzo (fijo)'!$D:$D,,0) -> PANAMA | G10: 46026 | H10: 64205199 | I10: 64205199 | K10: nelisperez955@gmail.com | O10: 46026 | S10: 8-969-831 | T10: MASIVO | U10: NPN | V10: =_xlfn.XLOOKUP(UTILIZADAS[[#This Row],[Contacto1]],Tabla2[phone_number_dialed],Tabla2[status_name],,0) -> #N/A
A11: Cobros Abril Canal Fijo | B11: Luz Mina solis diaz | C11: 369328670000 | D11: Cobros Abril Canal Fijo 2 meses a NPN | E11: =+_xlfn.XLOOKUP(UTILIZADAS[[#This Row],[Numero_Cuenta]],'[1]cobros_marzo (fijo)'!$B:$B,'[1]cobros_marzo (fijo)'!$D:$D,,0) -> 0 | G11: 46026 | H11: 66330979 | I11: 66330979 | K11: diaslineth73@gmail.com | O11: 46026 | S11: 8-897-1143 | T11: MASIVO | U11: NPN | V11: =_xlfn.XLOOKUP(UTILIZADAS[[#This Row],[Contacto1]],Tabla2[phone_number_dialed],Tabla2[status_name],,0) -> #N/A
A12: Cobros Abril Canal Fijo | B12: Gloria Saday Peralta Espino | C12: 355318600000 | D12: Cobros Abril Canal Fijo 2 meses a NPN | E12: =+_xlfn.XLOOKUP(UTILIZADAS[[#This Row],[Numero_Cuenta]],'[1]cobros_marzo (fijo)'!$B:$B,'[1]cobros_marzo (fijo)'!$D:$D,,0) -> PANAMA | G12: 46026 | H12: 63498225 | I12: 63498225 | K12: 06.alayna@gmail.com | O12: 46026 | S12: 8-1043-2239 | T12: MASIVO | U12: NPN | V12: =_xlfn.XLOOKUP(UTILIZADAS[[#This Row],[Contacto1]],Tabla2[phone_number_dialed],Tabla2[status_name],,0) -> #N/A
A13: Cobros Abril Canal Fijo | B13: Disleydis quintero | C13: 356340020000 | D13: Cobros Abril Canal Fijo 2 meses a NPN | E13: =+_xlfn.XLOOKUP(UTILIZADAS[[#This Row],[Numero_Cuenta]],'[1]cobros_marzo (fijo)'!$B:$B,'[1]cobros_marzo (fijo)'!$D:$D,,0) -> PANAMA | G13: 46026 | H13: 67778877 | I13: 67778877 | K13: Disleydiquintero@gmail.com | O13: 46026 | S13: 8-1033-671 | T13: MASIVO | U13: NPN | V13: =_xlfn.XLOOKUP(UTILIZADAS[[#This Row],[Contacto1]],Tabla2[phone_number_dialed],Tabla2[status_name],,0) -> #N/A
... A189: Cobros Abril Canal Fijo | B189: EMIDIO ROBINSON GARCIA | C189: 351354250000 | D189: Cobros Abril Canal Fijo 2 meses a NPN | E189: =+_xlfn.XLOOKUP(UTILIZADAS[[#This Row],[Numero_Cuenta]],'[1]cobros_marzo (fijo)'!$B:$B,'[1]cobros_marzo (fijo)'!$D:$D,,0) -> CHIRIQUI | G189: 46026 | H189: 67369139 | I189: 67369139 | K189: Emidiorobinson@gmail.com | O189: 46026 | S189: 10-708-2196 | T189: MASIVO | U189: NPN | V189: =_xlfn.XLOOKUP(UTILIZADAS[[#This Row],[Contacto1]],Tabla2[phone_number_dialed],Tabla2[status_name],,0) -> #N/A
A190: Cobros Abril Canal Fijo | B190: María Aleida Cooper | C190: 351353940000 | D190: Cobros Abril Canal Fijo 2 meses a NPN | E190: =+_xlfn.XLOOKUP(UTILIZADAS[[#This Row],[Numero_Cuenta]],'[1]cobros_marzo (fijo)'!$B:$B,'[1]cobros_marzo (fijo)'!$D:$D,,0) -> PANAMA | G190: 46026 | H190: 68244153 | I190: 68244153 | K190: patricia5042056601@gmail.com | O190: 46026 | S190: 570783804 | T190: MASIVO | U190: NPN | V190: =_xlfn.XLOOKUP(UTILIZADAS[[#This Row],[Contacto1]],Tabla2[phone_number_dialed],Tabla2[status_name],,0) -> #N/A
A191: Cobros Abril Canal Fijo | B191: Gerson Ney Lasso Balanta | C191: 354352440000 | D191: Cobros Abril Canal Fijo 2 meses a NPN | E191: =+_xlfn.XLOOKUP(UTILIZADAS[[#This Row],[Numero_Cuenta]],'[1]cobros_marzo (fijo)'!$B:$B,'[1]cobros_marzo (fijo)'!$D:$D,,0) -> PANAMA | G191: 46026 | H191: 69054703 | I191: 69054703 | K191: Lassogerson35@gmail.com | O191: 46026 | S191: FB662738 | T191: MASIVO | U191: NPN | V191: =_xlfn.XLOOKUP(UTILIZADAS[[#This Row],[Contacto1]],Tabla2[phone_number_dialed],Tabla2[status_name],,0) -> #N/A
A192: Cobros Abril Canal Fijo | B192: KAREN CAMACHO | C192: 358348350000 | D192: Cobros Abril Canal Fijo 2 meses a NPN | E192: =+_xlfn.XLOOKUP(UTILIZADAS[[#This Row],[Numero_Cuenta]],'[1]cobros_marzo (fijo)'!$B:$B,'[1]cobros_marzo (fijo)'!$D:$D,,0) -> COLON | G192: 46026 | H192: 67787532 | I192: 67787532 | K192: Barcenaseder58@gmail.com | O192: 46026 | S192: 3-743-363 | T192: MASIVO | U192: NPN | V192: =_xlfn.XLOOKUP(UTILIZADAS[[#This Row],[Contacto1]],Tabla2[phone_number_dialed],Tabla2[status_name],,0) -> #N/A
A193: Cobros Abril Canal Fijo | B193: Rony garcia | C193: 359354680000 | D193: Cobros Abril Canal Fijo 2 meses a NPN | E193: =+_xlfn.XLOOKUP(UTILIZADAS[[#This Row],[Numero_Cuenta]],'[1]cobros_marzo (fijo)'!$B:$B,'[1]cobros_marzo (fijo)'!$D:$D,,0) -> COLON | G193: 46026 | H193: 61669203 | I193: 61669203 | K193: ronygarcia24@gmail.com | O193: 46026 | S193: 8-1047-2365 | T193: MASIVO | U193: NPN | V193: =_xlfn.XLOOKUP(UTILIZADAS[[#This Row],[Contacto1]],Tabla2[phone_number_dialed],Tabla2[status_name],,0) -> #N/A
A194: Cobros Abril Canal Fijo | B194: Sofía Navarro | C194: 357335980000 | D194: Cobros Abril Canal Fijo 2 meses a NPN | E194: =+_xlfn.XLOOKUP(UTILIZADAS[[#This Row],[Numero_Cuenta]],'[1]cobros_marzo (fijo)'!$B:$B,'[1]cobros_marzo (fijo)'!$D:$D,,0) -> PANAMA | G194: 46026 | H194: 62665510 | I194: 62665510 | K194: sofiadenavarro@gmail.com | O194: 46026 | S194: AX939366 | T194: SOHO | U194: NPN | V194: =_xlfn.XLOOKUP(UTILIZADAS[[#This Row],[Contacto1]],Tabla2[phone_number_dialed],Tabla2[status_name],,0) -> #N/A
A195: Cobros Abril Canal Fijo | B195: Karen Vergara | C195: 354352630000 | D195: Cobros Abril Canal Fijo 2 meses a NPN | E195: =+_xlfn.XLOOKUP(UTILIZADAS[[#This Row],[Numero_Cuenta]],'[1]cobros_marzo (fijo)'!$B:$B,'[1]cobros_marzo (fijo)'!$D:$D,,0) -> PANAMA | G195: 46026 | H195: 68162584 | I195: 68162584 | K195: kvergara0328@gmail.com | O195: 46026 | S195: 8-998-2253 | T195: MASIVO | U195: NPN | V195: =_xlfn.XLOOKUP(UTILIZADAS[[#This Row],[Contacto1]],Tabla2[phone_number_dialed],Tabla2[status_name],,0) -> #N/A
A196: Cobros Abril Canal Fijo | B196: CESAR GONZALEZ | C196: 356353170000 | D196: Cobros Abril Canal Fijo 2 meses a NPN | E196: =+_xlfn.XLOOKUP(UTILIZADAS[[#This Row],[Numero_Cuenta]],'[1]cobros_marzo (fijo)'!$B:$B,'[1]cobros_marzo (fijo)'!$D:$D,,0) -> HERRERA | G196: 46026 | H196: 68462020 | I196: 68462020 | K196: Eutimiaguerra213@gmail.com | O196: 46026 | S196: 9-61-437 | T196: MASIVO | U196: NPN | V196: =_xlfn.XLOOKUP(UTILIZADAS[[#This Row],[Contacto1]],Tabla2[phone_number_dialed],Tabla2[status_name],,0) -> #N/A
A197: Cobros Abril Canal Fijo | B197: Cecibel rios | C197: 357353980000 | D197: Cobros Abril Canal Fijo 2 meses a NPN | E197: =+_xlfn.XLOOKUP(UTILIZADAS[[#This Row],[Numero_Cuenta]],'[1]cobros_marzo (fijo)'!$B:$B,'[1]cobros_marzo (fijo)'!$D:$D,,0) -> VERAGUAS | G197: 46026 | H197: 65279813 | I197: 65279813 | K197: crios3131@hotmail.com | O197: 46026 | S197: 8-303-7 | T197: MASIVO | U197: NPN | V197: =_xlfn.XLOOKUP(UTILIZADAS[[#This Row],[Contacto1]],Tabla2[phone_number_dialed],Tabla2[status_name],,0) -> #N/A
A198: Cobros Abril Canal Fijo | B198: Alexandra Raquel Mora Quijano | C198: 357353490000 | D198: Cobros Abril Canal Fijo 2 meses a NPN | E198: =+_xlfn.XLOOKUP(UTILIZADAS[[#This Row],[Numero_Cuenta]],'[1]cobros_marzo (fijo)'!$B:$B,'[1]cobros_marzo (fijo)'!$D:$D,,0) -> PANAMA | G198: 46026 | H198: 67011734 | I198: 67011734 | K198: lilymoraquijano1705@gmail.com | O198: 46026 | S198: 4-763-1902 | T198: MASIVO | U198: NPN | V198: =_xlfn.XLOOKUP(UTILIZADAS[[#This Row],[Contacto1]],Tabla2[phone_number_dialed],Tabla2[status_name],,0) -> #N/A
A199: Cobros Abril Canal Fijo | B199: YENITZEL ARGELYS AGUILAR SANTOS | C199: 351355390000 | D199: Cobros Abril Canal Fijo 2 meses a NPN | E199: =+_xlfn.XLOOKUP(UTILIZADAS[[#This Row],[Numero_Cuenta]],'[1]cobros_marzo (fijo)'!$B:$B,'[1]cobros_marzo (fijo)'!$D:$D,,0) -> CHIRIQUI | G199: 46026 | H199: 61948388 | I199: 61948388 | K199: msantoscontrera@gmail.com | O199: 46026 | S199: 4-827-1762 | T199: MASIVO | U199: NPN | V199: =_xlfn.XLOOKUP(UTILIZADAS[[#This Row],[Contacto1]],Tabla2[phone_number_dialed],Tabla2[status_name],,0) -> #N/A
A200: Cobros Abril Canal Fijo | B200: ESTEBAN GARY ROJAS | C200: 357355760000 | D200: Cobros Abril Canal Fijo 2 meses a NPN | E200: =+_xlfn.XLOOKUP(UTILIZADAS[[#This Row],[Numero_Cuenta]],'[1]cobros_marzo (fijo)'!$B:$B,'[1]cobros_marzo (fijo)'!$D:$D,,0) -> CHIRIQUI | G200: 46026 | H200: 68930634 | I200: 68930634 | K200: mariadegary1959@gmail.com | O200: 46026 | S200: 3-42-581 | T200: MASIVO | U200: NPN | V200: =_xlfn.XLOOKUP(UTILIZADAS[[#This Row],[Contacto1]],Tabla2[phone_number_dialed],Tabla2[status_name],,0) -> #N/A
A201: Cobros Abril Canal Fijo | B201: Enilda Yuribel Perrz Ruiz | C201: 354354860000 | D201: Cobros Abril Canal Fijo 2 meses a NPN | E201: =+_xlfn.XLOOKUP(UTILIZADAS[[#This Row],[Numero_Cuenta]],'[1]cobros_marzo (fijo)'!$B:$B,'[1]cobros_marzo (fijo)'!$D:$D,,0) -> CHIRIQUI | G201: 46026 | H201: 68366223 | I201: 68366223 | K201: eperez@corromaduro.com | O201: 46026 | S201: 9-734-1467 | T201: MASIVO | U201: NPN | V201: =_xlfn.XLOOKUP(UTILIZADAS[[#This Row],[Contacto1]],Tabla2[phone_number_dialed],Tabla2[status_name],,0) -> #N/A
A202: Cobros Abril Canal Fijo | B202: Horacia solis | C202: 356789050000 | D202: Cobros Abril Canal Fijo 2 meses a NPN | E202: =+_xlfn.XLOOKUP(UTILIZADAS[[#This Row],[Numero_Cuenta]],'[1]cobros_marzo (fijo)'!$B:$B,'[1]cobros_marzo (fijo)'!$D:$D,,0) -> PANAMA | G202: 46026 | H202: 67890453 | I202: 67890453 | K202: juancarlos@gmail.com | O202: 46026 | S202: 9-139-25 | T202: MASIVO | U202: NPN | V202: =_xlfn.XLOOKUP(UTILIZADAS[[#This Row],[Contacto1]],Tabla2[phone_number_dialed],Tabla2[status_name],,0) -> Buzon de voz
... A243: Cobros Abril Canal Fijo | B243: Alan Yeison Castillo Ruiz | C243: 358358400000 | D243: Cobros Abril Canal Fijo 2 meses a NPN | E243: =+_xlfn.XLOOKUP(UTILIZADAS[[#This Row],[Numero_Cuenta]],'[1]cobros_marzo (fijo)'!$B:$B,'[1]cobros_marzo (fijo)'!$D:$D,,0) -> 0 | G243: 46026 | H243: 69799498 | I243: 69799498 | K243: josekeran@gmail.com | O243: 46026 | S243: 8-912-1027 | T243: MASIVO | U243: NPN | V243: =_xlfn.XLOOKUP(UTILIZADAS[[#This Row],[Contacto1]],Tabla2[phone_number_dialed],Tabla2[status_name],,0) -> #N/A
A244: Cobros Abril Canal Fijo | B244: Yenifer Michelle ruiz Duarte | C244: 352358100000 | D244: Cobros Abril Canal Fijo 2 meses a NPN | E244: =+_xlfn.XLOOKUP(UTILIZADAS[[#This Row],[Numero_Cuenta]],'[1]cobros_marzo (fijo)'!$B:$B,'[1]cobros_marzo (fijo)'!$D:$D,,0) -> 0 | G244: 46026 | H244: 64178091 | I244: 64178091 | K244: ruizyenifer905@gmail.com | O244: 46026 | S244: 9762438 | T244: MASIVO | U244: NPN | V244: =_xlfn.XLOOKUP(UTILIZADAS[[#This Row],[Contacto1]],Tabla2[phone_number_dialed],Tabla2[status_name],,0) -> #N/A
A245: Cobros Abril Canal Fijo | B245: Isidra Méndez barsallo | C245: 354359510000 | D245: Cobros Abril Canal Fijo 2 meses a NPN | E245: =+_xlfn.XLOOKUP(UTILIZADAS[[#This Row],[Numero_Cuenta]],'[1]cobros_marzo (fijo)'!$B:$B,'[1]cobros_marzo (fijo)'!$D:$D,,0) -> 0 | G245: 46026 | H245: 66641321 | I245: 66641321 | K245: mendeznba13@gmail.com | O245: 46026 | S245: 9-66-513 | T245: MASIVO | U245: NPN | V245: =_xlfn.XLOOKUP(UTILIZADAS[[#This Row],[Contacto1]],Tabla2[phone_number_dialed],Tabla2[status_name],,0) -> #N/A
A246: Cobros Abril Canal Fijo | B246: Irving Virgilio Perez Madrid | C246: 352343340000 | D246: Cobros Abril Canal Fijo 2 meses a NPN | E246: =+_xlfn.XLOOKUP(UTILIZADAS[[#This Row],[Numero_Cuenta]],'[1]cobros_marzo (fijo)'!$B:$B,'[1]cobros_marzo (fijo)'!$D:$D,,0) -> 0 | G246: 46026 | H246: 68010681 | I246: 68010681 | K246: Vergararosaalicia@gmail.com | O246: 46026 | S246: 8-870-2359 | T246: MASIVO | U246: NPN | V246: =_xlfn.XLOOKUP(UTILIZADAS[[#This Row],[Contacto1]],Tabla2[phone_number_dialed],Tabla2[status_name],,0) -> #N/A
A247: Cobros Abril Canal Fijo | B247: William Solis Clement | C247: 354360650000 | D247: Cobros Abril Canal Fijo 2 meses a NPN | E247: =+_xlfn.XLOOKUP(UTILIZADAS[[#This Row],[Numero_Cuenta]],'[1]cobros_marzo (fijo)'!$B:$B,'[1]cobros_marzo (fijo)'!$D:$D,,0) -> 0 | G247: 46026 | H247: 61016174 | I247: 61016174 | K247: idilciaortega049@gmail.com | O247: 46026 | S247: 10-32-500 | T247: MASIVO | U247: NPN | V247: =_xlfn.XLOOKUP(UTILIZADAS[[#This Row],[Contacto1]],Tabla2[phone_number_dialed],Tabla2[status_name],,0) -> #N/A
A248: Cobros Abril Canal Fijo | B248: Mavelyn palacio | C248: 357334100000 | D248: Cobros Abril Canal Fijo 2 meses a NPN | E248: =+_xlfn.XLOOKUP(UTILIZADAS[[#This Row],[Numero_Cuenta]],'[1]cobros_marzo (fijo)'!$B:$B,'[1]cobros_marzo (fijo)'!$D:$D,,0) -> 0 | G248: 46026 | H248: 66839768 | I248: 66839768 | K248: Palaciomabelin346@gmail.com | O248: 46026 | S248: 5-716-2130 | T248: MASIVO | U248: NPN | V248: =_xlfn.XLOOKUP(UTILIZADAS[[#This Row],[Contacto1]],Tabla2[phone_number_dialed],Tabla2[status_name],,0) -> #N/A
A249: Cobros Abril Canal Fijo | B249: Nasaret masckill Tenorio | C249: 358355590000 | D249: Cobros Abril Canal Fijo 2 meses a NPN | E249: =+_xlfn.XLOOKUP(UTILIZADAS[[#This Row],[Numero_Cuenta]],'[1]cobros_marzo (fijo)'!$B:$B,'[1]cobros_marzo (fijo)'!$D:$D,,0) -> 0 | G249: 46026 | H249: 63321872 | I249: 63321872 | K249: tenorio.06@outlook.com | O249: 46026 | S249: 9-749-486 | T249: MASIVO | U249: NPN | V249: =_xlfn.XLOOKUP(UTILIZADAS[[#This Row],[Contacto1]],Tabla2[phone_number_dialed],Tabla2[status_name],,0) -> No Answer AutoDial
A250: Cobros Abril Canal Fijo | B250: Julieth Ortega | C250: 357082970000 | D250: Cobros Abril Canal Fijo 2 meses a NPN | E250: =+_xlfn.XLOOKUP(UTILIZADAS[[#This Row],[Numero_Cuenta]],'[1]cobros_marzo (fijo)'!$B:$B,'[1]cobros_marzo (fijo)'!$D:$D,,0) -> 0 | G250: 46026 | H250: 67030325 | I250: 67030325 | K250: juliethdelrosario@gmail.com | O250: 46026 | S250: 8-927-546 | T250: MASIVO | U250: NPN | V250: =_xlfn.XLOOKUP(UTILIZADAS[[#This Row],[Contacto1]],Tabla2[phone_number_dialed],Tabla2[status_name],,0) -> #N/A
A251: Cobros Abril Canal Fijo | B251: Angel lorenzo | C251: 354358380000 | D251: Cobros Abril Canal Fijo 2 meses a NPN | E251: =+_xlfn.XLOOKUP(UTILIZADAS[[#This Row],[Numero_Cuenta]],'[1]cobros_marzo (fijo)'!$B:$B,'[1]cobros_marzo (fijo)'!$D:$D,,0) -> 0 | G251: 46026 | H251: 68906543 | I251: 68906543 | K251: tribaldoszadkiel88@gmail.com | O251: 46026 | S251: 2-162-764 | T251: MASIVO | U251: NPN | V251: =_xlfn.XLOOKUP(UTILIZADAS[[#This Row],[Contacto1]],Tabla2[phone_number_dialed],Tabla2[status_name],,0) -> Agent Not Available
A252: Cobros Abril Canal Fijo | B252: Eduardo Abel Iturralde Duarte | C252: 353360370000 | D252: Cobros Abril Canal Fijo 2 meses a NPN | E252: =+_xlfn.XLOOKUP(UTILIZADAS[[#This Row],[Numero_Cuenta]],'[1]cobros_marzo (fijo)'!$B:$B,'[1]cobros_marzo (fijo)'!$D:$D,,0) -> 0 | G252: 46026 | H252: 65880586 | I252: 65880586 | K252: iturraldee053@gmail.com | O252: 46026 | S252: 8-444-381 | T252: SOHO | U252: NPN | V252: =_xlfn.XLOOKUP(UTILIZADAS[[#This Row],[Contacto1]],Tabla2[phone_number_dialed],Tabla2[status_name],,0) -> Agent Not Available
A253: Cobros Abril Canal Fijo | B253: Maryerlin Ballesteros | C253: 352351310000 | D253: Cobros Abril Canal Fijo 2 meses a NPN | E253: =+_xlfn.XLOOKUP(UTILIZADAS[[#This Row],[Numero_Cuenta]],'[1]cobros_marzo (fijo)'!$B:$B,'[1]cobros_marzo (fijo)'!$D:$D,,0) -> 0 | G253: 46026 | H253: 68981704 | I253: 68981704 | K253: maryerlingb@gmail.com | O253: 46026 | S253: 2-731-577 | T253: MASIVO | U253: NPN | V253: =_xlfn.XLOOKUP(UTILIZADAS[[#This Row],[Contacto1]],Tabla2[phone_number_dialed],Tabla2[status_name],,0) -> #N/A
A254: Cobros Abril Canal Fijo | B254: Mariela Atencio barria de Aparicio | C254: 354278250000 | D254: Cobros Abril Canal Fijo 2 meses a NPN | E254: =+_xlfn.XLOOKUP(UTILIZADAS[[#This Row],[Numero_Cuenta]],'[1]cobros_marzo (fijo)'!$B:$B,'[1]cobros_marzo (fijo)'!$D:$D,,0) -> 0 | G254: 46026 | H254: 61598243 | I254: 61598243 | K254: Lupiita33343@gmail.com | O254: 46026 | S254: 6-701-40 | T254: MASIVO | U254: NPN | V254: =_xlfn.XLOOKUP(UTILIZADAS[[#This Row],[Contacto1]],Tabla2[phone_number_dialed],Tabla2[status_name],,0) -> Auto busy
A255: Cobros Abril Canal Fijo | B255: Mariela Atencio barria de Aparicio | C255: 354278250000 | D255: Cobros Abril Canal Fijo 2 meses a NPN | E255: =+_xlfn.XLOOKUP(UTILIZADAS[[#This Row],[Numero_Cuenta]],'[1]cobros_marzo (fijo)'!$B:$B,'[1]cobros_marzo (fijo)'!$D:$D,,0) -> 0 | G255: 46026 | H255: 61598243 | I255: 61598243 | K255: Lupiita33344@gmail.com | O255: 46026 | S255: 6-701-40 | T255: MASIVO | U255: NPN | V255: =_xlfn.XLOOKUP(UTILIZADAS[[#This Row],[Contacto1]],Tabla2[phone_number_dialed],Tabla2[status_name],,0) -> Auto busy
...

Sheet Promesas se pago dinero
A1: Fecha | B1: Marca temporal | C1: Agente | D1: Numero celular | E1: Cuenta | F1: Identificación (cedula) | G1: Campaña | H1: Canal | I1: Escenario | J1: Motivo | K1: Fecha promesa de pago | L1: Monto de promesa de pago | M1: Realiza el pago | N1: Fecha de Pago | O1: Monto pagado | P1: Tiempo de mora (días) | Q1: Campaña | R1: Mes Pago | S1: Mes Promesa | T1: Dia Pago | U1: Dia Promesa | V1: Intentos de Promesas | W1: Intentos de pago
A2: =TEXT(promesas[[#This Row],[Marca temporal]],"dd/mmm") -> 04/may | B2: 46146.426 | C2: Lili Velez | D2: 68503631 | E2: 366022500000 | F2: 10-717-221 | G2: Fijo | H2: Masivo (D2D) | I2: Correo de voz | M2: no | P2: 3 MESES PENDIENTES | R2: =IF(promesas[[#This Row],[Fecha de Pago]]="", "", TEXT(promesas[[#This Row],[Fecha de Pago]], "mmm")) | S2: =IF(promesas[[#This Row],[Fecha promesa de pago]]="", "", TEXT(promesas[[#This Row],[Fecha promesa de pago]], "mmm")) | T2: =IF(promesas[[#This Row],[Fecha de Pago]]="", "", TEXT(promesas[[#This Row],[Fecha de Pago]], "dd/mmm")) | U2: =IF(promesas[[#This Row],[Fecha promesa de pago]]="", "", TEXT(promesas[[#This Row],[Fecha promesa de pago]], "dd/mmm")) | V2: =IF(LEN(TRIM(promesas[[#This Row],[Fecha promesa de pago]]))>0,1,"") | W2: =IF(LEN(TRIM(promesas[[#This Row],[Fecha de Pago]]))>0,1,"")
A3: =TEXT(promesas[[#This Row],[Marca temporal]],"dd/mmm") -> 04/may | B3: 46146.434 | C3: Lili Velez | D3: 66293335 | E3: 363026120000 | F3: 9-755-801 | G3: Fijo | H3: Masivo (D2D) | I3: Correo de voz | M3: no | P3: 3 MESES PENDIENTES | R3: =IF(promesas[[#This Row],[Fecha de Pago]]="", "", TEXT(promesas[[#This Row],[Fecha de Pago]], "mmm")) | S3: =IF(promesas[[#This Row],[Fecha promesa de pago]]="", "", TEXT(promesas[[#This Row],[Fecha promesa de pago]], "mmm")) | T3: =IF(promesas[[#This Row],[Fecha de Pago]]="", "", TEXT(promesas[[#This Row],[Fecha de Pago]], "dd/mmm")) | U3: =IF(promesas[[#This Row],[Fecha promesa de pago]]="", "", TEXT(promesas[[#This Row],[Fecha promesa de pago]], "dd/mmm")) | V3: =IF(LEN(TRIM(promesas[[#This Row],[Fecha promesa de pago]]))>0,1,"") | W3: =IF(LEN(TRIM(promesas[[#This Row],[Fecha de Pago]]))>0,1,"")
A4: =TEXT(promesas[[#This Row],[Marca temporal]],"dd/mmm") -> 04/may | B4: 46146.441 | C4: Lili Velez | D4: 67450828 | E4: 357317130000 | F4: 10-716-744 | G4: Fijo | H4: Masivo (D2D) | I4: Correo de voz | M4: no | P4: 2 MESES PENDIENTES | R4: =IF(promesas[[#This Row],[Fecha de Pago]]="", "", TEXT(promesas[[#This Row],[Fecha de Pago]], "mmm")) | S4: =IF(promesas[[#This Row],[Fecha promesa de pago]]="", "", TEXT(promesas[[#This Row],[Fecha promesa de pago]], "mmm")) | T4: =IF(promesas[[#This Row],[Fecha de Pago]]="", "", TEXT(promesas[[#This Row],[Fecha de Pago]], "dd/mmm")) | U4: =IF(promesas[[#This Row],[Fecha promesa de pago]]="", "", TEXT(promesas[[#This Row],[Fecha promesa de pago]], "dd/mmm")) | V4: =IF(LEN(TRIM(promesas[[#This Row],[Fecha promesa de pago]]))>0,1,"") | W4: =IF(LEN(TRIM(promesas[[#This Row],[Fecha de Pago]]))>0,1,"")
A5: =TEXT(promesas[[#This Row],[Marca temporal]],"dd/mmm") -> 04/may | B5: 46146.446 | C5: Lili Velez | D5: 68612220 | E5: 352368230000 | F5: 8-992-495 | G5: Fijo | H5: Masivo (D2D) | I5: Mensaje a tercero | M5: no | P5: 2 MESES PENDIENTES | R5: =IF(promesas[[#This Row],[Fecha de Pago]]="", "", TEXT(promesas[[#This Row],[Fecha de Pago]], "mmm")) | S5: =IF(promesas[[#This Row],[Fecha promesa de pago]]="", "", TEXT(promesas[[#This Row],[Fecha promesa de pago]], "mmm")) | T5: =IF(promesas[[#This Row],[Fecha de Pago]]="", "", TEXT(promesas[[#This Row],[Fecha de Pago]], "dd/mmm")) | U5: =IF(promesas[[#This Row],[Fecha promesa de pago]]="", "", TEXT(promesas[[#This Row],[Fecha promesa de pago]], "dd/mmm")) | V5: =IF(LEN(TRIM(promesas[[#This Row],[Fecha promesa de pago]]))>0,1,"") | W5: =IF(LEN(TRIM(promesas[[#This Row],[Fecha de Pago]]))>0,1,"")
A6: =TEXT(promesas[[#This Row],[Marca temporal]],"dd/mmm") -> 04/may | B6: 46146.461 | C6: Lili Velez | D6: 62389137 | E6: 362010140000 | F6: 8-825-575 | G6: Fijo | H6: Masivo (D2D) | I6: Correo de voz | M6: no | P6: 1 MES PENDIENTE | R6: =IF(promesas[[#This Row],[Fecha de Pago]]="", "", TEXT(promesas[[#This Row],[Fecha de Pago]], "mmm")) | S6: =IF(promesas[[#This Row],[Fecha promesa de pago]]="", "", TEXT(promesas[[#This Row],[Fecha promesa de pago]], "mmm")) | T6: =IF(promesas[[#This Row],[Fecha de Pago]]="", "", TEXT(promesas[[#This Row],[Fecha de Pago]], "dd/mmm")) | U6: =IF(promesas[[#This Row],[Fecha promesa de pago]]="", "", TEXT(promesas[[#This Row],[Fecha promesa de pago]], "dd/mmm")) | V6: =IF(LEN(TRIM(promesas[[#This Row],[Fecha promesa de pago]]))>0,1,"") | W6: =IF(LEN(TRIM(promesas[[#This Row],[Fecha de Pago]]))>0,1,"")
A7: =TEXT(promesas[[#This Row],[Marca temporal]],"dd/mmm") -> 04/may | B7: 46146.466 | C7: Lili Velez | D7: 63645460 | E7: 359347200000 | F7: 8-876-1341 | G7: Fijo | H7: Masivo (D2D) | I7: Correo de voz | M7: no | P7: 2 MESES PENDIENTES | R7: =IF(promesas[[#This Row],[Fecha de Pago]]="", "", TEXT(promesas[[#This Row],[Fecha de Pago]], "mmm")) | S7: =IF(promesas[[#This Row],[Fecha promesa de pago]]="", "", TEXT(promesas[[#This Row],[Fecha promesa de pago]], "mmm")) | T7: =IF(promesas[[#This Row],[Fecha de Pago]]="", "", TEXT(promesas[[#This Row],[Fecha de Pago]], "dd/mmm")) | U7: =IF(promesas[[#This Row],[Fecha promesa de pago]]="", "", TEXT(promesas[[#This Row],[Fecha promesa de pago]], "dd/mmm")) | V7: =IF(LEN(TRIM(promesas[[#This Row],[Fecha promesa de pago]]))>0,1,"") | W7: =IF(LEN(TRIM(promesas[[#This Row],[Fecha de Pago]]))>0,1,"")
A8: =TEXT(promesas[[#This Row],[Marca temporal]],"dd/mmm") -> 04/may | B8: 46146.472 | C8: Lili Velez | D8: 66634767 | E8: 152071270000 | F8: 8-357-660 | G8: Fijo | H8: Masivo (D2D) | I8: Cliente al dia | M8: si | N8: 46142 | O8: 40.82 | P8: 2 MESES PENDIENTES | R8: =IF(promesas[[#This Row],[Fecha de Pago]]="", "", TEXT(promesas[[#This Row],[Fecha de Pago]], "mmm")) -> abr | S8: =IF(promesas[[#This Row],[Fecha promesa de pago]]="", "", TEXT(promesas[[#This Row],[Fecha promesa de pago]], "mmm")) | T8: =IF(promesas[[#This Row],[Fecha de Pago]]="", "", TEXT(promesas[[#This Row],[Fecha de Pago]], "dd/mmm")) -> 30/abr | U8: =IF(promesas[[#This Row],[Fecha promesa de pago]]="", "", TEXT(promesas[[#This Row],[Fecha promesa de pago]], "dd/mmm")) | V8: =IF(LEN(TRIM(promesas[[#This Row],[Fecha promesa de pago]]))>0,1,"") | W8: =IF(LEN(TRIM(promesas[[#This Row],[Fecha de Pago]]))>0,1,"") -> 1
A9: =TEXT(promesas[[#This Row],[Marca temporal]],"dd/mmm") -> 04/may | B9: 46146.487 | C9: Lili Velez | D9: 66047682 | E9: 361074360000 | F9: 8-956-716 | G9: Fijo | H9: Masivo (D2D) | I9: Contactado | K9: 46146 | L9: 37.52 | M9: no | P9: 1 MES PENDIENTE | R9: =IF(promesas[[#This Row],[Fecha de Pago]]="", "", TEXT(promesas[[#This Row],[Fecha de Pago]], "mmm")) | S9: =IF(promesas[[#This Row],[Fecha promesa de pago]]="", "", TEXT(promesas[[#This Row],[Fecha promesa de pago]], "mmm")) -> may | T9: =IF(promesas[[#This Row],[Fecha de Pago]]="", "", TEXT(promesas[[#This Row],[Fecha de Pago]], "dd/mmm")) | U9: =IF(promesas[[#This Row],[Fecha promesa de pago]]="", "", TEXT(promesas[[#This Row],[Fecha promesa de pago]], "dd/mmm")) -> 04/may | V9: =IF(LEN(TRIM(promesas[[#This Row],[Fecha promesa de pago]]))>0,1,"") -> 1 | W9: =IF(LEN(TRIM(promesas[[#This Row],[Fecha de Pago]]))>0,1,"")
A10: =TEXT(promesas[[#This Row],[Marca temporal]],"dd/mmm") -> 04/may | B10: 46146.492 | C10: Lili Velez | D10: 64320903 | E10: 352366440000 | F10: 4-277-831 | G10: Fijo | H10: Masivo (D2D) | I10: Contactado | M10: no | P10: 2 MESES PENDIENTES | R10: =IF(promesas[[#This Row],[Fecha de Pago]]="", "", TEXT(promesas[[#This Row],[Fecha de Pago]], "mmm")) | S10: =IF(promesas[[#This Row],[Fecha promesa de pago]]="", "", TEXT(promesas[[#This Row],[Fecha promesa de pago]], "mmm")) | T10: =IF(promesas[[#This Row],[Fecha de Pago]]="", "", TEXT(promesas[[#This Row],[Fecha de Pago]], "dd/mmm")) | U10: =IF(promesas[[#This Row],[Fecha promesa de pago]]="", "", TEXT(promesas[[#This Row],[Fecha promesa de pago]], "dd/mmm")) | V10: =IF(LEN(TRIM(promesas[[#This Row],[Fecha promesa de pago]]))>0,1,"") | W10: =IF(LEN(TRIM(promesas[[#This Row],[Fecha de Pago]]))>0,1,"")
A11: =TEXT(promesas[[#This Row],[Marca temporal]],"dd/mmm") -> 04/may | B11: 46146.497 | C11: Lili Velez | D11: 65441317 | E11: 358381400000 | F11: 8-989-2135 | G11: Fijo | H11: Soho | I11: Correo de voz | M11: no | P11: 2 MESES PENDIENTES | R11: =IF(promesas[[#This Row],[Fecha de Pago]]="", "", TEXT(promesas[[#This Row],[Fecha de Pago]], "mmm")) | S11: =IF(promesas[[#This Row],[Fecha promesa de pago]]="", "", TEXT(promesas[[#This Row],[Fecha promesa de pago]], "mmm")) | T11: =IF(promesas[[#This Row],[Fecha de Pago]]="", "", TEXT(promesas[[#This Row],[Fecha de Pago]], "dd/mmm")) | U11: =IF(promesas[[#This Row],[Fecha promesa de pago]]="", "", TEXT(promesas[[#This Row],[Fecha promesa de pago]], "dd/mmm")) | V11: =IF(LEN(TRIM(promesas[[#This Row],[Fecha promesa de pago]]))>0,1,"") | W11: =IF(LEN(TRIM(promesas[[#This Row],[Fecha de Pago]]))>0,1,"")
A12: =TEXT(promesas[[#This Row],[Marca temporal]],"dd/mmm") -> 04/may | B12: 46146.503 | C12: Lili Velez | D12: 66103004 | E12: 353339160000 | F12: 8-794-5030 | G12: Fijo | H12: Digital | I12: Contactado | K12: 46148 | L12: 79.65 | M12: no | P12: 4 MESES PENDIENTES | R12: =IF(promesas[[#This Row],[Fecha de Pago]]="", "", TEXT(promesas[[#This Row],[Fecha de Pago]], "mmm")) | S12: =IF(promesas[[#This Row],[Fecha promesa de pago]]="", "", TEXT(promesas[[#This Row],[Fecha promesa de pago]], "mmm")) -> may | T12: =IF(promesas[[#This Row],[Fecha de Pago]]="", "", TEXT(promesas[[#This Row],[Fecha de Pago]], "dd/mmm")) | U12: =IF(promesas[[#This Row],[Fecha promesa de pago]]="", "", TEXT(promesas[[#This Row],[Fecha promesa de pago]], "dd/mmm")) -> 06/may | V12: =IF(LEN(TRIM(promesas[[#This Row],[Fecha promesa de pago]]))>0,1,"") -> 1 | W12: =IF(LEN(TRIM(promesas[[#This Row],[Fecha de Pago]]))>0,1,"")
A13: =TEXT(promesas[[#This Row],[Marca temporal]],"dd/mmm") -> 04/may | B13: 46146.514 | C13: Lili Velez | D13: 67611194 | E13: 155078170000 | F13: 2-46-534 | G13: Fijo | H13: Masivo (D2D) | I13: Contactado | K13: 46146 | L13: 34.92 | M13: no | P13: 2 MESES PENDIENTES | R13: =IF(promesas[[#This Row],[Fecha de Pago]]="", "", TEXT(promesas[[#This Row],[Fecha de Pago]], "mmm")) | S13: =IF(promesas[[#This Row],[Fecha promesa de pago]]="", "", TEXT(promesas[[#This Row],[Fecha promesa de pago]], "mmm")) -> may | T13: =IF(promesas[[#This Row],[Fecha de Pago]]="", "", TEXT(promesas[[#This Row],[Fecha de Pago]], "dd/mmm")) | U13: =IF(promesas[[#This Row],[Fecha promesa de pago]]="", "", TEXT(promesas[[#This Row],[Fecha promesa de pago]], "dd/mmm")) -> 04/may | V13: =IF(LEN(TRIM(promesas[[#This Row],[Fecha promesa de pago]]))>0,1,"") -> 1 | W13: =IF(LEN(TRIM(promesas[[#This Row],[Fecha de Pago]]))>0,1,"")
A14: =TEXT(promesas[[#This Row],[Marca temporal]],"dd/mmm") -> 04/may | B14: 46146.522 | C14: Lili Velez | D14: 66386838 | E14: 364028530000 | F14: 167126182 | G14: Fijo | H14: Masivo (D2D) | I14: Correo de voz | M14: no | P14: 3 MESES PENDIENTES | R14: =IF(promesas[[#This Row],[Fecha de Pago]]="", "", TEXT(promesas[[#This Row],[Fecha de Pago]], "mmm")) | S14: =IF(promesas[[#This Row],[Fecha promesa de pago]]="", "", TEXT(promesas[[#This Row],[Fecha promesa de pago]], "mmm")) | T14: =IF(promesas[[#This Row],[Fecha de Pago]]="", "", TEXT(promesas[[#This Row],[Fecha de Pago]], "dd/mmm")) | U14: =IF(promesas[[#This Row],[Fecha promesa de pago]]="", "", TEXT(promesas[[#This Row],[Fecha promesa de pago]], "dd/mmm")) | V14: =IF(LEN(TRIM(promesas[[#This Row],[Fecha promesa de pago]]))>0,1,"") | W14: =IF(LEN(TRIM(promesas[[#This Row],[Fecha de Pago]]))>0,1,"")
A15: =TEXT(promesas[[#This Row],[Marca temporal]],"dd/mmm") -> 04/may | B15: 46146.528 | C15: Lili Velez | D15: 63026745 | E15: 366022910000 | F15: 8-1056-88 | G15: Fijo | H15: Masivo (D2D) | I15: No contactado | M15: no | P15: 3 MESES PENDIENTES | R15: =IF(promesas[[#This Row],[Fecha de Pago]]="", "", TEXT(promesas[[#This Row],[Fecha de Pago]], "mmm")) | S15: =IF(promesas[[#This Row],[Fecha promesa de pago]]="", "", TEXT(promesas[[#This Row],[Fecha promesa de pago]], "mmm")) | T15: =IF(promesas[[#This Row],[Fecha de Pago]]="", "", TEXT(promesas[[#This Row],[Fecha de Pago]], "dd/mmm")) | U15: =IF(promesas[[#This Row],[Fecha promesa de pago]]="", "", TEXT(promesas[[#This Row],[Fecha promesa de pago]], "dd/mmm")) | V15: =IF(LEN(TRIM(promesas[[#This Row],[Fecha promesa de pago]]))>0,1,"") | W15: =IF(LEN(TRIM(promesas[[#This Row],[Fecha de Pago]]))>0,1,"")
A16: =TEXT(promesas[[#This Row],[Marca temporal]],"dd/mmm") -> 04/may | B16: 46146.534 | C16: Lili Velez | D16: 63836298 | E16: 365022950000 | F16: 4-113-733 | G16: Fijo | H16: Masivo (D2D) | I16: Correo de voz | M16: no | P16: 2 MESES PENDIENTES | R16: =IF(promesas[[#This Row],[Fecha de Pago]]="", "", TEXT(promesas[[#This Row],[Fecha de Pago]], "mmm")) | S16: =IF(promesas[[#This Row],[Fecha promesa de pago]]="", "", TEXT(promesas[[#This Row],[Fecha promesa de pago]], "mmm")) | T16: =IF(promesas[[#This Row],[Fecha de Pago]]="", "", TEXT(promesas[[#This Row],[Fecha de Pago]], "dd/mmm")) | U16: =IF(promesas[[#This Row],[Fecha promesa de pago]]="", "", TEXT(promesas[[#This Row],[Fecha promesa de pago]], "dd/mmm")) | V16: =IF(LEN(TRIM(promesas[[#This Row],[Fecha promesa de pago]]))>0,1,"") | W16: =IF(LEN(TRIM(promesas[[#This Row],[Fecha de Pago]]))>0,1,"")
A17: =TEXT(promesas[[#This Row],[Marca temporal]],"dd/mmm") -> 04/may | B17: 46146.541 | C17: Lili Velez | D17: 63165778 | E17: 366023610000 | F17: 8-761-80 | G17: Fijo | H17: Masivo (D2D) | I17: Correo de voz | M17: no | P17: 3 MESES PENDIENTES | R17: =IF(promesas[[#This Row],[Fecha de Pago]]="", "", TEXT(promesas[[#This Row],[Fecha de Pago]], "mmm")) | S17: =IF(promesas[[#This Row],[Fecha promesa de pago]]="", "", TEXT(promesas[[#This Row],[Fecha promesa de pago]], "mmm")) | T17: =IF(promesas[[#This Row],[Fecha de Pago]]="", "", TEXT(promesas[[#This Row],[Fecha de Pago]], "dd/mmm")) | U17: =IF(promesas[[#This Row],[Fecha promesa de pago]]="", "", TEXT(promesas[[#This Row],[Fecha promesa de pago]], "dd/mmm")) | V17: =IF(LEN(TRIM(promesas[[#This Row],[Fecha promesa de pago]]))>0,1,"") | W17: =IF(LEN(TRIM(promesas[[#This Row],[Fecha de Pago]]))>0,1,"")
A18: =TEXT(promesas[[#This Row],[Marca temporal]],"dd/mmm") -> 04/may | B18: 46146.596 | C18: Lili Velez | D18: 62294843 | E18: 272063460000 | F18: 8-898-2194 | G18: Fijo | H18: Masivo (D2D) | I18: Correo de voz | M18: no | P18: 3 MESES PENDIENTES | R18: =IF(promesas[[#This Row],[Fecha de Pago]]="", "", TEXT(promesas[[#This Row],[Fecha de Pago]], "mmm")) | S18: =IF(promesas[[#This Row],[Fecha promesa de pago]]="", "", TEXT(promesas[[#This Row],[Fecha promesa de pago]], "mmm")) | T18: =IF(promesas[[#This Row],[Fecha de Pago]]="", "", TEXT(promesas[[#This Row],[Fecha de Pago]], "dd/mmm")) | U18: =IF(promesas[[#This Row],[Fecha promesa de pago]]="", "", TEXT(promesas[[#This Row],[Fecha promesa de pago]], "dd/mmm")) | V18: =IF(LEN(TRIM(promesas[[#This Row],[Fecha promesa de pago]]))>0,1,"") | W18: =IF(LEN(TRIM(promesas[[#This Row],[Fecha de Pago]]))>0,1,"")
A19: =TEXT(promesas[[#This Row],[Marca temporal]],"dd/mmm") -> 04/may | B19: 46146.61 | C19: Lili Velez | D19: 66189666 | E19: 138017580000 | F19: 3-711-225 | G19: Fijo | H19: Digital | I19: Correo de voz | M19: no | P19: 2 MESES PENDIENTES | R19: =IF(promesas[[#This Row],[Fecha de Pago]]="", "", TEXT(promesas[[#This Row],[Fecha de Pago]], "mmm")) | S19: =IF(promesas[[#This Row],[Fecha promesa de pago]]="", "", TEXT(promesas[[#This Row],[Fecha promesa de pago]], "mmm")) | T19: =IF(promesas[[#This Row],[Fecha de Pago]]="", "", TEXT(promesas[[#This Row],[Fecha de Pago]], "dd/mmm")) | U19: =IF(promesas[[#This Row],[Fecha promesa de pago]]="", "", TEXT(promesas[[#This Row],[Fecha promesa de pago]], "dd/mmm")) | V19: =IF(LEN(TRIM(promesas[[#This Row],[Fecha promesa de pago]]))>0,1,"") | W19: =IF(LEN(TRIM(promesas[[#This Row],[Fecha de Pago]]))>0,1,"")
A20: =TEXT(promesas[[#This Row],[Marca temporal]],"dd/mmm") -> 04/may | B20: 46146.621 | C20: Lili Velez | D20: 64381146 | E20: 361023080000 | F20: 9-754-2237 | G20: Fijo | H20: Masivo (D2D) | I20: Contactado | K20: 46147 | L20: 76.18 | M20: no | P20: 3 MESES PENDIENTES | R20: =IF(promesas[[#This Row],[Fecha de Pago]]="", "", TEXT(promesas[[#This Row],[Fecha de Pago]], "mmm")) | S20: =IF(promesas[[#This Row],[Fecha promesa de pago]]="", "", TEXT(promesas[[#This Row],[Fecha promesa de pago]], "mmm")) -> may | T20: =IF(promesas[[#This Row],[Fecha de Pago]]="", "", TEXT(promesas[[#This Row],[Fecha de Pago]], "dd/mmm")) | U20: =IF(promesas[[#This Row],[Fecha promesa de pago]]="", "", TEXT(promesas[[#This Row],[Fecha promesa de pago]], "dd/mmm")) -> 05/may | V20: =IF(LEN(TRIM(promesas[[#This Row],[Fecha promesa de pago]]))>0,1,"") -> 1 | W20: =IF(LEN(TRIM(promesas[[#This Row],[Fecha de Pago]]))>0,1,"")
A21: =TEXT(promesas[[#This Row],[Marca temporal]],"dd/mmm") -> 04/may | B21: 46146.626 | C21: Lili Velez | D21: 64590545 | E21: 313014210000 | F21: 8-210-104 | G21: Fijo | H21: Call Center Outbound | I21: Correo de voz | M21: no | P21: 2 MESES PENDIENTES | R21: =IF(promesas[[#This Row],[Fecha de Pago]]="", "", TEXT(promesas[[#This Row],[Fecha de Pago]], "mmm")) | S21: =IF(promesas[[#This Row],[Fecha promesa de pago]]="", "", TEXT(promesas[[#This Row],[Fecha promesa de pago]], "mmm")) | T21: =IF(promesas[[#This Row],[Fecha de Pago]]="", "", TEXT(promesas[[#This Row],[Fecha de Pago]], "dd/mmm")) | U21: =IF(promesas[[#This Row],[Fecha promesa de pago]]="", "", TEXT(promesas[[#This Row],[Fecha promesa de pago]], "dd/mmm")) | V21: =IF(LEN(TRIM(promesas[[#This Row],[Fecha promesa de pago]]))>0,1,"") | W21: =IF(LEN(TRIM(promesas[[#This Row],[Fecha de Pago]]))>0,1,"")
A22: =TEXT(promesas[[#This Row],[Marca temporal]],"dd/mmm") -> 04/may | B22: 46146.637 | C22: Lili Velez | D22: 65245107 | E22: 367021660000 | F22: 9-208-975 | G22: Fijo | H22: Masivo (D2D) | I22: Correo de voz | M22: no | P22: 1 MES PENDIENTE | R22: =IF(promesas[[#This Row],[Fecha de Pago]]="", "", TEXT(promesas[[#This Row],[Fecha de Pago]], "mmm")) | S22: =IF(promesas[[#This Row],[Fecha promesa de pago]]="", "", TEXT(promesas[[#This Row],[Fecha promesa de pago]], "mmm")) | T22: =IF(promesas[[#This Row],[Fecha de Pago]]="", "", TEXT(promesas[[#This Row],[Fecha de Pago]], "dd/mmm")) | U22: =IF(promesas[[#This Row],[Fecha promesa de pago]]="", "", TEXT(promesas[[#This Row],[Fecha promesa de pago]], "dd/mmm")) | V22: =IF(LEN(TRIM(promesas[[#This Row],[Fecha promesa de pago]]))>0,1,"") | W22: =IF(LEN(TRIM(promesas[[#This Row],[Fecha de Pago]]))>0,1,"")
A23: =TEXT(promesas[[#This Row],[Marca temporal]],"dd/mmm") -> 04/may | B23: 46146.646 | C23: Lili Velez | D23: 66469658 | E23: 369019030000 | F23: 7-119-519 | G23: Fijo | H23: Masivo (D2D) | I23: Correo de voz | M23: no | P23: 3 MESES PENDIENTES | R23: =IF(promesas[[#This Row],[Fecha de Pago]]="", "", TEXT(promesas[[#This Row],[Fecha de Pago]], "mmm")) | S23: =IF(promesas[[#This Row],[Fecha promesa de pago]]="", "", TEXT(promesas[[#This Row],[Fecha promesa de pago]], "mmm")) | T23: =IF(promesas[[#This Row],[Fecha de Pago]]="", "", TEXT(promesas[[#This Row],[Fecha de Pago]], "dd/mmm")) | U23: =IF(promesas[[#This Row],[Fecha promesa de pago]]="", "", TEXT(promesas[[#This Row],[Fecha promesa de pago]], "dd/mmm")) | V23: =IF(LEN(TRIM(promesas[[#This Row],[Fecha promesa de pago]]))>0,1,"") | W23: =IF(LEN(TRIM(promesas[[#This Row],[Fecha de Pago]]))>0,1,"")
A24: =TEXT(promesas[[#This Row],[Marca temporal]],"dd/mmm") -> 04/may | B24: 46146.652 | C24: Lili Velez | D24: 67283336 | E24: 362024880000 | F24: 8-513-298 | G24: Fijo | H24: Masivo (D2D) | I24: No contactado | M24: no | P24: 1 MES PENDIENTE | R24: =IF(promesas[[#This Row],[Fecha de Pago]]="", "", TEXT(promesas[[#This Row],[Fecha de Pago]], "mmm")) | S24: =IF(promesas[[#This Row],[Fecha promesa de pago]]="", "", TEXT(promesas[[#This Row],[Fecha promesa de pago]], "mmm")) | T24: =IF(promesas[[#This Row],[Fecha de Pago]]="", "", TEXT(promesas[[#This Row],[Fecha de Pago]], "dd/mmm")) | U24: =IF(promesas[[#This Row],[Fecha promesa de pago]]="", "", TEXT(promesas[[#This Row],[Fecha promesa de pago]], "dd/mmm")) | V24: =IF(LEN(TRIM(promesas[[#This Row],[Fecha promesa de pago]]))>0,1,"") | W24: =IF(LEN(TRIM(promesas[[#This Row],[Fecha de Pago]]))>0,1,"")
A25: =TEXT(promesas[[#This Row],[Marca temporal]],"dd/mmm") -> 04/may | B25: 46146.657 | C25: Lili Velez | D25: 69023547 | E25: 361023680000 | F25: 3-70-145 | G25: Fijo | H25: Masivo (D2D) | I25: Numero equivocado | M25: no | P25: 3 MESES PENDIENTES | R25: =IF(promesas[[#This Row],[Fecha de Pago]]="", "", TEXT(promesas[[#This Row],[Fecha de Pago]], "mmm")) | S25: =IF(promesas[[#This Row],[Fecha promesa de pago]]="", "", TEXT(promesas[[#This Row],[Fecha promesa de pago]], "mmm")) | T25: =IF(promesas[[#This Row],[Fecha de Pago]]="", "", TEXT(promesas[[#This Row],[Fecha de Pago]], "dd/mmm")) | U25: =IF(promesas[[#This Row],[Fecha promesa de pago]]="", "", TEXT(promesas[[#This Row],[Fecha promesa de pago]], "dd/mmm")) | V25: =IF(LEN(TRIM(promesas[[#This Row],[Fecha promesa de pago]]))>0,1,"") | W25: =IF(LEN(TRIM(promesas[[#This Row],[Fecha de Pago]]))>0,1,"")
A26: =TEXT(promesas[[#This Row],[Marca temporal]],"dd/mmm") -> 04/may | B26: 46146.66 | C26: Lili Velez | D26: 65097861 | E26: 364023810000 | F26: 2-725-700 | G26: Fijo | H26: Masivo (D2D) | I26: No contactado | M26: no | P26: NPN | R26: =IF(promesas[[#This Row],[Fecha de Pago]]="", "", TEXT(promesas[[#This Row],[Fecha de Pago]], "mmm")) | S26: =IF(promesas[[#This Row],[Fecha promesa de pago]]="", "", TEXT(promesas[[#This Row],[Fecha promesa de pago]], "mmm")) | T26: =IF(promesas[[#This Row],[Fecha de Pago]]="", "", TEXT(promesas[[#This Row],[Fecha de Pago]], "dd/mmm")) | U26: =IF(promesas[[#This Row],[Fecha promesa de pago]]="", "", TEXT(promesas[[#This Row],[Fecha promesa de pago]], "dd/mmm")) | V26: =IF(LEN(TRIM(promesas[[#This Row],[Fecha promesa de pago]]))>0,1,"") | W26: =IF(LEN(TRIM(promesas[[#This Row],[Fecha de Pago]]))>0,1,"")
A27: =TEXT(promesas[[#This Row],[Marca temporal]],"dd/mmm") -> 04/may | B27: 46146.673 | C27: Lili Velez | D27: 69601798 | E27: 361023570000 | F27: 8-716-184 | G27: Fijo | H27: Masivo (D2D) | I27: Contactado | K27: 46150 | L27: 67.56 | M27: no | P27: 3 MESES PENDIENTES | R27: =IF(promesas[[#This Row],[Fecha de Pago]]="", "", TEXT(promesas[[#This Row],[Fecha de Pago]], "mmm")) | S27: =IF(promesas[[#This Row],[Fecha promesa de pago]]="", "", TEXT(promesas[[#This Row],[Fecha promesa de pago]], "mmm")) -> may | T27: =IF(promesas[[#This Row],[Fecha de Pago]]="", "", TEXT(promesas[[#This Row],[Fecha de Pago]], "dd/mmm")) | U27: =IF(promesas[[#This Row],[Fecha promesa de pago]]="", "", TEXT(promesas[[#This Row],[Fecha promesa de pago]], "dd/mmm")) -> 08/may | V27: =IF(LEN(TRIM(promesas[[#This Row],[Fecha promesa de pago]]))>0,1,"") -> 1 | W27: =IF(LEN(TRIM(promesas[[#This Row],[Fecha de Pago]]))>0,1,"")
A28: =TEXT(promesas[[#This Row],[Marca temporal]],"dd/mmm") -> 04/may | B28: 46146.681 | C28: Lili Velez | D28: 67467158 | E28: 361011900000 | F28: 8-1001-1937 | G28: Fijo | H28: Masivo (D2D) | I28: Correo de voz | M28: no | P28: 2 MESES PENDIENTES | R28: =IF(promesas[[#This Row],[Fecha de Pago]]="", "", TEXT(promesas[[#This Row],[Fecha de Pago]], "mmm")) | S28: =IF(promesas[[#This Row],[Fecha promesa de pago]]="", "", TEXT(promesas[[#This Row],[Fecha promesa de pago]], "mmm")) | T28: =IF(promesas[[#This Row],[Fecha de Pago]]="", "", TEXT(promesas[[#This Row],[Fecha de Pago]], "dd/mmm")) | U28: =IF(promesas[[#This Row],[Fecha promesa de pago]]="", "", TEXT(promesas[[#This Row],[Fecha promesa de pago]], "dd/mmm")) | V28: =IF(LEN(TRIM(promesas[[#This Row],[Fecha promesa de pago]]))>0,1,"") | W28: =IF(LEN(TRIM(promesas[[#This Row],[Fecha de Pago]]))>0,1,"")
A29: =TEXT(promesas[[#This Row],[Marca temporal]],"dd/mmm") -> 04/may | B29: 46146.69 | C29: Lili Velez | D29: 65556178 | E29: 365023490000 | F29: PE-9-1322 | G29: Fijo | H29: Masivo (D2D) | I29: Contactado | K29: 46172 | L29: 60.88 | M29: no | P29: 3 MESES PENDIENTES | R29: =IF(promesas[[#This Row],[Fecha de Pago]]="", "", TEXT(promesas[[#This Row],[Fecha de Pago]], "mmm")) | S29: =IF(promesas[[#This Row],[Fecha promesa de pago]]="", "", TEXT(promesas[[#This Row],[Fecha promesa de pago]], "mmm")) -> may | T29: =IF(promesas[[#This Row],[Fecha de Pago]]="", "", TEXT(promesas[[#This Row],[Fecha de Pago]], "dd/mmm")) | U29: =IF(promesas[[#This Row],[Fecha promesa de pago]]="", "", TEXT(promesas[[#This Row],[Fecha promesa de pago]], "dd/mmm")) -> 30/may | V29: =IF(LEN(TRIM(promesas[[#This Row],[Fecha promesa de pago]]))>0,1,"") -> 1 | W29: =IF(LEN(TRIM(promesas[[#This Row],[Fecha de Pago]]))>0,1,"")
