Workbook

Sheet Datos
A1: FUENTE | B1: CUENTA | C1: CUST_NO | D1: NOMBRE | E1: NKEY | F1: MRC | G1: EJECUTIVA | H1: CODIGO | I1: TELEFONO | J1: CANAL | K1: SERVICIOS | L1: CONTACTO_MOVIL
A2: NP | B2: 355382970000 | C2: 35538297 | D2: EDIL GOMEZ ARCE | E2: EDILGOMEZARCE | F2: 15 | G2: Solanye Acuña | H2: Y | I2: 68879413.0 | J2: TIENDA CALL CENTER TIENDA | K2: 0 | L2: 1
A3: NP | B3: 353338240000 | C3: 35333824 | D3: MEYVIS CALVO | E3: MEYVISCALVO | F3: 15 | G3: Michelle Zambrano | H3: V | I3: 67325039.0 | J3: 0 | K3: 0 | L3: 1
A4: NP | B4: 321157030000 | C4: 32115703 | D4: GRUPO CORPORA | E4: GRUPOCORPORA | F4: 226.5 | G4: Ines Lizbeth Trujillo | H4: T | I4: 66711672.0 | J4: TIENDA CALL CENTER TIENDA | K4: 0 | L4: 1
A5: NP | B5: 369050850000 | C5: 36905085 | D5: SILVIA ARAUZ | E5: SILVIAARAUZ | F5: 19.52 | G5: Alejandra Mabel Hawkins | H5: Y | K5: 0 | L5: 1
A6: NP | B6: 355282350000 | C6: 35528235 | D6: SIMON WALTEROVA | E6: SIMONWALTEROVA | F6: 30 | G6: Maria Fernanda | H6: B | I6: 62110427.0 | J6: 0 | K6: 0 | L6: 1
A7: NP | B7: 312235730000 | C7: 31223573 | D7: CORPORACION JEMS, S.A. -- | E7: CORPORACIONJEMSSA | F7: 326.24 | G7: Yarelis Tulloch | H7: C | I7: 62005659.0 | J7: TIENDA CALL CENTER TIENDA | K7: 0 | L7: 1
A8: NP | B8: 322504520000 | C8: 32250452 | D8: Ardines CPA Y Asociados Sa | E8: ARDINESCPAYASOCIADOSSA | F8: 64.25 | G8: Abril Aparicio | H8: T | I8: 69493738.0 | J8: TIENDA CALL CENTER TIENDA | K8: 0 | L8: 1
A9: NP | B9: 323672910000 | C9: 32367291 | D9: Ademar SA | E9: ADEMARSA | F9: 44 | G9: Yariela Galarce | H9: W | I9: 66131951.0 | J9: TIENDA CALL CENTER TIENDA | K9: 0 | L9: 1
A10: NP | B10: 349277210000 | C10: 34927721 | D10: SMART COMMUNICATIONS, SA | E10: SMARTCOMMUNICATIONSSA | F10: 16.25 | G10: Nailyn Martinez | H10: U | I10: 67424735.0 | J10: TIENDA CALL CENTER TIENDA | K10: 0 | L10: 1
A11: NP | B11: 324167750000 | C11: 32416775 | D11: HACIENDA LOMA LINDA | E11: HACIENDALOMALINDA | F11: 291.5 | G11: Yamali Rodriguez | H11: U | I11: 69834668.0 | J11: TIENDA CALL CENTER TIENDA | K11: 0 | L11: 1
A12: NP | B12: 361003450000 | C12: 36100345 | D12: FERNANDO JOSE ARAUZ HERNANDEZ | E12: FERNANDOJOSEARAUZHERNANDEZ | F12: 15 | G12: Osiris Aguilar | H12: A | I12: 69722675.0 | J12: TIENDA CALL CENTER TIENDA | K12: 0 | L12: 1
A13: NP | B13: 352329430000 | C13: 35232943 | D13: YDALIDES VALDES | E13: YDALIDESVALDES | F13: 15 | G13: Karla Mc Intryre | H13: H | I13: 67344173.0 | J13: 0 | K13: 0 | L13: 1
A14: NP | B14: 354175000000 | C14: 35417500 | D14: THIAGO DAVID CABALLERO | E14: THIAGODAVIDCABALLERO | F14: 15 | G14: Michelle Zambrano | H14: U | I14: 62475467.0 | J14: 0 | K14: 0 | L14: 1
A15: NP | B15: 327604400000 | C15: 32760440 | D15: GLOBAL LANGUAGE,S.A. | E15: GLOBALLANGUAGESA | F15: 275 | G15: Ines Lizbeth Trujillo | H15: W | I15: 69973283.0 | J15: TIENDA CALL CENTER TIENDA | K15: 0 | L15: 1
A16: NP | B16: 322366890200 | C16: 32236689 | D16: LIMAYON, S.A | E16: LIMAYONSA | F16: 124.95 | G16: Alejandra Mabel Hawkins | H16: T | I16: 69824192.0 | J16: TIENDA CALL CENTER TIENDA | K16: 0 | L16: 1
A17: NP | B17: 322366890200 | C17: 32236689 | D17: Asociacion de | E17: ASOCIACIONDE | F17: 30.74 | G17: Maria Fernanda | H17: T | I17: 69824192.0 | J17: TIENDA CALL CENTER TIENDA | K17: 0 | L17: 1
... A86: NP | B86: 312209940000 | C86: 31220994 | D86: UROLOGOS ASOCIADOS, S.A. - | E86: UROLOGOSASOCIADOSSA | F86: 31 | G86: Maria Fernanda | H86: S | I86: 62082799.0 | J86: TIENDA CALL CENTER TIENDA | K86: 0 | L86: 1
A87: NP | B87: 364043730000 | C87: 36404373 | D87: BALTAZAR GOMEZ | E87: BALTAZARGOMEZ | F87: 16.94 | G87: Yarelis Tulloch | H87: U | J87: 0 | K87: 0 | L87: 1
A88: NP | B88: 359354310000 | C88: 35935431 | D88: JAFETH LOPEZ | E88: JAFETHLOPEZ | F88: 15 | G88: Abril Aparicio | H88: C | I88: 67793454.0 | J88: 0 | K88: 0 | L88: 1
A89: NP | B89: 325374980000 | C89: 32537498 | D89: HENG CHANG, S.A. | E89: HENGCHANGSA | F89: 215 | G89: Yariela Galarce | H89: V | I89: 67076180.0 | J89: TIENDA CALL CENTER TIENDA | K89: 0 | L89: 1
A90: NP | B90: 353355830000 | C90: 35335583 | D90: MARÍA RIVAS | E90: MARIARIVAS | F90: 15 | G90: Nailyn Martinez | H90: H | I90: 65161910.0 | J90: 0 | K90: 0 | L90: 1
A91: NP | B91: 321439070100 | C91: 32143907 | D91: POWER EXTERMINATOR | E91: POWEREXTERMINATOR | F91: 353.77 | G91: Yamali Rodriguez | H91: U | I91: 69987657.0 | J91: TIENDA CALL CENTER TIENDA | K91: 0 | L91: 1
A92: NP | B92: 346090040000 | C92: 34609004 | D92: MARY HELEN CASTAÑEDA DE CALDERON | E92: MARYHELENCASTANEDADECALDERON | F92: 15 | G92: Osiris Aguilar | H92: T | I92: 66600631.0 | J92: TIENDA CALL CENTER TIENDA | K92: 0 | L92: 1
A93: NP | B93: 345006480000 | C93: 34500648 | D93: THOMAS JEFFERSON SCHOOL, S.A. | E93: THOMASJEFFERSONSCHOOLSA | F93: 245 | G93: Karla Mc Intryre | H93: U | I93: 68784059.0 | J93: TIENDA CALL CENTER TIENDA | K93: 0 | L93: 1
A94: NP | B94: 343249890000 | C94: 34324989 | D94: ISELA MARIA CASTAÑEDAS DE SINGH | E94: ISELAMARIACASTANEDASDESINGH | F94: 12 | G94: Solanye Acuña | H94: S | I94: 66409300.0 | J94: TIENDA CALL CENTER TIENDA | K94: 0 | L94: 1
A95: NP | B95: 353003570000 | C95: 35300357 | D95: FAVIO VANEGAS | E95: FAVIOVANEGAS | F95: 15 | G95: Michelle Zambrano | H95: F | I95: 67035338.0 | J95: TIENDA CALL CENTER TIENDA | K95: 0 | L95: 1
A96: NP | B96: 342412720000 | C96: 34241272 | D96: JAFET BERTIAGA MOSQUERA | E96: JAFETBERTIAGAMOSQUERA | F96: 16.25 | G96: Ines Lizbeth Trujillo | H96: U | I96: 66011050.0 | J96: TIENDA CALL CENTER TIENDA | K96: 0 | L96: 1
A97: NP | B97: 354334670000 | C97: 35433467 | D97: ARISTIDES BARRIOS CARRION | E97: ARISTIDESBARRIOSCARRION | F97: 15 | G97: Alejandra Mabel Hawkins | H97: U | I97: 66951128.0 | J97: 0 | K97: 0 | L97: 1
A98: NP | B98: 312216560000 | C98: 31221656 | D98: JADE TECHNOLOGY S.A - | E98: JADETECHNOLOGYSA | F98: 109.5 | G98: Maria Fernanda | H98: C | I98: 61126980.0 | J98: TIENDA CALL CENTER TIENDA | K98: 0 | L98: 1
A99: NP | B99: 369039290000 | C99: 36903929 | D99: PETRA PABLA MOSQUERA BLANCO | E99: PETRAPABLAMOSQUERABLANCO | F99: 16.94 | G99: Yarelis Tulloch | H99: L | J99: TIENDA CALL CENTER TIENDA | K99: 0 | L99: 1
A100: NP | B100: 323540060100 | C100: 32354006 | D100: Jacqueline Quintero Dominguez | E100: JACQUELINEQUINTERODOMINGUEZ | F100: 52.74 | G100: Abril Aparicio | H100: V | I100: 67812138.0 | J100: TIENDA CALL CENTER TIENDA | K100: 0 | L100: 1
A101: NP | B101: 323540060100 | C101: 32354006 | D101: Jacqueline Quintero Dominguez | E101: JACQUELINEQUINTERODOMINGUEZ | F101: 14.99 | G101: Yariela Galarce | H101: V | I101: 67812138.0 | J101: TIENDA CALL CENTER TIENDA | K101: 0 | L101: 1
A102: NP | B102: 345179830000 | C102: 34517983 | D102: LEGUMBRES Y FRUTAS IVERSON | E102: LEGUMBRESYFRUTASIVERSON | F102: 40 | G102: Nailyn Martinez | H102: W | I102: 69505541.0 | J102: TIENDA CALL CENTER TIENDA | K102: 0 | L102: 1
A103: NP | B103: 349132360000 | C103: 34913236 | D103: AHAVA LATIN AMERCA | E103: AHAVALATINAMERCA | F103: 21 | G103: Yamali Rodriguez | H103: U | I103: 60138979.0 | J103: TIENDA CALL CENTER TIENDA | K103: 0 | L103: 1
A104: NP | B104: 344414740000 | C104: 34441474 | D104: NORBERTO ANTONIO CERNA LOPEZ | E104: NORBERTOANTONIOCERNALOPEZ | F104: 16.25 | G104: Osiris Aguilar | H104: U | I104: 67769361.0 | J104: TIENDA CALL CENTER TIENDA | K104: 0 | L104: 1
A105: NP | B105: 341297900000 | C105: 34129790 | D105: HERCILIA PACHECO SECAIDA | E105: HERCILIAPACHECOSECAIDA | F105: 16.25 | G105: Karla Mc Intryre | H105: C | I105: 65372281.0 | J105: TIENDA CALL CENTER TIENDA | K105: 0 | L105: 1
A106: NP | B106: 312209910000 | C106: 31220991 | D106: DISTRIBUIDORA CARIVA, S.A. - | E106: DISTRIBUIDORACARIVASA | F106: 64 | G106: Michelle Zambrano | H106: S | I106: 62269500.0 | J106: TIENDA CALL CENTER TIENDA | K106: 0 | L106: 1
A107: NP | B107: 325409780200 | C107: 32540978 | D107: NUBIA ARENAS GOMEZ | E107: NUBIAARENASGOMEZ | F107: 28.75 | G107: Ines Lizbeth Trujillo | H107: V | I107: 66131158.0 | J107: TIENDA CALL CENTER TIENDA | K107: 0 | L107: 1
A108: NP | B108: 322462760200 | C108: 32246276 | D108: A.J.FOTOS S.A. | E108: AJFOTOSSA | F108: 42 | G108: Alejandra Mabel Hawkins | H108: V | I108: 67810778.0 | J108: TIENDA CALL CENTER TIENDA | K108: 0 | L108: 1
...

Sheet Winback
A1: CLIENTE | B1: NKEY | C1: EJECUTIVA | D1: MRC | E1: RAZON_SALIDA | F1: RGU | G1: CONTACTO | H1: CORREO | I1: TEL1 | J1: TEL2
A2: COIMSA | B2: COIMSA | C2: Michelle Zambrano | D2: 95 | E2: Solicitado por el Cliente | F2: 3 | G2: Jorge Villarreal ced 8-299-399 | H2: gerencia.coimsa@gmail.com | I2: 66776809.0 | J2: 2602749.0
A3: GRAPHIC SOLUTIONS/ CARMEN R. WILLIAMS 2 | B3: GRAPHICSOLUTIONSCARMENRWILLIAMS2 | C3: Solanye Acuña | D3: 12 | E3: Solicitado por el Cliente | F3: 1 | G3: Angelica Gallego E-8-79314 | I3: 3140588.0
A4: ALEXIS ALEXANDER GOMEZ MENDIETA | B4: ALEXISALEXANDERGOMEZMENDIETA | C4: Maria Fernanda Rivas | D4: 20.75 | E4: Solicitado por el Cliente | F4: 1 | G4: ALEXIS ALEXANDER GOMEZ MENDIETA | I4: 67472064.0
A5: PH COUNTRY CLUB - | B5: PHCOUNTRYCLUB | C5: Nailyn Martinez Johnson | D5: 166 | E5: Solicitado por el Cliente | F5: 8 | G5: MICHAEL HAMOUI | I5: 69144044.0
C6: Michelle Zambrano | D6: 20.75 | E6: Solicitado por el Cliente | F6: 1
C7: Solanye Acuña | D7: 40.5 | E7: Solicitado por el Cliente | F7: 1
C8: Maria Fernanda Rivas | D8: 31 | E8: Solicitado por el Cliente | F8: 1
A9: IDEALO | B9: IDEALO | C9: Nailyn Martinez Johnson | D9: 41.5 | E9: Solicitado por el Cliente | F9: 2 | G9: IDEALO | I9: 68800852.0
A10: INFINITY LOGISTICS INFINITY LOGISTICS AGENCY, CORP | B10: INFINITYLOGISTICSINFINITYLOGISTICSAGENCYCORP | C10: Michelle Zambrano | D10: 60 | E10: Solicitado por el Cliente | F10: 3 | G10: ARCELIS ASPRILLA | I10: 4304648.0
C11: Solanye Acuña | D11: 50 | E11: Solicitado por el Cliente | F11: 2
C12: Maria Fernanda Rivas | D12: 50 | E12: Solicitado por el Cliente | F12: 1
C13: Nailyn Martinez Johnson | D13: 17 | E13: Solicitado por el Cliente | F13: 1
C14: Michelle Zambrano | D14: 170 | E14: Solicitado por el Cliente | F14: 5
C15: Solanye Acuña | D15: 35 | E15: Solicitado por el Cliente | F15: 1
A16: RC SOLUTION, S.A - | B16: RCSOLUTIONSA | C16: Maria Fernanda Rivas | D16: 41.5 | E16: Solicitado por el Cliente | F16: 2 | G16: RC SOLUTION, S.A - | I16: 62608877.0
C17: Nailyn Martinez Johnson | D17: 113.5 | E17: Solicitado por el Cliente | F17: 4
A18: Servicios Logitisticos Imperial S.A | B18: SERVICIOSLOGITISTICOSIMPERIALSA | C18: Michelle Zambrano | D18: 30 | E18: Solicitado por el Cliente | F18: 2 | G18: Servicios Logisticos Imperial S.A. | H18: comercial.panama@petentrega.com | I18: 65146298.0
A19: CLINICA TU SALUD Y BELLEZA - | B19: CLINICATUSALUDYBELLEZA | C19: Solanye Acuña | D19: 16.25 | E19: Solicitado por el Cliente | F19: 1 | G19: Soy Yoli calu N-20-930 | I19: 65081722.0
A20: SERVIEDUCA S,A. - | B20: SERVIEDUCASA | C20: Maria Fernanda Rivas | D20: 20 | E20: Solicitado por el Cliente | F20: 1 | G20: SERVIEDUCA S,A. - GABRIELA ALEJANDRA, | I20: 2366783.0
C21: Nailyn Martinez Johnson | D21: 25 | E21: Solicitado por el Cliente | F21: 1
A22: PANAMA JOURNEYS S,A - | B22: PANAMAJOURNEYSSA | C22: Michelle Zambrano | D22: 31 | E22: Solicitado por el Cliente | F22: 1 | G22: PANAMA JOURNEYS S,A - | I22: 63134216.0
A23: AGRO JP / NILKA ATENCIO | B23: AGROJPNILKAATENCIO | C23: Solanye Acuña | D23: 65 | E23: Solicitado por el Cliente | F23: 2 | G23: AGRO JP / NILKA ATENCIO | H23: ni.lka@hotmail.com | I23: 65767586.0 | J23: 65767586.0
C24: Maria Fernanda Rivas | D24: 31 | E24: Solicitado por el Cliente | F24: 1
C25: Nailyn Martinez Johnson | D25: 40.5 | E25: Solicitado por el Cliente | F25: 1
C26: Michelle Zambrano | D26: 66.5 | E26: Solicitado por el Cliente | F26: 1
A27: UPPER EAST TOWER | B27: UPPEREASTTOWER | C27: Solanye Acuña | D27: 124 | E27: Solicitado por el Cliente | F27: 4 | G27: UPPER EAST TOWER | I27: 2027194.0
A28: FLIX CINEVISION PANAMA, S. DE R.L. - | B28: FLIXCINEVISIONPANAMASDERL | C28: Maria Fernanda Rivas | D28: 81 | E28: Solicitado por el Cliente | F28: 1 | G28: FLIX CINEVISION PANAMA, S. DE R.L. - | I28: 64993246.0
A29: AVAPSA | B29: AVAPSA | C29: Nailyn Martinez Johnson | D29: 40.5 | E29: Solicitado por el Cliente | F29: 1 | G29: AVAPSA | H29: magt.67vetequi@gmail.com | I29: 62605786.0 | J29: 66150700.0
A30: DRAG COLORS | B30: DRAGCOLORS | C30: Michelle Zambrano | D30: 22 | E30: Solicitado por el Cliente | F30: 1 | G30: Salvador Orantes | H30: Chambascar27@gmail.com | I30: 69207844.0 | J30: 69207844.0
C31: Solanye Acuña | D31: 150 | E31: Solicitado por el Cliente | F31: 6
C32: Maria Fernanda Rivas | D32: 21 | E32: Solicitado por el Cliente | F32: 3
A33: Anagan | B33: ANAGAN | C33: Nailyn Martinez Johnson | D33: 42 | E33: Solicitado por el Cliente | F33: 1 | G33: LUIS MARTINEZ 7-83-25 // Amarilis Cristóbal 8-841-1249 | H33: anagan1@cwpanama.net | I33: 3140633.0 | J33: 3140633.0
C34: Michelle Zambrano | D34: 44 | E34: Solicitado por el Cliente | F34: 1
A35: Carmen Valdivia Valdes | B35: CARMENVALDIVIAVALDES | C35: Solanye Acuña | D35: 21 | E35: Solicitado por el Cliente | F35: 1 | I35: 66773196.0
A36: Gixel Guevara Almanza | B36: GIXELGUEVARAALMANZA | C36: Maria Fernanda Rivas | D36: 16 | E36: Solicitado por el Cliente | F36: 1 | I36: 69822979.0
A37: Jaime Arroyo Atencio | B37: JAIMEARROYOATENCIO | C37: Nailyn Martinez Johnson | D37: 21.75 | E37: Solicitado por el Cliente | F37: 1 | I37: 2287216.0
A38: Shirley y Asociados | B38: SHIRLEYYASOCIADOS | C38: Michelle Zambrano | D38: 45.5 | E38: Solicitado por el Cliente | F38: 1 | G38: Luis Antonio Shirley Campbell | H38: administracion@shirleylaw.com | I38: 66752321.0 | J38: 66752321.0
A39: M. Contratista | B39: MCONTRATISTA | C39: Solanye Acuña | D39: 42 | E39: MIGRACION POST-PRE | F39: 1 | G39: Ricardo Raul Mezquita | I39: 2790469.0
A40: Solidus Secur | B40: SOLIDUSSECUR | C40: Maria Fernanda Rivas | D40: 15.99 | E40: Solicitado por el Cliente | F40: 1 | G40: HEINER SPEICH | H40: karoll.arguelles@sardona-capital.com | I40: 69826252.0 | J40: 69826252.0
...

Sheet Resumen
A1: CONSOLIDADO SOHO - RESUMEN POR FUENTE
A3: FUENTE | B3: REGISTROS | C3: MRC TOTAL $ | D3: MRC PROM $ | E3: DATO CLAVE
A4: Nextphone | B4: =COUNTIF(Datos!$A$2:$A$6000,"NP") | C4: =SUMIFS(Datos!$F$2:$F$6000,Datos!$A$2:$A$6000,"NP") | D4: =IF($B4=0,0,$C4/$B4) | E4: Base principal de clientes
A5: Móvil sin fijo | B5: =COUNTIF(Datos!$A$2:$A$6000,"MOV") | C5: =SUMIFS(Datos!$F$2:$F$6000,Datos!$A$2:$A$6000,"MOV") | D5: =IF($B5=0,0,$C5/$B5) | E5: Clientes móvil sin fijo
A6: Cross-sell | B6: =COUNTIF(Datos!$A$2:$A$6000,"CS") | C6: =SUMIFS(Datos!$F$2:$F$6000,Datos!$A$2:$A$6000,"CS") | D6: =IF($B6=0,0,$C6/$B6) | E6: Oportunidades de venta
A7: Winback | B7: =COUNTA(Winback!$A$2:$A$300) | C7: =SUM(Winback!$D$2:$D$300) | D7: =IF($B7=0,0,$C7/$B7) | E7: Clientes a recuperar
A8: Llamadas (Vici) | B8: 15796 | C8: N/A | D8: =IF($B8=0,0,$C8/$B8) | E8: Del reporte .xlsb (ver hoja Vici)
A9: TOTAL | B9: =SUM(B4:B8) | C9: =SUMIFS(C4:C8,C4:C8,">0")
A11: VICI (resumen)
A12: Total llamadas | B12: 15796
A13: Números únicos | B13: 7063
A14: Contactados | B14: 6562
A15: No contestan | B15: 8268
A16: Tasa contacto % | B16: =ROUND(6562/15796*100,1)
A17: Duración prom (s) | B17: 70

Sheet Ejecutivas
A1: EJECUTIVA | B1: CLIENTES (NP) | C1: MRC NP $ | D1: CLIENTES WB | E1: MRC WB $
A2: Michelle Zambrano | B2: =COUNTIFS(Datos!$A$2:$A$6000,"NP",Datos!$G$2:$G$6000,$A2) | C2: =SUMIFS(Datos!$F$2:$F$6000,Datos!$A$2:$A$6000,"NP",Datos!$G$2:$G$6000,$A2) | D2: =COUNTIF(Winback!$C$2:$C$300,$A2) | E2: =SUMIFS(Winback!$D$2:$D$300,Winback!$C$2:$C$300,$A2)
A3: Yarelis Tulloch | B3: =COUNTIFS(Datos!$A$2:$A$6000,"NP",Datos!$G$2:$G$6000,$A3) | C3: =SUMIFS(Datos!$F$2:$F$6000,Datos!$A$2:$A$6000,"NP",Datos!$G$2:$G$6000,$A3) | D3: =COUNTIF(Winback!$C$2:$C$300,$A3) | E3: =SUMIFS(Winback!$D$2:$D$300,Winback!$C$2:$C$300,$A3)
A4: Yariela Galarce | B4: =COUNTIFS(Datos!$A$2:$A$6000,"NP",Datos!$G$2:$G$6000,$A4) | C4: =SUMIFS(Datos!$F$2:$F$6000,Datos!$A$2:$A$6000,"NP",Datos!$G$2:$G$6000,$A4) | D4: =COUNTIF(Winback!$C$2:$C$300,$A4) | E4: =SUMIFS(Winback!$D$2:$D$300,Winback!$C$2:$C$300,$A4)
A5: Abril Aparicio | B5: =COUNTIFS(Datos!$A$2:$A$6000,"NP",Datos!$G$2:$G$6000,$A5) | C5: =SUMIFS(Datos!$F$2:$F$6000,Datos!$A$2:$A$6000,"NP",Datos!$G$2:$G$6000,$A5) | D5: =COUNTIF(Winback!$C$2:$C$300,$A5) | E5: =SUMIFS(Winback!$D$2:$D$300,Winback!$C$2:$C$300,$A5)
A6: Karla Mc Intryre | B6: =COUNTIFS(Datos!$A$2:$A$6000,"NP",Datos!$G$2:$G$6000,$A6) | C6: =SUMIFS(Datos!$F$2:$F$6000,Datos!$A$2:$A$6000,"NP",Datos!$G$2:$G$6000,$A6) | D6: =COUNTIF(Winback!$C$2:$C$300,$A6) | E6: =SUMIFS(Winback!$D$2:$D$300,Winback!$C$2:$C$300,$A6)
A7: Alejandra Mabel Hawkins | B7: =COUNTIFS(Datos!$A$2:$A$6000,"NP",Datos!$G$2:$G$6000,$A7) | C7: =SUMIFS(Datos!$F$2:$F$6000,Datos!$A$2:$A$6000,"NP",Datos!$G$2:$G$6000,$A7) | D7: =COUNTIF(Winback!$C$2:$C$300,$A7) | E7: =SUMIFS(Winback!$D$2:$D$300,Winback!$C$2:$C$300,$A7)
A8: Ines Lizbeth Trujillo | B8: =COUNTIFS(Datos!$A$2:$A$6000,"NP",Datos!$G$2:$G$6000,$A8) | C8: =SUMIFS(Datos!$F$2:$F$6000,Datos!$A$2:$A$6000,"NP",Datos!$G$2:$G$6000,$A8) | D8: =COUNTIF(Winback!$C$2:$C$300,$A8) | E8: =SUMIFS(Winback!$D$2:$D$300,Winback!$C$2:$C$300,$A8)
A9: Osiris Aguilar | B9: =COUNTIFS(Datos!$A$2:$A$6000,"NP",Datos!$G$2:$G$6000,$A9) | C9: =SUMIFS(Datos!$F$2:$F$6000,Datos!$A$2:$A$6000,"NP",Datos!$G$2:$G$6000,$A9) | D9: =COUNTIF(Winback!$C$2:$C$300,$A9) | E9: =SUMIFS(Winback!$D$2:$D$300,Winback!$C$2:$C$300,$A9)
A10: Yamali Rodriguez | B10: =COUNTIFS(Datos!$A$2:$A$6000,"NP",Datos!$G$2:$G$6000,$A10) | C10: =SUMIFS(Datos!$F$2:$F$6000,Datos!$A$2:$A$6000,"NP",Datos!$G$2:$G$6000,$A10) | D10: =COUNTIF(Winback!$C$2:$C$300,$A10) | E10: =SUMIFS(Winback!$D$2:$D$300,Winback!$C$2:$C$300,$A10)
A11: Nailyn Martinez | B11: =COUNTIFS(Datos!$A$2:$A$6000,"NP",Datos!$G$2:$G$6000,$A11) | C11: =SUMIFS(Datos!$F$2:$F$6000,Datos!$A$2:$A$6000,"NP",Datos!$G$2:$G$6000,$A11) | D11: =COUNTIF(Winback!$C$2:$C$300,$A11) | E11: =SUMIFS(Winback!$D$2:$D$300,Winback!$C$2:$C$300,$A11)
A12: Maria Fernanda | B12: =COUNTIFS(Datos!$A$2:$A$6000,"NP",Datos!$G$2:$G$6000,$A12) | C12: =SUMIFS(Datos!$F$2:$F$6000,Datos!$A$2:$A$6000,"NP",Datos!$G$2:$G$6000,$A12) | D12: =COUNTIF(Winback!$C$2:$C$300,$A12) | E12: =SUMIFS(Winback!$D$2:$D$300,Winback!$C$2:$C$300,$A12)
A13: Solanye Acuña | B13: =COUNTIFS(Datos!$A$2:$A$6000,"NP",Datos!$G$2:$G$6000,$A13) | C13: =SUMIFS(Datos!$F$2:$F$6000,Datos!$A$2:$A$6000,"NP",Datos!$G$2:$G$6000,$A13) | D13: =COUNTIF(Winback!$C$2:$C$300,$A13) | E13: =SUMIFS(Winback!$D$2:$D$300,Winback!$C$2:$C$300,$A13)
... A16: Keisy Vargas | B16: =COUNTIFS(Datos!$A$2:$A$6000,"NP",Datos!$G$2:$G$6000,$A16) | C16: =SUMIFS(Datos!$F$2:$F$6000,Datos!$A$2:$A$6000,"NP",Datos!$G$2:$G$6000,$A16) | D16: =COUNTIF(Winback!$C$2:$C$300,$A16) | E16: =SUMIFS(Winback!$D$2:$D$300,Winback!$C$2:$C$300,$A16)

Sheet Planes
A1: CODIGO | B1: CLIENTES | C1: MRC TOTAL $
A2: U | B2: =COUNTIFS(Datos!$A$2:$A$6000,"NP",Datos!$H$2:$H$6000,$A2) | C2: =SUMIFS(Datos!$F$2:$F$6000,Datos!$A$2:$A$6000,"NP",Datos!$H$2:$H$6000,$A2)
A3: T | B3: =COUNTIFS(Datos!$A$2:$A$6000,"NP",Datos!$H$2:$H$6000,$A3) | C3: =SUMIFS(Datos!$F$2:$F$6000,Datos!$A$2:$A$6000,"NP",Datos!$H$2:$H$6000,$A3)
A4: W | B4: =COUNTIFS(Datos!$A$2:$A$6000,"NP",Datos!$H$2:$H$6000,$A4) | C4: =SUMIFS(Datos!$F$2:$F$6000,Datos!$A$2:$A$6000,"NP",Datos!$H$2:$H$6000,$A4)
A5: V | B5: =COUNTIFS(Datos!$A$2:$A$6000,"NP",Datos!$H$2:$H$6000,$A5) | C5: =SUMIFS(Datos!$F$2:$F$6000,Datos!$A$2:$A$6000,"NP",Datos!$H$2:$H$6000,$A5)
A6: C | B6: =COUNTIFS(Datos!$A$2:$A$6000,"NP",Datos!$H$2:$H$6000,$A6) | C6: =SUMIFS(Datos!$F$2:$F$6000,Datos!$A$2:$A$6000,"NP",Datos!$H$2:$H$6000,$A6)
A7: S | B7: =COUNTIFS(Datos!$A$2:$A$6000,"NP",Datos!$H$2:$H$6000,$A7) | C7: =SUMIFS(Datos!$F$2:$F$6000,Datos!$A$2:$A$6000,"NP",Datos!$H$2:$H$6000,$A7)
A8: A | B8: =COUNTIFS(Datos!$A$2:$A$6000,"NP",Datos!$H$2:$H$6000,$A8) | C8: =SUMIFS(Datos!$F$2:$F$6000,Datos!$A$2:$A$6000,"NP",Datos!$H$2:$H$6000,$A8)
A9: Y | B9: =COUNTIFS(Datos!$A$2:$A$6000,"NP",Datos!$H$2:$H$6000,$A9) | C9: =SUMIFS(Datos!$F$2:$F$6000,Datos!$A$2:$A$6000,"NP",Datos!$H$2:$H$6000,$A9)
A10: H | B10: =COUNTIFS(Datos!$A$2:$A$6000,"NP",Datos!$H$2:$H$6000,$A10) | C10: =SUMIFS(Datos!$F$2:$F$6000,Datos!$A$2:$A$6000,"NP",Datos!$H$2:$H$6000,$A10)
A11: D | B11: =COUNTIFS(Datos!$A$2:$A$6000,"NP",Datos!$H$2:$H$6000,$A11) | C11: =SUMIFS(Datos!$F$2:$F$6000,Datos!$A$2:$A$6000,"NP",Datos!$H$2:$H$6000,$A11)
A12: B | B12: =COUNTIFS(Datos!$A$2:$A$6000,"NP",Datos!$H$2:$H$6000,$A12) | C12: =SUMIFS(Datos!$F$2:$F$6000,Datos!$A$2:$A$6000,"NP",Datos!$H$2:$H$6000,$A12)
A13: R | B13: =COUNTIFS(Datos!$A$2:$A$6000,"NP",Datos!$H$2:$H$6000,$A13) | C13: =SUMIFS(Datos!$F$2:$F$6000,Datos!$A$2:$A$6000,"NP",Datos!$H$2:$H$6000,$A13)
... A16: F | B16: =COUNTIFS(Datos!$A$2:$A$6000,"NP",Datos!$H$2:$H$6000,$A16) | C16: =SUMIFS(Datos!$F$2:$F$6000,Datos!$A$2:$A$6000,"NP",Datos!$H$2:$H$6000,$A16)

Sheet Vici
A1: VICI - LLAMADAS (del reporte .xlsb)
A2: MÉTRICA | B2: VALOR | C2: NOTA
A3: Total llamadas | B3: 15796 | C3: Hoja Vici del reporte SOHO .xlsb
A4: Números únicos marcados | B4: 7063
A5: Promedio intentos por número | B5: 2.24
A6: Llamadas contactadas | B6: 6562 | C6: Tasa contacto 41.5%
A7: No contestan | B7: 8268 | C7: 52.3% del total
A8: Duración total | B8: 306 h
A9: Duración promedio | B9: 70 s
A10: Máximo intentos a un número | B10: 1 | C10: Ver consolidado.html
A12: Fuente: Reporte_soho_junio_25 (1).xlsb / consolidado.html (datos estáticos de llamadas).
