Workbook

Sheet Registros
A1: FUENTE | B1: CUENTA | C1: CUST_NO | D1: NOMBRE | E1: NKEY | F1: MRC | G1: EJECUTIVA | H1: TELEFONO | I1: SERVICIOS | J1: CONTACTO_MOVIL | K1: TIPO
A2: NP | B2: 355382970000 | C2: 35538297 | D2: EDIL GOMEZ ARCE | E2: EDILGOMEZARCE | F2: 15 | G2: Solanye Acuña | H2: 68879413.0 | I2: 0 | J2: 1
A3: NP | B3: 353338240000 | C3: 35333824 | D3: MEYVIS CALVO | E3: MEYVISCALVO | F3: 15 | G3: Michelle Zambrano | H3: 67325039.0 | I3: 0 | J3: 1
A4: NP | B4: 321157030000 | C4: 32115703 | D4: GRUPO CORPORA | E4: GRUPOCORPORA | F4: 226.5 | G4: Ines Lizbeth Trujillo | H4: 66711672.0 | I4: 0 | J4: 1
A5: NP | B5: 369050850000 | C5: 36905085 | D5: SILVIA ARAUZ | E5: SILVIAARAUZ | F5: 19.52 | G5: Alejandra Mabel Hawkins | I5: 0 | J5: 1
A6: NP | B6: 355282350000 | C6: 35528235 | D6: SIMON WALTEROVA | E6: SIMONWALTEROVA | F6: 30 | G6: Maria Fernanda | H6: 62110427.0 | I6: 0 | J6: 1
A7: NP | B7: 312235730000 | C7: 31223573 | D7: CORPORACION JEMS, S.A. -- | E7: CORPORACIONJEMSSA | F7: 326.24 | G7: Yarelis Tulloch | H7: 62005659.0 | I7: 0 | J7: 1
A8: NP | B8: 322504520000 | C8: 32250452 | D8: Ardines CPA Y Asociados Sa | E8: ARDINESCPAYASOCIADOSSA | F8: 64.25 | G8: Abril Aparicio | H8: 69493738.0 | I8: 0 | J8: 1
A9: NP | B9: 323672910000 | C9: 32367291 | D9: Ademar SA | E9: ADEMARSA | F9: 44 | G9: Yariela Galarce | H9: 66131951.0 | I9: 0 | J9: 1
A10: NP | B10: 349277210000 | C10: 34927721 | D10: SMART COMMUNICATIONS, SA | E10: SMARTCOMMUNICATIONSSA | F10: 16.25 | G10: Nailyn Martinez | H10: 67424735.0 | I10: 0 | J10: 1
A11: NP | B11: 324167750000 | C11: 32416775 | D11: HACIENDA LOMA LINDA | E11: HACIENDALOMALINDA | F11: 291.5 | G11: Yamali Rodriguez | H11: 69834668.0 | I11: 0 | J11: 1
A12: NP | B12: 361003450000 | C12: 36100345 | D12: FERNANDO JOSE ARAUZ HERNANDEZ | E12: FERNANDOJOSEARAUZHERNANDEZ | F12: 15 | G12: Osiris Aguilar | H12: 69722675.0 | I12: 0 | J12: 1
A13: NP | B13: 352329430000 | C13: 35232943 | D13: YDALIDES VALDES | E13: YDALIDESVALDES | F13: 15 | G13: Karla Mc Intryre | H13: 67344173.0 | I13: 0 | J13: 1
A14: NP | B14: 354175000000 | C14: 35417500 | D14: THIAGO DAVID CABALLERO | E14: THIAGODAVIDCABALLERO | F14: 15 | G14: Michelle Zambrano | H14: 62475467.0 | I14: 0 | J14: 1
A15: NP | B15: 327604400000 | C15: 32760440 | D15: GLOBAL LANGUAGE,S.A. | E15: GLOBALLANGUAGESA | F15: 275 | G15: Ines Lizbeth Trujillo | H15: 69973283.0 | I15: 0 | J15: 1
A16: NP | B16: 322366890200 | C16: 32236689 | D16: LIMAYON, S.A | E16: LIMAYONSA | F16: 124.95 | G16: Alejandra Mabel Hawkins | H16: 69824192.0 | I16: 0 | J16: 1
A17: NP | B17: 322366890200 | C17: 32236689 | D17: Asociacion de | E17: ASOCIACIONDE | F17: 30.74 | G17: Maria Fernanda | H17: 69824192.0 | I17: 0 | J17: 1
... A86: NP | B86: 312209940000 | C86: 31220994 | D86: UROLOGOS ASOCIADOS, S.A. - | E86: UROLOGOSASOCIADOSSA | F86: 31 | G86: Maria Fernanda | H86: 62082799.0 | I86: 0 | J86: 1
A87: NP | B87: 364043730000 | C87: 36404373 | D87: BALTAZAR GOMEZ | E87: BALTAZARGOMEZ | F87: 16.94 | G87: Yarelis Tulloch | I87: 0 | J87: 1
A88: NP | B88: 359354310000 | C88: 35935431 | D88: JAFETH LOPEZ | E88: JAFETHLOPEZ | F88: 15 | G88: Abril Aparicio | H88: 67793454.0 | I88: 0 | J88: 1
A89: NP | B89: 325374980000 | C89: 32537498 | D89: HENG CHANG, S.A. | E89: HENGCHANGSA | F89: 215 | G89: Yariela Galarce | H89: 67076180.0 | I89: 0 | J89: 1
A90: NP | B90: 353355830000 | C90: 35335583 | D90: MARÍA RIVAS | E90: MARIARIVAS | F90: 15 | G90: Nailyn Martinez | H90: 65161910.0 | I90: 0 | J90: 1
A91: NP | B91: 321439070100 | C91: 32143907 | D91: POWER EXTERMINATOR | E91: POWEREXTERMINATOR | F91: 353.77 | G91: Yamali Rodriguez | H91: 69987657.0 | I91: 0 | J91: 1
A92: NP | B92: 346090040000 | C92: 34609004 | D92: MARY HELEN CASTAÑEDA DE CALDERON | E92: MARYHELENCASTANEDADECALDERON | F92: 15 | G92: Osiris Aguilar | H92: 66600631.0 | I92: 0 | J92: 1
A93: NP | B93: 345006480000 | C93: 34500648 | D93: THOMAS JEFFERSON SCHOOL, S.A. | E93: THOMASJEFFERSONSCHOOLSA | F93: 245 | G93: Karla Mc Intryre | H93: 68784059.0 | I93: 0 | J93: 1
A94: NP | B94: 343249890000 | C94: 34324989 | D94: ISELA MARIA CASTAÑEDAS DE SINGH | E94: ISELAMARIACASTANEDASDESINGH | F94: 12 | G94: Solanye Acuña | H94: 66409300.0 | I94: 0 | J94: 1
A95: NP | B95: 353003570000 | C95: 35300357 | D95: FAVIO VANEGAS | E95: FAVIOVANEGAS | F95: 15 | G95: Michelle Zambrano | H95: 67035338.0 | I95: 0 | J95: 1
A96: NP | B96: 342412720000 | C96: 34241272 | D96: JAFET BERTIAGA MOSQUERA | E96: JAFETBERTIAGAMOSQUERA | F96: 16.25 | G96: Ines Lizbeth Trujillo | H96: 66011050.0 | I96: 0 | J96: 1
A97: NP | B97: 354334670000 | C97: 35433467 | D97: ARISTIDES BARRIOS CARRION | E97: ARISTIDESBARRIOSCARRION | F97: 15 | G97: Alejandra Mabel Hawkins | H97: 66951128.0 | I97: 0 | J97: 1
A98: NP | B98: 312216560000 | C98: 31221656 | D98: JADE TECHNOLOGY S.A - | E98: JADETECHNOLOGYSA | F98: 109.5 | G98: Maria Fernanda | H98: 61126980.0 | I98: 0 | J98: 1
A99: NP | B99: 369039290000 | C99: 36903929 | D99: PETRA PABLA MOSQUERA BLANCO | E99: PETRAPABLAMOSQUERABLANCO | F99: 16.94 | G99: Yarelis Tulloch | I99: 0 | J99: 1
A100: NP | B100: 323540060100 | C100: 32354006 | D100: Jacqueline Quintero Dominguez | E100: JACQUELINEQUINTERODOMINGUEZ | F100: 52.74 | G100: Abril Aparicio | H100: 67812138.0 | I100: 0 | J100: 1
A101: NP | B101: 323540060100 | C101: 32354006 | D101: Jacqueline Quintero Dominguez | E101: JACQUELINEQUINTERODOMINGUEZ | F101: 14.99 | G101: Yariela Galarce | H101: 67812138.0 | I101: 0 | J101: 1
A102: NP | B102: 345179830000 | C102: 34517983 | D102: LEGUMBRES Y FRUTAS IVERSON | E102: LEGUMBRESYFRUTASIVERSON | F102: 40 | G102: Nailyn Martinez | H102: 69505541.0 | I102: 0 | J102: 1
A103: NP | B103: 349132360000 | C103: 34913236 | D103: AHAVA LATIN AMERCA | E103: AHAVALATINAMERCA | F103: 21 | G103: Yamali Rodriguez | H103: 60138979.0 | I103: 0 | J103: 1
A104: NP | B104: 344414740000 | C104: 34441474 | D104: NORBERTO ANTONIO CERNA LOPEZ | E104: NORBERTOANTONIOCERNALOPEZ | F104: 16.25 | G104: Osiris Aguilar | H104: 67769361.0 | I104: 0 | J104: 1
A105: NP | B105: 341297900000 | C105: 34129790 | D105: HERCILIA PACHECO SECAIDA | E105: HERCILIAPACHECOSECAIDA | F105: 16.25 | G105: Karla Mc Intryre | H105: 65372281.0 | I105: 0 | J105: 1
A106: NP | B106: 312209910000 | C106: 31220991 | D106: DISTRIBUIDORA CARIVA, S.A. - | E106: DISTRIBUIDORACARIVASA | F106: 64 | G106: Michelle Zambrano | H106: 62269500.0 | I106: 0 | J106: 1
A107: NP | B107: 325409780200 | C107: 32540978 | D107: NUBIA ARENAS GOMEZ | E107: NUBIAARENASGOMEZ | F107: 28.75 | G107: Ines Lizbeth Trujillo | H107: 66131158.0 | I107: 0 | J107: 1
A108: NP | B108: 322462760200 | C108: 32246276 | D108: A.J.FOTOS S.A. | E108: AJFOTOSSA | F108: 42 | G108: Alejandra Mabel Hawkins | H108: 67810778.0 | I108: 0 | J108: 1
...

Sheet Winback
A1: CLIENTE | B1: NKEY | C1: EJECUTIVA | D1: MRC | E1: RAZON_SALIDA | F1: RGU | G1: CONTACTO | H1: CORREO | I1: TEL1 | J1: TEL2 | K1: NKEY_MATCH | L1: RECUPERADO
A2: COIMSA | B2: COIMSA | C2: Michelle Zambrano | D2: 95 | E2: Solicitado por el Cliente | F2: 3 | G2: Jorge Villarreal ced 8-299-399 | H2: gerencia.coimsa@gmail.com | I2: 66776809.0 | J2: 2602749.0 | K2: COIMSA | L2: =IF(SUMPRODUCT((Cruce!$E$2:$E$6000+Cruce!$G$2:$G$6000+Cruce!$I$2:$I$6000>0)*(Cruce!$D$2:$D$6000=$K2))>0,"SI","NO")
A3: GRAPHIC SOLUTIONS/ CARMEN R. WILLIAMS 2 | B3: GRAPHICSOLUTIONSCARMENRWILLIAMS2 | C3: Solanye Acuña | D3: 12 | E3: Solicitado por el Cliente | F3: 1 | G3: Angelica Gallego E-8-79314 | I3: 3140588.0 | K3: GRAPHICSOLUTIONSCARMENRWILLIAMS2 | L3: =IF(SUMPRODUCT((Cruce!$E$2:$E$6000+Cruce!$G$2:$G$6000+Cruce!$I$2:$I$6000>0)*(Cruce!$D$2:$D$6000=$K3))>0,"SI","NO")
A4: ALEXIS ALEXANDER GOMEZ MENDIETA | B4: ALEXISALEXANDERGOMEZMENDIETA | C4: Maria Fernanda Rivas | D4: 20.75 | E4: Solicitado por el Cliente | F4: 1 | G4: ALEXIS ALEXANDER GOMEZ MENDIETA | I4: 67472064.0 | K4: ALEXISALEXANDERGOMEZMENDIETA | L4: =IF(SUMPRODUCT((Cruce!$E$2:$E$6000+Cruce!$G$2:$G$6000+Cruce!$I$2:$I$6000>0)*(Cruce!$D$2:$D$6000=$K4))>0,"SI","NO")
A5: PH COUNTRY CLUB - | B5: PHCOUNTRYCLUB | C5: Nailyn Martinez Johnson | D5: 166 | E5: Solicitado por el Cliente | F5: 8 | G5: MICHAEL HAMOUI | I5: 69144044.0 | K5: PHCOUNTRYCLUB | L5: =IF(SUMPRODUCT((Cruce!$E$2:$E$6000+Cruce!$G$2:$G$6000+Cruce!$I$2:$I$6000>0)*(Cruce!$D$2:$D$6000=$K5))>0,"SI","NO")
C6: Michelle Zambrano | D6: 20.75 | E6: Solicitado por el Cliente | F6: 1 | L6: =IF(SUMPRODUCT((Cruce!$E$2:$E$6000+Cruce!$G$2:$G$6000+Cruce!$I$2:$I$6000>0)*(Cruce!$D$2:$D$6000=$K6))>0,"SI","NO")
C7: Solanye Acuña | D7: 40.5 | E7: Solicitado por el Cliente | F7: 1 | L7: =IF(SUMPRODUCT((Cruce!$E$2:$E$6000+Cruce!$G$2:$G$6000+Cruce!$I$2:$I$6000>0)*(Cruce!$D$2:$D$6000=$K7))>0,"SI","NO")
C8: Maria Fernanda Rivas | D8: 31 | E8: Solicitado por el Cliente | F8: 1 | L8: =IF(SUMPRODUCT((Cruce!$E$2:$E$6000+Cruce!$G$2:$G$6000+Cruce!$I$2:$I$6000>0)*(Cruce!$D$2:$D$6000=$K8))>0,"SI","NO")
A9: IDEALO | B9: IDEALO | C9: Nailyn Martinez Johnson | D9: 41.5 | E9: Solicitado por el Cliente | F9: 2 | G9: IDEALO | I9: 68800852.0 | K9: IDEALO | L9: =IF(SUMPRODUCT((Cruce!$E$2:$E$6000+Cruce!$G$2:$G$6000+Cruce!$I$2:$I$6000>0)*(Cruce!$D$2:$D$6000=$K9))>0,"SI","NO")
A10: INFINITY LOGISTICS INFINITY LOGISTICS AGENCY, CORP | B10: INFINITYLOGISTICSINFINITYLOGISTICSAGENCYCORP | C10: Michelle Zambrano | D10: 60 | E10: Solicitado por el Cliente | F10: 3 | G10: ARCELIS ASPRILLA | I10: 4304648.0 | K10: INFINITYLOGISTICSINFINITYLOGISTICSAGENCYCORP | L10: =IF(SUMPRODUCT((Cruce!$E$2:$E$6000+Cruce!$G$2:$G$6000+Cruce!$I$2:$I$6000>0)*(Cruce!$D$2:$D$6000=$K10))>0,"SI","NO")
C11: Solanye Acuña | D11: 50 | E11: Solicitado por el Cliente | F11: 2 | L11: =IF(SUMPRODUCT((Cruce!$E$2:$E$6000+Cruce!$G$2:$G$6000+Cruce!$I$2:$I$6000>0)*(Cruce!$D$2:$D$6000=$K11))>0,"SI","NO")
C12: Maria Fernanda Rivas | D12: 50 | E12: Solicitado por el Cliente | F12: 1 | L12: =IF(SUMPRODUCT((Cruce!$E$2:$E$6000+Cruce!$G$2:$G$6000+Cruce!$I$2:$I$6000>0)*(Cruce!$D$2:$D$6000=$K12))>0,"SI","NO")
C13: Nailyn Martinez Johnson | D13: 17 | E13: Solicitado por el Cliente | F13: 1 | L13: =IF(SUMPRODUCT((Cruce!$E$2:$E$6000+Cruce!$G$2:$G$6000+Cruce!$I$2:$I$6000>0)*(Cruce!$D$2:$D$6000=$K13))>0,"SI","NO")
C14: Michelle Zambrano | D14: 170 | E14: Solicitado por el Cliente | F14: 5 | L14: =IF(SUMPRODUCT((Cruce!$E$2:$E$6000+Cruce!$G$2:$G$6000+Cruce!$I$2:$I$6000>0)*(Cruce!$D$2:$D$6000=$K14))>0,"SI","NO")
C15: Solanye Acuña | D15: 35 | E15: Solicitado por el Cliente | F15: 1 | L15: =IF(SUMPRODUCT((Cruce!$E$2:$E$6000+Cruce!$G$2:$G$6000+Cruce!$I$2:$I$6000>0)*(Cruce!$D$2:$D$6000=$K15))>0,"SI","NO")
A16: RC SOLUTION, S.A - | B16: RCSOLUTIONSA | C16: Maria Fernanda Rivas | D16: 41.5 | E16: Solicitado por el Cliente | F16: 2 | G16: RC SOLUTION, S.A - | I16: 62608877.0 | K16: RCSOLUTIONSA | L16: =IF(SUMPRODUCT((Cruce!$E$2:$E$6000+Cruce!$G$2:$G$6000+Cruce!$I$2:$I$6000>0)*(Cruce!$D$2:$D$6000=$K16))>0,"SI","NO")
C17: Nailyn Martinez Johnson | D17: 113.5 | E17: Solicitado por el Cliente | F17: 4 | L17: =IF(SUMPRODUCT((Cruce!$E$2:$E$6000+Cruce!$G$2:$G$6000+Cruce!$I$2:$I$6000>0)*(Cruce!$D$2:$D$6000=$K17))>0,"SI","NO")
A18: Servicios Logitisticos Imperial S.A | B18: SERVICIOSLOGITISTICOSIMPERIALSA | C18: Michelle Zambrano | D18: 30 | E18: Solicitado por el Cliente | F18: 2 | G18: Servicios Logisticos Imperial S.A. | H18: comercial.panama@petentrega.com | I18: 65146298.0 | K18: SERVICIOSLOGITISTICOSIMPERIALSA | L18: =IF(SUMPRODUCT((Cruce!$E$2:$E$6000+Cruce!$G$2:$G$6000+Cruce!$I$2:$I$6000>0)*(Cruce!$D$2:$D$6000=$K18))>0,"SI","NO")
A19: CLINICA TU SALUD Y BELLEZA - | B19: CLINICATUSALUDYBELLEZA | C19: Solanye Acuña | D19: 16.25 | E19: Solicitado por el Cliente | F19: 1 | G19: Soy Yoli calu N-20-930 | I19: 65081722.0 | K19: CLINICATUSALUDYBELLEZA | L19: =IF(SUMPRODUCT((Cruce!$E$2:$E$6000+Cruce!$G$2:$G$6000+Cruce!$I$2:$I$6000>0)*(Cruce!$D$2:$D$6000=$K19))>0,"SI","NO")
A20: SERVIEDUCA S,A. - | B20: SERVIEDUCASA | C20: Maria Fernanda Rivas | D20: 20 | E20: Solicitado por el Cliente | F20: 1 | G20: SERVIEDUCA S,A. - GABRIELA ALEJANDRA, | I20: 2366783.0 | K20: SERVIEDUCASA | L20: =IF(SUMPRODUCT((Cruce!$E$2:$E$6000+Cruce!$G$2:$G$6000+Cruce!$I$2:$I$6000>0)*(Cruce!$D$2:$D$6000=$K20))>0,"SI","NO")
C21: Nailyn Martinez Johnson | D21: 25 | E21: Solicitado por el Cliente | F21: 1 | L21: =IF(SUMPRODUCT((Cruce!$E$2:$E$6000+Cruce!$G$2:$G$6000+Cruce!$I$2:$I$6000>0)*(Cruce!$D$2:$D$6000=$K21))>0,"SI","NO")
A22: PANAMA JOURNEYS S,A - | B22: PANAMAJOURNEYSSA | C22: Michelle Zambrano | D22: 31 | E22: Solicitado por el Cliente | F22: 1 | G22: PANAMA JOURNEYS S,A - | I22: 63134216.0 | K22: PANAMAJOURNEYSSA | L22: =IF(SUMPRODUCT((Cruce!$E$2:$E$6000+Cruce!$G$2:$G$6000+Cruce!$I$2:$I$6000>0)*(Cruce!$D$2:$D$6000=$K22))>0,"SI","NO")
A23: AGRO JP / NILKA ATENCIO | B23: AGROJPNILKAATENCIO | C23: Solanye Acuña | D23: 65 | E23: Solicitado por el Cliente | F23: 2 | G23: AGRO JP / NILKA ATENCIO | H23: ni.lka@hotmail.com | I23: 65767586.0 | J23: 65767586.0 | K23: AGROJPNILKAATENCIO | L23: =IF(SUMPRODUCT((Cruce!$E$2:$E$6000+Cruce!$G$2:$G$6000+Cruce!$I$2:$I$6000>0)*(Cruce!$D$2:$D$6000=$K23))>0,"SI","NO")
C24: Maria Fernanda Rivas | D24: 31 | E24: Solicitado por el Cliente | F24: 1 | L24: =IF(SUMPRODUCT((Cruce!$E$2:$E$6000+Cruce!$G$2:$G$6000+Cruce!$I$2:$I$6000>0)*(Cruce!$D$2:$D$6000=$K24))>0,"SI","NO")
C25: Nailyn Martinez Johnson | D25: 40.5 | E25: Solicitado por el Cliente | F25: 1 | L25: =IF(SUMPRODUCT((Cruce!$E$2:$E$6000+Cruce!$G$2:$G$6000+Cruce!$I$2:$I$6000>0)*(Cruce!$D$2:$D$6000=$K25))>0,"SI","NO")
C26: Michelle Zambrano | D26: 66.5 | E26: Solicitado por el Cliente | F26: 1 | L26: =IF(SUMPRODUCT((Cruce!$E$2:$E$6000+Cruce!$G$2:$G$6000+Cruce!$I$2:$I$6000>0)*(Cruce!$D$2:$D$6000=$K26))>0,"SI","NO")
A27: UPPER EAST TOWER | B27: UPPEREASTTOWER | C27: Solanye Acuña | D27: 124 | E27: Solicitado por el Cliente | F27: 4 | G27: UPPER EAST TOWER | I27: 2027194.0 | K27: UPPEREASTTOWER | L27: =IF(SUMPRODUCT((Cruce!$E$2:$E$6000+Cruce!$G$2:$G$6000+Cruce!$I$2:$I$6000>0)*(Cruce!$D$2:$D$6000=$K27))>0,"SI","NO")
A28: FLIX CINEVISION PANAMA, S. DE R.L. - | B28: FLIXCINEVISIONPANAMASDERL | C28: Maria Fernanda Rivas | D28: 81 | E28: Solicitado por el Cliente | F28: 1 | G28: FLIX CINEVISION PANAMA, S. DE R.L. - | I28: 64993246.0 | K28: FLIXCINEVISIONPANAMASDERL | L28: =IF(SUMPRODUCT((Cruce!$E$2:$E$6000+Cruce!$G$2:$G$6000+Cruce!$I$2:$I$6000>0)*(Cruce!$D$2:$D$6000=$K28))>0,"SI","NO")
A29: AVAPSA | B29: AVAPSA | C29: Nailyn Martinez Johnson | D29: 40.5 | E29: Solicitado por el Cliente | F29: 1 | G29: AVAPSA | H29: magt.67vetequi@gmail.com | I29: 62605786.0 | J29: 66150700.0 | K29: AVAPSA | L29: =IF(SUMPRODUCT((Cruce!$E$2:$E$6000+Cruce!$G$2:$G$6000+Cruce!$I$2:$I$6000>0)*(Cruce!$D$2:$D$6000=$K29))>0,"SI","NO")
A30: DRAG COLORS | B30: DRAGCOLORS | C30: Michelle Zambrano | D30: 22 | E30: Solicitado por el Cliente | F30: 1 | G30: Salvador Orantes | H30: Chambascar27@gmail.com | I30: 69207844.0 | J30: 69207844.0 | K30: DRAGCOLORS | L30: =IF(SUMPRODUCT((Cruce!$E$2:$E$6000+Cruce!$G$2:$G$6000+Cruce!$I$2:$I$6000>0)*(Cruce!$D$2:$D$6000=$K30))>0,"SI","NO")
C31: Solanye Acuña | D31: 150 | E31: Solicitado por el Cliente | F31: 6 | L31: =IF(SUMPRODUCT((Cruce!$E$2:$E$6000+Cruce!$G$2:$G$6000+Cruce!$I$2:$I$6000>0)*(Cruce!$D$2:$D$6000=$K31))>0,"SI","NO")
C32: Maria Fernanda Rivas | D32: 21 | E32: Solicitado por el Cliente | F32: 3 | L32: =IF(SUMPRODUCT((Cruce!$E$2:$E$6000+Cruce!$G$2:$G$6000+Cruce!$I$2:$I$6000>0)*(Cruce!$D$2:$D$6000=$K32))>0,"SI","NO")
A33: Anagan | B33: ANAGAN | C33: Nailyn Martinez Johnson | D33: 42 | E33: Solicitado por el Cliente | F33: 1 | G33: LUIS MARTINEZ 7-83-25 // Amarilis Cristóbal 8-841-1249 | H33: anagan1@cwpanama.net | I33: 3140633.0 | J33: 3140633.0 | K33: ANAGAN | L33: =IF(SUMPRODUCT((Cruce!$E$2:$E$6000+Cruce!$G$2:$G$6000+Cruce!$I$2:$I$6000>0)*(Cruce!$D$2:$D$6000=$K33))>0,"SI","NO")
C34: Michelle Zambrano | D34: 44 | E34: Solicitado por el Cliente | F34: 1 | L34: =IF(SUMPRODUCT((Cruce!$E$2:$E$6000+Cruce!$G$2:$G$6000+Cruce!$I$2:$I$6000>0)*(Cruce!$D$2:$D$6000=$K34))>0,"SI","NO")
A35: Carmen Valdivia Valdes | B35: CARMENVALDIVIAVALDES | C35: Solanye Acuña | D35: 21 | E35: Solicitado por el Cliente | F35: 1 | I35: 66773196.0 | K35: CARMENVALDIVIAVALDES | L35: =IF(SUMPRODUCT((Cruce!$E$2:$E$6000+Cruce!$G$2:$G$6000+Cruce!$I$2:$I$6000>0)*(Cruce!$D$2:$D$6000=$K35))>0,"SI","NO")
A36: Gixel Guevara Almanza | B36: GIXELGUEVARAALMANZA | C36: Maria Fernanda Rivas | D36: 16 | E36: Solicitado por el Cliente | F36: 1 | I36: 69822979.0 | K36: GIXELGUEVARAALMANZA | L36: =IF(SUMPRODUCT((Cruce!$E$2:$E$6000+Cruce!$G$2:$G$6000+Cruce!$I$2:$I$6000>0)*(Cruce!$D$2:$D$6000=$K36))>0,"SI","NO")
A37: Jaime Arroyo Atencio | B37: JAIMEARROYOATENCIO | C37: Nailyn Martinez Johnson | D37: 21.75 | E37: Solicitado por el Cliente | F37: 1 | I37: 2287216.0 | K37: JAIMEARROYOATENCIO | L37: =IF(SUMPRODUCT((Cruce!$E$2:$E$6000+Cruce!$G$2:$G$6000+Cruce!$I$2:$I$6000>0)*(Cruce!$D$2:$D$6000=$K37))>0,"SI","NO")
A38: Shirley y Asociados | B38: SHIRLEYYASOCIADOS | C38: Michelle Zambrano | D38: 45.5 | E38: Solicitado por el Cliente | F38: 1 | G38: Luis Antonio Shirley Campbell | H38: administracion@shirleylaw.com | I38: 66752321.0 | J38: 66752321.0 | K38: SHIRLEYYASOCIADOS | L38: =IF(SUMPRODUCT((Cruce!$E$2:$E$6000+Cruce!$G$2:$G$6000+Cruce!$I$2:$I$6000>0)*(Cruce!$D$2:$D$6000=$K38))>0,"SI","NO")
A39: M. Contratista | B39: MCONTRATISTA | C39: Solanye Acuña | D39: 42 | E39: MIGRACION POST-PRE | F39: 1 | G39: Ricardo Raul Mezquita | I39: 2790469.0 | K39: MCONTRATISTA | L39: =IF(SUMPRODUCT((Cruce!$E$2:$E$6000+Cruce!$G$2:$G$6000+Cruce!$I$2:$I$6000>0)*(Cruce!$D$2:$D$6000=$K39))>0,"SI","NO")
A40: Solidus Secur | B40: SOLIDUSSECUR | C40: Maria Fernanda Rivas | D40: 15.99 | E40: Solicitado por el Cliente | F40: 1 | G40: HEINER SPEICH | H40: karoll.arguelles@sardona-capital.com | I40: 69826252.0 | J40: 69826252.0 | K40: SOLIDUSSECUR | L40: =IF(SUMPRODUCT((Cruce!$E$2:$E$6000+Cruce!$G$2:$G$6000+Cruce!$I$2:$I$6000>0)*(Cruce!$D$2:$D$6000=$K40))>0,"SI","NO")
...

Sheet Cruce
A1: CUENTA | B1: CUST_NO | C1: NOMBRE | D1: NKEY | E1: EN_NP | F1: MRC_NP | G1: EN_MOV | H1: MRC_MOV | I1: EN_CS | J1: SERVICIOS_CS | K1: EN_WB | L1: MRC_WB | M1: MOVIL | N1: SERVICIOS | O1: SEGMENTO | P1: OPORTUNIDAD | Q1: MRC_TOTAL | R1: EJECUTIVA | S1: FUENTES | T1: N.BASES
A2: 355382970000 | B2: 35538297 | C2: EDIL GOMEZ ARCE | D2: EDILGOMEZARCE | E2: =IF(COUNTIFS(Registros!$A$2:$A$6000,"NP",Registros!$B$2:$B$6000,$A2)>0,1,0) | F2: =IF($E2=1,SUMIFS(Registros!$F$2:$F$6000,Registros!$A$2:$A$6000,"NP",Registros!$B$2:$B$6000,$A2),0) | G2: =IF(COUNTIFS(Registros!$A$2:$A$6000,"MOV",Registros!$B$2:$B$6000,$A2)>0,1,0) | H2: =IF($G2=1,SUMIFS(Registros!$F$2:$F$6000,Registros!$A$2:$A$6000,"MOV",Registros!$B$2:$B$6000,$A2),0) | I2: =IF(COUNTIFS(Registros!$A$2:$A$6000,"CS",Registros!$B$2:$B$6000,$A2)>0,1,0) | J2: =IF($I2=1,SUMIFS(Registros!$I$2:$I$6000,Registros!$A$2:$A$6000,"CS",Registros!$B$2:$B$6000,$A2),0) | K2: =IF(COUNTIFS(Winback!$K$2:$K$300,$D2)>0,1,0) | L2: =IF(AND($K2=1,LEFT($A2,3)="WB-"),SUMIFS(Winback!$D$2:$D$300,Winback!$K$2:$K$300,$D2),0) | M2: =IF(OR($E2=1,$G2=1,SUMIFS(Registros!$J$2:$J$6000,Registros!$B$2:$B$6000,$A2)>0),1,0) | N2: =IF($J2>0,1,IF(COUNTIFS(Registros!$A$2:$A$6000,"CS",Registros!$B$2:$B$6000,$A2,Registros!$K$2:$K$6000,"<>")>0,1,0)) | O2: =IF(AND($K2=1,$E2=0,$G2=0,$I2=0),"WINBACK",IF(AND($M2=1,$N2>0),"CONVERGENTE",IF($M2=1,"SOLO MÓVIL",IF($N2>0,"SOLO FIJO / INTERNET","SIN SERVICIOS")))) | P2: =IF($O2="WINBACK","Recuperar (winback)",IF($O2="CONVERGENTE","Upgrade / más líneas",IF($O2="SOLO MÓVIL","Ofrecer fijo + internet (FLBBTV)",IF($O2="SOLO FIJO / INTERNET","Ofrecer línea móvil Nextphone","Oferta completa (móvil + fijo + internet)")))) | Q2: =$F2+$H2+$L2 | R2: =IFERROR(VLOOKUP($A2,Registros!$B$2:$G$6000,6,0),IFERROR(VLOOKUP($D2,Winback!$B$2:$C$300,2,0),"")) | S2: =IF($E2=1,"NP","")&IF($G2=1,"+MOV","")&IF($I2=1,"+CS","")&IF($K2=1,"+WB","") | T2: =$E2+$G2+$I2+$K2
A3: 353338240000 | B3: 35333824 | C3: MEYVIS CALVO | D3: MEYVISCALVO | E3: =IF(COUNTIFS(Registros!$A$2:$A$6000,"NP",Registros!$B$2:$B$6000,$A3)>0,1,0) | F3: =IF($E3=1,SUMIFS(Registros!$F$2:$F$6000,Registros!$A$2:$A$6000,"NP",Registros!$B$2:$B$6000,$A3),0) | G3: =IF(COUNTIFS(Registros!$A$2:$A$6000,"MOV",Registros!$B$2:$B$6000,$A3)>0,1,0) | H3: =IF($G3=1,SUMIFS(Registros!$F$2:$F$6000,Registros!$A$2:$A$6000,"MOV",Registros!$B$2:$B$6000,$A3),0) | I3: =IF(COUNTIFS(Registros!$A$2:$A$6000,"CS",Registros!$B$2:$B$6000,$A3)>0,1,0) | J3: =IF($I3=1,SUMIFS(Registros!$I$2:$I$6000,Registros!$A$2:$A$6000,"CS",Registros!$B$2:$B$6000,$A3),0) | K3: =IF(COUNTIFS(Winback!$K$2:$K$300,$D3)>0,1,0) | L3: =IF(AND($K3=1,LEFT($A3,3)="WB-"),SUMIFS(Winback!$D$2:$D$300,Winback!$K$2:$K$300,$D3),0) | M3: =IF(OR($E3=1,$G3=1,SUMIFS(Registros!$J$2:$J$6000,Registros!$B$2:$B$6000,$A3)>0),1,0) | N3: =IF($J3>0,1,IF(COUNTIFS(Registros!$A$2:$A$6000,"CS",Registros!$B$2:$B$6000,$A3,Registros!$K$2:$K$6000,"<>")>0,1,0)) | O3: =IF(AND($K3=1,$E3=0,$G3=0,$I3=0),"WINBACK",IF(AND($M3=1,$N3>0),"CONVERGENTE",IF($M3=1,"SOLO MÓVIL",IF($N3>0,"SOLO FIJO / INTERNET","SIN SERVICIOS")))) | P3: =IF($O3="WINBACK","Recuperar (winback)",IF($O3="CONVERGENTE","Upgrade / más líneas",IF($O3="SOLO MÓVIL","Ofrecer fijo + internet (FLBBTV)",IF($O3="SOLO FIJO / INTERNET","Ofrecer línea móvil Nextphone","Oferta completa (móvil + fijo + internet)")))) | Q3: =$F3+$H3+$L3 | R3: =IFERROR(VLOOKUP($A3,Registros!$B$2:$G$6000,6,0),IFERROR(VLOOKUP($D3,Winback!$B$2:$C$300,2,0),"")) | S3: =IF($E3=1,"NP","")&IF($G3=1,"+MOV","")&IF($I3=1,"+CS","")&IF($K3=1,"+WB","") | T3: =$E3+$G3+$I3+$K3
A4: 321157030000 | B4: 32115703 | C4: GRUPO CORPORA | D4: GRUPOCORPORA | E4: =IF(COUNTIFS(Registros!$A$2:$A$6000,"NP",Registros!$B$2:$B$6000,$A4)>0,1,0) | F4: =IF($E4=1,SUMIFS(Registros!$F$2:$F$6000,Registros!$A$2:$A$6000,"NP",Registros!$B$2:$B$6000,$A4),0) | G4: =IF(COUNTIFS(Registros!$A$2:$A$6000,"MOV",Registros!$B$2:$B$6000,$A4)>0,1,0) | H4: =IF($G4=1,SUMIFS(Registros!$F$2:$F$6000,Registros!$A$2:$A$6000,"MOV",Registros!$B$2:$B$6000,$A4),0) | I4: =IF(COUNTIFS(Registros!$A$2:$A$6000,"CS",Registros!$B$2:$B$6000,$A4)>0,1,0) | J4: =IF($I4=1,SUMIFS(Registros!$I$2:$I$6000,Registros!$A$2:$A$6000,"CS",Registros!$B$2:$B$6000,$A4),0) | K4: =IF(COUNTIFS(Winback!$K$2:$K$300,$D4)>0,1,0) | L4: =IF(AND($K4=1,LEFT($A4,3)="WB-"),SUMIFS(Winback!$D$2:$D$300,Winback!$K$2:$K$300,$D4),0) | M4: =IF(OR($E4=1,$G4=1,SUMIFS(Registros!$J$2:$J$6000,Registros!$B$2:$B$6000,$A4)>0),1,0) | N4: =IF($J4>0,1,IF(COUNTIFS(Registros!$A$2:$A$6000,"CS",Registros!$B$2:$B$6000,$A4,Registros!$K$2:$K$6000,"<>")>0,1,0)) | O4: =IF(AND($K4=1,$E4=0,$G4=0,$I4=0),"WINBACK",IF(AND($M4=1,$N4>0),"CONVERGENTE",IF($M4=1,"SOLO MÓVIL",IF($N4>0,"SOLO FIJO / INTERNET","SIN SERVICIOS")))) | P4: =IF($O4="WINBACK","Recuperar (winback)",IF($O4="CONVERGENTE","Upgrade / más líneas",IF($O4="SOLO MÓVIL","Ofrecer fijo + internet (FLBBTV)",IF($O4="SOLO FIJO / INTERNET","Ofrecer línea móvil Nextphone","Oferta completa (móvil + fijo + internet)")))) | Q4: =$F4+$H4+$L4 | R4: =IFERROR(VLOOKUP($A4,Registros!$B$2:$G$6000,6,0),IFERROR(VLOOKUP($D4,Winback!$B$2:$C$300,2,0),"")) | S4: =IF($E4=1,"NP","")&IF($G4=1,"+MOV","")&IF($I4=1,"+CS","")&IF($K4=1,"+WB","") | T4: =$E4+$G4+$I4+$K4
A5: 369050850000 | B5: 36905085 | C5: SILVIA ARAUZ | D5: SILVIAARAUZ | E5: =IF(COUNTIFS(Registros!$A$2:$A$6000,"NP",Registros!$B$2:$B$6000,$A5)>0,1,0) | F5: =IF($E5=1,SUMIFS(Registros!$F$2:$F$6000,Registros!$A$2:$A$6000,"NP",Registros!$B$2:$B$6000,$A5),0) | G5: =IF(COUNTIFS(Registros!$A$2:$A$6000,"MOV",Registros!$B$2:$B$6000,$A5)>0,1,0) | H5: =IF($G5=1,SUMIFS(Registros!$F$2:$F$6000,Registros!$A$2:$A$6000,"MOV",Registros!$B$2:$B$6000,$A5),0) | I5: =IF(COUNTIFS(Registros!$A$2:$A$6000,"CS",Registros!$B$2:$B$6000,$A5)>0,1,0) | J5: =IF($I5=1,SUMIFS(Registros!$I$2:$I$6000,Registros!$A$2:$A$6000,"CS",Registros!$B$2:$B$6000,$A5),0) | K5: =IF(COUNTIFS(Winback!$K$2:$K$300,$D5)>0,1,0) | L5: =IF(AND($K5=1,LEFT($A5,3)="WB-"),SUMIFS(Winback!$D$2:$D$300,Winback!$K$2:$K$300,$D5),0) | M5: =IF(OR($E5=1,$G5=1,SUMIFS(Registros!$J$2:$J$6000,Registros!$B$2:$B$6000,$A5)>0),1,0) | N5: =IF($J5>0,1,IF(COUNTIFS(Registros!$A$2:$A$6000,"CS",Registros!$B$2:$B$6000,$A5,Registros!$K$2:$K$6000,"<>")>0,1,0)) | O5: =IF(AND($K5=1,$E5=0,$G5=0,$I5=0),"WINBACK",IF(AND($M5=1,$N5>0),"CONVERGENTE",IF($M5=1,"SOLO MÓVIL",IF($N5>0,"SOLO FIJO / INTERNET","SIN SERVICIOS")))) | P5: =IF($O5="WINBACK","Recuperar (winback)",IF($O5="CONVERGENTE","Upgrade / más líneas",IF($O5="SOLO MÓVIL","Ofrecer fijo + internet (FLBBTV)",IF($O5="SOLO FIJO / INTERNET","Ofrecer línea móvil Nextphone","Oferta completa (móvil + fijo + internet)")))) | Q5: =$F5+$H5+$L5 | R5: =IFERROR(VLOOKUP($A5,Registros!$B$2:$G$6000,6,0),IFERROR(VLOOKUP($D5,Winback!$B$2:$C$300,2,0),"")) | S5: =IF($E5=1,"NP","")&IF($G5=1,"+MOV","")&IF($I5=1,"+CS","")&IF($K5=1,"+WB","") | T5: =$E5+$G5+$I5+$K5
A6: 355282350000 | B6: 35528235 | C6: SIMON WALTEROVA | D6: SIMONWALTEROVA | E6: =IF(COUNTIFS(Registros!$A$2:$A$6000,"NP",Registros!$B$2:$B$6000,$A6)>0,1,0) | F6: =IF($E6=1,SUMIFS(Registros!$F$2:$F$6000,Registros!$A$2:$A$6000,"NP",Registros!$B$2:$B$6000,$A6),0) | G6: =IF(COUNTIFS(Registros!$A$2:$A$6000,"MOV",Registros!$B$2:$B$6000,$A6)>0,1,0) | H6: =IF($G6=1,SUMIFS(Registros!$F$2:$F$6000,Registros!$A$2:$A$6000,"MOV",Registros!$B$2:$B$6000,$A6),0) | I6: =IF(COUNTIFS(Registros!$A$2:$A$6000,"CS",Registros!$B$2:$B$6000,$A6)>0,1,0) | J6: =IF($I6=1,SUMIFS(Registros!$I$2:$I$6000,Registros!$A$2:$A$6000,"CS",Registros!$B$2:$B$6000,$A6),0) | K6: =IF(COUNTIFS(Winback!$K$2:$K$300,$D6)>0,1,0) | L6: =IF(AND($K6=1,LEFT($A6,3)="WB-"),SUMIFS(Winback!$D$2:$D$300,Winback!$K$2:$K$300,$D6),0) | M6: =IF(OR($E6=1,$G6=1,SUMIFS(Registros!$J$2:$J$6000,Registros!$B$2:$B$6000,$A6)>0),1,0) | N6: =IF($J6>0,1,IF(COUNTIFS(Registros!$A$2:$A$6000,"CS",Registros!$B$2:$B$6000,$A6,Registros!$K$2:$K$6000,"<>")>0,1,0)) | O6: =IF(AND($K6=1,$E6=0,$G6=0,$I6=0),"WINBACK",IF(AND($M6=1,$N6>0),"CONVERGENTE",IF($M6=1,"SOLO MÓVIL",IF($N6>0,"SOLO FIJO / INTERNET","SIN SERVICIOS")))) | P6: =IF($O6="WINBACK","Recuperar (winback)",IF($O6="CONVERGENTE","Upgrade / más líneas",IF($O6="SOLO MÓVIL","Ofrecer fijo + internet (FLBBTV)",IF($O6="SOLO FIJO / INTERNET","Ofrecer línea móvil Nextphone","Oferta completa (móvil + fijo + internet)")))) | Q6: =$F6+$H6+$L6 | R6: =IFERROR(VLOOKUP($A6,Registros!$B$2:$G$6000,6,0),IFERROR(VLOOKUP($D6,Winback!$B$2:$C$300,2,0),"")) | S6: =IF($E6=1,"NP","")&IF($G6=1,"+MOV","")&IF($I6=1,"+CS","")&IF($K6=1,"+WB","") | T6: =$E6+$G6+$I6+$K6
A7: 312235730000 | B7: 31223573 | C7: CORPORACION JEMS, S.A. -- | D7: CORPORACIONJEMSSA | E7: =IF(COUNTIFS(Registros!$A$2:$A$6000,"NP",Registros!$B$2:$B$6000,$A7)>0,1,0) | F7: =IF($E7=1,SUMIFS(Registros!$F$2:$F$6000,Registros!$A$2:$A$6000,"NP",Registros!$B$2:$B$6000,$A7),0) | G7: =IF(COUNTIFS(Registros!$A$2:$A$6000,"MOV",Registros!$B$2:$B$6000,$A7)>0,1,0) | H7: =IF($G7=1,SUMIFS(Registros!$F$2:$F$6000,Registros!$A$2:$A$6000,"MOV",Registros!$B$2:$B$6000,$A7),0) | I7: =IF(COUNTIFS(Registros!$A$2:$A$6000,"CS",Registros!$B$2:$B$6000,$A7)>0,1,0) | J7: =IF($I7=1,SUMIFS(Registros!$I$2:$I$6000,Registros!$A$2:$A$6000,"CS",Registros!$B$2:$B$6000,$A7),0) | K7: =IF(COUNTIFS(Winback!$K$2:$K$300,$D7)>0,1,0) | L7: =IF(AND($K7=1,LEFT($A7,3)="WB-"),SUMIFS(Winback!$D$2:$D$300,Winback!$K$2:$K$300,$D7),0) | M7: =IF(OR($E7=1,$G7=1,SUMIFS(Registros!$J$2:$J$6000,Registros!$B$2:$B$6000,$A7)>0),1,0) | N7: =IF($J7>0,1,IF(COUNTIFS(Registros!$A$2:$A$6000,"CS",Registros!$B$2:$B$6000,$A7,Registros!$K$2:$K$6000,"<>")>0,1,0)) | O7: =IF(AND($K7=1,$E7=0,$G7=0,$I7=0),"WINBACK",IF(AND($M7=1,$N7>0),"CONVERGENTE",IF($M7=1,"SOLO MÓVIL",IF($N7>0,"SOLO FIJO / INTERNET","SIN SERVICIOS")))) | P7: =IF($O7="WINBACK","Recuperar (winback)",IF($O7="CONVERGENTE","Upgrade / más líneas",IF($O7="SOLO MÓVIL","Ofrecer fijo + internet (FLBBTV)",IF($O7="SOLO FIJO / INTERNET","Ofrecer línea móvil Nextphone","Oferta completa (móvil + fijo + internet)")))) | Q7: =$F7+$H7+$L7 | R7: =IFERROR(VLOOKUP($A7,Registros!$B$2:$G$6000,6,0),IFERROR(VLOOKUP($D7,Winback!$B$2:$C$300,2,0),"")) | S7: =IF($E7=1,"NP","")&IF($G7=1,"+MOV","")&IF($I7=1,"+CS","")&IF($K7=1,"+WB","") | T7: =$E7+$G7+$I7+$K7
A8: 322504520000 | B8: 32250452 | C8: Ardines CPA Y Asociados Sa | D8: ARDINESCPAYASOCIADOSSA | E8: =IF(COUNTIFS(Registros!$A$2:$A$6000,"NP",Registros!$B$2:$B$6000,$A8)>0,1,0) | F8: =IF($E8=1,SUMIFS(Registros!$F$2:$F$6000,Registros!$A$2:$A$6000,"NP",Registros!$B$2:$B$6000,$A8),0) | G8: =IF(COUNTIFS(Registros!$A$2:$A$6000,"MOV",Registros!$B$2:$B$6000,$A8)>0,1,0) | H8: =IF($G8=1,SUMIFS(Registros!$F$2:$F$6000,Registros!$A$2:$A$6000,"MOV",Registros!$B$2:$B$6000,$A8),0) | I8: =IF(COUNTIFS(Registros!$A$2:$A$6000,"CS",Registros!$B$2:$B$6000,$A8)>0,1,0) | J8: =IF($I8=1,SUMIFS(Registros!$I$2:$I$6000,Registros!$A$2:$A$6000,"CS",Registros!$B$2:$B$6000,$A8),0) | K8: =IF(COUNTIFS(Winback!$K$2:$K$300,$D8)>0,1,0) | L8: =IF(AND($K8=1,LEFT($A8,3)="WB-"),SUMIFS(Winback!$D$2:$D$300,Winback!$K$2:$K$300,$D8),0) | M8: =IF(OR($E8=1,$G8=1,SUMIFS(Registros!$J$2:$J$6000,Registros!$B$2:$B$6000,$A8)>0),1,0) | N8: =IF($J8>0,1,IF(COUNTIFS(Registros!$A$2:$A$6000,"CS",Registros!$B$2:$B$6000,$A8,Registros!$K$2:$K$6000,"<>")>0,1,0)) | O8: =IF(AND($K8=1,$E8=0,$G8=0,$I8=0),"WINBACK",IF(AND($M8=1,$N8>0),"CONVERGENTE",IF($M8=1,"SOLO MÓVIL",IF($N8>0,"SOLO FIJO / INTERNET","SIN SERVICIOS")))) | P8: =IF($O8="WINBACK","Recuperar (winback)",IF($O8="CONVERGENTE","Upgrade / más líneas",IF($O8="SOLO MÓVIL","Ofrecer fijo + internet (FLBBTV)",IF($O8="SOLO FIJO / INTERNET","Ofrecer línea móvil Nextphone","Oferta completa (móvil + fijo + internet)")))) | Q8: =$F8+$H8+$L8 | R8: =IFERROR(VLOOKUP($A8,Registros!$B$2:$G$6000,6,0),IFERROR(VLOOKUP($D8,Winback!$B$2:$C$300,2,0),"")) | S8: =IF($E8=1,"NP","")&IF($G8=1,"+MOV","")&IF($I8=1,"+CS","")&IF($K8=1,"+WB","") | T8: =$E8+$G8+$I8+$K8
A9: 323672910000 | B9: 32367291 | C9: Ademar SA | D9: ADEMARSA | E9: =IF(COUNTIFS(Registros!$A$2:$A$6000,"NP",Registros!$B$2:$B$6000,$A9)>0,1,0) | F9: =IF($E9=1,SUMIFS(Registros!$F$2:$F$6000,Registros!$A$2:$A$6000,"NP",Registros!$B$2:$B$6000,$A9),0) | G9: =IF(COUNTIFS(Registros!$A$2:$A$6000,"MOV",Registros!$B$2:$B$6000,$A9)>0,1,0) | H9: =IF($G9=1,SUMIFS(Registros!$F$2:$F$6000,Registros!$A$2:$A$6000,"MOV",Registros!$B$2:$B$6000,$A9),0) | I9: =IF(COUNTIFS(Registros!$A$2:$A$6000,"CS",Registros!$B$2:$B$6000,$A9)>0,1,0) | J9: =IF($I9=1,SUMIFS(Registros!$I$2:$I$6000,Registros!$A$2:$A$6000,"CS",Registros!$B$2:$B$6000,$A9),0) | K9: =IF(COUNTIFS(Winback!$K$2:$K$300,$D9)>0,1,0) | L9: =IF(AND($K9=1,LEFT($A9,3)="WB-"),SUMIFS(Winback!$D$2:$D$300,Winback!$K$2:$K$300,$D9),0) | M9: =IF(OR($E9=1,$G9=1,SUMIFS(Registros!$J$2:$J$6000,Registros!$B$2:$B$6000,$A9)>0),1,0) | N9: =IF($J9>0,1,IF(COUNTIFS(Registros!$A$2:$A$6000,"CS",Registros!$B$2:$B$6000,$A9,Registros!$K$2:$K$6000,"<>")>0,1,0)) | O9: =IF(AND($K9=1,$E9=0,$G9=0,$I9=0),"WINBACK",IF(AND($M9=1,$N9>0),"CONVERGENTE",IF($M9=1,"SOLO MÓVIL",IF($N9>0,"SOLO FIJO / INTERNET","SIN SERVICIOS")))) | P9: =IF($O9="WINBACK","Recuperar (winback)",IF($O9="CONVERGENTE","Upgrade / más líneas",IF($O9="SOLO MÓVIL","Ofrecer fijo + internet (FLBBTV)",IF($O9="SOLO FIJO / INTERNET","Ofrecer línea móvil Nextphone","Oferta completa (móvil + fijo + internet)")))) | Q9: =$F9+$H9+$L9 | R9: =IFERROR(VLOOKUP($A9,Registros!$B$2:$G$6000,6,0),IFERROR(VLOOKUP($D9,Winback!$B$2:$C$300,2,0),"")) | S9: =IF($E9=1,"NP","")&IF($G9=1,"+MOV","")&IF($I9=1,"+CS","")&IF($K9=1,"+WB","") | T9: =$E9+$G9+$I9+$K9
A10: 349277210000 | B10: 34927721 | C10: SMART COMMUNICATIONS, SA | D10: SMARTCOMMUNICATIONSSA | E10: =IF(COUNTIFS(Registros!$A$2:$A$6000,"NP",Registros!$B$2:$B$6000,$A10)>0,1,0) | F10: =IF($E10=1,SUMIFS(Registros!$F$2:$F$6000,Registros!$A$2:$A$6000,"NP",Registros!$B$2:$B$6000,$A10),0) | G10: =IF(COUNTIFS(Registros!$A$2:$A$6000,"MOV",Registros!$B$2:$B$6000,$A10)>0,1,0) | H10: =IF($G10=1,SUMIFS(Registros!$F$2:$F$6000,Registros!$A$2:$A$6000,"MOV",Registros!$B$2:$B$6000,$A10),0) | I10: =IF(COUNTIFS(Registros!$A$2:$A$6000,"CS",Registros!$B$2:$B$6000,$A10)>0,1,0) | J10: =IF($I10=1,SUMIFS(Registros!$I$2:$I$6000,Registros!$A$2:$A$6000,"CS",Registros!$B$2:$B$6000,$A10),0) | K10: =IF(COUNTIFS(Winback!$K$2:$K$300,$D10)>0,1,0) | L10: =IF(AND($K10=1,LEFT($A10,3)="WB-"),SUMIFS(Winback!$D$2:$D$300,Winback!$K$2:$K$300,$D10),0) | M10: =IF(OR($E10=1,$G10=1,SUMIFS(Registros!$J$2:$J$6000,Registros!$B$2:$B$6000,$A10)>0),1,0) | N10: =IF($J10>0,1,IF(COUNTIFS(Registros!$A$2:$A$6000,"CS",Registros!$B$2:$B$6000,$A10,Registros!$K$2:$K$6000,"<>")>0,1,0)) | O10: =IF(AND($K10=1,$E10=0,$G10=0,$I10=0),"WINBACK",IF(AND($M10=1,$N10>0),"CONVERGENTE",IF($M10=1,"SOLO MÓVIL",IF($N10>0,"SOLO FIJO / INTERNET","SIN SERVICIOS")))) | P10: =IF($O10="WINBACK","Recuperar (winback)",IF($O10="CONVERGENTE","Upgrade / más líneas",IF($O10="SOLO MÓVIL","Ofrecer fijo + internet (FLBBTV)",IF($O10="SOLO FIJO / INTERNET","Ofrecer línea móvil Nextphone","Oferta completa (móvil + fijo + internet)")))) | Q10: =$F10+$H10+$L10 | R10: =IFERROR(VLOOKUP($A10,Registros!$B$2:$G$6000,6,0),IFERROR(VLOOKUP($D10,Winback!$B$2:$C$300,2,0),"")) | S10: =IF($E10=1,"NP","")&IF($G10=1,"+MOV","")&IF($I10=1,"+CS","")&IF($K10=1,"+WB","") | T10: =$E10+$G10+$I10+$K10
A11: 324167750000 | B11: 32416775 | C11: HACIENDA LOMA LINDA | D11: HACIENDALOMALINDA | E11: =IF(COUNTIFS(Registros!$A$2:$A$6000,"NP",Registros!$B$2:$B$6000,$A11)>0,1,0) | F11: =IF($E11=1,SUMIFS(Registros!$F$2:$F$6000,Registros!$A$2:$A$6000,"NP",Registros!$B$2:$B$6000,$A11),0) | G11: =IF(COUNTIFS(Registros!$A$2:$A$6000,"MOV",Registros!$B$2:$B$6000,$A11)>0,1,0) | H11: =IF($G11=1,SUMIFS(Registros!$F$2:$F$6000,Registros!$A$2:$A$6000,"MOV",Registros!$B$2:$B$6000,$A11),0) | I11: =IF(COUNTIFS(Registros!$A$2:$A$6000,"CS",Registros!$B$2:$B$6000,$A11)>0,1,0) | J11: =IF($I11=1,SUMIFS(Registros!$I$2:$I$6000,Registros!$A$2:$A$6000,"CS",Registros!$B$2:$B$6000,$A11),0) | K11: =IF(COUNTIFS(Winback!$K$2:$K$300,$D11)>0,1,0) | L11: =IF(AND($K11=1,LEFT($A11,3)="WB-"),SUMIFS(Winback!$D$2:$D$300,Winback!$K$2:$K$300,$D11),0) | M11: =IF(OR($E11=1,$G11=1,SUMIFS(Registros!$J$2:$J$6000,Registros!$B$2:$B$6000,$A11)>0),1,0) | N11: =IF($J11>0,1,IF(COUNTIFS(Registros!$A$2:$A$6000,"CS",Registros!$B$2:$B$6000,$A11,Registros!$K$2:$K$6000,"<>")>0,1,0)) | O11: =IF(AND($K11=1,$E11=0,$G11=0,$I11=0),"WINBACK",IF(AND($M11=1,$N11>0),"CONVERGENTE",IF($M11=1,"SOLO MÓVIL",IF($N11>0,"SOLO FIJO / INTERNET","SIN SERVICIOS")))) | P11: =IF($O11="WINBACK","Recuperar (winback)",IF($O11="CONVERGENTE","Upgrade / más líneas",IF($O11="SOLO MÓVIL","Ofrecer fijo + internet (FLBBTV)",IF($O11="SOLO FIJO / INTERNET","Ofrecer línea móvil Nextphone","Oferta completa (móvil + fijo + internet)")))) | Q11: =$F11+$H11+$L11 | R11: =IFERROR(VLOOKUP($A11,Registros!$B$2:$G$6000,6,0),IFERROR(VLOOKUP($D11,Winback!$B$2:$C$300,2,0),"")) | S11: =IF($E11=1,"NP","")&IF($G11=1,"+MOV","")&IF($I11=1,"+CS","")&IF($K11=1,"+WB","") | T11: =$E11+$G11+$I11+$K11
A12: 361003450000 | B12: 36100345 | C12: FERNANDO JOSE ARAUZ HERNANDEZ | D12: FERNANDOJOSEARAUZHERNANDEZ | E12: =IF(COUNTIFS(Registros!$A$2:$A$6000,"NP",Registros!$B$2:$B$6000,$A12)>0,1,0) | F12: =IF($E12=1,SUMIFS(Registros!$F$2:$F$6000,Registros!$A$2:$A$6000,"NP",Registros!$B$2:$B$6000,$A12),0) | G12: =IF(COUNTIFS(Registros!$A$2:$A$6000,"MOV",Registros!$B$2:$B$6000,$A12)>0,1,0) | H12: =IF($G12=1,SUMIFS(Registros!$F$2:$F$6000,Registros!$A$2:$A$6000,"MOV",Registros!$B$2:$B$6000,$A12),0) | I12: =IF(COUNTIFS(Registros!$A$2:$A$6000,"CS",Registros!$B$2:$B$6000,$A12)>0,1,0) | J12: =IF($I12=1,SUMIFS(Registros!$I$2:$I$6000,Registros!$A$2:$A$6000,"CS",Registros!$B$2:$B$6000,$A12),0) | K12: =IF(COUNTIFS(Winback!$K$2:$K$300,$D12)>0,1,0) | L12: =IF(AND($K12=1,LEFT($A12,3)="WB-"),SUMIFS(Winback!$D$2:$D$300,Winback!$K$2:$K$300,$D12),0) | M12: =IF(OR($E12=1,$G12=1,SUMIFS(Registros!$J$2:$J$6000,Registros!$B$2:$B$6000,$A12)>0),1,0) | N12: =IF($J12>0,1,IF(COUNTIFS(Registros!$A$2:$A$6000,"CS",Registros!$B$2:$B$6000,$A12,Registros!$K$2:$K$6000,"<>")>0,1,0)) | O12: =IF(AND($K12=1,$E12=0,$G12=0,$I12=0),"WINBACK",IF(AND($M12=1,$N12>0),"CONVERGENTE",IF($M12=1,"SOLO MÓVIL",IF($N12>0,"SOLO FIJO / INTERNET","SIN SERVICIOS")))) | P12: =IF($O12="WINBACK","Recuperar (winback)",IF($O12="CONVERGENTE","Upgrade / más líneas",IF($O12="SOLO MÓVIL","Ofrecer fijo + internet (FLBBTV)",IF($O12="SOLO FIJO / INTERNET","Ofrecer línea móvil Nextphone","Oferta completa (móvil + fijo + internet)")))) | Q12: =$F12+$H12+$L12 | R12: =IFERROR(VLOOKUP($A12,Registros!$B$2:$G$6000,6,0),IFERROR(VLOOKUP($D12,Winback!$B$2:$C$300,2,0),"")) | S12: =IF($E12=1,"NP","")&IF($G12=1,"+MOV","")&IF($I12=1,"+CS","")&IF($K12=1,"+WB","") | T12: =$E12+$G12+$I12+$K12
A13: 352329430000 | B13: 35232943 | C13: YDALIDES VALDES | D13: YDALIDESVALDES | E13: =IF(COUNTIFS(Registros!$A$2:$A$6000,"NP",Registros!$B$2:$B$6000,$A13)>0,1,0) | F13: =IF($E13=1,SUMIFS(Registros!$F$2:$F$6000,Registros!$A$2:$A$6000,"NP",Registros!$B$2:$B$6000,$A13),0) | G13: =IF(COUNTIFS(Registros!$A$2:$A$6000,"MOV",Registros!$B$2:$B$6000,$A13)>0,1,0) | H13: =IF($G13=1,SUMIFS(Registros!$F$2:$F$6000,Registros!$A$2:$A$6000,"MOV",Registros!$B$2:$B$6000,$A13),0) | I13: =IF(COUNTIFS(Registros!$A$2:$A$6000,"CS",Registros!$B$2:$B$6000,$A13)>0,1,0) | J13: =IF($I13=1,SUMIFS(Registros!$I$2:$I$6000,Registros!$A$2:$A$6000,"CS",Registros!$B$2:$B$6000,$A13),0) | K13: =IF(COUNTIFS(Winback!$K$2:$K$300,$D13)>0,1,0) | L13: =IF(AND($K13=1,LEFT($A13,3)="WB-"),SUMIFS(Winback!$D$2:$D$300,Winback!$K$2:$K$300,$D13),0) | M13: =IF(OR($E13=1,$G13=1,SUMIFS(Registros!$J$2:$J$6000,Registros!$B$2:$B$6000,$A13)>0),1,0) | N13: =IF($J13>0,1,IF(COUNTIFS(Registros!$A$2:$A$6000,"CS",Registros!$B$2:$B$6000,$A13,Registros!$K$2:$K$6000,"<>")>0,1,0)) | O13: =IF(AND($K13=1,$E13=0,$G13=0,$I13=0),"WINBACK",IF(AND($M13=1,$N13>0),"CONVERGENTE",IF($M13=1,"SOLO MÓVIL",IF($N13>0,"SOLO FIJO / INTERNET","SIN SERVICIOS")))) | P13: =IF($O13="WINBACK","Recuperar (winback)",IF($O13="CONVERGENTE","Upgrade / más líneas",IF($O13="SOLO MÓVIL","Ofrecer fijo + internet (FLBBTV)",IF($O13="SOLO FIJO / INTERNET","Ofrecer línea móvil Nextphone","Oferta completa (móvil + fijo + internet)")))) | Q13: =$F13+$H13+$L13 | R13: =IFERROR(VLOOKUP($A13,Registros!$B$2:$G$6000,6,0),IFERROR(VLOOKUP($D13,Winback!$B$2:$C$300,2,0),"")) | S13: =IF($E13=1,"NP","")&IF($G13=1,"+MOV","")&IF($I13=1,"+CS","")&IF($K13=1,"+WB","") | T13: =$E13+$G13+$I13+$K13
... A284: 367023820000 | B284: 36702382 | C284: JOSUE CORDOBA | D284: JOSUECORDOBA | E284: =IF(COUNTIFS(Registros!$A$2:$A$6000,"NP",Registros!$B$2:$B$6000,$A284)>0,1,0) | F284: =IF($E284=1,SUMIFS(Registros!$F$2:$F$6000,Registros!$A$2:$A$6000,"NP",Registros!$B$2:$B$6000,$A284),0) | G284: =IF(COUNTIFS(Registros!$A$2:$A$6000,"MOV",Registros!$B$2:$B$6000,$A284)>0,1,0) | H284: =IF($G284=1,SUMIFS(Registros!$F$2:$F$6000,Registros!$A$2:$A$6000,"MOV",Registros!$B$2:$B$6000,$A284),0) | I284: =IF(COUNTIFS(Registros!$A$2:$A$6000,"CS",Registros!$B$2:$B$6000,$A284)>0,1,0) | J284: =IF($I284=1,SUMIFS(Registros!$I$2:$I$6000,Registros!$A$2:$A$6000,"CS",Registros!$B$2:$B$6000,$A284),0) | K284: =IF(COUNTIFS(Winback!$K$2:$K$300,$D284)>0,1,0) | L284: =IF(AND($K284=1,LEFT($A284,3)="WB-"),SUMIFS(Winback!$D$2:$D$300,Winback!$K$2:$K$300,$D284),0) | M284: =IF(OR($E284=1,$G284=1,SUMIFS(Registros!$J$2:$J$6000,Registros!$B$2:$B$6000,$A284)>0),1,0) | N284: =IF($J284>0,1,IF(COUNTIFS(Registros!$A$2:$A$6000,"CS",Registros!$B$2:$B$6000,$A284,Registros!$K$2:$K$6000,"<>")>0,1,0)) | O284: =IF(AND($K284=1,$E284=0,$G284=0,$I284=0),"WINBACK",IF(AND($M284=1,$N284>0),"CONVERGENTE",IF($M284=1,"SOLO MÓVIL",IF($N284>0,"SOLO FIJO / INTERNET","SIN SERVICIOS")))) | P284: =IF($O284="WINBACK","Recuperar (winback)",IF($O284="CONVERGENTE","Upgrade / más líneas",IF($O284="SOLO MÓVIL","Ofrecer fijo + internet (FLBBTV)",IF($O284="SOLO FIJO / INTERNET","Ofrecer línea móvil Nextphone","Oferta completa (móvil + fijo + internet)")))) | Q284: =$F284+$H284+$L284 | R284: =IFERROR(VLOOKUP($A284,Registros!$B$2:$G$6000,6,0),IFERROR(VLOOKUP($D284,Winback!$B$2:$C$300,2,0),"")) | S284: =IF($E284=1,"NP","")&IF($G284=1,"+MOV","")&IF($I284=1,"+CS","")&IF($K284=1,"+WB","") | T284: =$E284+$G284+$I284+$K284
B285: 35828394 | C285: ELIGIO MOSQUERA BARCO | D285: ELIGIOMOSQUERABARCO | E285: =IF(COUNTIFS(Registros!$A$2:$A$6000,"NP",Registros!$B$2:$B$6000,$A285)>0,1,0) | F285: =IF($E285=1,SUMIFS(Registros!$F$2:$F$6000,Registros!$A$2:$A$6000,"NP",Registros!$B$2:$B$6000,$A285),0) | G285: =IF(COUNTIFS(Registros!$A$2:$A$6000,"MOV",Registros!$B$2:$B$6000,$A285)>0,1,0) | H285: =IF($G285=1,SUMIFS(Registros!$F$2:$F$6000,Registros!$A$2:$A$6000,"MOV",Registros!$B$2:$B$6000,$A285),0) | I285: =IF(COUNTIFS(Registros!$A$2:$A$6000,"CS",Registros!$B$2:$B$6000,$A285)>0,1,0) | J285: =IF($I285=1,SUMIFS(Registros!$I$2:$I$6000,Registros!$A$2:$A$6000,"CS",Registros!$B$2:$B$6000,$A285),0) | K285: =IF(COUNTIFS(Winback!$K$2:$K$300,$D285)>0,1,0) | L285: =IF(AND($K285=1,LEFT($A285,3)="WB-"),SUMIFS(Winback!$D$2:$D$300,Winback!$K$2:$K$300,$D285),0) | M285: =IF(OR($E285=1,$G285=1,SUMIFS(Registros!$J$2:$J$6000,Registros!$B$2:$B$6000,$A285)>0),1,0) | N285: =IF($J285>0,1,IF(COUNTIFS(Registros!$A$2:$A$6000,"CS",Registros!$B$2:$B$6000,$A285,Registros!$K$2:$K$6000,"<>")>0,1,0)) | O285: =IF(AND($K285=1,$E285=0,$G285=0,$I285=0),"WINBACK",IF(AND($M285=1,$N285>0),"CONVERGENTE",IF($M285=1,"SOLO MÓVIL",IF($N285>0,"SOLO FIJO / INTERNET","SIN SERVICIOS")))) | P285: =IF($O285="WINBACK","Recuperar (winback)",IF($O285="CONVERGENTE","Upgrade / más líneas",IF($O285="SOLO MÓVIL","Ofrecer fijo + internet (FLBBTV)",IF($O285="SOLO FIJO / INTERNET","Ofrecer línea móvil Nextphone","Oferta completa (móvil + fijo + internet)")))) | Q285: =$F285+$H285+$L285 | R285: =IFERROR(VLOOKUP($A285,Registros!$B$2:$G$6000,6,0),IFERROR(VLOOKUP($D285,Winback!$B$2:$C$300,2,0),"")) | S285: =IF($E285=1,"NP","")&IF($G285=1,"+MOV","")&IF($I285=1,"+CS","")&IF($K285=1,"+WB","") | T285: =$E285+$G285+$I285+$K285
A286: 355039520000 | B286: 35503952 | C286: PRISCILA MEDINA | D286: PRISCILAMEDINA | E286: =IF(COUNTIFS(Registros!$A$2:$A$6000,"NP",Registros!$B$2:$B$6000,$A286)>0,1,0) | F286: =IF($E286=1,SUMIFS(Registros!$F$2:$F$6000,Registros!$A$2:$A$6000,"NP",Registros!$B$2:$B$6000,$A286),0) | G286: =IF(COUNTIFS(Registros!$A$2:$A$6000,"MOV",Registros!$B$2:$B$6000,$A286)>0,1,0) | H286: =IF($G286=1,SUMIFS(Registros!$F$2:$F$6000,Registros!$A$2:$A$6000,"MOV",Registros!$B$2:$B$6000,$A286),0) | I286: =IF(COUNTIFS(Registros!$A$2:$A$6000,"CS",Registros!$B$2:$B$6000,$A286)>0,1,0) | J286: =IF($I286=1,SUMIFS(Registros!$I$2:$I$6000,Registros!$A$2:$A$6000,"CS",Registros!$B$2:$B$6000,$A286),0) | K286: =IF(COUNTIFS(Winback!$K$2:$K$300,$D286)>0,1,0) | L286: =IF(AND($K286=1,LEFT($A286,3)="WB-"),SUMIFS(Winback!$D$2:$D$300,Winback!$K$2:$K$300,$D286),0) | M286: =IF(OR($E286=1,$G286=1,SUMIFS(Registros!$J$2:$J$6000,Registros!$B$2:$B$6000,$A286)>0),1,0) | N286: =IF($J286>0,1,IF(COUNTIFS(Registros!$A$2:$A$6000,"CS",Registros!$B$2:$B$6000,$A286,Registros!$K$2:$K$6000,"<>")>0,1,0)) | O286: =IF(AND($K286=1,$E286=0,$G286=0,$I286=0),"WINBACK",IF(AND($M286=1,$N286>0),"CONVERGENTE",IF($M286=1,"SOLO MÓVIL",IF($N286>0,"SOLO FIJO / INTERNET","SIN SERVICIOS")))) | P286: =IF($O286="WINBACK","Recuperar (winback)",IF($O286="CONVERGENTE","Upgrade / más líneas",IF($O286="SOLO MÓVIL","Ofrecer fijo + internet (FLBBTV)",IF($O286="SOLO FIJO / INTERNET","Ofrecer línea móvil Nextphone","Oferta completa (móvil + fijo + internet)")))) | Q286: =$F286+$H286+$L286 | R286: =IFERROR(VLOOKUP($A286,Registros!$B$2:$G$6000,6,0),IFERROR(VLOOKUP($D286,Winback!$B$2:$C$300,2,0),"")) | S286: =IF($E286=1,"NP","")&IF($G286=1,"+MOV","")&IF($I286=1,"+CS","")&IF($K286=1,"+WB","") | T286: =$E286+$G286+$I286+$K286
A287: 351246120000 | B287: 35124612 | C287: NORBERTO VELANCIA | D287: NORBERTOVELANCIA | E287: =IF(COUNTIFS(Registros!$A$2:$A$6000,"NP",Registros!$B$2:$B$6000,$A287)>0,1,0) | F287: =IF($E287=1,SUMIFS(Registros!$F$2:$F$6000,Registros!$A$2:$A$6000,"NP",Registros!$B$2:$B$6000,$A287),0) | G287: =IF(COUNTIFS(Registros!$A$2:$A$6000,"MOV",Registros!$B$2:$B$6000,$A287)>0,1,0) | H287: =IF($G287=1,SUMIFS(Registros!$F$2:$F$6000,Registros!$A$2:$A$6000,"MOV",Registros!$B$2:$B$6000,$A287),0) | I287: =IF(COUNTIFS(Registros!$A$2:$A$6000,"CS",Registros!$B$2:$B$6000,$A287)>0,1,0) | J287: =IF($I287=1,SUMIFS(Registros!$I$2:$I$6000,Registros!$A$2:$A$6000,"CS",Registros!$B$2:$B$6000,$A287),0) | K287: =IF(COUNTIFS(Winback!$K$2:$K$300,$D287)>0,1,0) | L287: =IF(AND($K287=1,LEFT($A287,3)="WB-"),SUMIFS(Winback!$D$2:$D$300,Winback!$K$2:$K$300,$D287),0) | M287: =IF(OR($E287=1,$G287=1,SUMIFS(Registros!$J$2:$J$6000,Registros!$B$2:$B$6000,$A287)>0),1,0) | N287: =IF($J287>0,1,IF(COUNTIFS(Registros!$A$2:$A$6000,"CS",Registros!$B$2:$B$6000,$A287,Registros!$K$2:$K$6000,"<>")>0,1,0)) | O287: =IF(AND($K287=1,$E287=0,$G287=0,$I287=0),"WINBACK",IF(AND($M287=1,$N287>0),"CONVERGENTE",IF($M287=1,"SOLO MÓVIL",IF($N287>0,"SOLO FIJO / INTERNET","SIN SERVICIOS")))) | P287: =IF($O287="WINBACK","Recuperar (winback)",IF($O287="CONVERGENTE","Upgrade / más líneas",IF($O287="SOLO MÓVIL","Ofrecer fijo + internet (FLBBTV)",IF($O287="SOLO FIJO / INTERNET","Ofrecer línea móvil Nextphone","Oferta completa (móvil + fijo + internet)")))) | Q287: =$F287+$H287+$L287 | R287: =IFERROR(VLOOKUP($A287,Registros!$B$2:$G$6000,6,0),IFERROR(VLOOKUP($D287,Winback!$B$2:$C$300,2,0),"")) | S287: =IF($E287=1,"NP","")&IF($G287=1,"+MOV","")&IF($I287=1,"+CS","")&IF($K287=1,"+WB","") | T287: =$E287+$G287+$I287+$K287
A288: 357364020000 | B288: 35736402 | C288: DAVID REYES | D288: DAVIDREYES | E288: =IF(COUNTIFS(Registros!$A$2:$A$6000,"NP",Registros!$B$2:$B$6000,$A288)>0,1,0) | F288: =IF($E288=1,SUMIFS(Registros!$F$2:$F$6000,Registros!$A$2:$A$6000,"NP",Registros!$B$2:$B$6000,$A288),0) | G288: =IF(COUNTIFS(Registros!$A$2:$A$6000,"MOV",Registros!$B$2:$B$6000,$A288)>0,1,0) | H288: =IF($G288=1,SUMIFS(Registros!$F$2:$F$6000,Registros!$A$2:$A$6000,"MOV",Registros!$B$2:$B$6000,$A288),0) | I288: =IF(COUNTIFS(Registros!$A$2:$A$6000,"CS",Registros!$B$2:$B$6000,$A288)>0,1,0) | J288: =IF($I288=1,SUMIFS(Registros!$I$2:$I$6000,Registros!$A$2:$A$6000,"CS",Registros!$B$2:$B$6000,$A288),0) | K288: =IF(COUNTIFS(Winback!$K$2:$K$300,$D288)>0,1,0) | L288: =IF(AND($K288=1,LEFT($A288,3)="WB-"),SUMIFS(Winback!$D$2:$D$300,Winback!$K$2:$K$300,$D288),0) | M288: =IF(OR($E288=1,$G288=1,SUMIFS(Registros!$J$2:$J$6000,Registros!$B$2:$B$6000,$A288)>0),1,0) | N288: =IF($J288>0,1,IF(COUNTIFS(Registros!$A$2:$A$6000,"CS",Registros!$B$2:$B$6000,$A288,Registros!$K$2:$K$6000,"<>")>0,1,0)) | O288: =IF(AND($K288=1,$E288=0,$G288=0,$I288=0),"WINBACK",IF(AND($M288=1,$N288>0),"CONVERGENTE",IF($M288=1,"SOLO MÓVIL",IF($N288>0,"SOLO FIJO / INTERNET","SIN SERVICIOS")))) | P288: =IF($O288="WINBACK","Recuperar (winback)",IF($O288="CONVERGENTE","Upgrade / más líneas",IF($O288="SOLO MÓVIL","Ofrecer fijo + internet (FLBBTV)",IF($O288="SOLO FIJO / INTERNET","Ofrecer línea móvil Nextphone","Oferta completa (móvil + fijo + internet)")))) | Q288: =$F288+$H288+$L288 | R288: =IFERROR(VLOOKUP($A288,Registros!$B$2:$G$6000,6,0),IFERROR(VLOOKUP($D288,Winback!$B$2:$C$300,2,0),"")) | S288: =IF($E288=1,"NP","")&IF($G288=1,"+MOV","")&IF($I288=1,"+CS","")&IF($K288=1,"+WB","") | T288: =$E288+$G288+$I288+$K288
A289: 356149210000 | B289: 35614921 | C289: NILVA MIGDALIA RIVAS ESPINOZA | D289: NILVAMIGDALIARIVASESPINOZA | E289: =IF(COUNTIFS(Registros!$A$2:$A$6000,"NP",Registros!$B$2:$B$6000,$A289)>0,1,0) | F289: =IF($E289=1,SUMIFS(Registros!$F$2:$F$6000,Registros!$A$2:$A$6000,"NP",Registros!$B$2:$B$6000,$A289),0) | G289: =IF(COUNTIFS(Registros!$A$2:$A$6000,"MOV",Registros!$B$2:$B$6000,$A289)>0,1,0) | H289: =IF($G289=1,SUMIFS(Registros!$F$2:$F$6000,Registros!$A$2:$A$6000,"MOV",Registros!$B$2:$B$6000,$A289),0) | I289: =IF(COUNTIFS(Registros!$A$2:$A$6000,"CS",Registros!$B$2:$B$6000,$A289)>0,1,0) | J289: =IF($I289=1,SUMIFS(Registros!$I$2:$I$6000,Registros!$A$2:$A$6000,"CS",Registros!$B$2:$B$6000,$A289),0) | K289: =IF(COUNTIFS(Winback!$K$2:$K$300,$D289)>0,1,0) | L289: =IF(AND($K289=1,LEFT($A289,3)="WB-"),SUMIFS(Winback!$D$2:$D$300,Winback!$K$2:$K$300,$D289),0) | M289: =IF(OR($E289=1,$G289=1,SUMIFS(Registros!$J$2:$J$6000,Registros!$B$2:$B$6000,$A289)>0),1,0) | N289: =IF($J289>0,1,IF(COUNTIFS(Registros!$A$2:$A$6000,"CS",Registros!$B$2:$B$6000,$A289,Registros!$K$2:$K$6000,"<>")>0,1,0)) | O289: =IF(AND($K289=1,$E289=0,$G289=0,$I289=0),"WINBACK",IF(AND($M289=1,$N289>0),"CONVERGENTE",IF($M289=1,"SOLO MÓVIL",IF($N289>0,"SOLO FIJO / INTERNET","SIN SERVICIOS")))) | P289: =IF($O289="WINBACK","Recuperar (winback)",IF($O289="CONVERGENTE","Upgrade / más líneas",IF($O289="SOLO MÓVIL","Ofrecer fijo + internet (FLBBTV)",IF($O289="SOLO FIJO / INTERNET","Ofrecer línea móvil Nextphone","Oferta completa (móvil + fijo + internet)")))) | Q289: =$F289+$H289+$L289 | R289: =IFERROR(VLOOKUP($A289,Registros!$B$2:$G$6000,6,0),IFERROR(VLOOKUP($D289,Winback!$B$2:$C$300,2,0),"")) | S289: =IF($E289=1,"NP","")&IF($G289=1,"+MOV","")&IF($I289=1,"+CS","")&IF($K289=1,"+WB","") | T289: =$E289+$G289+$I289+$K289
A290: 356118310000 | B290: 35611831 | C290: DAIHANA DE LA ROSA | D290: DAIHANADELAROSA | E290: =IF(COUNTIFS(Registros!$A$2:$A$6000,"NP",Registros!$B$2:$B$6000,$A290)>0,1,0) | F290: =IF($E290=1,SUMIFS(Registros!$F$2:$F$6000,Registros!$A$2:$A$6000,"NP",Registros!$B$2:$B$6000,$A290),0) | G290: =IF(COUNTIFS(Registros!$A$2:$A$6000,"MOV",Registros!$B$2:$B$6000,$A290)>0,1,0) | H290: =IF($G290=1,SUMIFS(Registros!$F$2:$F$6000,Registros!$A$2:$A$6000,"MOV",Registros!$B$2:$B$6000,$A290),0) | I290: =IF(COUNTIFS(Registros!$A$2:$A$6000,"CS",Registros!$B$2:$B$6000,$A290)>0,1,0) | J290: =IF($I290=1,SUMIFS(Registros!$I$2:$I$6000,Registros!$A$2:$A$6000,"CS",Registros!$B$2:$B$6000,$A290),0) | K290: =IF(COUNTIFS(Winback!$K$2:$K$300,$D290)>0,1,0) | L290: =IF(AND($K290=1,LEFT($A290,3)="WB-"),SUMIFS(Winback!$D$2:$D$300,Winback!$K$2:$K$300,$D290),0) | M290: =IF(OR($E290=1,$G290=1,SUMIFS(Registros!$J$2:$J$6000,Registros!$B$2:$B$6000,$A290)>0),1,0) | N290: =IF($J290>0,1,IF(COUNTIFS(Registros!$A$2:$A$6000,"CS",Registros!$B$2:$B$6000,$A290,Registros!$K$2:$K$6000,"<>")>0,1,0)) | O290: =IF(AND($K290=1,$E290=0,$G290=0,$I290=0),"WINBACK",IF(AND($M290=1,$N290>0),"CONVERGENTE",IF($M290=1,"SOLO MÓVIL",IF($N290>0,"SOLO FIJO / INTERNET","SIN SERVICIOS")))) | P290: =IF($O290="WINBACK","Recuperar (winback)",IF($O290="CONVERGENTE","Upgrade / más líneas",IF($O290="SOLO MÓVIL","Ofrecer fijo + internet (FLBBTV)",IF($O290="SOLO FIJO / INTERNET","Ofrecer línea móvil Nextphone","Oferta completa (móvil + fijo + internet)")))) | Q290: =$F290+$H290+$L290 | R290: =IFERROR(VLOOKUP($A290,Registros!$B$2:$G$6000,6,0),IFERROR(VLOOKUP($D290,Winback!$B$2:$C$300,2,0),"")) | S290: =IF($E290=1,"NP","")&IF($G290=1,"+MOV","")&IF($I290=1,"+CS","")&IF($K290=1,"+WB","") | T290: =$E290+$G290+$I290+$K290
A291: 349331440000 | B291: 34933144 | C291: ARNALDO LOPEZ | D291: ARNALDOLOPEZ | E291: =IF(COUNTIFS(Registros!$A$2:$A$6000,"NP",Registros!$B$2:$B$6000,$A291)>0,1,0) | F291: =IF($E291=1,SUMIFS(Registros!$F$2:$F$6000,Registros!$A$2:$A$6000,"NP",Registros!$B$2:$B$6000,$A291),0) | G291: =IF(COUNTIFS(Registros!$A$2:$A$6000,"MOV",Registros!$B$2:$B$6000,$A291)>0,1,0) | H291: =IF($G291=1,SUMIFS(Registros!$F$2:$F$6000,Registros!$A$2:$A$6000,"MOV",Registros!$B$2:$B$6000,$A291),0) | I291: =IF(COUNTIFS(Registros!$A$2:$A$6000,"CS",Registros!$B$2:$B$6000,$A291)>0,1,0) | J291: =IF($I291=1,SUMIFS(Registros!$I$2:$I$6000,Registros!$A$2:$A$6000,"CS",Registros!$B$2:$B$6000,$A291),0) | K291: =IF(COUNTIFS(Winback!$K$2:$K$300,$D291)>0,1,0) | L291: =IF(AND($K291=1,LEFT($A291,3)="WB-"),SUMIFS(Winback!$D$2:$D$300,Winback!$K$2:$K$300,$D291),0) | M291: =IF(OR($E291=1,$G291=1,SUMIFS(Registros!$J$2:$J$6000,Registros!$B$2:$B$6000,$A291)>0),1,0) | N291: =IF($J291>0,1,IF(COUNTIFS(Registros!$A$2:$A$6000,"CS",Registros!$B$2:$B$6000,$A291,Registros!$K$2:$K$6000,"<>")>0,1,0)) | O291: =IF(AND($K291=1,$E291=0,$G291=0,$I291=0),"WINBACK",IF(AND($M291=1,$N291>0),"CONVERGENTE",IF($M291=1,"SOLO MÓVIL",IF($N291>0,"SOLO FIJO / INTERNET","SIN SERVICIOS")))) | P291: =IF($O291="WINBACK","Recuperar (winback)",IF($O291="CONVERGENTE","Upgrade / más líneas",IF($O291="SOLO MÓVIL","Ofrecer fijo + internet (FLBBTV)",IF($O291="SOLO FIJO / INTERNET","Ofrecer línea móvil Nextphone","Oferta completa (móvil + fijo + internet)")))) | Q291: =$F291+$H291+$L291 | R291: =IFERROR(VLOOKUP($A291,Registros!$B$2:$G$6000,6,0),IFERROR(VLOOKUP($D291,Winback!$B$2:$C$300,2,0),"")) | S291: =IF($E291=1,"NP","")&IF($G291=1,"+MOV","")&IF($I291=1,"+CS","")&IF($K291=1,"+WB","") | T291: =$E291+$G291+$I291+$K291
A292: 355130350000 | B292: 35513035 | C292: DISMA TOCAMO | D292: DISMATOCAMO | E292: =IF(COUNTIFS(Registros!$A$2:$A$6000,"NP",Registros!$B$2:$B$6000,$A292)>0,1,0) | F292: =IF($E292=1,SUMIFS(Registros!$F$2:$F$6000,Registros!$A$2:$A$6000,"NP",Registros!$B$2:$B$6000,$A292),0) | G292: =IF(COUNTIFS(Registros!$A$2:$A$6000,"MOV",Registros!$B$2:$B$6000,$A292)>0,1,0) | H292: =IF($G292=1,SUMIFS(Registros!$F$2:$F$6000,Registros!$A$2:$A$6000,"MOV",Registros!$B$2:$B$6000,$A292),0) | I292: =IF(COUNTIFS(Registros!$A$2:$A$6000,"CS",Registros!$B$2:$B$6000,$A292)>0,1,0) | J292: =IF($I292=1,SUMIFS(Registros!$I$2:$I$6000,Registros!$A$2:$A$6000,"CS",Registros!$B$2:$B$6000,$A292),0) | K292: =IF(COUNTIFS(Winback!$K$2:$K$300,$D292)>0,1,0) | L292: =IF(AND($K292=1,LEFT($A292,3)="WB-"),SUMIFS(Winback!$D$2:$D$300,Winback!$K$2:$K$300,$D292),0) | M292: =IF(OR($E292=1,$G292=1,SUMIFS(Registros!$J$2:$J$6000,Registros!$B$2:$B$6000,$A292)>0),1,0) | N292: =IF($J292>0,1,IF(COUNTIFS(Registros!$A$2:$A$6000,"CS",Registros!$B$2:$B$6000,$A292,Registros!$K$2:$K$6000,"<>")>0,1,0)) | O292: =IF(AND($K292=1,$E292=0,$G292=0,$I292=0),"WINBACK",IF(AND($M292=1,$N292>0),"CONVERGENTE",IF($M292=1,"SOLO MÓVIL",IF($N292>0,"SOLO FIJO / INTERNET","SIN SERVICIOS")))) | P292: =IF($O292="WINBACK","Recuperar (winback)",IF($O292="CONVERGENTE","Upgrade / más líneas",IF($O292="SOLO MÓVIL","Ofrecer fijo + internet (FLBBTV)",IF($O292="SOLO FIJO / INTERNET","Ofrecer línea móvil Nextphone","Oferta completa (móvil + fijo + internet)")))) | Q292: =$F292+$H292+$L292 | R292: =IFERROR(VLOOKUP($A292,Registros!$B$2:$G$6000,6,0),IFERROR(VLOOKUP($D292,Winback!$B$2:$C$300,2,0),"")) | S292: =IF($E292=1,"NP","")&IF($G292=1,"+MOV","")&IF($I292=1,"+CS","")&IF($K292=1,"+WB","") | T292: =$E292+$G292+$I292+$K292
A293: 364037000000 | B293: 36403700 | C293: LIANNE SHERILL PINEDA MOSQUERA | D293: LIANNESHERILLPINEDAMOSQUERA | E293: =IF(COUNTIFS(Registros!$A$2:$A$6000,"NP",Registros!$B$2:$B$6000,$A293)>0,1,0) | F293: =IF($E293=1,SUMIFS(Registros!$F$2:$F$6000,Registros!$A$2:$A$6000,"NP",Registros!$B$2:$B$6000,$A293),0) | G293: =IF(COUNTIFS(Registros!$A$2:$A$6000,"MOV",Registros!$B$2:$B$6000,$A293)>0,1,0) | H293: =IF($G293=1,SUMIFS(Registros!$F$2:$F$6000,Registros!$A$2:$A$6000,"MOV",Registros!$B$2:$B$6000,$A293),0) | I293: =IF(COUNTIFS(Registros!$A$2:$A$6000,"CS",Registros!$B$2:$B$6000,$A293)>0,1,0) | J293: =IF($I293=1,SUMIFS(Registros!$I$2:$I$6000,Registros!$A$2:$A$6000,"CS",Registros!$B$2:$B$6000,$A293),0) | K293: =IF(COUNTIFS(Winback!$K$2:$K$300,$D293)>0,1,0) | L293: =IF(AND($K293=1,LEFT($A293,3)="WB-"),SUMIFS(Winback!$D$2:$D$300,Winback!$K$2:$K$300,$D293),0) | M293: =IF(OR($E293=1,$G293=1,SUMIFS(Registros!$J$2:$J$6000,Registros!$B$2:$B$6000,$A293)>0),1,0) | N293: =IF($J293>0,1,IF(COUNTIFS(Registros!$A$2:$A$6000,"CS",Registros!$B$2:$B$6000,$A293,Registros!$K$2:$K$6000,"<>")>0,1,0)) | O293: =IF(AND($K293=1,$E293=0,$G293=0,$I293=0),"WINBACK",IF(AND($M293=1,$N293>0),"CONVERGENTE",IF($M293=1,"SOLO MÓVIL",IF($N293>0,"SOLO FIJO / INTERNET","SIN SERVICIOS")))) | P293: =IF($O293="WINBACK","Recuperar (winback)",IF($O293="CONVERGENTE","Upgrade / más líneas",IF($O293="SOLO MÓVIL","Ofrecer fijo + internet (FLBBTV)",IF($O293="SOLO FIJO / INTERNET","Ofrecer línea móvil Nextphone","Oferta completa (móvil + fijo + internet)")))) | Q293: =$F293+$H293+$L293 | R293: =IFERROR(VLOOKUP($A293,Registros!$B$2:$G$6000,6,0),IFERROR(VLOOKUP($D293,Winback!$B$2:$C$300,2,0),"")) | S293: =IF($E293=1,"NP","")&IF($G293=1,"+MOV","")&IF($I293=1,"+CS","")&IF($K293=1,"+WB","") | T293: =$E293+$G293+$I293+$K293
A294: 347400570000 | B294: 34740057 | C294: DAYANIS DIMAS | D294: DAYANISDIMAS | E294: =IF(COUNTIFS(Registros!$A$2:$A$6000,"NP",Registros!$B$2:$B$6000,$A294)>0,1,0) | F294: =IF($E294=1,SUMIFS(Registros!$F$2:$F$6000,Registros!$A$2:$A$6000,"NP",Registros!$B$2:$B$6000,$A294),0) | G294: =IF(COUNTIFS(Registros!$A$2:$A$6000,"MOV",Registros!$B$2:$B$6000,$A294)>0,1,0) | H294: =IF($G294=1,SUMIFS(Registros!$F$2:$F$6000,Registros!$A$2:$A$6000,"MOV",Registros!$B$2:$B$6000,$A294),0) | I294: =IF(COUNTIFS(Registros!$A$2:$A$6000,"CS",Registros!$B$2:$B$6000,$A294)>0,1,0) | J294: =IF($I294=1,SUMIFS(Registros!$I$2:$I$6000,Registros!$A$2:$A$6000,"CS",Registros!$B$2:$B$6000,$A294),0) | K294: =IF(COUNTIFS(Winback!$K$2:$K$300,$D294)>0,1,0) | L294: =IF(AND($K294=1,LEFT($A294,3)="WB-"),SUMIFS(Winback!$D$2:$D$300,Winback!$K$2:$K$300,$D294),0) | M294: =IF(OR($E294=1,$G294=1,SUMIFS(Registros!$J$2:$J$6000,Registros!$B$2:$B$6000,$A294)>0),1,0) | N294: =IF($J294>0,1,IF(COUNTIFS(Registros!$A$2:$A$6000,"CS",Registros!$B$2:$B$6000,$A294,Registros!$K$2:$K$6000,"<>")>0,1,0)) | O294: =IF(AND($K294=1,$E294=0,$G294=0,$I294=0),"WINBACK",IF(AND($M294=1,$N294>0),"CONVERGENTE",IF($M294=1,"SOLO MÓVIL",IF($N294>0,"SOLO FIJO / INTERNET","SIN SERVICIOS")))) | P294: =IF($O294="WINBACK","Recuperar (winback)",IF($O294="CONVERGENTE","Upgrade / más líneas",IF($O294="SOLO MÓVIL","Ofrecer fijo + internet (FLBBTV)",IF($O294="SOLO FIJO / INTERNET","Ofrecer línea móvil Nextphone","Oferta completa (móvil + fijo + internet)")))) | Q294: =$F294+$H294+$L294 | R294: =IFERROR(VLOOKUP($A294,Registros!$B$2:$G$6000,6,0),IFERROR(VLOOKUP($D294,Winback!$B$2:$C$300,2,0),"")) | S294: =IF($E294=1,"NP","")&IF($G294=1,"+MOV","")&IF($I294=1,"+CS","")&IF($K294=1,"+WB","") | T294: =$E294+$G294+$I294+$K294
A295: 341182820000 | B295: 34118282 | C295: ELIDIA PERALTA | D295: ELIDIAPERALTA | E295: =IF(COUNTIFS(Registros!$A$2:$A$6000,"NP",Registros!$B$2:$B$6000,$A295)>0,1,0) | F295: =IF($E295=1,SUMIFS(Registros!$F$2:$F$6000,Registros!$A$2:$A$6000,"NP",Registros!$B$2:$B$6000,$A295),0) | G295: =IF(COUNTIFS(Registros!$A$2:$A$6000,"MOV",Registros!$B$2:$B$6000,$A295)>0,1,0) | H295: =IF($G295=1,SUMIFS(Registros!$F$2:$F$6000,Registros!$A$2:$A$6000,"MOV",Registros!$B$2:$B$6000,$A295),0) | I295: =IF(COUNTIFS(Registros!$A$2:$A$6000,"CS",Registros!$B$2:$B$6000,$A295)>0,1,0) | J295: =IF($I295=1,SUMIFS(Registros!$I$2:$I$6000,Registros!$A$2:$A$6000,"CS",Registros!$B$2:$B$6000,$A295),0) | K295: =IF(COUNTIFS(Winback!$K$2:$K$300,$D295)>0,1,0) | L295: =IF(AND($K295=1,LEFT($A295,3)="WB-"),SUMIFS(Winback!$D$2:$D$300,Winback!$K$2:$K$300,$D295),0) | M295: =IF(OR($E295=1,$G295=1,SUMIFS(Registros!$J$2:$J$6000,Registros!$B$2:$B$6000,$A295)>0),1,0) | N295: =IF($J295>0,1,IF(COUNTIFS(Registros!$A$2:$A$6000,"CS",Registros!$B$2:$B$6000,$A295,Registros!$K$2:$K$6000,"<>")>0,1,0)) | O295: =IF(AND($K295=1,$E295=0,$G295=0,$I295=0),"WINBACK",IF(AND($M295=1,$N295>0),"CONVERGENTE",IF($M295=1,"SOLO MÓVIL",IF($N295>0,"SOLO FIJO / INTERNET","SIN SERVICIOS")))) | P295: =IF($O295="WINBACK","Recuperar (winback)",IF($O295="CONVERGENTE","Upgrade / más líneas",IF($O295="SOLO MÓVIL","Ofrecer fijo + internet (FLBBTV)",IF($O295="SOLO FIJO / INTERNET","Ofrecer línea móvil Nextphone","Oferta completa (móvil + fijo + internet)")))) | Q295: =$F295+$H295+$L295 | R295: =IFERROR(VLOOKUP($A295,Registros!$B$2:$G$6000,6,0),IFERROR(VLOOKUP($D295,Winback!$B$2:$C$300,2,0),"")) | S295: =IF($E295=1,"NP","")&IF($G295=1,"+MOV","")&IF($I295=1,"+CS","")&IF($K295=1,"+WB","") | T295: =$E295+$G295+$I295+$K295
