Workbook

Sheet DASHBOARD2
A2: DATAPHONE | COBROS | H2: FUNNEL DE COBROS
H3: Status | I3: Cant
H4: Asignadas | I4: =datos!B33 -> 3566
H5: Gestionadas | I5: =datos!B34 -> 831
H6: Contactadas | I6: =datos!B35 -> 940
H7: Promesas | I7: =datos!B36 -> 181
H8: Pagos | I8: =datos!B37 -> 100
A12: RESUMEN | MES EN TRANSITO (MAYO) | C12: Resultados Financieros | F12: % PROMESA
A13: HC | B13: 1 | C13: Segmento | D13: Promesa de Pago | E13: Monto Recuperado | F13: =B20/B14 -> 0.050757151
A14: Cuentas asignadas | B14: =datos!B4 -> 3566 | C14: Call Center Outbound | D14: =+IFERROR(_xlfn.XLOOKUP(C14,datos!A16:A23,datos!B16:B23,,0),0) -> 831.1 | E14: =+IFERROR(_xlfn.XLOOKUP(C14,datos!A16:A23,datos!C16:C23,,0),0) -> 788.27
A15: Cartera ($) | B15: =datos!B5 -> 6890.04 | C15: Digital | D15: =+IFERROR(_xlfn.XLOOKUP(C15,datos!A17:A24,datos!B17:B24,,0),0) -> 511.71 | E15: =+IFERROR(_xlfn.XLOOKUP(C15,datos!A17:A24,datos!C17:C24,,0),0) -> 482.34
A16: Recuperación ($) | B16: =datos!B6 -> 8084.35 | C16: La doña | D16: =+IFERROR(_xlfn.XLOOKUP(C16,datos!A18:A25,datos!B18:B25,,0),0) -> 0 | E16: =+IFERROR(_xlfn.XLOOKUP(C16,datos!A18:A25,datos!C18:C25,,0),0) -> 0
A17: % Recuperación | B17: =datos!B7 -> 1.1733386 | C17: Masivo (D2D) | D17: =+IFERROR(_xlfn.XLOOKUP(C17,datos!A19:A26,datos!B19:B26,,0),0) -> 4552.24 | E17: =+IFERROR(_xlfn.XLOOKUP(C17,datos!A19:A26,datos!C19:C26,,0),0) -> 4881.61
A18: Contactabilidad | B18: =datos!B8 -> 0.43538675 | C18: Movil | D18: =+IFERROR(_xlfn.XLOOKUP(C18,datos!A20:A27,datos!B20:B27,,0),0) -> 0 | E18: =+IFERROR(_xlfn.XLOOKUP(C18,datos!A20:A27,datos!C20:C27,,0),0) -> 0
A19: RPC | B19: =datos!B9 -> 0.84893617 | C19: Oeste | D19: =+IFERROR(_xlfn.XLOOKUP(C19,datos!A21:A28,datos!B21:B28,,0),0) -> 0 | E19: =+IFERROR(_xlfn.XLOOKUP(C19,datos!A21:A28,datos!C21:C28,,0),0) -> 0 | F19: % RECUPERACION
A20: Promesas | B20: =datos!B10 -> 181 | C20: Punto de ventas | D20: =+IFERROR(_xlfn.XLOOKUP(C20,datos!A21:A29,datos!B21:B29,,0),0) -> 30.53 | E20: =+IFERROR(_xlfn.XLOOKUP(C20,datos!A21:A29,datos!C21:C29,,0),0) -> 61.47 | F20: =B21/B14 -> 0.028042625
A21: Promesas cumplidas | B21: =datos!B11 -> 100 | C21: Soho | D21: =GETPIVOTDATA(" Promesa de Pago",datos!$A$16,"Canal","Soho") -> 855.19 | E21: =GETPIVOTDATA(" Monto Recuperado",datos!$A$16,"Canal","Soho") -> 1604.69
A22: % Cumplimiento | B22: =datos!B12 -> 0.55248619 | C22: Soho -Callcenter | D22: =GETPIVOTDATA(" Promesa de Pago",datos!$A$16,"Canal","Soho -Callcenter") -> 109.27 | E22: =+IFERROR(_xlfn.XLOOKUP(C22,datos!A23:A31,datos!C23:C31,,0),0) -> 265.97
C23: Total general | D23: =SUM(D14:D22) -> 6890.04 | E23: =SUM(E14:E22) -> 8084.35
A25: PERFORMANCE POR AGENTE
A26: AGENTE | B26: Cartera | C26: Recuperado | D26: % Recuperación | E26: Promesas | F26: Cumplidas | G26: % Efectividad
A27: Lili Velez | B27: =datos!B27 -> 3566 | C27: =datos!C27 -> 298 | D27: =datos!D27 -> 0.083567022 | E27: =datos!E27 -> 6890.04 | F27: =datos!F27 -> 8084.35 | G27: =datos!G27 -> 1.1733386
A28: Total | B28: =+SUM(B27:B27) -> 3566 | C28: =+SUM(C27:C27) -> 298 | D28: =+SUM(D27:D27) -> 0.083567022 | E28: =+SUM(E27:E27) -> 6890.04 | F28: =+SUM(F27:F27) -> 8084.35 | G28: =AVERAGE(G27:G27) -> 1.1733386
A29: PRODUCTIVIDAD OPERATIVA | H29: PROMESA VS PAGOS
A30: AGENTE | B30: Llamadas | C30: Contactos | D30: RPC | E30: Cant Promesas de pago | F30: % RPC | G30: % Contactos
A31: Lili Velez | B31: =GETPIVOTDATA("Intentos",[1]analisis!$A$11,"full_name","Lili Velez") -> 1814 | C31: =GETPIVOTDATA(" Connect",[1]analisis!$A$21,"full_name","Lili Velez") -> 940 | D31: =GETPIVOTDATA(" RPC",[1]analisis!$A$21,"full_name","Lili Velez") -> 798 | E31: =GETPIVOTDATA("Suma de Intentos de Promesas",[1]analisis!$G$34,"Agente ","Lili Velez") -> 181 | F31: =D31/C31 -> 0.84893617 | G31: =C31/B31 -> 0.51819184
A32: Total | B32: =+SUM(B31:B31) -> 1814 | C32: =+SUM(C31:C31) -> 940 | D32: =+SUM(D31:D31) -> 798 | E32: =+SUM(E31:E31) -> 181 | F32: =D32/C32 -> 0.84893617 | G32: =C32/B32 -> 0.51819184
A33: DIVISION POR MES PENDIENTE | E33: Cuentas Cesadas / Al Dia
A34: PENDIENTES POR MES | B34: REGISTROS CARGADOS | C34: RECUPERADO | E34: Cliente al dia | F34: Cuenta cesada
A35: 1 MES PENDIENTE | B35: =datos!B57 -> 176 | C35: =datos!C57 -> 71 | E35: =GETPIVOTDATA("Contacto1",[1]analisis!$Z$21,"_Producto_Linea","Cliente al dia") -> 77 | F35: =GETPIVOTDATA("Contacto1",[1]analisis!$Z$21,"_Producto_Linea","Cuenta cesada") -> 358
A36: 2 MESES PENDIENTES | B36: =datos!B58 -> 641 | C36: =datos!C58 -> 117
A37: 3 MESES PENDIENTES | B37: =datos!B59 -> 155 | C37: =datos!C59 -> 2
A38: 4 MESES PENDIENTES | B38: =datos!B60 -> 0 | C38: =datos!C60 -> 0
A39: NPN | B39: =datos!B61 -> 178 | C39: =datos!C61 -> 8
A41: LLAMADAS DIARIAS

Sheet datos
A2: Resumen Ejecutivo | E2: Productividad Operativa
A3: HC | B3: 1 | E3: Indicador | F3: Valor
A4: Cuentas asignadas | B4: =[1]analisis!L17 -> 3566 | E4: Llamadas | F4: Contactos | G4: RPC | H4: Cant Promesas de pago | I4: % RPC
A5: Cartera ($) | B5: =GETPIVOTDATA(" Monto de Promesa de Pago",[1]analisis!$G$34) -> 6890.04 | E5: =GETPIVOTDATA("Intentos",[1]analisis!$A$11) -> 2159 | F5: =GETPIVOTDATA(" Connect",[1]analisis!$A$21) -> 940 | G5: =GETPIVOTDATA(" RPC",[1]analisis!$A$21) -> 798 | H5: =[1]analisis!J33 -> 181 | I5: =G5/F5 -> 0.84893617
A6: Recuperación ($) | B6: =GETPIVOTDATA("Suma de Monto pagado",[1]analisis!$G$34) -> 8084.35
A7: % Recuperación | B7: =B6/B5 -> 1.1733386
A8: Contactabilidad | B8: =F5/E5 -> 0.43538675
A9: RPC | B9: =G5/F5 -> 0.84893617
A10: Promesas | B10: =H5 -> 181
A11: Promesas cumplidas | B11: =B37 -> 100
A12: % Cumplimiento | B12: =B11/B10 -> 0.55248619
A15: Resultados Financieros
A16: Canal | B16: Promesa de Pago | C16: Monto Recuperado
A17: Call Center Outbound | B17: 831.1 | C17: 788.27
A18: Digital | B18: 511.71 | C18: 482.34
A19: Masivo (D2D) | B19: 4552.24 | C19: 4881.61
A20: Oeste | B20: 0 | C20: 0
A21: Punto de ventas | B21: 30.53 | C21: 61.47
A22: Soho | B22: 855.19 | C22: 1604.69
A23: Soho -Callcenter | B23: 109.27 | C23: 265.97
A24: Total general | B24: 6890.04 | C24: 8084.35
A25: Performance por Agente
A26: Agente | B26: Cartera | C26: Recuperado | D26: % Recuperación | E26: Promesas | F26: Cumplidas | G26: % Efectividad
A27: Lili Velez | B27: =[1]analisis!C57 -> 3566 | C27: =GETPIVOTDATA("Suma de Intentos de pago",[1]analisis!$G$34,"Agente ","Lili Velez") -> 298 | D27: =C27/B27 -> 0.083567022 | E27: =GETPIVOTDATA(" Monto de Promesa de Pago",[1]analisis!$G$34,"Agente ","Lili Velez") -> 6890.04 | F27: =GETPIVOTDATA("Suma de Monto pagado",[1]analisis!$G$34,"Agente ","Lili Velez") -> 8084.35 | G27: =F27/E27 -> 1.1733386
A31: Funnel de Cobranza
A32: Etapa | B32: Cantidad
A33: Asignadas | B33: =B4 -> 3566
A34: Gestionadas | B34: =[1]analisis!I17 -> 831
A35: Contactadas | B35: =F5 -> 940
A36: Promesas | B36: =[1]analisis!J33 -> 181
A37: Pagos | B37: =[1]analisis!K33 -> 100
A40: Promesas vs Pagos
A41: Indicador | B41: Valor | C41: Porcentaje
A42: Promesas | B42: =H5 -> 181 | C42: =B42/$B$4 -> 0.050757151
A43: Pagos | B43: =B11 -> 100 | C43: =B43/$B$4 -> 0.028042625
A44: % Cumplimiento | B44: =(B43/B42) -> 0.55248619
A47: Barrido de base
A48: Indicador | B48: Valor
A49: Gestiones Totales | B49: =[1]analisis!L17 -> 3566
A50: Gestiones Productivas | B50: =[1]analisis!I17 -> 831
...
