Workbook

Sheet DASHBOARD2
A2: DATAPHONE | COBROS | H2: FUNNEL DE COBROS
H3: Status | I3: Cant
H4: Asignadas | I4: =datos!B33 -> 3566
H5: Gestionadas | I5: =datos!B34 -> 3468
H6: Contactadas | I6: =datos!B35 -> 772
H7: Promesas | I7: =datos!B36 -> 115
H8: Pagos | I8: =datos!B37 -> 91
A12: RESUMEN | MES EN TRANSITO (MAYO) | C12: Resultados Financieros | F12: % PROMESA
A13: HC | B13: 1 | C13: Segmento | D13: Promesa de Pago | E13: Monto Recuperado | F13: =B20/B14 -> 0.032249019
A14: Cuentas asignadas | B14: =datos!B4 -> 3566 | C14: Call Center Outbound | D14: =+IFERROR(_xlfn.XLOOKUP(C14,datos!A16:A23,datos!B16:B23,,0),0) -> 500.99 | E14: =+IFERROR(_xlfn.XLOOKUP(C14,datos!A16:A23,datos!C16:C23,,0),0) -> 204.98
A15: Cartera ($) | B15: =datos!B5 -> 4667.45 | C15: Digital | D15: =+IFERROR(_xlfn.XLOOKUP(C15,datos!A17:A24,datos!B17:B24,,0),0) -> 160.35 | E15: =+IFERROR(_xlfn.XLOOKUP(C15,datos!A17:A24,datos!C17:C24,,0),0) -> 0
A16: Recuperación ($) | B16: =datos!B6 -> 1671.46 | C16: La doña | D16: =+IFERROR(_xlfn.XLOOKUP(C16,datos!A18:A25,datos!B18:B25,,0),0) -> 0 | E16: =+IFERROR(_xlfn.XLOOKUP(C16,datos!A18:A25,datos!C18:C25,,0),0) -> 0
A17: % Recuperación | B17: =datos!B7 -> 0.35810989 | C17: Masivo (D2D) | D17: =+IFERROR(_xlfn.XLOOKUP(C17,datos!A19:A26,datos!B19:B26,,0),0) -> 3133.18 | E17: =+IFERROR(_xlfn.XLOOKUP(C17,datos!A19:A26,datos!C19:C26,,0),0) -> 1083.71
A18: Contactabilidad | B18: =datos!B8 -> 0.11884236 | C18: Movil | D18: =+IFERROR(_xlfn.XLOOKUP(C18,datos!A20:A27,datos!B20:B27,,0),0) -> 0 | E18: =+IFERROR(_xlfn.XLOOKUP(C18,datos!A20:A27,datos!C20:C27,,0),0) -> 0
A19: RPC | B19: =datos!B9 -> 0.80958549 | C19: Oeste | D19: =+IFERROR(_xlfn.XLOOKUP(C19,datos!A21:A28,datos!B21:B28,,0),0) -> 0 | E19: =+IFERROR(_xlfn.XLOOKUP(C19,datos!A21:A28,datos!C21:C28,,0),0) -> 0 | F19: % RECUPERACION
A20: Promesas | B20: =datos!B10 -> 115 | C20: Punto de ventas | D20: =+IFERROR(_xlfn.XLOOKUP(C20,datos!A22:A29,datos!B22:B29,,0),0) -> 0 | E20: =+IFERROR(_xlfn.XLOOKUP(C20,datos!A22:A29,datos!C22:C29,,0),0) -> 0 | F20: =B21/B14 -> 0.025518789
A21: Promesas cumplidas | B21: =datos!B11 -> 91 | C21: Soho | D21: =GETPIVOTDATA(" Promesa de Pago",datos!$A$16,"Canal","Soho") -> 801.69 | E21: =GETPIVOTDATA(" Monto Recuperado",datos!$A$16,"Canal","Soho") -> 382.77
A22: % Cumplimiento | B22: =datos!B12 -> 0.79130435 | C22: Soho -Callcenter | D22: =GETPIVOTDATA(" Promesa de Pago",datos!$A$16,"Canal","Soho -Callcenter") -> 71.24 | E22: =+IFERROR(_xlfn.XLOOKUP(C21,datos!A24:A31,datos!C24:C31,,0),0) -> 0
C23: Total general | D23: =SUM(D14:D22) -> 4667.45 | E23: =SUM(E14:E22) -> 1671.46
A25: PERFORMANCE POR AGENTE
A26: AGENTE | B26: Cartera | C26: Recuperado | D26: % Recuperación | E26: Promesas | F26: Cumplidas | G26: % Efectividad
A27: Lili Velez | B27: =datos!B27 -> 3566 | C27: =datos!C27 -> 91 | D27: =datos!D27 -> 0.025518789 | E27: =datos!E27 -> 4667.45 | F27: =datos!F27 -> 1671.46 | G27: =datos!G27 -> 0.35810989
A28: Total | B28: =+SUM(B27:B27) -> 3566 | C28: =+SUM(C27:C27) -> 91 | D28: =+SUM(D27:D27) -> 0.025518789 | E28: =+SUM(E27:E27) -> 4667.45 | F28: =+SUM(F27:F27) -> 1671.46 | G28: =AVERAGE(G27:G27) -> 0.35810989
A29: PRODUCTIVIDAD OPERATIVA | H29: PROMESA VS PAGOS
A30: AGENTE | B30: Llamadas | C30: Contactos | D30: RPC | E30: Cant Promesas de pago | F30: % RPC | G30: % Contactos
A31: Lili Velez | B31: =GETPIVOTDATA("Intentos",analisis!$A$11,"full_name","Lili Velez") -> 1499 | C31: =GETPIVOTDATA(" Connect",analisis!$A$21,"full_name","Lili Velez") -> 772 | D31: =GETPIVOTDATA(" RPC",analisis!$A$21,"full_name","Lili Velez") -> 625 | E31: =GETPIVOTDATA("Suma de Intentos de Promesas",analisis!$G$34,"Agente ","Lili Velez") -> 115 | F31: =D31/C31 -> 0.80958549 | G31: =C31/B31 -> 0.51501001
A32: Total | B32: =+SUM(B31:B31) -> 1499 | C32: =+SUM(C31:C31) -> 772 | D32: =+SUM(D31:D31) -> 625 | E32: =+SUM(E31:E31) -> 115 | F32: =D32/C32 -> 0.80958549 | G32: =C32/B32 -> 0.51501001
A33: DIVISION POR MES PENDIENTE | E33: Cuentas Cesadas / Al Dia
A34: PENDIENTES POR MES | B34: REGISTROS CARGADOS | C34: RECUPERADO | E34: Cliente al dia | F34: Cuenta cesada
A35: 1 MES PENDIENTE | B35: =datos!B57 -> 48 | C35: =datos!C57 -> 6 | E35: =GETPIVOTDATA("Contacto1",analisis!$Z$21,"_Producto_Linea","Cliente al dia") -> 23 | F35: =GETPIVOTDATA("Contacto1",analisis!$Z$21,"_Producto_Linea","Cuenta cesada") -> 91
A36: 2 MESES PENDIENTES | B36: =datos!B58 -> 226 | C36: =datos!C58 -> 20
A37: 3 MESES PENDIENTES | B37: =datos!B59 -> 200 | C37: =datos!C59 -> 11
A38: 4 MESES PENDIENTES | B38: =datos!B60 -> 26 | C38: =datos!C60 -> 0
A39: NPN | B39: =datos!B61 -> 469 | C39: =datos!C61 -> 54
A41: LLAMADAS DIARIAS

Sheet dashboard

Sheet analisis
B1: =GETPIVOTDATA("Intentos",$A$2) -> 6496 | S1: =GETPIVOTDATA("Intentos",$A$2,"full_name","Lili Velez") -> 1499 | AH1: Fecha | AI1: (Todas)
A2: Llamadas diarias | B2: Dia | AH2: Escenario | AI2: (Todas)
A3: Agentes | B3: 02/may | C3: 04/may | D3: 05/may | E3: 06/may | F3: 07/may | G3: 08/may | H3: 09/may | I3: 11/may | J3: 12/may | K3: 13/may | L3: 14/may | M3: 15/may | N3: 16/may | O3: 18/may | P3: 19/may | Q3: 20/may | R3: 21/may | S3: 22/may | T3: 23/may | U3: 25/may | V3: 26/may | W3: 27/may | X3: 28/may | Y3: 29/may | Z3: 30/may | AA3: Total general | AI3: =GETPIVOTDATA(" Monto de Promesa de Pago",$G$34) -> 4667.45 | AJ3: =GETPIVOTDATA("Suma de Monto pagado",$G$34) -> 1671.46 | AK3: =GETPIVOTDATA("Suma de Intentos de Promesas",$G$34,"Agente ","Lili Velez") -> 115 | AL3: =GETPIVOTDATA("Suma de Intentos de pago",$G$34,"Agente ","Lili Velez") -> 91
A4: Lili Velez | B4: 17 | C4: 42 | D4: 27 | E4: 55 | F4: 38 | G4: 60 | H4: 48 | I4: 102 | J4: 110 | K4: 101 | L4: 99 | M4: 35 | N4: 21 | O4: 91 | P4: 83 | Q4: 95 | R4: 102 | S4: 81 | T4: 33 | U4: 13 | V4: 65 | W4: 44 | X4: 54 | Y4: 37 | Z4: 46 | AA4: 1499 | AH4: Agentes | AI4: Promesa de Pago | AJ4: Cant Promesa
A5: Outbound Auto Dial | B5: 51 | C5: 108 | D5: 44 | E5: 119 | F5: 75 | G5: 122 | H5: 150 | I5: 350 | J5: 354 | K5: 363 | L5: 355 | M5: 147 | N5: 70 | O5: 311 | P5: 298 | Q5: 309 | R5: 412 | S5: 389 | T5: 200 | U5: 79 | V5: 425 | W5: 142 | X5: 115 | Z5: 9 | AA5: 4997 | AH5: Lili Velez | AI5: 4667.45 | AJ5: 114
A6: Total general | B6: 68 | C6: 150 | D6: 71 | E6: 174 | F6: 113 | G6: 182 | H6: 198 | I6: 452 | J6: 464 | K6: 464 | L6: 454 | M6: 182 | N6: 91 | O6: 402 | P6: 381 | Q6: 404 | R6: 514 | S6: 470 | T6: 233 | U6: 92 | V6: 490 | W6: 186 | X6: 169 | Y6: 37 | Z6: 55 | AA6: 6496 | AH6: may | AI6: 4184.74 | AJ6: 104
Y8: PENDIENTES POR MES | Z8: REGISTROS CARGADOS | AA8: RECUPERADO | AH8: jun | AI8: 482.71 | AJ8: 10
A9: Contar | B9: (Todas) | Y9: 1 MES PENDIENTE | AH9: Total general | AI9: 4667.45 | AJ9: 114
D10: Contar | E10: 1 | H10: _Producto_Linea | I10: (Varios elementos) | K10: _Producto_Linea | L10: (Todas) | T10: Fecha | U10: (Todas) | Y10: 2 MESES PENDIENTES
A11: Agentes | B11: Llamadas | D11: unicos | H11: utiliuzada | K11: Base | T11: Escenario | U11: (Varios elementos) | Y11: 3 MESES PENDIENTES
A12: Lili Velez | B12: 1499 | D12: Agentes | E12: Llamadas | H12: Etiquetas de fila | I12: Cuenta de Contacto1 | K12: Etiquetas de fila | L12: Cuenta de Contacto1 | Y12: 4 MESES PENDIENTES
A13: Outbound Auto Dial | B13: 4997 | D13: Lili Velez | E13: 1139 | H13: Cobros Mayo | I13: 3468 | K13: Cobros Mayo | L13: 3566 | T13: Etiquetas de fila | U13: Cuenta de Tiempo de mora (días) | Y13: NPN
A14: Total general | B14: 6496 | D14: Outbound Auto Dial | E14: 282 | H14: Total general | I14: 3468 | K14: Total general | L14: 3566 | T14: 1 MES PENDIENTE | U14: 48
D15: Total general | E15: 1421 | T15: 2 MESES PENDIENTES | U15: 226
T16: 3 MESES PENDIENTES | U16: 200
I17: =GETPIVOTDATA("Contacto1",$H$12,"Source.Name","Cobros Mayo") -> 3468 | L17: =GETPIVOTDATA("Contacto1",$K$12) -> 3566 | T17: 4 MESES PENDIENTES | U17: 26
T18: NPN | U18: 469 | AH18: Fecha | AI18: (Todas)
A19: Contar | B19: 1 | T19: Total general | U19: 969 | Z19: Source.Name | AA19: Cobros Mayo | AH19: Escenario | AI19: (Todas)
H20: _Producto_Linea | I20: (Todas) | Z20: utiliuzada | AI20: =GETPIVOTDATA(" Monto de Promesa de Pago",$G$34) -> 4667.45 | AJ20: =GETPIVOTDATA("Suma de Monto pagado",$G$34) -> 1671.46
A21: Agentes | B21: Connect | C21: RPC | H21: Base | T21: Fecha | U21: (Todas) | Z21: Etiquetas de fila | AA21: Cuenta de Contacto1 | AH21: Meses | AI21: Monto pagado | AJ21: Intentos de pago
A22: Lili Velez | B22: 772 | C22: 625 | H22: Etiquetas de fila | I22: Cuenta de Contacto1 | T22: Mes Pago | U22: (Varios elementos) | Z22: Cliente al dia | AA22: 23 | AH22: abr | AI22: 197.5 | AJ22: 7
A23: Outbound Auto Dial | B23: 0 | C23: 0 | H23: Cobros Mayo | I23: 3566 | T23: Escenario | U23: (Todas) | Z23: Cuenta cesada | AA23: 91 | AH23: may | AI23: 1473.96 | AJ23: 84
A24: Total general | B24: 772 | C24: 625 | H24: Total general | I24: 3566 | Z24: #N/D | AA24: 7 | AH24: Total general | AI24: 1671.46 | AJ24: 91
T25: Etiquetas de fila | U25: Cuenta de Mes Pago | Z25: Total general | AA25: 121
T26: 1 MES PENDIENTE | U26: 6
T27: 2 MESES PENDIENTES | U27: 20
T28: 3 MESES PENDIENTES | U28: 11
T29: NPN | U29: 54 | AA29: 1347
B30: =GETPIVOTDATA("Monto de Promesa de Pago",$A$34) -> 4667.45 | C30: =GETPIVOTDATA(" Monto Recuperado",$A$34) -> 1671.46 | T30: Total general | U30: 91 | AA30: -361
A31: Mes Pago | B31: (Todas) | G31: Fecha | H31: (Todas)
A32: Mes Promesa | B32: (Todas) | G32: Escenario | H32: (Todas) | Q32: Agentes | R32: Suma de Monto pagado
A33: Resultados Financieros | H33: =GETPIVOTDATA(" Monto de Promesa de Pago",$G$34) -> 4667.45 | I33: =GETPIVOTDATA("Suma de Monto pagado",$G$34) -> 1671.46 | J33: =GETPIVOTDATA("Suma de Intentos de Promesas",$G$34) -> 115 | K33: =GETPIVOTDATA("Cuenta de Intentos de pago",$G$45,"Agente ","Lili Velez") -> 91 | Q33: Lili Velez | R33: 1671.46
A34: Canal | B34: Promesa de Pago | C34: Monto Recuperado | G34: Canal | H34: Monto de Promesa de Pago | I34: Suma de Monto pagado | J34: Suma de Intentos de Promesas | K34: Suma de Intentos de pago | L34: Cartera | Q34: Total general | R34: 1671.46
A35: Call Center Outbound | B35: 500.99 | C35: 204.98 | D35: =+GETPIVOTDATA(" Monto Recuperado",$A$34)/GETPIVOTDATA(" Promesa de Pago",$A$34) -> 0.35810989 | G35: Lili Velez | H35: 4667.45 | I35: 1671.46 | J35: 115 | K35: 91 | L35: =C54/C55 -> 3566
A36: Digital | B36: 160.35 | C36: 0 | G36: Total general | H36: 4667.45 | I36: 1671.46 | J36: 115 | K36: 91 | L36: =C54/C55 -> 3566
A37: Masivo (D2D) | B37: 3133.18 | C37: 1083.71
A38: Punto de ventas | B38: 0 | C38: 0
A39: Soho | B39: 801.69 | C39: 382.77
A40: Soho -Callcenter | B40: 71.24 | C40: 0
A41: Total general | B41: 4667.45 | C41: 1671.46 | G41: Fecha | H41: (Todas)
...

Sheet datos
A2: Resumen Ejecutivo | E2: Productividad Operativa
A3: HC | B3: 1 | E3: Indicador | F3: Valor
A4: Cuentas asignadas | B4: =analisis!L17 -> 3566 | E4: Llamadas | F4: Contactos | G4: RPC | H4: Cant Promesas de pago | I4: % RPC
A5: Cartera ($) | B5: =GETPIVOTDATA(" Monto de Promesa de Pago",analisis!$G$34) -> 4667.45 | E5: =GETPIVOTDATA("Intentos",analisis!$A$11) -> 6496 | F5: =GETPIVOTDATA(" Connect",analisis!$A$21) -> 772 | G5: =GETPIVOTDATA(" RPC",analisis!$A$21) -> 625 | H5: =analisis!J33 -> 115 | I5: =G5/F5 -> 0.80958549
A6: Recuperación ($) | B6: =GETPIVOTDATA("Suma de Monto pagado",analisis!$G$34) -> 1671.46
A7: % Recuperación | B7: =B6/B5 -> 0.35810989
A8: Contactabilidad | B8: =F5/E5 -> 0.11884236
A9: RPC | B9: =G5/F5 -> 0.80958549
A10: Promesas | B10: =H5 -> 115
A11: Promesas cumplidas | B11: =B37 -> 91
A12: % Cumplimiento | B12: =B11/B10 -> 0.79130435
A15: Resultados Financieros
A16: Canal | B16: Promesa de Pago | C16: Monto Recuperado
A17: Call Center Outbound | B17: 500.99 | C17: 204.98
A18: Digital | B18: 160.35 | C18: 0
A19: Masivo (D2D) | B19: 3133.18 | C19: 1083.71
A20: Punto de ventas | B20: 0 | C20: 0
A21: Soho | B21: 801.69 | C21: 382.77
A22: Soho -Callcenter | B22: 71.24 | C22: 0
A23: Total general | B23: 4667.45 | C23: 1671.46
A25: Performance por Agente
A26: Agente | B26: Cartera | C26: Recuperado | D26: % Recuperación | E26: Promesas | F26: Cumplidas | G26: % Efectividad
A27: Lili Velez | B27: =analisis!C57 -> 3566 | C27: =GETPIVOTDATA("Suma de Intentos de pago",analisis!$G$34,"Agente ","Lili Velez") -> 91 | D27: =C27/B27 -> 0.025518789 | E27: =GETPIVOTDATA(" Monto de Promesa de Pago",analisis!$G$34,"Agente ","Lili Velez") -> 4667.45 | F27: =GETPIVOTDATA("Suma de Monto pagado",analisis!$G$34,"Agente ","Lili Velez") -> 1671.46 | G27: =F27/E27 -> 0.35810989
A31: Funnel de Cobranza
A32: Etapa | B32: Cantidad
A33: Asignadas | B33: =B4 -> 3566
A34: Gestionadas | B34: =analisis!I17 -> 3468
A35: Contactadas | B35: =F5 -> 772
A36: Promesas | B36: =analisis!J33 -> 115
A37: Pagos | B37: =analisis!K33 -> 91
A40: Promesas vs Pagos
A41: Indicador | B41: Valor | C41: Porcentaje
A42: Promesas | B42: =H5 -> 115 | C42: =B42/$B$4 -> 0.032249019
A43: Pagos | B43: =B11 -> 91 | C43: =B43/$B$4 -> 0.025518789
A44: % Cumplimiento | B44: =(B43/B42) -> 0.79130435
A47: Barrido de base
A48: Indicador | B48: Valor
A49: Gestiones Totales | B49: =analisis!L17 -> 3566
A50: Gestiones Productivas | B50: =analisis!I17 -> 3468
A51: % Efectividad | B51: =B50/B49 -> 0.97251823
...

Sheet Resumen Ejecutivo
A2: Resumen Ejecutivo
A3: HC | B3: 2
A4: Cuentas asignadas | B4: 1000
A5: Cartera ($) | B5: 150000
A6: Recuperación ($) | B6: 45000
A7: % Recuperación | B7: =B6/B5 -> 0.3
A8: RPC | B8: 300
A9: Contactabilidad | B9: 0.65
A10: Promesas | B10: 120
A11: Promesas cumplidas | B11: 90
A12: % Cumplimiento | B12: =B11/B10 -> 0.75

Sheet Productividad
A1: Indicador | B1: Valor
A2: Llamadas | B2: Contactos | C2: RPC | D2: Cant Promesas de pago
A3: 2500 | B3: 1600 | C3: 300 | D3: 120

Sheet Financieros
A1: Segmento | B1: Recuperación ($)
A2: Call Center | B2: 30000
A3: Digital | B3: 15000

Sheet Agentes
A1: Agente | B1: Cartera | C1: Recuperado | D1: % Recuperación | E1: Promesas | F1: Cumplidas | G1: % Efectividad
A2: Agente 1 | B2: 75000 | C2: 25000 | D2: =C2/B2 -> 0.33333333 | E2: 70 | F2: 50 | G2: =F2/E2 -> 0.71428571
A3: Agente 2 | B3: 75000 | C3: 20000 | D3: =C3/B3 -> 0.26666667 | E3: 50 | F3: 40 | G3: =F3/E3 -> 0.8

Sheet Funnel
A1: Etapa | B1: Cantidad
A2: Asignadas | B2: 1000
A3: Gestionadas | B3: 800
A4: Contactadas | B4: 650
A5: Promesas | B5: 120
A6: Pagos | B6: 90

Sheet Promesas vs Pagos
A1: Indicador | B1: Valor
A2: Promesas | B2: 120
A3: Pagos | B3: 90
A4: % Cumplimiento | B4: =B3/B2 -> 0.75

Sheet Efectividad
A1: Indicador | B1: Valor
A2: Gestiones Totales | B2: 2500
A3: Gestiones Productivas | B3: 300
A4: % Efectividad | B4: =B3/B2 -> 0.12

Sheet bases UTILIZADAS
A1: Source.Name | B1: Nombre_Cliente | C1: Numero_Cuenta | D1: Nombre de Lista | E1: Provincia | F1: Dias_morosidad | G1: Fecha_Ult_Pago | H1: Contacto1 | I1: Contacto2 | J1: Contacto3 | K1: email | L1: Monto_Vencido | M1: Monto_Total | N1: Ciclo | O1: Fecha_Promesa_Pago | P1: Numero_de_orden | Q1: Segmentacion_de_cliente | R1: Direccion | S1: Cedula_del_cliente | T1: Canal | U1: Tiempo de mora | V1: _Producto_Linea | W1: _Renta_BB | X1: _Renta_Linea | Y1: _Renta_TV | Z1: Pago_de_entrada
A2: Cobros Abril Canal Fijo | B2: Delfina gonzalez Martinez | C2: 359331050000 | D2: Cobros Abril Canal Fijo 2 meses a NPN | E2: =+_xlfn.XLOOKUP(UTILIZADAS[[#This Row],[Numero_Cuenta]],'[1]cobros_marzo (fijo)'!$B:$B,'[1]cobros_marzo (fijo)'!$D:$D,,0) -> Provincia | G2: 46026 | H2: 67523877 | I2: 67523877 | K2: preciadoiranelda@gmail.com | O2: 46026 | S2: 10-8-653 | T2: MASIVO | U2: NPN | V2: =_xlfn.XLOOKUP(UTILIZADAS[[#This Row],[Contacto1]],Tabla2[phone_number_dialed],Tabla2[status_name],,0) -> #N/A
A3: Cobros Abril Canal Fijo | B3: Juliana concepción | C3: 356789000000 | D3: Cobros Abril Canal Fijo 2 meses a NPN | E3: =+_xlfn.XLOOKUP(UTILIZADAS[[#This Row],[Numero_Cuenta]],'[1]cobros_marzo (fijo)'!$B:$B,'[1]cobros_marzo (fijo)'!$D:$D,,0) -> PANAMA | G3: 46026 | H3: 68905432 | I3: 68905432 | K3: juancarlos@gmail.com | O3: 46026 | S3: 9-748-246 | T3: MASIVO | U3: NPN | V3: =_xlfn.XLOOKUP(UTILIZADAS[[#This Row],[Contacto1]],Tabla2[phone_number_dialed],Tabla2[status_name],,0) -> #N/A
A4: Cobros Abril Canal Fijo | B4: Angeles barahona | C4: 355339190000 | D4: Cobros Abril Canal Fijo 2 meses a NPN | E4: =+_xlfn.XLOOKUP(UTILIZADAS[[#This Row],[Numero_Cuenta]],'[1]cobros_marzo (fijo)'!$B:$B,'[1]cobros_marzo (fijo)'!$D:$D,,0) -> PANAMA | G4: 46026 | H4: 68905432 | I4: 68905432 | K4: danirudas42@gmail.com | O4: 46026 | S4: 7-712-2265 | T4: MASIVO | U4: NPN | V4: =_xlfn.XLOOKUP(UTILIZADAS[[#This Row],[Contacto1]],Tabla2[phone_number_dialed],Tabla2[status_name],,0) -> #N/A
A5: Cobros Abril Canal Fijo | B5: Stacy suseth Murillo de Leon | C5: 357337110000 | D5: Cobros Abril Canal Fijo 2 meses a NPN | E5: =+_xlfn.XLOOKUP(UTILIZADAS[[#This Row],[Numero_Cuenta]],'[1]cobros_marzo (fijo)'!$B:$B,'[1]cobros_marzo (fijo)'!$D:$D,,0) -> PANAMA | G5: 46026 | H5: 63277219 | I5: 63277219 | K5: stacymrillo28@icloud.com | O5: 46026 | S5: 8-994-968 | T5: MASIVO | U5: NPN | V5: =_xlfn.XLOOKUP(UTILIZADAS[[#This Row],[Contacto1]],Tabla2[phone_number_dialed],Tabla2[status_name],,0) -> #N/A
A6: Cobros Abril Canal Fijo | B6: Roberto Linton | C6: 359338710000 | D6: Cobros Abril Canal Fijo 2 meses a NPN | E6: =+_xlfn.XLOOKUP(UTILIZADAS[[#This Row],[Numero_Cuenta]],'[1]cobros_marzo (fijo)'!$B:$B,'[1]cobros_marzo (fijo)'!$D:$D,,0) -> 0 | G6: 46026 | H6: 64628032 | I6: 64628032 | K6: Fabian022431@gmail.com | O6: 46026 | S6: 8-257-865 | T6: MASIVO | U6: NPN | V6: =_xlfn.XLOOKUP(UTILIZADAS[[#This Row],[Contacto1]],Tabla2[phone_number_dialed],Tabla2[status_name],,0) -> #N/A
A7: Cobros Abril Canal Fijo | B7: MARIO AUGUSTO ARJONA ARJONA | C7: 352335700000 | D7: Cobros Abril Canal Fijo 2 meses a NPN | E7: =+_xlfn.XLOOKUP(UTILIZADAS[[#This Row],[Numero_Cuenta]],'[1]cobros_marzo (fijo)'!$B:$B,'[1]cobros_marzo (fijo)'!$D:$D,,0) -> PANAMA | G7: 46026 | H7: 65117775 | I7: 65117775 | K7: marioarjona1956@gmail.com | O7: 46026 | S7: 6-41-2503 | T7: MASIVO | U7: NPN | V7: =_xlfn.XLOOKUP(UTILIZADAS[[#This Row],[Contacto1]],Tabla2[phone_number_dialed],Tabla2[status_name],,0) -> #N/A
A8: Cobros Abril Canal Fijo | B8: Edith Montes | C8: 357338020000 | D8: Cobros Abril Canal Fijo 2 meses a NPN | E8: =+_xlfn.XLOOKUP(UTILIZADAS[[#This Row],[Numero_Cuenta]],'[1]cobros_marzo (fijo)'!$B:$B,'[1]cobros_marzo (fijo)'!$D:$D,,0) -> HERRERA | G8: 46026 | H8: 63822556 | I8: 63822556 | K8: Edithmontes300@gmail.com | O8: 46026 | S8: 9-742-14 | T8: MASIVO | U8: NPN | V8: =_xlfn.XLOOKUP(UTILIZADAS[[#This Row],[Contacto1]],Tabla2[phone_number_dialed],Tabla2[status_name],,0) -> #N/A
A9: Cobros Abril Canal Fijo | B9: CARLOSENRIQUE DOMINGUEZVERGARA | C9: 359339470000 | D9: Cobros Abril Canal Fijo 2 meses a NPN | E9: =+_xlfn.XLOOKUP(UTILIZADAS[[#This Row],[Numero_Cuenta]],'[1]cobros_marzo (fijo)'!$B:$B,'[1]cobros_marzo (fijo)'!$D:$D,,0) -> VERAGUAS | G9: 46026 | H9: 63701410 | I9: 63701410 | K9: Cdominguezvergara939@gmail.com | O9: 46026 | S9: 8-796-2451 | T9: MASIVO | U9: NPN | V9: =_xlfn.XLOOKUP(UTILIZADAS[[#This Row],[Contacto1]],Tabla2[phone_number_dialed],Tabla2[status_name],,0) -> #N/A
A10: Cobros Abril Canal Fijo | B10: Nelis Pérez Jiménez | C10: 356338650000 | D10: Cobros Abril Canal Fijo 2 meses a NPN | E10: =+_xlfn.XLOOKUP(UTILIZADAS[[#This Row],[Numero_Cuenta]],'[1]cobros_marzo (fijo)'!$B:$B,'[1]cobros_marzo (fijo)'!$D:$D,,0) -> PANAMA | G10: 46026 | H10: 64205199 | I10: 64205199 | K10: nelisperez955@gmail.com | O10: 46026 | S10: 8-969-831 | T10: MASIVO | U10: NPN | V10: =_xlfn.XLOOKUP(UTILIZADAS[[#This Row],[Contacto1]],Tabla2[phone_number_dialed],Tabla2[status_name],,0) -> #N/A
A11: Cobros Abril Canal Fijo | B11: Luz Mina solis diaz | C11: 369328670000 | D11: Cobros Abril Canal Fijo 2 meses a NPN | E11: =+_xlfn.XLOOKUP(UTILIZADAS[[#This Row],[Numero_Cuenta]],'[1]cobros_marzo (fijo)'!$B:$B,'[1]cobros_marzo (fijo)'!$D:$D,,0) -> 0 | G11: 46026 | H11: 66330979 | I11: 66330979 | K11: diaslineth73@gmail.com | O11: 46026 | S11: 8-897-1143 | T11: MASIVO | U11: NPN | V11: =_xlfn.XLOOKUP(UTILIZADAS[[#This Row],[Contacto1]],Tabla2[phone_number_dialed],Tabla2[status_name],,0) -> #N/A
A12: Cobros Abril Canal Fijo | B12: Gloria Saday Peralta Espino | C12: 355318600000 | D12: Cobros Abril Canal Fijo 2 meses a NPN | E12: =+_xlfn.XLOOKUP(UTILIZADAS[[#This Row],[Numero_Cuenta]],'[1]cobros_marzo (fijo)'!$B:$B,'[1]cobros_marzo (fijo)'!$D:$D,,0) -> PANAMA | G12: 46026 | H12: 63498225 | I12: 63498225 | K12: 06.alayna@gmail.com | O12: 46026 | S12: 8-1043-2239 | T12: MASIVO | U12: NPN | V12: =_xlfn.XLOOKUP(UTILIZADAS[[#This Row],[Contacto1]],Tabla2[phone_number_dialed],Tabla2[status_name],,0) -> #N/A
A13: Cobros Abril Canal Fijo | B13: Disleydis quintero | C13: 356340020000 | D13: Cobros Abril Canal Fijo 2 meses a NPN | E13: =+_xlfn.XLOOKUP(UTILIZADAS[[#This Row],[Numero_Cuenta]],'[1]cobros_marzo (fijo)'!$B:$B,'[1]cobros_marzo (fijo)'!$D:$D,,0) -> PANAMA | G13: 46026 | H13: 67778877 | I13: 67778877 | K13: Disleydiquintero@gmail.com | O13: 46026 | S13: 8-1033-671 | T13: MASIVO | U13: NPN | V13: =_xlfn.XLOOKUP(UTILIZADAS[[#This Row],[Contacto1]],Tabla2[phone_number_dialed],Tabla2[status_name],,0) -> #N/A
... A189: Cobros Abril Canal Fijo | B189: EMIDIO ROBINSON GARCIA | C189: 351354250000 | D189: Cobros Abril Canal Fijo 2 meses a NPN | E189: =+_xlfn.XLOOKUP(UTILIZADAS[[#This Row],[Numero_Cuenta]],'[1]cobros_marzo (fijo)'!$B:$B,'[1]cobros_marzo (fijo)'!$D:$D,,0) -> CHIRIQUI | G189: 46026 | H189: 67369139 | I189: 67369139 | K189: Emidiorobinson@gmail.com | O189: 46026 | S189: 10-708-2196 | T189: MASIVO | U189: NPN | V189: =_xlfn.XLOOKUP(UTILIZADAS[[#This Row],[Contacto1]],Tabla2[phone_number_dialed],Tabla2[status_name],,0) -> #N/A
A190: Cobros Abril Canal Fijo | B190: María Aleida Cooper | C190: 351353940000 | D190: Cobros Abril Canal Fijo 2 meses a NPN | E190: =+_xlfn.XLOOKUP(UTILIZADAS[[#This Row],[Numero_Cuenta]],'[1]cobros_marzo (fijo)'!$B:$B,'[1]cobros_marzo (fijo)'!$D:$D,,0) -> PANAMA | G190: 46026 | H190: 68244153 | I190: 68244153 | K190: patricia5042056601@gmail.com | O190: 46026 | S190: 570783804 | T190: MASIVO | U190: NPN | V190: =_xlfn.XLOOKUP(UTILIZADAS[[#This Row],[Contacto1]],Tabla2[phone_number_dialed],Tabla2[status_name],,0) -> #N/A
A191: Cobros Abril Canal Fijo | B191: Gerson Ney Lasso Balanta | C191: 354352440000 | D191: Cobros Abril Canal Fijo 2 meses a NPN | E191: =+_xlfn.XLOOKUP(UTILIZADAS[[#This Row],[Numero_Cuenta]],'[1]cobros_marzo (fijo)'!$B:$B,'[1]cobros_marzo (fijo)'!$D:$D,,0) -> PANAMA | G191: 46026 | H191: 69054703 | I191: 69054703 | K191: Lassogerson35@gmail.com | O191: 46026 | S191: FB662738 | T191: MASIVO | U191: NPN | V191: =_xlfn.XLOOKUP(UTILIZADAS[[#This Row],[Contacto1]],Tabla2[phone_number_dialed],Tabla2[status_name],,0) -> #N/A
A192: Cobros Abril Canal Fijo | B192: KAREN CAMACHO | C192: 358348350000 | D192: Cobros Abril Canal Fijo 2 meses a NPN | E192: =+_xlfn.XLOOKUP(UTILIZADAS[[#This Row],[Numero_Cuenta]],'[1]cobros_marzo (fijo)'!$B:$B,'[1]cobros_marzo (fijo)'!$D:$D,,0) -> COLON | G192: 46026 | H192: 67787532 | I192: 67787532 | K192: Barcenaseder58@gmail.com | O192: 46026 | S192: 3-743-363 | T192: MASIVO | U192: NPN | V192: =_xlfn.XLOOKUP(UTILIZADAS[[#This Row],[Contacto1]],Tabla2[phone_number_dialed],Tabla2[status_name],,0) -> #N/A
A193: Cobros Abril Canal Fijo | B193: Rony garcia | C193: 359354680000 | D193: Cobros Abril Canal Fijo 2 meses a NPN | E193: =+_xlfn.XLOOKUP(UTILIZADAS[[#This Row],[Numero_Cuenta]],'[1]cobros_marzo (fijo)'!$B:$B,'[1]cobros_marzo (fijo)'!$D:$D,,0) -> COLON | G193: 46026 | H193: 61669203 | I193: 61669203 | K193: ronygarcia24@gmail.com | O193: 46026 | S193: 8-1047-2365 | T193: MASIVO | U193: NPN | V193: =_xlfn.XLOOKUP(UTILIZADAS[[#This Row],[Contacto1]],Tabla2[phone_number_dialed],Tabla2[status_name],,0) -> #N/A
A194: Cobros Abril Canal Fijo | B194: Sofía Navarro | C194: 357335980000 | D194: Cobros Abril Canal Fijo 2 meses a NPN | E194: =+_xlfn.XLOOKUP(UTILIZADAS[[#This Row],[Numero_Cuenta]],'[1]cobros_marzo (fijo)'!$B:$B,'[1]cobros_marzo (fijo)'!$D:$D,,0) -> PANAMA | G194: 46026 | H194: 62665510 | I194: 62665510 | K194: sofiadenavarro@gmail.com | O194: 46026 | S194: AX939366 | T194: SOHO | U194: NPN | V194: =_xlfn.XLOOKUP(UTILIZADAS[[#This Row],[Contacto1]],Tabla2[phone_number_dialed],Tabla2[status_name],,0) -> #N/A
A195: Cobros Abril Canal Fijo | B195: Karen Vergara | C195: 354352630000 | D195: Cobros Abril Canal Fijo 2 meses a NPN | E195: =+_xlfn.XLOOKUP(UTILIZADAS[[#This Row],[Numero_Cuenta]],'[1]cobros_marzo (fijo)'!$B:$B,'[1]cobros_marzo (fijo)'!$D:$D,,0) -> PANAMA | G195: 46026 | H195: 68162584 | I195: 68162584 | K195: kvergara0328@gmail.com | O195: 46026 | S195: 8-998-2253 | T195: MASIVO | U195: NPN | V195: =_xlfn.XLOOKUP(UTILIZADAS[[#This Row],[Contacto1]],Tabla2[phone_number_dialed],Tabla2[status_name],,0) -> #N/A
A196: Cobros Abril Canal Fijo | B196: CESAR GONZALEZ | C196: 356353170000 | D196: Cobros Abril Canal Fijo 2 meses a NPN | E196: =+_xlfn.XLOOKUP(UTILIZADAS[[#This Row],[Numero_Cuenta]],'[1]cobros_marzo (fijo)'!$B:$B,'[1]cobros_marzo (fijo)'!$D:$D,,0) -> HERRERA | G196: 46026 | H196: 68462020 | I196: 68462020 | K196: Eutimiaguerra213@gmail.com | O196: 46026 | S196: 9-61-437 | T196: MASIVO | U196: NPN | V196: =_xlfn.XLOOKUP(UTILIZADAS[[#This Row],[Contacto1]],Tabla2[phone_number_dialed],Tabla2[status_name],,0) -> #N/A
A197: Cobros Abril Canal Fijo | B197: Cecibel rios | C197: 357353980000 | D197: Cobros Abril Canal Fijo 2 meses a NPN | E197: =+_xlfn.XLOOKUP(UTILIZADAS[[#This Row],[Numero_Cuenta]],'[1]cobros_marzo (fijo)'!$B:$B,'[1]cobros_marzo (fijo)'!$D:$D,,0) -> VERAGUAS | G197: 46026 | H197: 65279813 | I197: 65279813 | K197: crios3131@hotmail.com | O197: 46026 | S197: 8-303-7 | T197: MASIVO | U197: NPN | V197: =_xlfn.XLOOKUP(UTILIZADAS[[#This Row],[Contacto1]],Tabla2[phone_number_dialed],Tabla2[status_name],,0) -> #N/A
A198: Cobros Abril Canal Fijo | B198: Alexandra Raquel Mora Quijano | C198: 357353490000 | D198: Cobros Abril Canal Fijo 2 meses a NPN | E198: =+_xlfn.XLOOKUP(UTILIZADAS[[#This Row],[Numero_Cuenta]],'[1]cobros_marzo (fijo)'!$B:$B,'[1]cobros_marzo (fijo)'!$D:$D,,0) -> PANAMA | G198: 46026 | H198: 67011734 | I198: 67011734 | K198: lilymoraquijano1705@gmail.com | O198: 46026 | S198: 4-763-1902 | T198: MASIVO | U198: NPN | V198: =_xlfn.XLOOKUP(UTILIZADAS[[#This Row],[Contacto1]],Tabla2[phone_number_dialed],Tabla2[status_name],,0) -> #N/A
A199: Cobros Abril Canal Fijo | B199: YENITZEL ARGELYS AGUILAR SANTOS | C199: 351355390000 | D199: Cobros Abril Canal Fijo 2 meses a NPN | E199: =+_xlfn.XLOOKUP(UTILIZADAS[[#This Row],[Numero_Cuenta]],'[1]cobros_marzo (fijo)'!$B:$B,'[1]cobros_marzo (fijo)'!$D:$D,,0) -> CHIRIQUI | G199: 46026 | H199: 61948388 | I199: 61948388 | K199: msantoscontrera@gmail.com | O199: 46026 | S199: 4-827-1762 | T199: MASIVO | U199: NPN | V199: =_xlfn.XLOOKUP(UTILIZADAS[[#This Row],[Contacto1]],Tabla2[phone_number_dialed],Tabla2[status_name],,0) -> #N/A
A200: Cobros Abril Canal Fijo | B200: ESTEBAN GARY ROJAS | C200: 357355760000 | D200: Cobros Abril Canal Fijo 2 meses a NPN | E200: =+_xlfn.XLOOKUP(UTILIZADAS[[#This Row],[Numero_Cuenta]],'[1]cobros_marzo (fijo)'!$B:$B,'[1]cobros_marzo (fijo)'!$D:$D,,0) -> CHIRIQUI | G200: 46026 | H200: 68930634 | I200: 68930634 | K200: mariadegary1959@gmail.com | O200: 46026 | S200: 3-42-581 | T200: MASIVO | U200: NPN | V200: =_xlfn.XLOOKUP(UTILIZADAS[[#This Row],[Contacto1]],Tabla2[phone_number_dialed],Tabla2[status_name],,0) -> #N/A
A201: Cobros Abril Canal Fijo | B201: Enilda Yuribel Perrz Ruiz | C201: 354354860000 | D201: Cobros Abril Canal Fijo 2 meses a NPN | E201: =+_xlfn.XLOOKUP(UTILIZADAS[[#This Row],[Numero_Cuenta]],'[1]cobros_marzo (fijo)'!$B:$B,'[1]cobros_marzo (fijo)'!$D:$D,,0) -> CHIRIQUI | G201: 46026 | H201: 68366223 | I201: 68366223 | K201: eperez@corromaduro.com | O201: 46026 | S201: 9-734-1467 | T201: MASIVO | U201: NPN | V201: =_xlfn.XLOOKUP(UTILIZADAS[[#This Row],[Contacto1]],Tabla2[phone_number_dialed],Tabla2[status_name],,0) -> #N/A
A202: Cobros Abril Canal Fijo | B202: Horacia solis | C202: 356789050000 | D202: Cobros Abril Canal Fijo 2 meses a NPN | E202: =+_xlfn.XLOOKUP(UTILIZADAS[[#This Row],[Numero_Cuenta]],'[1]cobros_marzo (fijo)'!$B:$B,'[1]cobros_marzo (fijo)'!$D:$D,,0) -> PANAMA | G202: 46026 | H202: 67890453 | I202: 67890453 | K202: juancarlos@gmail.com | O202: 46026 | S202: 9-139-25 | T202: MASIVO | U202: NPN | V202: =_xlfn.XLOOKUP(UTILIZADAS[[#This Row],[Contacto1]],Tabla2[phone_number_dialed],Tabla2[status_name],,0) -> #N/A
... A243: Cobros Abril Canal Fijo | B243: Alan Yeison Castillo Ruiz | C243: 358358400000 | D243: Cobros Abril Canal Fijo 2 meses a NPN | E243: =+_xlfn.XLOOKUP(UTILIZADAS[[#This Row],[Numero_Cuenta]],'[1]cobros_marzo (fijo)'!$B:$B,'[1]cobros_marzo (fijo)'!$D:$D,,0) -> 0 | G243: 46026 | H243: 69799498 | I243: 69799498 | K243: josekeran@gmail.com | O243: 46026 | S243: 8-912-1027 | T243: MASIVO | U243: NPN | V243: =_xlfn.XLOOKUP(UTILIZADAS[[#This Row],[Contacto1]],Tabla2[phone_number_dialed],Tabla2[status_name],,0) -> #N/A
A244: Cobros Abril Canal Fijo | B244: Yenifer Michelle ruiz Duarte | C244: 352358100000 | D244: Cobros Abril Canal Fijo 2 meses a NPN | E244: =+_xlfn.XLOOKUP(UTILIZADAS[[#This Row],[Numero_Cuenta]],'[1]cobros_marzo (fijo)'!$B:$B,'[1]cobros_marzo (fijo)'!$D:$D,,0) -> 0 | G244: 46026 | H244: 64178091 | I244: 64178091 | K244: ruizyenifer905@gmail.com | O244: 46026 | S244: 9762438 | T244: MASIVO | U244: NPN | V244: =_xlfn.XLOOKUP(UTILIZADAS[[#This Row],[Contacto1]],Tabla2[phone_number_dialed],Tabla2[status_name],,0) -> #N/A
A245: Cobros Abril Canal Fijo | B245: Isidra Méndez barsallo | C245: 354359510000 | D245: Cobros Abril Canal Fijo 2 meses a NPN | E245: =+_xlfn.XLOOKUP(UTILIZADAS[[#This Row],[Numero_Cuenta]],'[1]cobros_marzo (fijo)'!$B:$B,'[1]cobros_marzo (fijo)'!$D:$D,,0) -> 0 | G245: 46026 | H245: 66641321 | I245: 66641321 | K245: mendeznba13@gmail.com | O245: 46026 | S245: 9-66-513 | T245: MASIVO | U245: NPN | V245: =_xlfn.XLOOKUP(UTILIZADAS[[#This Row],[Contacto1]],Tabla2[phone_number_dialed],Tabla2[status_name],,0) -> #N/A
A246: Cobros Abril Canal Fijo | B246: Irving Virgilio Perez Madrid | C246: 352343340000 | D246: Cobros Abril Canal Fijo 2 meses a NPN | E246: =+_xlfn.XLOOKUP(UTILIZADAS[[#This Row],[Numero_Cuenta]],'[1]cobros_marzo (fijo)'!$B:$B,'[1]cobros_marzo (fijo)'!$D:$D,,0) -> 0 | G246: 46026 | H246: 68010681 | I246: 68010681 | K246: Vergararosaalicia@gmail.com | O246: 46026 | S246: 8-870-2359 | T246: MASIVO | U246: NPN | V246: =_xlfn.XLOOKUP(UTILIZADAS[[#This Row],[Contacto1]],Tabla2[phone_number_dialed],Tabla2[status_name],,0) -> #N/A
A247: Cobros Abril Canal Fijo | B247: William Solis Clement | C247: 354360650000 | D247: Cobros Abril Canal Fijo 2 meses a NPN | E247: =+_xlfn.XLOOKUP(UTILIZADAS[[#This Row],[Numero_Cuenta]],'[1]cobros_marzo (fijo)'!$B:$B,'[1]cobros_marzo (fijo)'!$D:$D,,0) -> 0 | G247: 46026 | H247: 61016174 | I247: 61016174 | K247: idilciaortega049@gmail.com | O247: 46026 | S247: 10-32-500 | T247: MASIVO | U247: NPN | V247: =_xlfn.XLOOKUP(UTILIZADAS[[#This Row],[Contacto1]],Tabla2[phone_number_dialed],Tabla2[status_name],,0) -> #N/A
A248: Cobros Abril Canal Fijo | B248: Mavelyn palacio | C248: 357334100000 | D248: Cobros Abril Canal Fijo 2 meses a NPN | E248: =+_xlfn.XLOOKUP(UTILIZADAS[[#This Row],[Numero_Cuenta]],'[1]cobros_marzo (fijo)'!$B:$B,'[1]cobros_marzo (fijo)'!$D:$D,,0) -> 0 | G248: 46026 | H248: 66839768 | I248: 66839768 | K248: Palaciomabelin346@gmail.com | O248: 46026 | S248: 5-716-2130 | T248: MASIVO | U248: NPN | V248: =_xlfn.XLOOKUP(UTILIZADAS[[#This Row],[Contacto1]],Tabla2[phone_number_dialed],Tabla2[status_name],,0) -> #N/A
A249: Cobros Abril Canal Fijo | B249: Nasaret masckill Tenorio | C249: 358355590000 | D249: Cobros Abril Canal Fijo 2 meses a NPN | E249: =+_xlfn.XLOOKUP(UTILIZADAS[[#This Row],[Numero_Cuenta]],'[1]cobros_marzo (fijo)'!$B:$B,'[1]cobros_marzo (fijo)'!$D:$D,,0) -> 0 | G249: 46026 | H249: 63321872 | I249: 63321872 | K249: tenorio.06@outlook.com | O249: 46026 | S249: 9-749-486 | T249: MASIVO | U249: NPN | V249: =_xlfn.XLOOKUP(UTILIZADAS[[#This Row],[Contacto1]],Tabla2[phone_number_dialed],Tabla2[status_name],,0) -> #N/A
A250: Cobros Abril Canal Fijo | B250: Julieth Ortega | C250: 357082970000 | D250: Cobros Abril Canal Fijo 2 meses a NPN | E250: =+_xlfn.XLOOKUP(UTILIZADAS[[#This Row],[Numero_Cuenta]],'[1]cobros_marzo (fijo)'!$B:$B,'[1]cobros_marzo (fijo)'!$D:$D,,0) -> 0 | G250: 46026 | H250: 67030325 | I250: 67030325 | K250: juliethdelrosario@gmail.com | O250: 46026 | S250: 8-927-546 | T250: MASIVO | U250: NPN | V250: =_xlfn.XLOOKUP(UTILIZADAS[[#This Row],[Contacto1]],Tabla2[phone_number_dialed],Tabla2[status_name],,0) -> #N/A
A251: Cobros Abril Canal Fijo | B251: Angel lorenzo | C251: 354358380000 | D251: Cobros Abril Canal Fijo 2 meses a NPN | E251: =+_xlfn.XLOOKUP(UTILIZADAS[[#This Row],[Numero_Cuenta]],'[1]cobros_marzo (fijo)'!$B:$B,'[1]cobros_marzo (fijo)'!$D:$D,,0) -> 0 | G251: 46026 | H251: 68906543 | I251: 68906543 | K251: tribaldoszadkiel88@gmail.com | O251: 46026 | S251: 2-162-764 | T251: MASIVO | U251: NPN | V251: =_xlfn.XLOOKUP(UTILIZADAS[[#This Row],[Contacto1]],Tabla2[phone_number_dialed],Tabla2[status_name],,0) -> #N/A
A252: Cobros Abril Canal Fijo | B252: Eduardo Abel Iturralde Duarte | C252: 353360370000 | D252: Cobros Abril Canal Fijo 2 meses a NPN | E252: =+_xlfn.XLOOKUP(UTILIZADAS[[#This Row],[Numero_Cuenta]],'[1]cobros_marzo (fijo)'!$B:$B,'[1]cobros_marzo (fijo)'!$D:$D,,0) -> 0 | G252: 46026 | H252: 65880586 | I252: 65880586 | K252: iturraldee053@gmail.com | O252: 46026 | S252: 8-444-381 | T252: SOHO | U252: NPN | V252: =_xlfn.XLOOKUP(UTILIZADAS[[#This Row],[Contacto1]],Tabla2[phone_number_dialed],Tabla2[status_name],,0) -> #N/A
A253: Cobros Abril Canal Fijo | B253: Maryerlin Ballesteros | C253: 352351310000 | D253: Cobros Abril Canal Fijo 2 meses a NPN | E253: =+_xlfn.XLOOKUP(UTILIZADAS[[#This Row],[Numero_Cuenta]],'[1]cobros_marzo (fijo)'!$B:$B,'[1]cobros_marzo (fijo)'!$D:$D,,0) -> 0 | G253: 46026 | H253: 68981704 | I253: 68981704 | K253: maryerlingb@gmail.com | O253: 46026 | S253: 2-731-577 | T253: MASIVO | U253: NPN | V253: =_xlfn.XLOOKUP(UTILIZADAS[[#This Row],[Contacto1]],Tabla2[phone_number_dialed],Tabla2[status_name],,0) -> #N/A
A254: Cobros Abril Canal Fijo | B254: Mariela Atencio barria de Aparicio | C254: 354278250000 | D254: Cobros Abril Canal Fijo 2 meses a NPN | E254: =+_xlfn.XLOOKUP(UTILIZADAS[[#This Row],[Numero_Cuenta]],'[1]cobros_marzo (fijo)'!$B:$B,'[1]cobros_marzo (fijo)'!$D:$D,,0) -> 0 | G254: 46026 | H254: 61598243 | I254: 61598243 | K254: Lupiita33343@gmail.com | O254: 46026 | S254: 6-701-40 | T254: MASIVO | U254: NPN | V254: =_xlfn.XLOOKUP(UTILIZADAS[[#This Row],[Contacto1]],Tabla2[phone_number_dialed],Tabla2[status_name],,0) -> #N/A
A255: Cobros Abril Canal Fijo | B255: Mariela Atencio barria de Aparicio | C255: 354278250000 | D255: Cobros Abril Canal Fijo 2 meses a NPN | E255: =+_xlfn.XLOOKUP(UTILIZADAS[[#This Row],[Numero_Cuenta]],'[1]cobros_marzo (fijo)'!$B:$B,'[1]cobros_marzo (fijo)'!$D:$D,,0) -> 0 | G255: 46026 | H255: 61598243 | I255: 61598243 | K255: Lupiita33344@gmail.com | O255: 46026 | S255: 6-701-40 | T255: MASIVO | U255: NPN | V255: =_xlfn.XLOOKUP(UTILIZADAS[[#This Row],[Contacto1]],Tabla2[phone_number_dialed],Tabla2[status_name],,0) -> #N/A
...

Sheet Promesas se pago dinero
A1: Fecha | B1: Marca temporal | C1: Agente | D1: Numero celular | E1: Cuenta | F1: Identificación (cedula) | G1: Campaña | H1: Canal | I1: Escenario | J1: Motivo | K1: Fecha promesa de pago | L1: Monto de promesa de pago | M1: Realiza el pago | N1: Fecha de Pago | O1: Monto pagado | P1: Tiempo de mora (días) | Q1: Campaña | R1: Mes Pago | S1: Mes Promesa | T1: Dia Pago | U1: Dia Promesa | V1: Intentos de Promesas | W1: Intentos de pago
A2: =TEXT(promesas[[#This Row],[Marca temporal]],"dd/mmm") -> 00/ene | R2: =IF(promesas[[#This Row],[Fecha de Pago]]="", "", TEXT(promesas[[#This Row],[Fecha de Pago]], "mmm")) | S2: =IF(promesas[[#This Row],[Fecha promesa de pago]]="", "", TEXT(promesas[[#This Row],[Fecha promesa de pago]], "mmm")) | T2: =IF(promesas[[#This Row],[Fecha de Pago]]="", "", TEXT(promesas[[#This Row],[Fecha de Pago]], "dd/mmm")) | U2: =IF(promesas[[#This Row],[Fecha promesa de pago]]="", "", TEXT(promesas[[#This Row],[Fecha promesa de pago]], "dd/mmm")) | V2: =IF(LEN(TRIM(promesas[[#This Row],[Fecha promesa de pago]]))>0,1,"") | W2: =IF(LEN(TRIM(promesas[[#This Row],[Fecha de Pago]]))>0,1,"")
A3: =TEXT(promesas[[#This Row],[Marca temporal]],"dd/mmm") -> 00/ene | R3: =IF(promesas[[#This Row],[Fecha de Pago]]="", "", TEXT(promesas[[#This Row],[Fecha de Pago]], "mmm")) | S3: =IF(promesas[[#This Row],[Fecha promesa de pago]]="", "", TEXT(promesas[[#This Row],[Fecha promesa de pago]], "mmm")) | T3: =IF(promesas[[#This Row],[Fecha de Pago]]="", "", TEXT(promesas[[#This Row],[Fecha de Pago]], "dd/mmm")) | U3: =IF(promesas[[#This Row],[Fecha promesa de pago]]="", "", TEXT(promesas[[#This Row],[Fecha promesa de pago]], "dd/mmm")) | V3: =IF(LEN(TRIM(promesas[[#This Row],[Fecha promesa de pago]]))>0,1,"") | W3: =IF(LEN(TRIM(promesas[[#This Row],[Fecha de Pago]]))>0,1,"")
A4: =TEXT(promesas[[#This Row],[Marca temporal]],"dd/mmm") -> 00/ene | R4: =IF(promesas[[#This Row],[Fecha de Pago]]="", "", TEXT(promesas[[#This Row],[Fecha de Pago]], "mmm")) | S4: =IF(promesas[[#This Row],[Fecha promesa de pago]]="", "", TEXT(promesas[[#This Row],[Fecha promesa de pago]], "mmm")) | T4: =IF(promesas[[#This Row],[Fecha de Pago]]="", "", TEXT(promesas[[#This Row],[Fecha de Pago]], "dd/mmm")) | U4: =IF(promesas[[#This Row],[Fecha promesa de pago]]="", "", TEXT(promesas[[#This Row],[Fecha promesa de pago]], "dd/mmm")) | V4: =IF(LEN(TRIM(promesas[[#This Row],[Fecha promesa de pago]]))>0,1,"") | W4: =IF(LEN(TRIM(promesas[[#This Row],[Fecha de Pago]]))>0,1,"")
A5: =TEXT(promesas[[#This Row],[Marca temporal]],"dd/mmm") -> 00/ene | R5: =IF(promesas[[#This Row],[Fecha de Pago]]="", "", TEXT(promesas[[#This Row],[Fecha de Pago]], "mmm")) | S5: =IF(promesas[[#This Row],[Fecha promesa de pago]]="", "", TEXT(promesas[[#This Row],[Fecha promesa de pago]], "mmm")) | T5: =IF(promesas[[#This Row],[Fecha de Pago]]="", "", TEXT(promesas[[#This Row],[Fecha de Pago]], "dd/mmm")) | U5: =IF(promesas[[#This Row],[Fecha promesa de pago]]="", "", TEXT(promesas[[#This Row],[Fecha promesa de pago]], "dd/mmm")) | V5: =IF(LEN(TRIM(promesas[[#This Row],[Fecha promesa de pago]]))>0,1,"") | W5: =IF(LEN(TRIM(promesas[[#This Row],[Fecha de Pago]]))>0,1,"")
A6: =TEXT(promesas[[#This Row],[Marca temporal]],"dd/mmm") -> 00/ene | R6: =IF(promesas[[#This Row],[Fecha de Pago]]="", "", TEXT(promesas[[#This Row],[Fecha de Pago]], "mmm")) | S6: =IF(promesas[[#This Row],[Fecha promesa de pago]]="", "", TEXT(promesas[[#This Row],[Fecha promesa de pago]], "mmm")) | T6: =IF(promesas[[#This Row],[Fecha de Pago]]="", "", TEXT(promesas[[#This Row],[Fecha de Pago]], "dd/mmm")) | U6: =IF(promesas[[#This Row],[Fecha promesa de pago]]="", "", TEXT(promesas[[#This Row],[Fecha promesa de pago]], "dd/mmm")) | V6: =IF(LEN(TRIM(promesas[[#This Row],[Fecha promesa de pago]]))>0,1,"") | W6: =IF(LEN(TRIM(promesas[[#This Row],[Fecha de Pago]]))>0,1,"")
A7: =TEXT(promesas[[#This Row],[Marca temporal]],"dd/mmm") -> 00/ene | R7: =IF(promesas[[#This Row],[Fecha de Pago]]="", "", TEXT(promesas[[#This Row],[Fecha de Pago]], "mmm")) | S7: =IF(promesas[[#This Row],[Fecha promesa de pago]]="", "", TEXT(promesas[[#This Row],[Fecha promesa de pago]], "mmm")) | T7: =IF(promesas[[#This Row],[Fecha de Pago]]="", "", TEXT(promesas[[#This Row],[Fecha de Pago]], "dd/mmm")) | U7: =IF(promesas[[#This Row],[Fecha promesa de pago]]="", "", TEXT(promesas[[#This Row],[Fecha promesa de pago]], "dd/mmm")) | V7: =IF(LEN(TRIM(promesas[[#This Row],[Fecha promesa de pago]]))>0,1,"") | W7: =IF(LEN(TRIM(promesas[[#This Row],[Fecha de Pago]]))>0,1,"")
A8: =TEXT(promesas[[#This Row],[Marca temporal]],"dd/mmm") -> 00/ene | R8: =IF(promesas[[#This Row],[Fecha de Pago]]="", "", TEXT(promesas[[#This Row],[Fecha de Pago]], "mmm")) | S8: =IF(promesas[[#This Row],[Fecha promesa de pago]]="", "", TEXT(promesas[[#This Row],[Fecha promesa de pago]], "mmm")) | T8: =IF(promesas[[#This Row],[Fecha de Pago]]="", "", TEXT(promesas[[#This Row],[Fecha de Pago]], "dd/mmm")) | U8: =IF(promesas[[#This Row],[Fecha promesa de pago]]="", "", TEXT(promesas[[#This Row],[Fecha promesa de pago]], "dd/mmm")) | V8: =IF(LEN(TRIM(promesas[[#This Row],[Fecha promesa de pago]]))>0,1,"") | W8: =IF(LEN(TRIM(promesas[[#This Row],[Fecha de Pago]]))>0,1,"")
A9: =TEXT(promesas[[#This Row],[Marca temporal]],"dd/mmm") -> 00/ene | R9: =IF(promesas[[#This Row],[Fecha de Pago]]="", "", TEXT(promesas[[#This Row],[Fecha de Pago]], "mmm")) | S9: =IF(promesas[[#This Row],[Fecha promesa de pago]]="", "", TEXT(promesas[[#This Row],[Fecha promesa de pago]], "mmm")) | T9: =IF(promesas[[#This Row],[Fecha de Pago]]="", "", TEXT(promesas[[#This Row],[Fecha de Pago]], "dd/mmm")) | U9: =IF(promesas[[#This Row],[Fecha promesa de pago]]="", "", TEXT(promesas[[#This Row],[Fecha promesa de pago]], "dd/mmm")) | V9: =IF(LEN(TRIM(promesas[[#This Row],[Fecha promesa de pago]]))>0,1,"") | W9: =IF(LEN(TRIM(promesas[[#This Row],[Fecha de Pago]]))>0,1,"")
A10: =TEXT(promesas[[#This Row],[Marca temporal]],"dd/mmm") -> 00/ene | R10: =IF(promesas[[#This Row],[Fecha de Pago]]="", "", TEXT(promesas[[#This Row],[Fecha de Pago]], "mmm")) | S10: =IF(promesas[[#This Row],[Fecha promesa de pago]]="", "", TEXT(promesas[[#This Row],[Fecha promesa de pago]], "mmm")) | T10: =IF(promesas[[#This Row],[Fecha de Pago]]="", "", TEXT(promesas[[#This Row],[Fecha de Pago]], "dd/mmm")) | U10: =IF(promesas[[#This Row],[Fecha promesa de pago]]="", "", TEXT(promesas[[#This Row],[Fecha promesa de pago]], "dd/mmm")) | V10: =IF(LEN(TRIM(promesas[[#This Row],[Fecha promesa de pago]]))>0,1,"") | W10: =IF(LEN(TRIM(promesas[[#This Row],[Fecha de Pago]]))>0,1,"")
A11: =TEXT(promesas[[#This Row],[Marca temporal]],"dd/mmm") -> 00/ene | R11: =IF(promesas[[#This Row],[Fecha de Pago]]="", "", TEXT(promesas[[#This Row],[Fecha de Pago]], "mmm")) | S11: =IF(promesas[[#This Row],[Fecha promesa de pago]]="", "", TEXT(promesas[[#This Row],[Fecha promesa de pago]], "mmm")) | T11: =IF(promesas[[#This Row],[Fecha de Pago]]="", "", TEXT(promesas[[#This Row],[Fecha de Pago]], "dd/mmm")) | U11: =IF(promesas[[#This Row],[Fecha promesa de pago]]="", "", TEXT(promesas[[#This Row],[Fecha promesa de pago]], "dd/mmm")) | V11: =IF(LEN(TRIM(promesas[[#This Row],[Fecha promesa de pago]]))>0,1,"") | W11: =IF(LEN(TRIM(promesas[[#This Row],[Fecha de Pago]]))>0,1,"")
A12: =TEXT(promesas[[#This Row],[Marca temporal]],"dd/mmm") -> 00/ene | R12: =IF(promesas[[#This Row],[Fecha de Pago]]="", "", TEXT(promesas[[#This Row],[Fecha de Pago]], "mmm")) | S12: =IF(promesas[[#This Row],[Fecha promesa de pago]]="", "", TEXT(promesas[[#This Row],[Fecha promesa de pago]], "mmm")) | T12: =IF(promesas[[#This Row],[Fecha de Pago]]="", "", TEXT(promesas[[#This Row],[Fecha de Pago]], "dd/mmm")) | U12: =IF(promesas[[#This Row],[Fecha promesa de pago]]="", "", TEXT(promesas[[#This Row],[Fecha promesa de pago]], "dd/mmm")) | V12: =IF(LEN(TRIM(promesas[[#This Row],[Fecha promesa de pago]]))>0,1,"") | W12: =IF(LEN(TRIM(promesas[[#This Row],[Fecha de Pago]]))>0,1,"")
A13: =TEXT(promesas[[#This Row],[Marca temporal]],"dd/mmm") -> 00/ene | R13: =IF(promesas[[#This Row],[Fecha de Pago]]="", "", TEXT(promesas[[#This Row],[Fecha de Pago]], "mmm")) | S13: =IF(promesas[[#This Row],[Fecha promesa de pago]]="", "", TEXT(promesas[[#This Row],[Fecha promesa de pago]], "mmm")) | T13: =IF(promesas[[#This Row],[Fecha de Pago]]="", "", TEXT(promesas[[#This Row],[Fecha de Pago]], "dd/mmm")) | U13: =IF(promesas[[#This Row],[Fecha promesa de pago]]="", "", TEXT(promesas[[#This Row],[Fecha promesa de pago]], "dd/mmm")) | V13: =IF(LEN(TRIM(promesas[[#This Row],[Fecha promesa de pago]]))>0,1,"") | W13: =IF(LEN(TRIM(promesas[[#This Row],[Fecha de Pago]]))>0,1,"")
... A1425: =TEXT(promesas[[#This Row],[Marca temporal]],"dd/mmm") -> 00/ene | R1425: =IF(promesas[[#This Row],[Fecha de Pago]]="", "", TEXT(promesas[[#This Row],[Fecha de Pago]], "mmm")) | S1425: =IF(promesas[[#This Row],[Fecha promesa de pago]]="", "", TEXT(promesas[[#This Row],[Fecha promesa de pago]], "mmm")) | T1425: =IF(promesas[[#This Row],[Fecha de Pago]]="", "", TEXT(promesas[[#This Row],[Fecha de Pago]], "dd/mmm")) | U1425: =IF(promesas[[#This Row],[Fecha promesa de pago]]="", "", TEXT(promesas[[#This Row],[Fecha promesa de pago]], "dd/mmm")) | V1425: =IF(LEN(TRIM(promesas[[#This Row],[Fecha promesa de pago]]))>0,1,"") | W1425: =IF(LEN(TRIM(promesas[[#This Row],[Fecha de Pago]]))>0,1,"")
K1426: =SUBTOTAL(109,promesas[Fecha promesa de pago]) -> 0 | N1426: =SUBTOTAL(109,promesas[Fecha de Pago]) -> 0 | R1426: =+COUNTA(promesas[Mes Pago]) -> 1424 | V1426: =SUBTOTAL(109,promesas[Intentos de Promesas]) -> 0 | W1426: =SUBTOTAL(109,promesas[Intentos de pago]) -> 0

Sheet Vici
A1: Campaña | B1: Connect | C1: RPC | D1: Call Day | E1: Frecuencia | F1: Intentos | G1: Contar | H1: call_date | I1: phone_number_dialed | J1: status | K1: user | L1: full_name | M1: campaign_id | N1: vendor_lead_code | O1: source_id | P1: list_id | Q1: gmt_offset_now | R1: phone_code | S1: phone_number | T1: title | U1: first_name | V1: middle_initial | W1: last_name | X1: address1 | Y1: address2 | Z1: address3 | AA1: city | AB1: state | AC1: province | AD1: postal_code | AE1: country_code | AF1: gender | AG1: date_of_birth | AH1: alt_phone | AI1: email | AJ1: security_phrase | AK1: comments | AL1: length_in_sec | AM1: user_group | AN1: alt_dial | AO1: rank | AP1: owner | AQ1: lead_id | AR1: list_name | AS1: list_description | AT1: status_name
A2: =_xlfn.XLOOKUP(I2,UTILIZADAS[Contacto1],UTILIZADAS[Source.Name],,0) -> #N/A | B2: =VLOOKUP(J2,Ref!A:C,3,0) -> #N/A | C2: =VLOOKUP(J2,Ref!A:D,4,0) -> #N/A | D2: =TEXT(H2,"dd/mmm") -> 00/ene | E2: =+COUNTIF(I:I,I2) -> 0 | F2: 1 | G2: =IF(I2=I3,0,1) -> 0
A3: =_xlfn.XLOOKUP(I3,UTILIZADAS[Contacto1],UTILIZADAS[Source.Name],,0) -> #N/A | B3: =VLOOKUP(J3,Ref!A:C,3,0) -> #N/A | C3: =VLOOKUP(J3,Ref!A:D,4,0) -> #N/A | D3: =TEXT(H3,"dd/mmm") -> 00/ene | E3: =+COUNTIF(I:I,I3) -> 0 | F3: 1 | G3: =IF(I3=I4,0,1) -> 0
A4: =_xlfn.XLOOKUP(I4,UTILIZADAS[Contacto1],UTILIZADAS[Source.Name],,0) -> #N/A | B4: =VLOOKUP(J4,Ref!A:C,3,0) -> #N/A | C4: =VLOOKUP(J4,Ref!A:D,4,0) -> #N/A | D4: =TEXT(H4,"dd/mmm") -> 00/ene | E4: =+COUNTIF(I:I,I4) -> 0 | F4: 1 | G4: =IF(I4=I5,0,1) -> 0
A5: =_xlfn.XLOOKUP(I5,UTILIZADAS[Contacto1],UTILIZADAS[Source.Name],,0) -> #N/A | B5: =VLOOKUP(J5,Ref!A:C,3,0) -> #N/A | C5: =VLOOKUP(J5,Ref!A:D,4,0) -> #N/A | D5: =TEXT(H5,"dd/mmm") -> 00/ene | E5: =+COUNTIF(I:I,I5) -> 0 | F5: 1 | G5: =IF(I5=I6,0,1) -> 0
A6: =_xlfn.XLOOKUP(I6,UTILIZADAS[Contacto1],UTILIZADAS[Source.Name],,0) -> #N/A | B6: =VLOOKUP(J6,Ref!A:C,3,0) -> #N/A | C6: =VLOOKUP(J6,Ref!A:D,4,0) -> #N/A | D6: =TEXT(H6,"dd/mmm") -> 00/ene | E6: =+COUNTIF(I:I,I6) -> 0 | F6: 1 | G6: =IF(I6=I7,0,1) -> 0
A7: =_xlfn.XLOOKUP(I7,UTILIZADAS[Contacto1],UTILIZADAS[Source.Name],,0) -> #N/A | B7: =VLOOKUP(J7,Ref!A:C,3,0) -> #N/A | C7: =VLOOKUP(J7,Ref!A:D,4,0) -> #N/A | D7: =TEXT(H7,"dd/mmm") -> 00/ene | E7: =+COUNTIF(I:I,I7) -> 0 | F7: 1 | G7: =IF(I7=I8,0,1) -> 0
A8: =_xlfn.XLOOKUP(I8,UTILIZADAS[Contacto1],UTILIZADAS[Source.Name],,0) -> #N/A | B8: =VLOOKUP(J8,Ref!A:C,3,0) -> #N/A | C8: =VLOOKUP(J8,Ref!A:D,4,0) -> #N/A | D8: =TEXT(H8,"dd/mmm") -> 00/ene | E8: =+COUNTIF(I:I,I8) -> 0 | F8: 1 | G8: =IF(I8=I9,0,1) -> 0
A9: =_xlfn.XLOOKUP(I9,UTILIZADAS[Contacto1],UTILIZADAS[Source.Name],,0) -> #N/A | B9: =VLOOKUP(J9,Ref!A:C,3,0) -> #N/A | C9: =VLOOKUP(J9,Ref!A:D,4,0) -> #N/A | D9: =TEXT(H9,"dd/mmm") -> 00/ene | E9: =+COUNTIF(I:I,I9) -> 0 | F9: 1 | G9: =IF(I9=I10,0,1) -> 0
A10: =_xlfn.XLOOKUP(I10,UTILIZADAS[Contacto1],UTILIZADAS[Source.Name],,0) -> #N/A | B10: =VLOOKUP(J10,Ref!A:C,3,0) -> #N/A | C10: =VLOOKUP(J10,Ref!A:D,4,0) -> #N/A | D10: =TEXT(H10,"dd/mmm") -> 00/ene | E10: =+COUNTIF(I:I,I10) -> 0 | F10: 1 | G10: =IF(I10=I11,0,1) -> 0
A11: =_xlfn.XLOOKUP(I11,UTILIZADAS[Contacto1],UTILIZADAS[Source.Name],,0) -> #N/A | B11: =VLOOKUP(J11,Ref!A:C,3,0) -> #N/A | C11: =VLOOKUP(J11,Ref!A:D,4,0) -> #N/A | D11: =TEXT(H11,"dd/mmm") -> 00/ene | E11: =+COUNTIF(I:I,I11) -> 0 | F11: 1 | G11: =IF(I11=I12,0,1) -> 0
A12: =_xlfn.XLOOKUP(I12,UTILIZADAS[Contacto1],UTILIZADAS[Source.Name],,0) -> #N/A | B12: =VLOOKUP(J12,Ref!A:C,3,0) -> #N/A | C12: =VLOOKUP(J12,Ref!A:D,4,0) -> #N/A | D12: =TEXT(H12,"dd/mmm") -> 00/ene | E12: =+COUNTIF(I:I,I12) -> 0 | F12: 1 | G12: =IF(I12=I13,0,1) -> 0
A13: =_xlfn.XLOOKUP(I13,UTILIZADAS[Contacto1],UTILIZADAS[Source.Name],,0) -> #N/A | B13: =VLOOKUP(J13,Ref!A:C,3,0) -> #N/A | C13: =VLOOKUP(J13,Ref!A:D,4,0) -> #N/A | D13: =TEXT(H13,"dd/mmm") -> 00/ene | E13: =+COUNTIF(I:I,I13) -> 0 | F13: 1 | G13: =IF(I13=I14,0,1) -> 0
... A3376: =_xlfn.XLOOKUP(I3376,UTILIZADAS[Contacto1],UTILIZADAS[Source.Name],,0) -> #N/A | B3376: =VLOOKUP(J3376,Ref!A:C,3,0) -> #N/A | C3376: =VLOOKUP(J3376,Ref!A:D,4,0) -> #N/A | D3376: =TEXT(H3376,"dd/mmm") -> 00/ene | E3376: =+COUNTIF(I:I,I3376) -> 0 | F3376: 1 | G3376: =IF(I3376=I3377,0,1) -> 0
A3377: =_xlfn.XLOOKUP(I3377,UTILIZADAS[Contacto1],UTILIZADAS[Source.Name],,0) -> #N/A | B3377: =VLOOKUP(J3377,Ref!A:C,3,0) -> #N/A | C3377: =VLOOKUP(J3377,Ref!A:D,4,0) -> #N/A | D3377: =TEXT(H3377,"dd/mmm") -> 00/ene | E3377: =+COUNTIF(I:I,I3377) -> 0 | F3377: 1 | G3377: =IF(I3377=I6498,0,1) -> 0
A3378: =_xlfn.XLOOKUP(I3378,UTILIZADAS[Contacto1],UTILIZADAS[Source.Name],,0) -> #N/A | B3378: =VLOOKUP(J3378,Ref!A:C,3,0) -> #N/A | C3378: =VLOOKUP(J3378,Ref!A:D,4,0) -> #N/A | D3378: =TEXT(H3378,"dd/mmm") -> 00/ene | E3378: =+COUNTIF(I:I,I3378) -> 0 | F3378: 1 | G3378: =IF(I3378=I3379,0,1) -> 0
A3379: =_xlfn.XLOOKUP(I3379,UTILIZADAS[Contacto1],UTILIZADAS[Source.Name],,0) -> #N/A | B3379: =VLOOKUP(J3379,Ref!A:C,3,0) -> #N/A | C3379: =VLOOKUP(J3379,Ref!A:D,4,0) -> #N/A | D3379: =TEXT(H3379,"dd/mmm") -> 00/ene | E3379: =+COUNTIF(I:I,I3379) -> 0 | F3379: 1 | G3379: =IF(I3379=I3380,0,1) -> 0
A3380: =_xlfn.XLOOKUP(I3380,UTILIZADAS[Contacto1],UTILIZADAS[Source.Name],,0) -> #N/A | B3380: =VLOOKUP(J3380,Ref!A:C,3,0) -> #N/A | C3380: =VLOOKUP(J3380,Ref!A:D,4,0) -> #N/A | D3380: =TEXT(H3380,"dd/mmm") -> 00/ene | E3380: =+COUNTIF(I:I,I3380) -> 0 | F3380: 1 | G3380: =IF(I3380=I3381,0,1) -> 0
A3381: =_xlfn.XLOOKUP(I3381,UTILIZADAS[Contacto1],UTILIZADAS[Source.Name],,0) -> #N/A | B3381: =VLOOKUP(J3381,Ref!A:C,3,0) -> #N/A | C3381: =VLOOKUP(J3381,Ref!A:D,4,0) -> #N/A | D3381: =TEXT(H3381,"dd/mmm") -> 00/ene | E3381: =+COUNTIF(I:I,I3381) -> 0 | F3381: 1 | G3381: =IF(I3381=I3382,0,1) -> 0
A3382: =_xlfn.XLOOKUP(I3382,UTILIZADAS[Contacto1],UTILIZADAS[Source.Name],,0) -> #N/A | B3382: =VLOOKUP(J3382,Ref!A:C,3,0) -> #N/A | C3382: =VLOOKUP(J3382,Ref!A:D,4,0) -> #N/A | D3382: =TEXT(H3382,"dd/mmm") -> 00/ene | E3382: =+COUNTIF(I:I,I3382) -> 0 | F3382: 1 | G3382: =IF(I3382=I3383,0,1) -> 0
A3383: =_xlfn.XLOOKUP(I3383,UTILIZADAS[Contacto1],UTILIZADAS[Source.Name],,0) -> #N/A | B3383: =VLOOKUP(J3383,Ref!A:C,3,0) -> #N/A | C3383: =VLOOKUP(J3383,Ref!A:D,4,0) -> #N/A | D3383: =TEXT(H3383,"dd/mmm") -> 00/ene | E3383: =+COUNTIF(I:I,I3383) -> 0 | F3383: 1 | G3383: =IF(I3383=I3384,0,1) -> 0
A3384: =_xlfn.XLOOKUP(I3384,UTILIZADAS[Contacto1],UTILIZADAS[Source.Name],,0) -> #N/A | B3384: =VLOOKUP(J3384,Ref!A:C,3,0) -> #N/A | C3384: =VLOOKUP(J3384,Ref!A:D,4,0) -> #N/A | D3384: =TEXT(H3384,"dd/mmm") -> 00/ene | E3384: =+COUNTIF(I:I,I3384) -> 0 | F3384: 1 | G3384: =IF(I3384=I3385,0,1) -> 0
A3385: =_xlfn.XLOOKUP(I3385,UTILIZADAS[Contacto1],UTILIZADAS[Source.Name],,0) -> #N/A | B3385: =VLOOKUP(J3385,Ref!A:C,3,0) -> #N/A | C3385: =VLOOKUP(J3385,Ref!A:D,4,0) -> #N/A | D3385: =TEXT(H3385,"dd/mmm") -> 00/ene | E3385: =+COUNTIF(I:I,I3385) -> 0 | F3385: 1 | G3385: =IF(I3385=I3386,0,1) -> 0
A3386: =_xlfn.XLOOKUP(I3386,UTILIZADAS[Contacto1],UTILIZADAS[Source.Name],,0) -> #N/A | B3386: =VLOOKUP(J3386,Ref!A:C,3,0) -> #N/A | C3386: =VLOOKUP(J3386,Ref!A:D,4,0) -> #N/A | D3386: =TEXT(H3386,"dd/mmm") -> 00/ene | E3386: =+COUNTIF(I:I,I3386) -> 0 | F3386: 1 | G3386: =IF(I3386=I3387,0,1) -> 0
A3387: =_xlfn.XLOOKUP(I3387,UTILIZADAS[Contacto1],UTILIZADAS[Source.Name],,0) -> #N/A | B3387: =VLOOKUP(J3387,Ref!A:C,3,0) -> #N/A | C3387: =VLOOKUP(J3387,Ref!A:D,4,0) -> #N/A | D3387: =TEXT(H3387,"dd/mmm") -> 00/ene | E3387: =+COUNTIF(I:I,I3387) -> 0 | F3387: 1 | G3387: =IF(I3387=I3388,0,1) -> 0
A3388: =_xlfn.XLOOKUP(I3388,UTILIZADAS[Contacto1],UTILIZADAS[Source.Name],,0) -> #N/A | B3388: =VLOOKUP(J3388,Ref!A:C,3,0) -> #N/A | C3388: =VLOOKUP(J3388,Ref!A:D,4,0) -> #N/A | D3388: =TEXT(H3388,"dd/mmm") -> 00/ene | E3388: =+COUNTIF(I:I,I3388) -> 0 | F3388: 1 | G3388: =IF(I3388=I3389,0,1) -> 0
A3389: =_xlfn.XLOOKUP(I3389,UTILIZADAS[Contacto1],UTILIZADAS[Source.Name],,0) -> #N/A | B3389: =VLOOKUP(J3389,Ref!A:C,3,0) -> #N/A | C3389: =VLOOKUP(J3389,Ref!A:D,4,0) -> #N/A | D3389: =TEXT(H3389,"dd/mmm") -> 00/ene | E3389: =+COUNTIF(I:I,I3389) -> 0 | F3389: 1 | G3389: =IF(I3389=I3390,0,1) -> 0
... A4943: =_xlfn.XLOOKUP(I4943,UTILIZADAS[Contacto1],UTILIZADAS[Source.Name],,0) -> #N/A | B4943: =VLOOKUP(J4943,Ref!A:C,3,0) -> #N/A | C4943: =VLOOKUP(J4943,Ref!A:D,4,0) -> #N/A | D4943: =TEXT(H4943,"dd/mmm") -> 00/ene | E4943: =+COUNTIF(I:I,I4943) -> 0 | F4943: 1 | G4943: =IF(I4943=I4944,0,1) -> 0
A4944: =_xlfn.XLOOKUP(I4944,UTILIZADAS[Contacto1],UTILIZADAS[Source.Name],,0) -> #N/A | B4944: =VLOOKUP(J4944,Ref!A:C,3,0) -> #N/A | C4944: =VLOOKUP(J4944,Ref!A:D,4,0) -> #N/A | D4944: =TEXT(H4944,"dd/mmm") -> 00/ene | E4944: =+COUNTIF(I:I,I4944) -> 0 | F4944: 1 | G4944: =IF(I4944=I6498,0,1) -> 0
A4945: =_xlfn.XLOOKUP(I4945,UTILIZADAS[Contacto1],UTILIZADAS[Source.Name],,0) -> #N/A | B4945: =VLOOKUP(J4945,Ref!A:C,3,0) -> #N/A | C4945: =VLOOKUP(J4945,Ref!A:D,4,0) -> #N/A | D4945: =TEXT(H4945,"dd/mmm") -> 00/ene | E4945: =+COUNTIF(I:I,I4945) -> 0 | F4945: 1 | G4945: =IF(I4945=I4946,0,1) -> 0
A4946: =_xlfn.XLOOKUP(I4946,UTILIZADAS[Contacto1],UTILIZADAS[Source.Name],,0) -> #N/A | B4946: =VLOOKUP(J4946,Ref!A:C,3,0) -> #N/A | C4946: =VLOOKUP(J4946,Ref!A:D,4,0) -> #N/A | D4946: =TEXT(H4946,"dd/mmm") -> 00/ene | E4946: =+COUNTIF(I:I,I4946) -> 0 | F4946: 1 | G4946: =IF(I4946=I4947,0,1) -> 0
A4947: =_xlfn.XLOOKUP(I4947,UTILIZADAS[Contacto1],UTILIZADAS[Source.Name],,0) -> #N/A | B4947: =VLOOKUP(J4947,Ref!A:C,3,0) -> #N/A | C4947: =VLOOKUP(J4947,Ref!A:D,4,0) -> #N/A | D4947: =TEXT(H4947,"dd/mmm") -> 00/ene | E4947: =+COUNTIF(I:I,I4947) -> 0 | F4947: 1 | G4947: =IF(I4947=I4948,0,1) -> 0
A4948: =_xlfn.XLOOKUP(I4948,UTILIZADAS[Contacto1],UTILIZADAS[Source.Name],,0) -> #N/A | B4948: =VLOOKUP(J4948,Ref!A:C,3,0) -> #N/A | C4948: =VLOOKUP(J4948,Ref!A:D,4,0) -> #N/A | D4948: =TEXT(H4948,"dd/mmm") -> 00/ene | E4948: =+COUNTIF(I:I,I4948) -> 0 | F4948: 1 | G4948: =IF(I4948=I4949,0,1) -> 0
A4949: =_xlfn.XLOOKUP(I4949,UTILIZADAS[Contacto1],UTILIZADAS[Source.Name],,0) -> #N/A | B4949: =VLOOKUP(J4949,Ref!A:C,3,0) -> #N/A | C4949: =VLOOKUP(J4949,Ref!A:D,4,0) -> #N/A | D4949: =TEXT(H4949,"dd/mmm") -> 00/ene | E4949: =+COUNTIF(I:I,I4949) -> 0 | F4949: 1 | G4949: =IF(I4949=I4950,0,1) -> 0
A4950: =_xlfn.XLOOKUP(I4950,UTILIZADAS[Contacto1],UTILIZADAS[Source.Name],,0) -> #N/A | B4950: =VLOOKUP(J4950,Ref!A:C,3,0) -> #N/A | C4950: =VLOOKUP(J4950,Ref!A:D,4,0) -> #N/A | D4950: =TEXT(H4950,"dd/mmm") -> 00/ene | E4950: =+COUNTIF(I:I,I4950) -> 0 | F4950: 1 | G4950: =IF(I4950=I4951,0,1) -> 0
A4951: =_xlfn.XLOOKUP(I4951,UTILIZADAS[Contacto1],UTILIZADAS[Source.Name],,0) -> #N/A | B4951: =VLOOKUP(J4951,Ref!A:C,3,0) -> #N/A | C4951: =VLOOKUP(J4951,Ref!A:D,4,0) -> #N/A | D4951: =TEXT(H4951,"dd/mmm") -> 00/ene | E4951: =+COUNTIF(I:I,I4951) -> 0 | F4951: 1 | G4951: =IF(I4951=I4952,0,1) -> 0
A4952: =_xlfn.XLOOKUP(I4952,UTILIZADAS[Contacto1],UTILIZADAS[Source.Name],,0) -> #N/A | B4952: =VLOOKUP(J4952,Ref!A:C,3,0) -> #N/A | C4952: =VLOOKUP(J4952,Ref!A:D,4,0) -> #N/A | D4952: =TEXT(H4952,"dd/mmm") -> 00/ene | E4952: =+COUNTIF(I:I,I4952) -> 0 | F4952: 1 | G4952: =IF(I4952=I4953,0,1) -> 0
A4953: =_xlfn.XLOOKUP(I4953,UTILIZADAS[Contacto1],UTILIZADAS[Source.Name],,0) -> #N/A | B4953: =VLOOKUP(J4953,Ref!A:C,3,0) -> #N/A | C4953: =VLOOKUP(J4953,Ref!A:D,4,0) -> #N/A | D4953: =TEXT(H4953,"dd/mmm") -> 00/ene | E4953: =+COUNTIF(I:I,I4953) -> 0 | F4953: 1 | G4953: =IF(I4953=I4954,0,1) -> 0
A4954: =_xlfn.XLOOKUP(I4954,UTILIZADAS[Contacto1],UTILIZADAS[Source.Name],,0) -> #N/A | B4954: =VLOOKUP(J4954,Ref!A:C,3,0) -> #N/A | C4954: =VLOOKUP(J4954,Ref!A:D,4,0) -> #N/A | D4954: =TEXT(H4954,"dd/mmm") -> 00/ene | E4954: =+COUNTIF(I:I,I4954) -> 0 | F4954: 1 | G4954: =IF(I4954=I4955,0,1) -> 0
A4955: =_xlfn.XLOOKUP(I4955,UTILIZADAS[Contacto1],UTILIZADAS[Source.Name],,0) -> #N/A | B4955: =VLOOKUP(J4955,Ref!A:C,3,0) -> #N/A | C4955: =VLOOKUP(J4955,Ref!A:D,4,0) -> #N/A | D4955: =TEXT(H4955,"dd/mmm") -> 00/ene | E4955: =+COUNTIF(I:I,I4955) -> 0 | F4955: 1 | G4955: =IF(I4955=I4956,0,1) -> 0
...

Sheet Ref
A3: Cod | B3: Tipificaciones | C3: Connect | D3: RPC | E3: First Outcome | I3: List ID | J3: Base
A4: 6000 | B4: Mensaje a tercero | C4: 1 | D4: 0 | E4: Agente | I4: 998 | J4: Base Cobros Octubre
A5: 6001 | B5: No conoce el titular | C5: 1 | D5: 0 | E5: Agente | I5: 16000 | J5: Base Cobros Octubre
A6: 6002 | B6: Cliente al dia | C6: 1 | D6: 1 | E6: Agente | I6: 9014 | J6: Base Cobros Octubre
A7: 6003 | B7: Cuenta cesada | C7: 1 | D7: 1 | E7: Agente | I7: 3000 | J7: Base Cobros Octubre
A8: 6004 | B8: Correo de voz | C8: 0 | D8: 0 | E8: Agente | I8: 9018 | J8: Base Cobros Octubre
A9: 6005 | B9: Cliente ocupado | C9: 1 | D9: 1 | E9: Agente | I9: 1001 | J9: Base Cobros Octubre
A10: 6006 | B10: Numero equivocado | C10: 1 | D10: 0 | E10: Agente | I10: 1002 | J10: Base Cobros Octubre
A11: 6007 | B11: Volver a llamar | C11: 1 | D11: 1 | E11: Agente | I11: 9007 | J11: Base Cobros Octubre
A12: 6008 | B12: Cliente con lenguaje inapropiado | C12: 1 | D12: 1 | E12: Agente | I12: 8006 | J12: Base Cobros Octubre
A13: 6009 | B13: Incidente en herramienta | C13: 1 | D13: 1 | E13: Agente | I13: 6002 | J13: Base Cobros Octubre
A14: 6010 | B14: Menor de edad | C14: 1 | D14: 0 | E14: Agente | I14: 9010 | J14: Base Cobros Octubre
A15: 6011 | B15: Persona detenida | C15: 1 | D15: 1 | E15: Agente | I15: 4004 | J15: Base Cobros Octubre
A16: 6012 | B16: Promesa de pago | C16: 1 | D16: 1 | E16: Agente | I16: 6005 | J16: Base Cobros Octubre
A17: AB | B17: Auto busy | C17: 0 | D17: 0 | E17: Dialer | I17: 51122 | J17: Base Cobros Octubre
A18: B | B18: Ocupado | C18: 0 | D18: 0 | E18: Dialer | I18: 9020 | J18: Base Cobros Octubre
A19: DNC | B19: No volver a llamar | C19: 0 | D19: 0 | E19: Dialer | I19: 1000 | J19: Base Cobros Octubre
A20: DROP | B20: Agent no available | C20: 0 | D20: 0 | E20: Dialer | I20: 10001 | J20: Base Cobros Octubre
A21: ERI | B21: Agent Error | C21: 0 | D21: 0 | E21: Dialer | I21: 9023 | J21: Base Cobros Octubre
A22: NA | B22: No Answer AutoDial | C22: 0 | D22: 0 | E22: Dialer | I22: 9022 | J22: Base Cobros Octubre
A23: PU | B23: Call Picked up | C23: 0 | D23: 0 | E23: Dialer | I23: 7007 | J23: Base Cobros Octubre
A24: INCALL | B24: Lead Being Called | C24: 0 | D24: 0 | E24: Dialer | I24: 8008 | J24: Base Cobros Octubre
A25: CALLBK | B25: Call back | C25: 0 | D25: 0 | E25: Dialer | I25: 5003 | J25: Base Cobros Octubre
A26: PDROP | B26: Agent no available | C26: 0 | D26: 0 | E26: Dialer | I26: 8010 | J26: Base Cobros Octubre
I27: 9025 | J27: Base Cobros Octubre
I28: 9021 | J28: Base Cobros Octubre
I29: 9000 | J29: Base Cobros Octubre
I30: 8011 | J30: Base Cobros Octubre
I31: 9012 | J31: Base Cobros Octubre
I32: 9008 | J32: Base Cobros Octubre
I33: 14000 | J33: Base Cobros Octubre
I34: 13003 | J34: Base Cobros Octubre
I35: 3002 | J35: Base Cobros Octubre
I36: 9015 | J36: Base Cobros Octubre
I37: 9006 | J37: Base Cobros Octubre
I38: 8004 | J38: Base Cobros Octubre
... I61: 16007 | J61: Base Cobros Dic
