Workbook

Sheet Consolidado VICI+LIKE
A1: MES GESTION | B1: (All)
A2: NO EFECTIVO | B2: (All)
A3: Consolidado VICI + LIKE - Datos reales Julio/Agosto 2026 | B3: (All)
A4: No Cumple Condiciones | B4: (All)
A5: GESTION | B5: (All)
A7: Campana / Tipificacion | B7: Asignados | C7: GESTION | D7: Sin Gestion | E7: EFECTIVO | F7: RPC | G7: WPC | H7: NPC | I7: %RPC | J7: % WPC | K7: % NPC | L7: % EFEC | M7: Prom % CONV | N7: % CONTACTO | O7: % NO CIERRE | P7: % NO CUMPLE
A8: Base 2025 | B8: 4991 | C8: =E8+F8+G8+H8 | D8: =B8-C8 | E8: 49 | F8: 78 | G8: 64 | H8: 206 | I8: =IF(C8=0,0,F8/C8) | J8: =IF(C8=0,0,G8/C8) | K8: =IF(C8=0,0,H8/C8) | L8: =IF(C8=0,0,E8/C8) | M8: =IF(F8=0,0,E8/F8) | N8: =IF(B8=0,0,C8/B8) | O8: =IF(C8=0,0,(F8+G8+H8)/C8) | P8: =IF(B8=0,0,D8/B8)
A9: Jan-Feb 2026 | B9: 1140 | C9: =E9+F9+G9+H9 | D9: =B9-C9 | E9: 7 | F9: 11 | G9: 14 | H9: 47 | I9: =IF(C9=0,0,F9/C9) | J9: =IF(C9=0,0,G9/C9) | K9: =IF(C9=0,0,H9/C9) | L9: =IF(C9=0,0,E9/C9) | M9: =IF(F9=0,0,E9/F9) | N9: =IF(B9=0,0,C9/B9) | O9: =IF(C9=0,0,(F9+G9+H9)/C9) | P9: =IF(B9=0,0,D9/B9)
A10: Mar-Jun 2026 | B10: 3239 | C10: =E10+F10+G10+H10 | D10: =B10-C10 | E10: 16 | F10: 25 | G10: 36 | H10: 116 | I10: =IF(C10=0,0,F10/C10) | J10: =IF(C10=0,0,G10/C10) | K10: =IF(C10=0,0,H10/C10) | L10: =IF(C10=0,0,E10/C10) | M10: =IF(F10=0,0,E10/F10) | N10: =IF(B10=0,0,C10/B10) | O10: =IF(C10=0,0,(F10+G10+H10)/C10) | P10: =IF(B10=0,0,D10/B10)
A11: July 2026 | B11: 405 | C11: =E11+F11+G11+H11 | D11: =B11-C11 | E11: 159 | F11: 466 | G11: 861 | H11: 4325 | I11: =IF(C11=0,0,F11/C11) | J11: =IF(C11=0,0,G11/C11) | K11: =IF(C11=0,0,H11/C11) | L11: =IF(C11=0,0,E11/C11) | M11: =IF(F11=0,0,E11/F11) | N11: =IF(B11=0,0,C11/B11) | O11: =IF(C11=0,0,(F11+G11+H11)/C11) | P11: =IF(B11=0,0,D11/B11)
A12: Se envia propuesta | B12: 142 | C12: =E12+F12+G12+H12 | D12: =B12-C12 | E12: 142 | F12: 0 | G12: 0 | H12: 0 | I12: =IF(C12=0,0,F12/C12) | J12: =IF(C12=0,0,G12/C12) | K12: =IF(C12=0,0,H12/C12) | L12: =IF(C12=0,0,E12/C12) | M12: =IF(F12=0,0,E12/F12) | N12: =IF(B12=0,0,C12/B12) | O12: =IF(C12=0,0,(F12+G12+H12)/C12) | P12: =IF(B12=0,0,D12/B12)
A13: Ya Renovo | B13: 12 | C13: =E13+F13+G13+H13 | D13: =B13-C13 | E13: 12 | F13: 0 | G13: 0 | H13: 0 | I13: =IF(C13=0,0,F13/C13) | J13: =IF(C13=0,0,G13/C13) | K13: =IF(C13=0,0,H13/C13) | L13: =IF(C13=0,0,E13/C13) | M13: =IF(F13=0,0,E13/F13) | N13: =IF(B13=0,0,C13/B13) | O13: =IF(C13=0,0,(F13+G13+H13)/C13) | P13: =IF(B13=0,0,D13/B13)
A14: Renovara en tienda | B14: 2 | C14: =E14+F14+G14+H14 | D14: =B14-C14 | E14: 2 | F14: 0 | G14: 0 | H14: 0 | I14: =IF(C14=0,0,F14/C14) | J14: =IF(C14=0,0,G14/C14) | K14: =IF(C14=0,0,H14/C14) | L14: =IF(C14=0,0,E14/C14) | M14: =IF(F14=0,0,E14/F14) | N14: =IF(B14=0,0,C14/B14) | O14: =IF(C14=0,0,(F14+G14+H14)/C14) | P14: =IF(B14=0,0,D14/B14)
A15: Por Aprobacion | B15: 3 | C15: =E15+F15+G15+H15 | D15: =B15-C15 | E15: 3 | F15: 0 | G15: 0 | H15: 0 | I15: =IF(C15=0,0,F15/C15) | J15: =IF(C15=0,0,G15/C15) | K15: =IF(C15=0,0,H15/C15) | L15: =IF(C15=0,0,E15/C15) | M15: =IF(F15=0,0,E15/F15) | N15: =IF(B15=0,0,C15/B15) | O15: =IF(C15=0,0,(F15+G15+H15)/C15) | P15: =IF(B15=0,0,D15/B15)
A16: No Acepta | B16: 381 | C16: =E16+F16+G16+H16 | D16: =B16-C16 | E16: 0 | F16: 381 | G16: 0 | H16: 0 | I16: =IF(C16=0,0,F16/C16) | J16: =IF(C16=0,0,G16/C16) | K16: =IF(C16=0,0,H16/C16) | L16: =IF(C16=0,0,E16/C16) | M16: =IF(F16=0,0,E16/F16) | N16: =IF(B16=0,0,C16/B16) | O16: =IF(C16=0,0,(F16+G16+H16)/C16) | P16: =IF(B16=0,0,D16/B16)
A17: No volver a llamar | B17: 79 | C17: =E17+F17+G17+H17 | D17: =B17-C17 | E17: 0 | F17: 79 | G17: 0 | H17: 0 | I17: =IF(C17=0,0,F17/C17) | J17: =IF(C17=0,0,G17/C17) | K17: =IF(C17=0,0,H17/C17) | L17: =IF(C17=0,0,E17/C17) | M17: =IF(F17=0,0,E17/F17) | N17: =IF(B17=0,0,C17/B17) | O17: =IF(C17=0,0,(F17+G17+H17)/C17) | P17: =IF(B17=0,0,D17/B17)
A18: Rechaza oferta | B18: 2 | C18: =E18+F18+G18+H18 | D18: =B18-C18 | E18: 0 | F18: 2 | G18: 0 | H18: 0 | I18: =IF(C18=0,0,F18/C18) | J18: =IF(C18=0,0,G18/C18) | K18: =IF(C18=0,0,H18/C18) | L18: =IF(C18=0,0,E18/C18) | M18: =IF(F18=0,0,E18/F18) | N18: =IF(B18=0,0,C18/B18) | O18: =IF(C18=0,0,(F18+G18+H18)/C18) | P18: =IF(B18=0,0,D18/B18)
A19: No acepta tiempo cuotas | B19: 1 | C19: =E19+F19+G19+H19 | D19: =B19-C19 | E19: 0 | F19: 1 | G19: 0 | H19: 0 | I19: =IF(C19=0,0,F19/C19) | J19: =IF(C19=0,0,G19/C19) | K19: =IF(C19=0,0,H19/C19) | L19: =IF(C19=0,0,E19/C19) | M19: =IF(F19=0,0,E19/F19) | N19: =IF(B19=0,0,C19/B19) | O19: =IF(C19=0,0,(F19+G19+H19)/C19) | P19: =IF(B19=0,0,D19/B19)
... A58: October 2026 | B58: 680 | C58: =E58+F58+G58+H58 | D58: =B58-C58 | E58: 2 | F58: 4 | G58: 2 | H58: 7 | I58: =IF(C58=0,0,F58/C58) | J58: =IF(C58=0,0,G58/C58) | K58: =IF(C58=0,0,H58/C58) | L58: =IF(C58=0,0,E58/C58) | M58: =IF(F58=0,0,E58/F58) | N58: =IF(B58=0,0,C58/B58) | O58: =IF(C58=0,0,(F58+G58+H58)/C58) | P58: =IF(B58=0,0,D58/B58)
A59: Grand Total | B59: =B8+B9+B10+B11+B35+B57+B58 | C59: =C8+C9+C10+C11+C35+C57+C58 | D59: =D8+D9+D10+D11+D35+D57+D58 | E59: =E8+E9+E10+E11+E35+E57+E58 | F59: =F8+F9+F10+F11+F35+F57+F58 | G59: =G8+G9+G10+G11+G35+G57+G58 | H59: =H8+H9+H10+H11+H35+H57+H58 | I59: =IF(C59=0,0,F59/C59) | J59: =IF(C59=0,0,G59/C59) | K59: =IF(C59=0,0,H59/C59) | L59: =IF(C59=0,0,E59/C59) | M59: =IF(F59=0,0,E59/F59) | N59: =IF(B59=0,0,C59/B59) | O59: =IF(C59=0,0,(F59+G59+H59)/C59) | P59: =IF(B59=0,0,D59/B59)
A62: RECORRIDO POR CAMPAÑA - BASE SOHO RENOVACIONES
A63: Fuente: -Recorrido de base SOHO (1).xlsx + VICI
A65: Campana | B65: Base Cant | C65: No Asignados | D65: Asignados | E65: Recorrido | F65: % Recorrido | G65: Marcaciones | H65: Contacto | I65: % Contacto | J65: RPC | K65: % RPC
A66: Base 2025 | B66: 4991 | C66: 133 | D66: 4858 | E66: 322 | F66: =IF(D66=0,0,E66/D66) | G66: 683 | H66: 236 | I66: =IF(G66=0,0,H66/G66) | J66: 41 | K66: =IF(H66=0,0,J66/H66)
A67: Jan-Feb 2026 | B67: 1140 | C67: 23 | D67: 1117 | E67: 63 | F67: =IF(D67=0,0,E67/D67) | G67: 133 | H67: 38 | I67: =IF(G67=0,0,H67/G67) | J67: 8 | K67: =IF(H67=0,0,J67/H67)
A68: Mar-Jun 2026 | B68: 3239 | C68: 79 | D68: 3160 | E68: 151 | F68: =IF(D68=0,0,E68/D68) | G68: 275 | H68: 90 | I68: =IF(G68=0,0,H68/G68) | J68: 14 | K68: =IF(H68=0,0,J68/H68)
A69: July 2026 | B69: 405 | C69: 12 | D69: 393 | E69: 5811 | F69: =IF(D69=0,0,E69/D69) | G69: 1486 | H69: 466 | I69: =IF(G69=0,0,H69/G69) | J69: 0 | K69: =IF(H69=0,0,J69/H69)
A70: August 2026 | B70: 538 | C70: 31 | D70: 507 | E70: 5903 | F70: =IF(D70=0,0,E70/D70) | G70: 1425 | H70: 340 | I70: =IF(G70=0,0,H70/G70) | J70: 0 | K70: =IF(H70=0,0,J70/H70)
A71: Septembre 2026 | B71: 521 | C71: 14 | D71: 507 | E71: 21 | F71: =IF(D71=0,0,E71/D71) | G71: 36 | H71: 16 | I71: =IF(G71=0,0,H71/G71) | J71: 6 | K71: =IF(H71=0,0,J71/H71)
A72: October 2026 | B72: 680 | C72: 14 | D72: 666 | E72: 11 | F72: =IF(D72=0,0,E72/D72) | G72: 32 | H72: 18 | I72: =IF(G72=0,0,H72/G72) | J72: 5 | K72: =IF(H72=0,0,J72/H72)
A73: Total | B73: =SUM(B66:B72) | C73: =SUM(C66:C72) | D73: =SUM(D66:D72) | E73: =SUM(E66:E72) | F73: =IF(D73=0,0,E73/D73) | G73: =SUM(G66:G72) | H73: =SUM(H66:H72) | I73: =IF(G73=0,0,H73/G73) | J73: =SUM(J66:J72) | K73: =IF(H73=0,0,J73/H73)
A76: RECORRIDO BASES SOHO RENOVACIONES - JULIO Y AGOSTO
A77: Fuente: Recorrido de las bases Soho Renovaciones1.xlsx
A79: Ejecutivo | B79: Registros | C79: Campanas
A80: Massiel Toledo | B80: 815 | C80: Mar-Jun(553), Base2025(237), Jan-Feb(192), Jul(70)
A81: Allison Barrios | B81: 105 | C81: Mar-Jun, Base2025, Jan-Feb
A82: Miguel Avila | B82: 78 | C82: Mar-Jun, Base2025, Jan-Feb
A83: Sully Penalba | B83: 54 | C83: Mar-Jun, Base2025, Jan-Feb
A84: TOTAL RENOVACIONES | B84: 1052 | C84: Julio: 70 registros gestionados
A86: BASE MOVIL SIN FIJO - JULIO
...

Sheet Resumen Comparativo
A1: RESUMEN COMPARATIVO - ORIGINAL vs COMPLETO
A2: Links a hoja Consolidado VICI+LIKE
A4: Campana | B4: Orig Gestion | C4: Orig Efectivo | D4: Orig RPC | E4: Orig NPC | F4: VICI Gestion | G4: VICI Efectivo | H4: VICI RPC | I4: VICI NPC | J4: Diferencia Gestion
A5: July 2026 | B5: 17 | C5: 1 | D5: 1 | E5: 14 | F5: ='Consolidado VICI+LIKE'!C11 | G5: ='Consolidado VICI+LIKE'!E11 | H5: ='Consolidado VICI+LIKE'!F11 | I5: ='Consolidado VICI+LIKE'!H11 | J5: =F5-B5
A6: August 2026 | B6: 18 | C6: 0 | D6: 1 | E6: 12 | F6: ='Consolidado VICI+LIKE'!C35 | G6: ='Consolidado VICI+LIKE'!E35 | H6: ='Consolidado VICI+LIKE'!F35 | I6: ='Consolidado VICI+LIKE'!H35 | J6: =F6-B6
A8: OBSERVACION:
A9: Los datos originales solo tenian 17-18 gestionados.
A10: Links a Consolidado para datos reales de VICI.

Sheet Resumen VICI
A1: RESUMEN VICI - JULIO Y AGOSTO 2026
A2: Links a hoja Consolidado VICI+LIKE
A4: Tipificacion | B4: Categoria | C4: Julio | D4: Agosto | E4: Total
A5: No contesta | B5: NPC | C5: 2894 | D5: 2854 | E5: =C5+D5
A6: Cierra Llamada | B6: NPC | C6: 956 | D6: 852 | E6: =C6+D6
A7: Contestador Automatico | B7: NPC | C7: 335 | D7: 551 | E7: =C7+D7
A8: Seguimiento | B8: WPC | C8: 439 | D8: 332 | E8: =C8+D8
A9: No Acepta | B9: RPC | C9: 381 | D9: 227 | E9: =C9+D9
A10: Volver a llamar | B10: WPC | C10: 222 | D10: 270 | E10: =C10+D10
A11: No es el titular | B11: WPC | C11: 197 | D11: 329 | E11: =C11+D11
A12: Se envia propuesta | B12: Efectivo | C12: 142 | D12: 129 | E12: =C12+D12
A13: No volver a llamar | B13: RPC | C13: 79 | D13: 105 | E13: =C13+D13
A14: Cliente con deuda | B14: NPC | C14: 51 | D14: 46 | E14: =C14+D14
A15: Llamada no contesta | B15: NPC | C15: 3 | D15: 44 | E15: =C15+D15
A16: Auto busy | B16: NPC | C16: 15 | D16: 37 | E16: =C16+D16
... A36: Problemas tecnicos | B36: NPC | C36: 0 | D36: 1 | E36: =C36+D36
A37: TOTAL | C37: ='Consolidado VICI+LIKE'!C11 | D37: ='Consolidado VICI+LIKE'!C35 | E37: =C37+D37
A39: RESUMEN POR CATEGORIA
A40: Categoria | B40: Julio | C40: Agosto | D40: Total | E40: % Julio | F40: % Agosto
A41: Efectivo | B41: ='Consolidado VICI+LIKE'!E11 | C41: ='Consolidado VICI+LIKE'!E35 | D41: =B41+C41 | E41: =IF(B41=0,0,B41/5811) | F41: =IF(C41=0,0,C41/5903)
A42: RPC | B42: ='Consolidado VICI+LIKE'!F11 | C42: ='Consolidado VICI+LIKE'!F35 | D42: =B42+C42 | E42: =IF(B42=0,0,B42/5811) | F42: =IF(C42=0,0,C42/5903)
A43: WPC | B43: ='Consolidado VICI+LIKE'!G11 | C43: ='Consolidado VICI+LIKE'!G35 | D43: =B43+C43 | E43: =IF(B43=0,0,B43/5811) | F43: =IF(C43=0,0,C43/5903)
A44: NPC | B44: ='Consolidado VICI+LIKE'!H11 | C44: ='Consolidado VICI+LIKE'!H35 | D44: =B44+C44 | E44: =IF(B44=0,0,B44/5811) | F44: =IF(C44=0,0,C44/5903)

Sheet LIKE Ventas
A1: RESUMEN VENTAS LIKE - JULIO Y AGOSTO 2026
A2: Fuente: LIKE - JULIO Y AGOSTO.xlsx
A4: Metrica | B4: Julio 2026 | C4: Agosto 2026
A5: Total Ventas | B5: 3415 | C5: 1478
A7: POR CANAL
A8: RENOVACIONES (CC) | B8: 1206 | C8: 589
A9: SOHO | B9: 953 | C9: 402
A10: CALL CENTER P2P | B10: 759 | C10: 348
A11: DIGITAL | B11: 204 | C11: 64
A12: CALL CENTER SOHO RENO | B12: 197 | C12: 42
A13: FIJO | B13: 24 | C13: 9
A15: TOP 5 VENDEDORES JULIO
A16: ROSE MARY CEDENO | B16: 73
A17: DANNA CAROLINA SALAS | B17: 72
A18: MASSIEL TOLEDO | B18: 67
A19: ALEXANDER BETANCOURT | B19: 66
A20: ROLANDO RUIZ | B20: 58
A22: TOP 5 VENDEDORES AGOSTO
A23: ROSE MARY CEDENO | C23: 49
A24: YOSUANY MUNOZ | C24: 37
A25: ALMA DELGADO | C25: 35
A26: YULITZA HERNANDEZ | C26: 34
A27: ALESHKA AMBULO | C27: 29
